[2023-11-30T12:42:03.604+0200] {taskinstance.py:1159} INFO - Dependencies all met for dep_context=non-requeueable deps ti=<TaskInstance: weather_data_pipeline.check_api_Zhmerynka scheduled__2023-11-30T04:00:00+00:00 [queued]>
[2023-11-30T12:42:03.610+0200] {taskinstance.py:1159} INFO - Dependencies all met for dep_context=requeueable deps ti=<TaskInstance: weather_data_pipeline.check_api_Zhmerynka scheduled__2023-11-30T04:00:00+00:00 [queued]>
[2023-11-30T12:42:03.610+0200] {taskinstance.py:1361} INFO - Starting attempt 1 of 1
[2023-11-30T12:42:03.630+0200] {taskinstance.py:1382} INFO - Executing <Task(HttpSensor): check_api_Zhmerynka> on 2023-11-30 04:00:00+00:00
[2023-11-30T12:42:03.633+0200] {standard_task_runner.py:57} INFO - Started process 18687 to run task
[2023-11-30T12:42:03.638+0200] {standard_task_runner.py:84} INFO - Running: ['airflow', 'tasks', 'run', 'weather_data_pipeline', 'check_api_Zhmerynka', 'scheduled__2023-11-30T04:00:00+00:00', '--job-id', '41', '--raw', '--subdir', 'DAGS_FOLDER/weather_pipeline.py', '--cfg-path', '/tmp/tmpq0aj8gjx']
[2023-11-30T12:42:03.640+0200] {standard_task_runner.py:85} INFO - Job 41: Subtask check_api_Zhmerynka
[2023-11-30T12:42:03.685+0200] {task_command.py:416} INFO - Running <TaskInstance: weather_data_pipeline.check_api_Zhmerynka scheduled__2023-11-30T04:00:00+00:00 [running]> on host DESKTOP-VD1PANR.
[2023-11-30T12:42:03.826+0200] {taskinstance.py:1662} INFO - Exporting env vars: AIRFLOW_CTX_DAG_OWNER='airflow' AIRFLOW_CTX_DAG_ID='weather_data_pipeline' AIRFLOW_CTX_TASK_ID='check_api_Zhmerynka' AIRFLOW_CTX_EXECUTION_DATE='2023-11-30T04:00:00+00:00' AIRFLOW_CTX_TRY_NUMBER='1' AIRFLOW_CTX_DAG_RUN_ID='scheduled__2023-11-30T04:00:00+00:00'
[2023-11-30T12:42:03.827+0200] {http.py:130} INFO - Poking: data/3.0/onecall
[2023-11-30T12:42:03.835+0200] {taskinstance.py:1937} ERROR - Task failed with exception
Traceback (most recent call last):
  File "/home/seva/.local/lib/python3.10/site-packages/airflow/sensors/base.py", line 257, in execute
    raise e
  File "/home/seva/.local/lib/python3.10/site-packages/airflow/sensors/base.py", line 239, in execute
    poke_return = self.poke(context)
  File "/home/seva/.local/lib/python3.10/site-packages/airflow/providers/http/sensors/http.py", line 148, in poke
    raise exc
  File "/home/seva/.local/lib/python3.10/site-packages/airflow/providers/http/sensors/http.py", line 132, in poke
    response = hook.run(
  File "/home/seva/.local/lib/python3.10/site-packages/airflow/providers/http/hooks/http.py", line 145, in run
    session = self.get_conn(headers)
  File "/home/seva/.local/lib/python3.10/site-packages/airflow/providers/http/hooks/http.py", line 98, in get_conn
    conn = self.get_connection(self.http_conn_id)
  File "/home/seva/.local/lib/python3.10/site-packages/airflow/hooks/base.py", line 72, in get_connection
    conn = Connection.get_connection_from_secrets(conn_id)
  File "/home/seva/.local/lib/python3.10/site-packages/airflow/models/connection.py", line 477, in get_connection_from_secrets
    raise AirflowNotFoundException(f"The conn_id `{conn_id}` isn't defined")
airflow.exceptions.AirflowNotFoundException: The conn_id `openweathermap_conn` isn't defined
[2023-11-30T12:42:03.838+0200] {taskinstance.py:1400} INFO - Marking task as FAILED. dag_id=weather_data_pipeline, task_id=check_api_Zhmerynka, execution_date=20231130T040000, start_date=20231130T104203, end_date=20231130T104203
[2023-11-30T12:42:03.857+0200] {standard_task_runner.py:104} ERROR - Failed to execute job 41 for task check_api_Zhmerynka (The conn_id `openweathermap_conn` isn't defined; 18687)
[2023-11-30T12:42:03.900+0200] {local_task_job_runner.py:228} INFO - Task exited with return code 1
[2023-11-30T12:42:04.017+0200] {taskinstance.py:2778} INFO - 0 downstream tasks scheduled from follow-on schedule check
[2023-11-30T12:57:02.213+0200] {taskinstance.py:1159} INFO - Dependencies all met for dep_context=non-requeueable deps ti=<TaskInstance: weather_data_pipeline.check_api_Zhmerynka scheduled__2023-11-30T04:00:00+00:00 [queued]>
[2023-11-30T12:57:02.220+0200] {taskinstance.py:1159} INFO - Dependencies all met for dep_context=requeueable deps ti=<TaskInstance: weather_data_pipeline.check_api_Zhmerynka scheduled__2023-11-30T04:00:00+00:00 [queued]>
[2023-11-30T12:57:02.221+0200] {taskinstance.py:1361} INFO - Starting attempt 1 of 1
[2023-11-30T12:57:02.241+0200] {taskinstance.py:1382} INFO - Executing <Task(HttpSensor): check_api_Zhmerynka> on 2023-11-30 04:00:00+00:00
[2023-11-30T12:57:02.244+0200] {standard_task_runner.py:57} INFO - Started process 20508 to run task
[2023-11-30T12:57:02.248+0200] {standard_task_runner.py:84} INFO - Running: ['airflow', 'tasks', 'run', 'weather_data_pipeline', 'check_api_Zhmerynka', 'scheduled__2023-11-30T04:00:00+00:00', '--job-id', '108', '--raw', '--subdir', 'DAGS_FOLDER/weather_pipeline.py', '--cfg-path', '/tmp/tmp28m6t5ya']
[2023-11-30T12:57:02.250+0200] {standard_task_runner.py:85} INFO - Job 108: Subtask check_api_Zhmerynka
[2023-11-30T12:57:02.349+0200] {task_command.py:416} INFO - Running <TaskInstance: weather_data_pipeline.check_api_Zhmerynka scheduled__2023-11-30T04:00:00+00:00 [running]> on host DESKTOP-VD1PANR.
[2023-11-30T12:57:02.407+0200] {taskinstance.py:1662} INFO - Exporting env vars: AIRFLOW_CTX_DAG_OWNER='airflow' AIRFLOW_CTX_DAG_ID='weather_data_pipeline' AIRFLOW_CTX_TASK_ID='check_api_Zhmerynka' AIRFLOW_CTX_EXECUTION_DATE='2023-11-30T04:00:00+00:00' AIRFLOW_CTX_TRY_NUMBER='1' AIRFLOW_CTX_DAG_RUN_ID='scheduled__2023-11-30T04:00:00+00:00'
[2023-11-30T12:57:02.408+0200] {http.py:130} INFO - Poking: data/3.0/onecall
[2023-11-30T12:57:02.413+0200] {base.py:73} INFO - Using connection ID 'openweathermap_conn' for task execution.
[2023-11-30T12:57:02.500+0200] {http.py:178} ERROR - HTTP error: Unauthorized
[2023-11-30T12:57:02.501+0200] {http.py:179} ERROR - {"cod":401, "message": "Please note that using One Call 3.0 requires a separate subscription to the One Call by Call plan. Learn more here https://openweathermap.org/price. If you have a valid subscription to the One Call by Call plan, but still receive this error, then please see https://openweathermap.org/faq#error401 for more info."}
[2023-11-30T12:57:02.508+0200] {taskinstance.py:1937} ERROR - Task failed with exception
Traceback (most recent call last):
  File "/home/seva/.local/lib/python3.10/site-packages/airflow/providers/http/hooks/http.py", line 176, in check_response
    response.raise_for_status()
  File "/home/seva/.local/lib/python3.10/site-packages/requests/models.py", line 1021, in raise_for_status
    raise HTTPError(http_error_msg, response=self)
requests.exceptions.HTTPError: 401 Client Error: Unauthorized for url: http://api.openweathermap.org/data/3.0/onecall?appid=***&q=Zhmerynka

During handling of the above exception, another exception occurred:

Traceback (most recent call last):
  File "/home/seva/.local/lib/python3.10/site-packages/airflow/sensors/base.py", line 257, in execute
    raise e
  File "/home/seva/.local/lib/python3.10/site-packages/airflow/sensors/base.py", line 239, in execute
    poke_return = self.poke(context)
  File "/home/seva/.local/lib/python3.10/site-packages/airflow/providers/http/sensors/http.py", line 148, in poke
    raise exc
  File "/home/seva/.local/lib/python3.10/site-packages/airflow/providers/http/sensors/http.py", line 132, in poke
    response = hook.run(
  File "/home/seva/.local/lib/python3.10/site-packages/airflow/providers/http/hooks/http.py", line 166, in run
    return self.run_and_check(session, prepped_request, extra_options)
  File "/home/seva/.local/lib/python3.10/site-packages/airflow/providers/http/hooks/http.py", line 217, in run_and_check
    self.check_response(response)
  File "/home/seva/.local/lib/python3.10/site-packages/airflow/providers/http/hooks/http.py", line 180, in check_response
    raise AirflowException(str(response.status_code) + ":" + response.reason)
airflow.exceptions.AirflowException: 401:Unauthorized
[2023-11-30T12:57:02.511+0200] {taskinstance.py:1400} INFO - Marking task as FAILED. dag_id=weather_data_pipeline, task_id=check_api_Zhmerynka, execution_date=20231130T040000, start_date=20231130T105702, end_date=20231130T105702
[2023-11-30T12:57:02.539+0200] {standard_task_runner.py:104} ERROR - Failed to execute job 108 for task check_api_Zhmerynka (401:Unauthorized; 20508)
[2023-11-30T12:57:02.558+0200] {local_task_job_runner.py:228} INFO - Task exited with return code 1
[2023-11-30T12:57:02.655+0200] {taskinstance.py:2778} INFO - 0 downstream tasks scheduled from follow-on schedule check
[2023-11-30T13:15:29.628+0200] {taskinstance.py:1159} INFO - Dependencies all met for dep_context=non-requeueable deps ti=<TaskInstance: weather_data_pipeline.check_api_Zhmerynka scheduled__2023-11-30T04:00:00+00:00 [queued]>
[2023-11-30T13:15:29.636+0200] {taskinstance.py:1159} INFO - Dependencies all met for dep_context=requeueable deps ti=<TaskInstance: weather_data_pipeline.check_api_Zhmerynka scheduled__2023-11-30T04:00:00+00:00 [queued]>
[2023-11-30T13:15:29.637+0200] {taskinstance.py:1361} INFO - Starting attempt 1 of 1
[2023-11-30T13:15:29.656+0200] {taskinstance.py:1382} INFO - Executing <Task(HttpSensor): check_api_Zhmerynka> on 2023-11-30 04:00:00+00:00
[2023-11-30T13:15:29.658+0200] {standard_task_runner.py:57} INFO - Started process 22679 to run task
[2023-11-30T13:15:29.663+0200] {standard_task_runner.py:84} INFO - Running: ['airflow', 'tasks', 'run', 'weather_data_pipeline', 'check_api_Zhmerynka', 'scheduled__2023-11-30T04:00:00+00:00', '--job-id', '199', '--raw', '--subdir', 'DAGS_FOLDER/weather_pipeline.py', '--cfg-path', '/tmp/tmpdjuyfy_r']
[2023-11-30T13:15:29.665+0200] {standard_task_runner.py:85} INFO - Job 199: Subtask check_api_Zhmerynka
[2023-11-30T13:15:29.706+0200] {task_command.py:416} INFO - Running <TaskInstance: weather_data_pipeline.check_api_Zhmerynka scheduled__2023-11-30T04:00:00+00:00 [running]> on host DESKTOP-VD1PANR.
[2023-11-30T13:15:29.823+0200] {taskinstance.py:1662} INFO - Exporting env vars: AIRFLOW_CTX_DAG_OWNER='airflow' AIRFLOW_CTX_DAG_ID='weather_data_pipeline' AIRFLOW_CTX_TASK_ID='check_api_Zhmerynka' AIRFLOW_CTX_EXECUTION_DATE='2023-11-30T04:00:00+00:00' AIRFLOW_CTX_TRY_NUMBER='1' AIRFLOW_CTX_DAG_RUN_ID='scheduled__2023-11-30T04:00:00+00:00'
[2023-11-30T13:15:29.823+0200] {http.py:130} INFO - Poking: data/3.0/onecall
[2023-11-30T13:15:29.826+0200] {base.py:73} INFO - Using connection ID 'openweathermap_conn' for task execution.
[2023-11-30T13:15:29.913+0200] {http.py:178} ERROR - HTTP error: Unauthorized
[2023-11-30T13:15:29.914+0200] {http.py:179} ERROR - {"cod":401, "message": "Please note that using One Call 3.0 requires a separate subscription to the One Call by Call plan. Learn more here https://openweathermap.org/price. If you have a valid subscription to the One Call by Call plan, but still receive this error, then please see https://openweathermap.org/faq#error401 for more info."}
[2023-11-30T13:15:29.921+0200] {taskinstance.py:1937} ERROR - Task failed with exception
Traceback (most recent call last):
  File "/home/seva/.local/lib/python3.10/site-packages/airflow/providers/http/hooks/http.py", line 176, in check_response
    response.raise_for_status()
  File "/home/seva/.local/lib/python3.10/site-packages/requests/models.py", line 1021, in raise_for_status
    raise HTTPError(http_error_msg, response=self)
requests.exceptions.HTTPError: 401 Client Error: Unauthorized for url: http://api.openweathermap.org/data/3.0/onecall?appid=***&q=Zhmerynka

During handling of the above exception, another exception occurred:

Traceback (most recent call last):
  File "/home/seva/.local/lib/python3.10/site-packages/airflow/sensors/base.py", line 257, in execute
    raise e
  File "/home/seva/.local/lib/python3.10/site-packages/airflow/sensors/base.py", line 239, in execute
    poke_return = self.poke(context)
  File "/home/seva/.local/lib/python3.10/site-packages/airflow/providers/http/sensors/http.py", line 148, in poke
    raise exc
  File "/home/seva/.local/lib/python3.10/site-packages/airflow/providers/http/sensors/http.py", line 132, in poke
    response = hook.run(
  File "/home/seva/.local/lib/python3.10/site-packages/airflow/providers/http/hooks/http.py", line 166, in run
    return self.run_and_check(session, prepped_request, extra_options)
  File "/home/seva/.local/lib/python3.10/site-packages/airflow/providers/http/hooks/http.py", line 217, in run_and_check
    self.check_response(response)
  File "/home/seva/.local/lib/python3.10/site-packages/airflow/providers/http/hooks/http.py", line 180, in check_response
    raise AirflowException(str(response.status_code) + ":" + response.reason)
airflow.exceptions.AirflowException: 401:Unauthorized
[2023-11-30T13:15:29.924+0200] {taskinstance.py:1400} INFO - Marking task as FAILED. dag_id=weather_data_pipeline, task_id=check_api_Zhmerynka, execution_date=20231130T040000, start_date=20231130T111529, end_date=20231130T111529
[2023-11-30T13:15:29.948+0200] {standard_task_runner.py:104} ERROR - Failed to execute job 199 for task check_api_Zhmerynka (401:Unauthorized; 22679)
[2023-11-30T13:15:29.976+0200] {local_task_job_runner.py:228} INFO - Task exited with return code 1
[2023-11-30T13:15:30.041+0200] {taskinstance.py:2778} INFO - 0 downstream tasks scheduled from follow-on schedule check
[2023-11-30T13:25:19.594+0200] {taskinstance.py:1159} INFO - Dependencies all met for dep_context=non-requeueable deps ti=<TaskInstance: weather_data_pipeline.check_api_Zhmerynka scheduled__2023-11-30T04:00:00+00:00 [queued]>
[2023-11-30T13:25:19.605+0200] {taskinstance.py:1159} INFO - Dependencies all met for dep_context=requeueable deps ti=<TaskInstance: weather_data_pipeline.check_api_Zhmerynka scheduled__2023-11-30T04:00:00+00:00 [queued]>
[2023-11-30T13:25:19.605+0200] {taskinstance.py:1361} INFO - Starting attempt 1 of 1
[2023-11-30T13:25:19.627+0200] {taskinstance.py:1382} INFO - Executing <Task(HttpSensor): check_api_Zhmerynka> on 2023-11-30 04:00:00+00:00
[2023-11-30T13:25:19.630+0200] {standard_task_runner.py:57} INFO - Started process 23893 to run task
[2023-11-30T13:25:19.637+0200] {standard_task_runner.py:84} INFO - Running: ['airflow', 'tasks', 'run', 'weather_data_pipeline', 'check_api_Zhmerynka', 'scheduled__2023-11-30T04:00:00+00:00', '--job-id', '270', '--raw', '--subdir', 'DAGS_FOLDER/weather_pipeline.py', '--cfg-path', '/tmp/tmpl6qtuubi']
[2023-11-30T13:25:19.640+0200] {standard_task_runner.py:85} INFO - Job 270: Subtask check_api_Zhmerynka
[2023-11-30T13:25:19.687+0200] {task_command.py:416} INFO - Running <TaskInstance: weather_data_pipeline.check_api_Zhmerynka scheduled__2023-11-30T04:00:00+00:00 [running]> on host DESKTOP-VD1PANR.
[2023-11-30T13:25:19.869+0200] {taskinstance.py:1662} INFO - Exporting env vars: AIRFLOW_CTX_DAG_OWNER='airflow' AIRFLOW_CTX_DAG_ID='weather_data_pipeline' AIRFLOW_CTX_TASK_ID='check_api_Zhmerynka' AIRFLOW_CTX_EXECUTION_DATE='2023-11-30T04:00:00+00:00' AIRFLOW_CTX_TRY_NUMBER='1' AIRFLOW_CTX_DAG_RUN_ID='scheduled__2023-11-30T04:00:00+00:00'
[2023-11-30T13:25:19.871+0200] {http.py:130} INFO - Poking: data/3.0/onecall
[2023-11-30T13:25:19.881+0200] {base.py:73} INFO - Using connection ID 'openweathermap_conn' for task execution.
[2023-11-30T13:25:19.977+0200] {http.py:178} ERROR - HTTP error: Unauthorized
[2023-11-30T13:25:19.978+0200] {http.py:179} ERROR - {"cod":401, "message": "Please note that using One Call 3.0 requires a separate subscription to the One Call by Call plan. Learn more here https://openweathermap.org/price. If you have a valid subscription to the One Call by Call plan, but still receive this error, then please see https://openweathermap.org/faq#error401 for more info."}
[2023-11-30T13:25:19.987+0200] {taskinstance.py:1937} ERROR - Task failed with exception
Traceback (most recent call last):
  File "/home/seva/.local/lib/python3.10/site-packages/airflow/providers/http/hooks/http.py", line 176, in check_response
    response.raise_for_status()
  File "/home/seva/.local/lib/python3.10/site-packages/requests/models.py", line 1021, in raise_for_status
    raise HTTPError(http_error_msg, response=self)
requests.exceptions.HTTPError: 401 Client Error: Unauthorized for url: http://api.openweathermap.org/data/3.0/onecall?appid=***&q=Zhmerynka

During handling of the above exception, another exception occurred:

Traceback (most recent call last):
  File "/home/seva/.local/lib/python3.10/site-packages/airflow/sensors/base.py", line 257, in execute
    raise e
  File "/home/seva/.local/lib/python3.10/site-packages/airflow/sensors/base.py", line 239, in execute
    poke_return = self.poke(context)
  File "/home/seva/.local/lib/python3.10/site-packages/airflow/providers/http/sensors/http.py", line 148, in poke
    raise exc
  File "/home/seva/.local/lib/python3.10/site-packages/airflow/providers/http/sensors/http.py", line 132, in poke
    response = hook.run(
  File "/home/seva/.local/lib/python3.10/site-packages/airflow/providers/http/hooks/http.py", line 166, in run
    return self.run_and_check(session, prepped_request, extra_options)
  File "/home/seva/.local/lib/python3.10/site-packages/airflow/providers/http/hooks/http.py", line 217, in run_and_check
    self.check_response(response)
  File "/home/seva/.local/lib/python3.10/site-packages/airflow/providers/http/hooks/http.py", line 180, in check_response
    raise AirflowException(str(response.status_code) + ":" + response.reason)
airflow.exceptions.AirflowException: 401:Unauthorized
[2023-11-30T13:25:19.994+0200] {taskinstance.py:1400} INFO - Marking task as FAILED. dag_id=weather_data_pipeline, task_id=check_api_Zhmerynka, execution_date=20231130T040000, start_date=20231130T112519, end_date=20231130T112519
[2023-11-30T13:25:20.032+0200] {standard_task_runner.py:104} ERROR - Failed to execute job 270 for task check_api_Zhmerynka (401:Unauthorized; 23893)
[2023-11-30T13:25:20.062+0200] {local_task_job_runner.py:228} INFO - Task exited with return code 1
[2023-11-30T13:25:20.158+0200] {taskinstance.py:2778} INFO - 0 downstream tasks scheduled from follow-on schedule check
