[2023-11-30T12:41:04.733+0200] {taskinstance.py:1159} INFO - Dependencies all met for dep_context=non-requeueable deps ti=<TaskInstance: weather_data_pipeline.check_api_Lviv manual__2023-11-30T10:40:45.601629+00:00 [queued]>
[2023-11-30T12:41:04.741+0200] {taskinstance.py:1159} INFO - Dependencies all met for dep_context=requeueable deps ti=<TaskInstance: weather_data_pipeline.check_api_Lviv manual__2023-11-30T10:40:45.601629+00:00 [queued]>
[2023-11-30T12:41:04.741+0200] {taskinstance.py:1361} INFO - Starting attempt 1 of 1
[2023-11-30T12:41:04.760+0200] {taskinstance.py:1382} INFO - Executing <Task(HttpSensor): check_api_Lviv> on 2023-11-30 10:40:45.601629+00:00
[2023-11-30T12:41:04.763+0200] {standard_task_runner.py:57} INFO - Started process 18516 to run task
[2023-11-30T12:41:04.766+0200] {standard_task_runner.py:84} INFO - Running: ['airflow', 'tasks', 'run', 'weather_data_pipeline', 'check_api_Lviv', 'manual__2023-11-30T10:40:45.601629+00:00', '--job-id', '13', '--raw', '--subdir', 'DAGS_FOLDER/weather_pipeline.py', '--cfg-path', '/tmp/tmpgt61x4wt']
[2023-11-30T12:41:04.769+0200] {standard_task_runner.py:85} INFO - Job 13: Subtask check_api_Lviv
[2023-11-30T12:41:04.817+0200] {task_command.py:416} INFO - Running <TaskInstance: weather_data_pipeline.check_api_Lviv manual__2023-11-30T10:40:45.601629+00:00 [running]> on host DESKTOP-VD1PANR.
[2023-11-30T12:41:04.965+0200] {taskinstance.py:1662} INFO - Exporting env vars: AIRFLOW_CTX_DAG_OWNER='airflow' AIRFLOW_CTX_DAG_ID='weather_data_pipeline' AIRFLOW_CTX_TASK_ID='check_api_Lviv' AIRFLOW_CTX_EXECUTION_DATE='2023-11-30T10:40:45.601629+00:00' AIRFLOW_CTX_TRY_NUMBER='1' AIRFLOW_CTX_DAG_RUN_ID='manual__2023-11-30T10:40:45.601629+00:00'
[2023-11-30T12:41:04.966+0200] {http.py:130} INFO - Poking: data/3.0/onecall
[2023-11-30T12:41:04.975+0200] {taskinstance.py:1937} ERROR - Task failed with exception
Traceback (most recent call last):
  File "/home/seva/.local/lib/python3.10/site-packages/airflow/sensors/base.py", line 257, in execute
    raise e
  File "/home/seva/.local/lib/python3.10/site-packages/airflow/sensors/base.py", line 239, in execute
    poke_return = self.poke(context)
  File "/home/seva/.local/lib/python3.10/site-packages/airflow/providers/http/sensors/http.py", line 148, in poke
    raise exc
  File "/home/seva/.local/lib/python3.10/site-packages/airflow/providers/http/sensors/http.py", line 132, in poke
    response = hook.run(
  File "/home/seva/.local/lib/python3.10/site-packages/airflow/providers/http/hooks/http.py", line 145, in run
    session = self.get_conn(headers)
  File "/home/seva/.local/lib/python3.10/site-packages/airflow/providers/http/hooks/http.py", line 98, in get_conn
    conn = self.get_connection(self.http_conn_id)
  File "/home/seva/.local/lib/python3.10/site-packages/airflow/hooks/base.py", line 72, in get_connection
    conn = Connection.get_connection_from_secrets(conn_id)
  File "/home/seva/.local/lib/python3.10/site-packages/airflow/models/connection.py", line 477, in get_connection_from_secrets
    raise AirflowNotFoundException(f"The conn_id `{conn_id}` isn't defined")
airflow.exceptions.AirflowNotFoundException: The conn_id `openweathermap_conn` isn't defined
[2023-11-30T12:41:04.979+0200] {taskinstance.py:1400} INFO - Marking task as FAILED. dag_id=weather_data_pipeline, task_id=check_api_Lviv, execution_date=20231130T104045, start_date=20231130T104104, end_date=20231130T104104
[2023-11-30T12:41:04.998+0200] {standard_task_runner.py:104} ERROR - Failed to execute job 13 for task check_api_Lviv (The conn_id `openweathermap_conn` isn't defined; 18516)
[2023-11-30T12:41:05.031+0200] {local_task_job_runner.py:228} INFO - Task exited with return code 1
[2023-11-30T12:41:05.120+0200] {taskinstance.py:2778} INFO - 0 downstream tasks scheduled from follow-on schedule check
