[2023-11-30T12:41:47.335+0200] {taskinstance.py:1159} INFO - Dependencies all met for dep_context=non-requeueable deps ti=<TaskInstance: weather_data_pipeline.check_api_Kharkiv scheduled__2023-11-30T03:00:00+00:00 [queued]>
[2023-11-30T12:41:47.341+0200] {taskinstance.py:1159} INFO - Dependencies all met for dep_context=requeueable deps ti=<TaskInstance: weather_data_pipeline.check_api_Kharkiv scheduled__2023-11-30T03:00:00+00:00 [queued]>
[2023-11-30T12:41:47.341+0200] {taskinstance.py:1361} INFO - Starting attempt 1 of 1
[2023-11-30T12:41:47.367+0200] {taskinstance.py:1382} INFO - Executing <Task(HttpSensor): check_api_Kharkiv> on 2023-11-30 03:00:00+00:00
[2023-11-30T12:41:47.369+0200] {standard_task_runner.py:57} INFO - Started process 18638 to run task
[2023-11-30T12:41:47.373+0200] {standard_task_runner.py:84} INFO - Running: ['airflow', 'tasks', 'run', 'weather_data_pipeline', 'check_api_Kharkiv', 'scheduled__2023-11-30T03:00:00+00:00', '--job-id', '33', '--raw', '--subdir', 'DAGS_FOLDER/weather_pipeline.py', '--cfg-path', '/tmp/tmpcisfo44f']
[2023-11-30T12:41:47.375+0200] {standard_task_runner.py:85} INFO - Job 33: Subtask check_api_Kharkiv
[2023-11-30T12:41:47.419+0200] {task_command.py:416} INFO - Running <TaskInstance: weather_data_pipeline.check_api_Kharkiv scheduled__2023-11-30T03:00:00+00:00 [running]> on host DESKTOP-VD1PANR.
[2023-11-30T12:41:47.543+0200] {taskinstance.py:1662} INFO - Exporting env vars: AIRFLOW_CTX_DAG_OWNER='airflow' AIRFLOW_CTX_DAG_ID='weather_data_pipeline' AIRFLOW_CTX_TASK_ID='check_api_Kharkiv' AIRFLOW_CTX_EXECUTION_DATE='2023-11-30T03:00:00+00:00' AIRFLOW_CTX_TRY_NUMBER='1' AIRFLOW_CTX_DAG_RUN_ID='scheduled__2023-11-30T03:00:00+00:00'
[2023-11-30T12:41:47.544+0200] {http.py:130} INFO - Poking: data/3.0/onecall
[2023-11-30T12:41:47.551+0200] {taskinstance.py:1937} ERROR - Task failed with exception
Traceback (most recent call last):
  File "/home/seva/.local/lib/python3.10/site-packages/airflow/sensors/base.py", line 257, in execute
    raise e
  File "/home/seva/.local/lib/python3.10/site-packages/airflow/sensors/base.py", line 239, in execute
    poke_return = self.poke(context)
  File "/home/seva/.local/lib/python3.10/site-packages/airflow/providers/http/sensors/http.py", line 148, in poke
    raise exc
  File "/home/seva/.local/lib/python3.10/site-packages/airflow/providers/http/sensors/http.py", line 132, in poke
    response = hook.run(
  File "/home/seva/.local/lib/python3.10/site-packages/airflow/providers/http/hooks/http.py", line 145, in run
    session = self.get_conn(headers)
  File "/home/seva/.local/lib/python3.10/site-packages/airflow/providers/http/hooks/http.py", line 98, in get_conn
    conn = self.get_connection(self.http_conn_id)
  File "/home/seva/.local/lib/python3.10/site-packages/airflow/hooks/base.py", line 72, in get_connection
    conn = Connection.get_connection_from_secrets(conn_id)
  File "/home/seva/.local/lib/python3.10/site-packages/airflow/models/connection.py", line 477, in get_connection_from_secrets
    raise AirflowNotFoundException(f"The conn_id `{conn_id}` isn't defined")
airflow.exceptions.AirflowNotFoundException: The conn_id `openweathermap_conn` isn't defined
[2023-11-30T12:41:47.553+0200] {taskinstance.py:1400} INFO - Marking task as FAILED. dag_id=weather_data_pipeline, task_id=check_api_Kharkiv, execution_date=20231130T030000, start_date=20231130T104147, end_date=20231130T104147
[2023-11-30T12:41:47.569+0200] {standard_task_runner.py:104} ERROR - Failed to execute job 33 for task check_api_Kharkiv (The conn_id `openweathermap_conn` isn't defined; 18638)
[2023-11-30T12:41:47.600+0200] {local_task_job_runner.py:228} INFO - Task exited with return code 1
[2023-11-30T12:41:47.699+0200] {taskinstance.py:2778} INFO - 0 downstream tasks scheduled from follow-on schedule check
[2023-11-30T12:56:47.987+0200] {taskinstance.py:1159} INFO - Dependencies all met for dep_context=non-requeueable deps ti=<TaskInstance: weather_data_pipeline.check_api_Kharkiv scheduled__2023-11-30T03:00:00+00:00 [queued]>
[2023-11-30T12:56:47.996+0200] {taskinstance.py:1159} INFO - Dependencies all met for dep_context=requeueable deps ti=<TaskInstance: weather_data_pipeline.check_api_Kharkiv scheduled__2023-11-30T03:00:00+00:00 [queued]>
[2023-11-30T12:56:47.997+0200] {taskinstance.py:1361} INFO - Starting attempt 1 of 1
[2023-11-30T12:56:48.018+0200] {taskinstance.py:1382} INFO - Executing <Task(HttpSensor): check_api_Kharkiv> on 2023-11-30 03:00:00+00:00
[2023-11-30T12:56:48.020+0200] {standard_task_runner.py:57} INFO - Started process 20467 to run task
[2023-11-30T12:56:48.024+0200] {standard_task_runner.py:84} INFO - Running: ['airflow', 'tasks', 'run', 'weather_data_pipeline', 'check_api_Kharkiv', 'scheduled__2023-11-30T03:00:00+00:00', '--job-id', '100', '--raw', '--subdir', 'DAGS_FOLDER/weather_pipeline.py', '--cfg-path', '/tmp/tmp4s0us5p8']
[2023-11-30T12:56:48.026+0200] {standard_task_runner.py:85} INFO - Job 100: Subtask check_api_Kharkiv
[2023-11-30T12:56:48.067+0200] {task_command.py:416} INFO - Running <TaskInstance: weather_data_pipeline.check_api_Kharkiv scheduled__2023-11-30T03:00:00+00:00 [running]> on host DESKTOP-VD1PANR.
[2023-11-30T12:56:48.178+0200] {taskinstance.py:1662} INFO - Exporting env vars: AIRFLOW_CTX_DAG_OWNER='airflow' AIRFLOW_CTX_DAG_ID='weather_data_pipeline' AIRFLOW_CTX_TASK_ID='check_api_Kharkiv' AIRFLOW_CTX_EXECUTION_DATE='2023-11-30T03:00:00+00:00' AIRFLOW_CTX_TRY_NUMBER='1' AIRFLOW_CTX_DAG_RUN_ID='scheduled__2023-11-30T03:00:00+00:00'
[2023-11-30T12:56:48.179+0200] {http.py:130} INFO - Poking: data/3.0/onecall
[2023-11-30T12:56:48.182+0200] {base.py:73} INFO - Using connection ID 'openweathermap_conn' for task execution.
[2023-11-30T12:56:48.271+0200] {http.py:178} ERROR - HTTP error: Unauthorized
[2023-11-30T12:56:48.272+0200] {http.py:179} ERROR - {"cod":401, "message": "Please note that using One Call 3.0 requires a separate subscription to the One Call by Call plan. Learn more here https://openweathermap.org/price. If you have a valid subscription to the One Call by Call plan, but still receive this error, then please see https://openweathermap.org/faq#error401 for more info."}
[2023-11-30T12:56:48.276+0200] {taskinstance.py:1937} ERROR - Task failed with exception
Traceback (most recent call last):
  File "/home/seva/.local/lib/python3.10/site-packages/airflow/providers/http/hooks/http.py", line 176, in check_response
    response.raise_for_status()
  File "/home/seva/.local/lib/python3.10/site-packages/requests/models.py", line 1021, in raise_for_status
    raise HTTPError(http_error_msg, response=self)
requests.exceptions.HTTPError: 401 Client Error: Unauthorized for url: http://api.openweathermap.org/data/3.0/onecall?appid=***&q=Kharkiv

During handling of the above exception, another exception occurred:

Traceback (most recent call last):
  File "/home/seva/.local/lib/python3.10/site-packages/airflow/sensors/base.py", line 257, in execute
    raise e
  File "/home/seva/.local/lib/python3.10/site-packages/airflow/sensors/base.py", line 239, in execute
    poke_return = self.poke(context)
  File "/home/seva/.local/lib/python3.10/site-packages/airflow/providers/http/sensors/http.py", line 148, in poke
    raise exc
  File "/home/seva/.local/lib/python3.10/site-packages/airflow/providers/http/sensors/http.py", line 132, in poke
    response = hook.run(
  File "/home/seva/.local/lib/python3.10/site-packages/airflow/providers/http/hooks/http.py", line 166, in run
    return self.run_and_check(session, prepped_request, extra_options)
  File "/home/seva/.local/lib/python3.10/site-packages/airflow/providers/http/hooks/http.py", line 217, in run_and_check
    self.check_response(response)
  File "/home/seva/.local/lib/python3.10/site-packages/airflow/providers/http/hooks/http.py", line 180, in check_response
    raise AirflowException(str(response.status_code) + ":" + response.reason)
airflow.exceptions.AirflowException: 401:Unauthorized
[2023-11-30T12:56:48.279+0200] {taskinstance.py:1400} INFO - Marking task as FAILED. dag_id=weather_data_pipeline, task_id=check_api_Kharkiv, execution_date=20231130T030000, start_date=20231130T105647, end_date=20231130T105648
[2023-11-30T12:56:48.297+0200] {standard_task_runner.py:104} ERROR - Failed to execute job 100 for task check_api_Kharkiv (401:Unauthorized; 20467)
[2023-11-30T12:56:48.338+0200] {local_task_job_runner.py:228} INFO - Task exited with return code 1
[2023-11-30T12:56:48.408+0200] {taskinstance.py:2778} INFO - 0 downstream tasks scheduled from follow-on schedule check
[2023-11-30T13:15:13.765+0200] {taskinstance.py:1159} INFO - Dependencies all met for dep_context=non-requeueable deps ti=<TaskInstance: weather_data_pipeline.check_api_Kharkiv scheduled__2023-11-30T03:00:00+00:00 [queued]>
[2023-11-30T13:15:13.773+0200] {taskinstance.py:1159} INFO - Dependencies all met for dep_context=requeueable deps ti=<TaskInstance: weather_data_pipeline.check_api_Kharkiv scheduled__2023-11-30T03:00:00+00:00 [queued]>
[2023-11-30T13:15:13.773+0200] {taskinstance.py:1361} INFO - Starting attempt 1 of 1
[2023-11-30T13:15:13.795+0200] {taskinstance.py:1382} INFO - Executing <Task(HttpSensor): check_api_Kharkiv> on 2023-11-30 03:00:00+00:00
[2023-11-30T13:15:13.798+0200] {standard_task_runner.py:57} INFO - Started process 22638 to run task
[2023-11-30T13:15:13.803+0200] {standard_task_runner.py:84} INFO - Running: ['airflow', 'tasks', 'run', 'weather_data_pipeline', 'check_api_Kharkiv', 'scheduled__2023-11-30T03:00:00+00:00', '--job-id', '191', '--raw', '--subdir', 'DAGS_FOLDER/weather_pipeline.py', '--cfg-path', '/tmp/tmpg2kop66z']
[2023-11-30T13:15:13.804+0200] {standard_task_runner.py:85} INFO - Job 191: Subtask check_api_Kharkiv
[2023-11-30T13:15:13.848+0200] {task_command.py:416} INFO - Running <TaskInstance: weather_data_pipeline.check_api_Kharkiv scheduled__2023-11-30T03:00:00+00:00 [running]> on host DESKTOP-VD1PANR.
[2023-11-30T13:15:13.988+0200] {taskinstance.py:1662} INFO - Exporting env vars: AIRFLOW_CTX_DAG_OWNER='airflow' AIRFLOW_CTX_DAG_ID='weather_data_pipeline' AIRFLOW_CTX_TASK_ID='check_api_Kharkiv' AIRFLOW_CTX_EXECUTION_DATE='2023-11-30T03:00:00+00:00' AIRFLOW_CTX_TRY_NUMBER='1' AIRFLOW_CTX_DAG_RUN_ID='scheduled__2023-11-30T03:00:00+00:00'
[2023-11-30T13:15:13.989+0200] {http.py:130} INFO - Poking: data/3.0/onecall
[2023-11-30T13:15:13.994+0200] {base.py:73} INFO - Using connection ID 'openweathermap_conn' for task execution.
[2023-11-30T13:15:14.067+0200] {http.py:178} ERROR - HTTP error: Unauthorized
[2023-11-30T13:15:14.068+0200] {http.py:179} ERROR - {"cod":401, "message": "Please note that using One Call 3.0 requires a separate subscription to the One Call by Call plan. Learn more here https://openweathermap.org/price. If you have a valid subscription to the One Call by Call plan, but still receive this error, then please see https://openweathermap.org/faq#error401 for more info."}
[2023-11-30T13:15:14.073+0200] {taskinstance.py:1937} ERROR - Task failed with exception
Traceback (most recent call last):
  File "/home/seva/.local/lib/python3.10/site-packages/airflow/providers/http/hooks/http.py", line 176, in check_response
    response.raise_for_status()
  File "/home/seva/.local/lib/python3.10/site-packages/requests/models.py", line 1021, in raise_for_status
    raise HTTPError(http_error_msg, response=self)
requests.exceptions.HTTPError: 401 Client Error: Unauthorized for url: http://api.openweathermap.org/data/3.0/onecall?appid=***&q=Kharkiv

During handling of the above exception, another exception occurred:

Traceback (most recent call last):
  File "/home/seva/.local/lib/python3.10/site-packages/airflow/sensors/base.py", line 257, in execute
    raise e
  File "/home/seva/.local/lib/python3.10/site-packages/airflow/sensors/base.py", line 239, in execute
    poke_return = self.poke(context)
  File "/home/seva/.local/lib/python3.10/site-packages/airflow/providers/http/sensors/http.py", line 148, in poke
    raise exc
  File "/home/seva/.local/lib/python3.10/site-packages/airflow/providers/http/sensors/http.py", line 132, in poke
    response = hook.run(
  File "/home/seva/.local/lib/python3.10/site-packages/airflow/providers/http/hooks/http.py", line 166, in run
    return self.run_and_check(session, prepped_request, extra_options)
  File "/home/seva/.local/lib/python3.10/site-packages/airflow/providers/http/hooks/http.py", line 217, in run_and_check
    self.check_response(response)
  File "/home/seva/.local/lib/python3.10/site-packages/airflow/providers/http/hooks/http.py", line 180, in check_response
    raise AirflowException(str(response.status_code) + ":" + response.reason)
airflow.exceptions.AirflowException: 401:Unauthorized
[2023-11-30T13:15:14.075+0200] {taskinstance.py:1400} INFO - Marking task as FAILED. dag_id=weather_data_pipeline, task_id=check_api_Kharkiv, execution_date=20231130T030000, start_date=20231130T111513, end_date=20231130T111514
[2023-11-30T13:15:14.096+0200] {standard_task_runner.py:104} ERROR - Failed to execute job 191 for task check_api_Kharkiv (401:Unauthorized; 22638)
[2023-11-30T13:15:14.109+0200] {local_task_job_runner.py:228} INFO - Task exited with return code 1
[2023-11-30T13:15:14.211+0200] {taskinstance.py:2778} INFO - 0 downstream tasks scheduled from follow-on schedule check
[2023-11-30T13:25:03.743+0200] {taskinstance.py:1159} INFO - Dependencies all met for dep_context=non-requeueable deps ti=<TaskInstance: weather_data_pipeline.check_api_Kharkiv scheduled__2023-11-30T03:00:00+00:00 [queued]>
[2023-11-30T13:25:03.749+0200] {taskinstance.py:1159} INFO - Dependencies all met for dep_context=requeueable deps ti=<TaskInstance: weather_data_pipeline.check_api_Kharkiv scheduled__2023-11-30T03:00:00+00:00 [queued]>
[2023-11-30T13:25:03.750+0200] {taskinstance.py:1361} INFO - Starting attempt 1 of 1
[2023-11-30T13:25:03.767+0200] {taskinstance.py:1382} INFO - Executing <Task(HttpSensor): check_api_Kharkiv> on 2023-11-30 03:00:00+00:00
[2023-11-30T13:25:03.769+0200] {standard_task_runner.py:57} INFO - Started process 23852 to run task
[2023-11-30T13:25:03.775+0200] {standard_task_runner.py:84} INFO - Running: ['airflow', 'tasks', 'run', 'weather_data_pipeline', 'check_api_Kharkiv', 'scheduled__2023-11-30T03:00:00+00:00', '--job-id', '263', '--raw', '--subdir', 'DAGS_FOLDER/weather_pipeline.py', '--cfg-path', '/tmp/tmpuewaxzkp']
[2023-11-30T13:25:03.777+0200] {standard_task_runner.py:85} INFO - Job 263: Subtask check_api_Kharkiv
[2023-11-30T13:25:03.818+0200] {task_command.py:416} INFO - Running <TaskInstance: weather_data_pipeline.check_api_Kharkiv scheduled__2023-11-30T03:00:00+00:00 [running]> on host DESKTOP-VD1PANR.
[2023-11-30T13:25:03.938+0200] {taskinstance.py:1662} INFO - Exporting env vars: AIRFLOW_CTX_DAG_OWNER='airflow' AIRFLOW_CTX_DAG_ID='weather_data_pipeline' AIRFLOW_CTX_TASK_ID='check_api_Kharkiv' AIRFLOW_CTX_EXECUTION_DATE='2023-11-30T03:00:00+00:00' AIRFLOW_CTX_TRY_NUMBER='1' AIRFLOW_CTX_DAG_RUN_ID='scheduled__2023-11-30T03:00:00+00:00'
[2023-11-30T13:25:03.938+0200] {http.py:130} INFO - Poking: data/3.0/onecall
[2023-11-30T13:25:03.942+0200] {base.py:73} INFO - Using connection ID 'openweathermap_conn' for task execution.
[2023-11-30T13:25:04.015+0200] {http.py:178} ERROR - HTTP error: Unauthorized
[2023-11-30T13:25:04.016+0200] {http.py:179} ERROR - {"cod":401, "message": "Please note that using One Call 3.0 requires a separate subscription to the One Call by Call plan. Learn more here https://openweathermap.org/price. If you have a valid subscription to the One Call by Call plan, but still receive this error, then please see https://openweathermap.org/faq#error401 for more info."}
[2023-11-30T13:25:04.023+0200] {taskinstance.py:1937} ERROR - Task failed with exception
Traceback (most recent call last):
  File "/home/seva/.local/lib/python3.10/site-packages/airflow/providers/http/hooks/http.py", line 176, in check_response
    response.raise_for_status()
  File "/home/seva/.local/lib/python3.10/site-packages/requests/models.py", line 1021, in raise_for_status
    raise HTTPError(http_error_msg, response=self)
requests.exceptions.HTTPError: 401 Client Error: Unauthorized for url: http://api.openweathermap.org/data/3.0/onecall?appid=***&q=Kharkiv

During handling of the above exception, another exception occurred:

Traceback (most recent call last):
  File "/home/seva/.local/lib/python3.10/site-packages/airflow/sensors/base.py", line 257, in execute
    raise e
  File "/home/seva/.local/lib/python3.10/site-packages/airflow/sensors/base.py", line 239, in execute
    poke_return = self.poke(context)
  File "/home/seva/.local/lib/python3.10/site-packages/airflow/providers/http/sensors/http.py", line 148, in poke
    raise exc
  File "/home/seva/.local/lib/python3.10/site-packages/airflow/providers/http/sensors/http.py", line 132, in poke
    response = hook.run(
  File "/home/seva/.local/lib/python3.10/site-packages/airflow/providers/http/hooks/http.py", line 166, in run
    return self.run_and_check(session, prepped_request, extra_options)
  File "/home/seva/.local/lib/python3.10/site-packages/airflow/providers/http/hooks/http.py", line 217, in run_and_check
    self.check_response(response)
  File "/home/seva/.local/lib/python3.10/site-packages/airflow/providers/http/hooks/http.py", line 180, in check_response
    raise AirflowException(str(response.status_code) + ":" + response.reason)
airflow.exceptions.AirflowException: 401:Unauthorized
[2023-11-30T13:25:04.026+0200] {taskinstance.py:1400} INFO - Marking task as FAILED. dag_id=weather_data_pipeline, task_id=check_api_Kharkiv, execution_date=20231130T030000, start_date=20231130T112503, end_date=20231130T112504
[2023-11-30T13:25:04.045+0200] {standard_task_runner.py:104} ERROR - Failed to execute job 263 for task check_api_Kharkiv (401:Unauthorized; 23852)
[2023-11-30T13:25:04.086+0200] {local_task_job_runner.py:228} INFO - Task exited with return code 1
[2023-11-30T13:25:04.161+0200] {taskinstance.py:2778} INFO - 0 downstream tasks scheduled from follow-on schedule check
