[2023-11-30T12:41:10.435+0200] {taskinstance.py:1159} INFO - Dependencies all met for dep_context=non-requeueable deps ti=<TaskInstance: weather_data_pipeline.check_api_Odesa manual__2023-11-30T10:40:45.601629+00:00 [queued]>
[2023-11-30T12:41:10.444+0200] {taskinstance.py:1159} INFO - Dependencies all met for dep_context=requeueable deps ti=<TaskInstance: weather_data_pipeline.check_api_Odesa manual__2023-11-30T10:40:45.601629+00:00 [queued]>
[2023-11-30T12:41:10.445+0200] {taskinstance.py:1361} INFO - Starting attempt 1 of 1
[2023-11-30T12:41:10.465+0200] {taskinstance.py:1382} INFO - Executing <Task(HttpSensor): check_api_Odesa> on 2023-11-30 10:40:45.601629+00:00
[2023-11-30T12:41:10.467+0200] {standard_task_runner.py:57} INFO - Started process 18534 to run task
[2023-11-30T12:41:10.472+0200] {standard_task_runner.py:84} INFO - Running: ['airflow', 'tasks', 'run', 'weather_data_pipeline', 'check_api_Odesa', 'manual__2023-11-30T10:40:45.601629+00:00', '--job-id', '16', '--raw', '--subdir', 'DAGS_FOLDER/weather_pipeline.py', '--cfg-path', '/tmp/tmpwxc7aqg2']
[2023-11-30T12:41:10.473+0200] {standard_task_runner.py:85} INFO - Job 16: Subtask check_api_Odesa
[2023-11-30T12:41:10.532+0200] {task_command.py:416} INFO - Running <TaskInstance: weather_data_pipeline.check_api_Odesa manual__2023-11-30T10:40:45.601629+00:00 [running]> on host DESKTOP-VD1PANR.
[2023-11-30T12:41:10.700+0200] {taskinstance.py:1662} INFO - Exporting env vars: AIRFLOW_CTX_DAG_OWNER='airflow' AIRFLOW_CTX_DAG_ID='weather_data_pipeline' AIRFLOW_CTX_TASK_ID='check_api_Odesa' AIRFLOW_CTX_EXECUTION_DATE='2023-11-30T10:40:45.601629+00:00' AIRFLOW_CTX_TRY_NUMBER='1' AIRFLOW_CTX_DAG_RUN_ID='manual__2023-11-30T10:40:45.601629+00:00'
[2023-11-30T12:41:10.701+0200] {http.py:130} INFO - Poking: data/3.0/onecall
[2023-11-30T12:41:10.708+0200] {taskinstance.py:1937} ERROR - Task failed with exception
Traceback (most recent call last):
  File "/home/seva/.local/lib/python3.10/site-packages/airflow/sensors/base.py", line 257, in execute
    raise e
  File "/home/seva/.local/lib/python3.10/site-packages/airflow/sensors/base.py", line 239, in execute
    poke_return = self.poke(context)
  File "/home/seva/.local/lib/python3.10/site-packages/airflow/providers/http/sensors/http.py", line 148, in poke
    raise exc
  File "/home/seva/.local/lib/python3.10/site-packages/airflow/providers/http/sensors/http.py", line 132, in poke
    response = hook.run(
  File "/home/seva/.local/lib/python3.10/site-packages/airflow/providers/http/hooks/http.py", line 145, in run
    session = self.get_conn(headers)
  File "/home/seva/.local/lib/python3.10/site-packages/airflow/providers/http/hooks/http.py", line 98, in get_conn
    conn = self.get_connection(self.http_conn_id)
  File "/home/seva/.local/lib/python3.10/site-packages/airflow/hooks/base.py", line 72, in get_connection
    conn = Connection.get_connection_from_secrets(conn_id)
  File "/home/seva/.local/lib/python3.10/site-packages/airflow/models/connection.py", line 477, in get_connection_from_secrets
    raise AirflowNotFoundException(f"The conn_id `{conn_id}` isn't defined")
airflow.exceptions.AirflowNotFoundException: The conn_id `openweathermap_conn` isn't defined
[2023-11-30T12:41:10.710+0200] {taskinstance.py:1400} INFO - Marking task as FAILED. dag_id=weather_data_pipeline, task_id=check_api_Odesa, execution_date=20231130T104045, start_date=20231130T104110, end_date=20231130T104110
[2023-11-30T12:41:10.735+0200] {standard_task_runner.py:104} ERROR - Failed to execute job 16 for task check_api_Odesa (The conn_id `openweathermap_conn` isn't defined; 18534)
[2023-11-30T12:41:10.778+0200] {local_task_job_runner.py:228} INFO - Task exited with return code 1
[2023-11-30T12:41:10.869+0200] {taskinstance.py:2778} INFO - 0 downstream tasks scheduled from follow-on schedule check
