[2023-11-30T13:00:05.029+0200] {taskinstance.py:1159} INFO - Dependencies all met for dep_context=non-requeueable deps ti=<TaskInstance: weather_data_pipeline.check_api_Lviv scheduled__2023-11-30T10:00:00+00:00 [queued]>
[2023-11-30T13:00:05.037+0200] {taskinstance.py:1159} INFO - Dependencies all met for dep_context=requeueable deps ti=<TaskInstance: weather_data_pipeline.check_api_Lviv scheduled__2023-11-30T10:00:00+00:00 [queued]>
[2023-11-30T13:00:05.037+0200] {taskinstance.py:1361} INFO - Starting attempt 1 of 1
[2023-11-30T13:00:05.057+0200] {taskinstance.py:1382} INFO - Executing <Task(HttpSensor): check_api_Lviv> on 2023-11-30 10:00:00+00:00
[2023-11-30T13:00:05.060+0200] {standard_task_runner.py:57} INFO - Started process 20897 to run task
[2023-11-30T13:00:05.064+0200] {standard_task_runner.py:84} INFO - Running: ['airflow', 'tasks', 'run', 'weather_data_pipeline', 'check_api_Lviv', 'scheduled__2023-11-30T10:00:00+00:00', '--job-id', '139', '--raw', '--subdir', 'DAGS_FOLDER/weather_pipeline.py', '--cfg-path', '/tmp/tmp0bjr8i14']
[2023-11-30T13:00:05.067+0200] {standard_task_runner.py:85} INFO - Job 139: Subtask check_api_Lviv
[2023-11-30T13:00:05.110+0200] {task_command.py:416} INFO - Running <TaskInstance: weather_data_pipeline.check_api_Lviv scheduled__2023-11-30T10:00:00+00:00 [running]> on host DESKTOP-VD1PANR.
[2023-11-30T13:00:05.232+0200] {taskinstance.py:1662} INFO - Exporting env vars: AIRFLOW_CTX_DAG_OWNER='airflow' AIRFLOW_CTX_DAG_ID='weather_data_pipeline' AIRFLOW_CTX_TASK_ID='check_api_Lviv' AIRFLOW_CTX_EXECUTION_DATE='2023-11-30T10:00:00+00:00' AIRFLOW_CTX_TRY_NUMBER='1' AIRFLOW_CTX_DAG_RUN_ID='scheduled__2023-11-30T10:00:00+00:00'
[2023-11-30T13:00:05.233+0200] {http.py:130} INFO - Poking: data/3.0/onecall
[2023-11-30T13:00:05.236+0200] {base.py:73} INFO - Using connection ID 'openweathermap_conn' for task execution.
[2023-11-30T13:00:05.316+0200] {http.py:178} ERROR - HTTP error: Unauthorized
[2023-11-30T13:00:05.317+0200] {http.py:179} ERROR - {"cod":401, "message": "Please note that using One Call 3.0 requires a separate subscription to the One Call by Call plan. Learn more here https://openweathermap.org/price. If you have a valid subscription to the One Call by Call plan, but still receive this error, then please see https://openweathermap.org/faq#error401 for more info."}
[2023-11-30T13:00:05.322+0200] {taskinstance.py:1937} ERROR - Task failed with exception
Traceback (most recent call last):
  File "/home/seva/.local/lib/python3.10/site-packages/airflow/providers/http/hooks/http.py", line 176, in check_response
    response.raise_for_status()
  File "/home/seva/.local/lib/python3.10/site-packages/requests/models.py", line 1021, in raise_for_status
    raise HTTPError(http_error_msg, response=self)
requests.exceptions.HTTPError: 401 Client Error: Unauthorized for url: http://api.openweathermap.org/data/3.0/onecall?appid=***&q=Lviv

During handling of the above exception, another exception occurred:

Traceback (most recent call last):
  File "/home/seva/.local/lib/python3.10/site-packages/airflow/sensors/base.py", line 257, in execute
    raise e
  File "/home/seva/.local/lib/python3.10/site-packages/airflow/sensors/base.py", line 239, in execute
    poke_return = self.poke(context)
  File "/home/seva/.local/lib/python3.10/site-packages/airflow/providers/http/sensors/http.py", line 148, in poke
    raise exc
  File "/home/seva/.local/lib/python3.10/site-packages/airflow/providers/http/sensors/http.py", line 132, in poke
    response = hook.run(
  File "/home/seva/.local/lib/python3.10/site-packages/airflow/providers/http/hooks/http.py", line 166, in run
    return self.run_and_check(session, prepped_request, extra_options)
  File "/home/seva/.local/lib/python3.10/site-packages/airflow/providers/http/hooks/http.py", line 217, in run_and_check
    self.check_response(response)
  File "/home/seva/.local/lib/python3.10/site-packages/airflow/providers/http/hooks/http.py", line 180, in check_response
    raise AirflowException(str(response.status_code) + ":" + response.reason)
airflow.exceptions.AirflowException: 401:Unauthorized
[2023-11-30T13:00:05.327+0200] {taskinstance.py:1400} INFO - Marking task as FAILED. dag_id=weather_data_pipeline, task_id=check_api_Lviv, execution_date=20231130T100000, start_date=20231130T110005, end_date=20231130T110005
[2023-11-30T13:00:05.350+0200] {standard_task_runner.py:104} ERROR - Failed to execute job 139 for task check_api_Lviv (401:Unauthorized; 20897)
[2023-11-30T13:00:05.377+0200] {local_task_job_runner.py:228} INFO - Task exited with return code 1
[2023-11-30T13:00:05.457+0200] {taskinstance.py:2778} INFO - 0 downstream tasks scheduled from follow-on schedule check
[2023-11-30T13:16:29.145+0200] {taskinstance.py:1159} INFO - Dependencies all met for dep_context=non-requeueable deps ti=<TaskInstance: weather_data_pipeline.check_api_Lviv scheduled__2023-11-30T10:00:00+00:00 [queued]>
[2023-11-30T13:16:29.153+0200] {taskinstance.py:1159} INFO - Dependencies all met for dep_context=requeueable deps ti=<TaskInstance: weather_data_pipeline.check_api_Lviv scheduled__2023-11-30T10:00:00+00:00 [queued]>
[2023-11-30T13:16:29.153+0200] {taskinstance.py:1361} INFO - Starting attempt 1 of 1
[2023-11-30T13:16:29.174+0200] {taskinstance.py:1382} INFO - Executing <Task(HttpSensor): check_api_Lviv> on 2023-11-30 10:00:00+00:00
[2023-11-30T13:16:29.176+0200] {standard_task_runner.py:57} INFO - Started process 22849 to run task
[2023-11-30T13:16:29.181+0200] {standard_task_runner.py:84} INFO - Running: ['airflow', 'tasks', 'run', 'weather_data_pipeline', 'check_api_Lviv', 'scheduled__2023-11-30T10:00:00+00:00', '--job-id', '230', '--raw', '--subdir', 'DAGS_FOLDER/weather_pipeline.py', '--cfg-path', '/tmp/tmpww29799e']
[2023-11-30T13:16:29.183+0200] {standard_task_runner.py:85} INFO - Job 230: Subtask check_api_Lviv
[2023-11-30T13:16:29.225+0200] {task_command.py:416} INFO - Running <TaskInstance: weather_data_pipeline.check_api_Lviv scheduled__2023-11-30T10:00:00+00:00 [running]> on host DESKTOP-VD1PANR.
[2023-11-30T13:16:29.349+0200] {taskinstance.py:1662} INFO - Exporting env vars: AIRFLOW_CTX_DAG_OWNER='airflow' AIRFLOW_CTX_DAG_ID='weather_data_pipeline' AIRFLOW_CTX_TASK_ID='check_api_Lviv' AIRFLOW_CTX_EXECUTION_DATE='2023-11-30T10:00:00+00:00' AIRFLOW_CTX_TRY_NUMBER='1' AIRFLOW_CTX_DAG_RUN_ID='scheduled__2023-11-30T10:00:00+00:00'
[2023-11-30T13:16:29.350+0200] {http.py:130} INFO - Poking: data/3.0/onecall
[2023-11-30T13:16:29.353+0200] {base.py:73} INFO - Using connection ID 'openweathermap_conn' for task execution.
[2023-11-30T13:16:29.442+0200] {http.py:178} ERROR - HTTP error: Bad Request
[2023-11-30T13:16:29.443+0200] {http.py:179} ERROR - {"cod":"400","message":"no location specified"}
[2023-11-30T13:16:29.449+0200] {taskinstance.py:1937} ERROR - Task failed with exception
Traceback (most recent call last):
  File "/home/seva/.local/lib/python3.10/site-packages/airflow/providers/http/hooks/http.py", line 176, in check_response
    response.raise_for_status()
  File "/home/seva/.local/lib/python3.10/site-packages/requests/models.py", line 1021, in raise_for_status
    raise HTTPError(http_error_msg, response=self)
requests.exceptions.HTTPError: 400 Client Error: Bad Request for url: http://api.openweathermap.org/data/3.0/onecall?appid=***&q=Lviv

During handling of the above exception, another exception occurred:

Traceback (most recent call last):
  File "/home/seva/.local/lib/python3.10/site-packages/airflow/sensors/base.py", line 257, in execute
    raise e
  File "/home/seva/.local/lib/python3.10/site-packages/airflow/sensors/base.py", line 239, in execute
    poke_return = self.poke(context)
  File "/home/seva/.local/lib/python3.10/site-packages/airflow/providers/http/sensors/http.py", line 148, in poke
    raise exc
  File "/home/seva/.local/lib/python3.10/site-packages/airflow/providers/http/sensors/http.py", line 132, in poke
    response = hook.run(
  File "/home/seva/.local/lib/python3.10/site-packages/airflow/providers/http/hooks/http.py", line 166, in run
    return self.run_and_check(session, prepped_request, extra_options)
  File "/home/seva/.local/lib/python3.10/site-packages/airflow/providers/http/hooks/http.py", line 217, in run_and_check
    self.check_response(response)
  File "/home/seva/.local/lib/python3.10/site-packages/airflow/providers/http/hooks/http.py", line 180, in check_response
    raise AirflowException(str(response.status_code) + ":" + response.reason)
airflow.exceptions.AirflowException: 400:Bad Request
[2023-11-30T13:16:29.451+0200] {taskinstance.py:1400} INFO - Marking task as FAILED. dag_id=weather_data_pipeline, task_id=check_api_Lviv, execution_date=20231130T100000, start_date=20231130T111629, end_date=20231130T111629
[2023-11-30T13:16:29.470+0200] {standard_task_runner.py:104} ERROR - Failed to execute job 230 for task check_api_Lviv (400:Bad Request; 22849)
[2023-11-30T13:16:29.488+0200] {local_task_job_runner.py:228} INFO - Task exited with return code 1
[2023-11-30T13:16:29.560+0200] {taskinstance.py:2778} INFO - 0 downstream tasks scheduled from follow-on schedule check
[2023-11-30T13:26:28.224+0200] {taskinstance.py:1159} INFO - Dependencies all met for dep_context=non-requeueable deps ti=<TaskInstance: weather_data_pipeline.check_api_Lviv scheduled__2023-11-30T10:00:00+00:00 [queued]>
[2023-11-30T13:26:28.233+0200] {taskinstance.py:1159} INFO - Dependencies all met for dep_context=requeueable deps ti=<TaskInstance: weather_data_pipeline.check_api_Lviv scheduled__2023-11-30T10:00:00+00:00 [queued]>
[2023-11-30T13:26:28.233+0200] {taskinstance.py:1361} INFO - Starting attempt 1 of 1
[2023-11-30T13:26:28.254+0200] {taskinstance.py:1382} INFO - Executing <Task(HttpSensor): check_api_Lviv> on 2023-11-30 10:00:00+00:00
[2023-11-30T13:26:28.257+0200] {standard_task_runner.py:57} INFO - Started process 24077 to run task
[2023-11-30T13:26:28.263+0200] {standard_task_runner.py:84} INFO - Running: ['airflow', 'tasks', 'run', 'weather_data_pipeline', 'check_api_Lviv', 'scheduled__2023-11-30T10:00:00+00:00', '--job-id', '302', '--raw', '--subdir', 'DAGS_FOLDER/weather_pipeline.py', '--cfg-path', '/tmp/tmpvx2r0ppf']
[2023-11-30T13:26:28.265+0200] {standard_task_runner.py:85} INFO - Job 302: Subtask check_api_Lviv
[2023-11-30T13:26:28.323+0200] {task_command.py:416} INFO - Running <TaskInstance: weather_data_pipeline.check_api_Lviv scheduled__2023-11-30T10:00:00+00:00 [running]> on host DESKTOP-VD1PANR.
[2023-11-30T13:26:28.466+0200] {taskinstance.py:1662} INFO - Exporting env vars: AIRFLOW_CTX_DAG_OWNER='airflow' AIRFLOW_CTX_DAG_ID='weather_data_pipeline' AIRFLOW_CTX_TASK_ID='check_api_Lviv' AIRFLOW_CTX_EXECUTION_DATE='2023-11-30T10:00:00+00:00' AIRFLOW_CTX_TRY_NUMBER='1' AIRFLOW_CTX_DAG_RUN_ID='scheduled__2023-11-30T10:00:00+00:00'
[2023-11-30T13:26:28.466+0200] {http.py:130} INFO - Poking: data/3.0/onecall
[2023-11-30T13:26:28.470+0200] {base.py:73} INFO - Using connection ID 'openweathermap_conn' for task execution.
[2023-11-30T13:26:28.547+0200] {http.py:178} ERROR - HTTP error: Unauthorized
[2023-11-30T13:26:28.548+0200] {http.py:179} ERROR - {"cod":401, "message": "Please note that using One Call 3.0 requires a separate subscription to the One Call by Call plan. Learn more here https://openweathermap.org/price. If you have a valid subscription to the One Call by Call plan, but still receive this error, then please see https://openweathermap.org/faq#error401 for more info."}
[2023-11-30T13:26:28.555+0200] {taskinstance.py:1937} ERROR - Task failed with exception
Traceback (most recent call last):
  File "/home/seva/.local/lib/python3.10/site-packages/airflow/providers/http/hooks/http.py", line 176, in check_response
    response.raise_for_status()
  File "/home/seva/.local/lib/python3.10/site-packages/requests/models.py", line 1021, in raise_for_status
    raise HTTPError(http_error_msg, response=self)
requests.exceptions.HTTPError: 401 Client Error: Unauthorized for url: http://api.openweathermap.org/data/3.0/onecall?appid=***&q=Lviv

During handling of the above exception, another exception occurred:

Traceback (most recent call last):
  File "/home/seva/.local/lib/python3.10/site-packages/airflow/sensors/base.py", line 257, in execute
    raise e
  File "/home/seva/.local/lib/python3.10/site-packages/airflow/sensors/base.py", line 239, in execute
    poke_return = self.poke(context)
  File "/home/seva/.local/lib/python3.10/site-packages/airflow/providers/http/sensors/http.py", line 148, in poke
    raise exc
  File "/home/seva/.local/lib/python3.10/site-packages/airflow/providers/http/sensors/http.py", line 132, in poke
    response = hook.run(
  File "/home/seva/.local/lib/python3.10/site-packages/airflow/providers/http/hooks/http.py", line 166, in run
    return self.run_and_check(session, prepped_request, extra_options)
  File "/home/seva/.local/lib/python3.10/site-packages/airflow/providers/http/hooks/http.py", line 217, in run_and_check
    self.check_response(response)
  File "/home/seva/.local/lib/python3.10/site-packages/airflow/providers/http/hooks/http.py", line 180, in check_response
    raise AirflowException(str(response.status_code) + ":" + response.reason)
airflow.exceptions.AirflowException: 401:Unauthorized
[2023-11-30T13:26:28.559+0200] {taskinstance.py:1400} INFO - Marking task as FAILED. dag_id=weather_data_pipeline, task_id=check_api_Lviv, execution_date=20231130T100000, start_date=20231130T112628, end_date=20231130T112628
[2023-11-30T13:26:28.576+0200] {standard_task_runner.py:104} ERROR - Failed to execute job 302 for task check_api_Lviv (401:Unauthorized; 24077)
[2023-11-30T13:26:28.614+0200] {local_task_job_runner.py:228} INFO - Task exited with return code 1
[2023-11-30T13:26:28.681+0200] {taskinstance.py:2778} INFO - 0 downstream tasks scheduled from follow-on schedule check
