[2023-11-30T12:41:45.452+0200] {taskinstance.py:1159} INFO - Dependencies all met for dep_context=non-requeueable deps ti=<TaskInstance: weather_data_pipeline.check_api_Kyiv scheduled__2023-11-30T03:00:00+00:00 [queued]>
[2023-11-30T12:41:45.457+0200] {taskinstance.py:1159} INFO - Dependencies all met for dep_context=requeueable deps ti=<TaskInstance: weather_data_pipeline.check_api_Kyiv scheduled__2023-11-30T03:00:00+00:00 [queued]>
[2023-11-30T12:41:45.458+0200] {taskinstance.py:1361} INFO - Starting attempt 1 of 1
[2023-11-30T12:41:45.475+0200] {taskinstance.py:1382} INFO - Executing <Task(HttpSensor): check_api_Kyiv> on 2023-11-30 03:00:00+00:00
[2023-11-30T12:41:45.477+0200] {standard_task_runner.py:57} INFO - Started process 18636 to run task
[2023-11-30T12:41:45.480+0200] {standard_task_runner.py:84} INFO - Running: ['airflow', 'tasks', 'run', 'weather_data_pipeline', 'check_api_Kyiv', 'scheduled__2023-11-30T03:00:00+00:00', '--job-id', '32', '--raw', '--subdir', 'DAGS_FOLDER/weather_pipeline.py', '--cfg-path', '/tmp/tmpqltpfjxa']
[2023-11-30T12:41:45.482+0200] {standard_task_runner.py:85} INFO - Job 32: Subtask check_api_Kyiv
[2023-11-30T12:41:45.524+0200] {task_command.py:416} INFO - Running <TaskInstance: weather_data_pipeline.check_api_Kyiv scheduled__2023-11-30T03:00:00+00:00 [running]> on host DESKTOP-VD1PANR.
[2023-11-30T12:41:45.663+0200] {taskinstance.py:1662} INFO - Exporting env vars: AIRFLOW_CTX_DAG_OWNER='airflow' AIRFLOW_CTX_DAG_ID='weather_data_pipeline' AIRFLOW_CTX_TASK_ID='check_api_Kyiv' AIRFLOW_CTX_EXECUTION_DATE='2023-11-30T03:00:00+00:00' AIRFLOW_CTX_TRY_NUMBER='1' AIRFLOW_CTX_DAG_RUN_ID='scheduled__2023-11-30T03:00:00+00:00'
[2023-11-30T12:41:45.663+0200] {http.py:130} INFO - Poking: data/3.0/onecall
[2023-11-30T12:41:45.672+0200] {taskinstance.py:1937} ERROR - Task failed with exception
Traceback (most recent call last):
  File "/home/seva/.local/lib/python3.10/site-packages/airflow/sensors/base.py", line 257, in execute
    raise e
  File "/home/seva/.local/lib/python3.10/site-packages/airflow/sensors/base.py", line 239, in execute
    poke_return = self.poke(context)
  File "/home/seva/.local/lib/python3.10/site-packages/airflow/providers/http/sensors/http.py", line 148, in poke
    raise exc
  File "/home/seva/.local/lib/python3.10/site-packages/airflow/providers/http/sensors/http.py", line 132, in poke
    response = hook.run(
  File "/home/seva/.local/lib/python3.10/site-packages/airflow/providers/http/hooks/http.py", line 145, in run
    session = self.get_conn(headers)
  File "/home/seva/.local/lib/python3.10/site-packages/airflow/providers/http/hooks/http.py", line 98, in get_conn
    conn = self.get_connection(self.http_conn_id)
  File "/home/seva/.local/lib/python3.10/site-packages/airflow/hooks/base.py", line 72, in get_connection
    conn = Connection.get_connection_from_secrets(conn_id)
  File "/home/seva/.local/lib/python3.10/site-packages/airflow/models/connection.py", line 477, in get_connection_from_secrets
    raise AirflowNotFoundException(f"The conn_id `{conn_id}` isn't defined")
airflow.exceptions.AirflowNotFoundException: The conn_id `openweathermap_conn` isn't defined
[2023-11-30T12:41:45.675+0200] {taskinstance.py:1400} INFO - Marking task as FAILED. dag_id=weather_data_pipeline, task_id=check_api_Kyiv, execution_date=20231130T030000, start_date=20231130T104145, end_date=20231130T104145
[2023-11-30T12:41:45.690+0200] {standard_task_runner.py:104} ERROR - Failed to execute job 32 for task check_api_Kyiv (The conn_id `openweathermap_conn` isn't defined; 18636)
[2023-11-30T12:41:45.711+0200] {local_task_job_runner.py:228} INFO - Task exited with return code 1
[2023-11-30T12:41:45.794+0200] {taskinstance.py:2778} INFO - 0 downstream tasks scheduled from follow-on schedule check
[2023-11-30T12:56:46.347+0200] {taskinstance.py:1159} INFO - Dependencies all met for dep_context=non-requeueable deps ti=<TaskInstance: weather_data_pipeline.check_api_Kyiv scheduled__2023-11-30T03:00:00+00:00 [queued]>
[2023-11-30T12:56:46.355+0200] {taskinstance.py:1159} INFO - Dependencies all met for dep_context=requeueable deps ti=<TaskInstance: weather_data_pipeline.check_api_Kyiv scheduled__2023-11-30T03:00:00+00:00 [queued]>
[2023-11-30T12:56:46.355+0200] {taskinstance.py:1361} INFO - Starting attempt 1 of 1
[2023-11-30T12:56:46.375+0200] {taskinstance.py:1382} INFO - Executing <Task(HttpSensor): check_api_Kyiv> on 2023-11-30 03:00:00+00:00
[2023-11-30T12:56:46.377+0200] {standard_task_runner.py:57} INFO - Started process 20465 to run task
[2023-11-30T12:56:46.381+0200] {standard_task_runner.py:84} INFO - Running: ['airflow', 'tasks', 'run', 'weather_data_pipeline', 'check_api_Kyiv', 'scheduled__2023-11-30T03:00:00+00:00', '--job-id', '99', '--raw', '--subdir', 'DAGS_FOLDER/weather_pipeline.py', '--cfg-path', '/tmp/tmpkrho_sh_']
[2023-11-30T12:56:46.384+0200] {standard_task_runner.py:85} INFO - Job 99: Subtask check_api_Kyiv
[2023-11-30T12:56:46.424+0200] {task_command.py:416} INFO - Running <TaskInstance: weather_data_pipeline.check_api_Kyiv scheduled__2023-11-30T03:00:00+00:00 [running]> on host DESKTOP-VD1PANR.
[2023-11-30T12:56:46.540+0200] {taskinstance.py:1662} INFO - Exporting env vars: AIRFLOW_CTX_DAG_OWNER='airflow' AIRFLOW_CTX_DAG_ID='weather_data_pipeline' AIRFLOW_CTX_TASK_ID='check_api_Kyiv' AIRFLOW_CTX_EXECUTION_DATE='2023-11-30T03:00:00+00:00' AIRFLOW_CTX_TRY_NUMBER='1' AIRFLOW_CTX_DAG_RUN_ID='scheduled__2023-11-30T03:00:00+00:00'
[2023-11-30T12:56:46.540+0200] {http.py:130} INFO - Poking: data/3.0/onecall
[2023-11-30T12:56:46.545+0200] {base.py:73} INFO - Using connection ID 'openweathermap_conn' for task execution.
[2023-11-30T12:56:46.649+0200] {http.py:178} ERROR - HTTP error: Unauthorized
[2023-11-30T12:56:46.650+0200] {http.py:179} ERROR - {"cod":401, "message": "Please note that using One Call 3.0 requires a separate subscription to the One Call by Call plan. Learn more here https://openweathermap.org/price. If you have a valid subscription to the One Call by Call plan, but still receive this error, then please see https://openweathermap.org/faq#error401 for more info."}
[2023-11-30T12:56:46.655+0200] {taskinstance.py:1937} ERROR - Task failed with exception
Traceback (most recent call last):
  File "/home/seva/.local/lib/python3.10/site-packages/airflow/providers/http/hooks/http.py", line 176, in check_response
    response.raise_for_status()
  File "/home/seva/.local/lib/python3.10/site-packages/requests/models.py", line 1021, in raise_for_status
    raise HTTPError(http_error_msg, response=self)
requests.exceptions.HTTPError: 401 Client Error: Unauthorized for url: http://api.openweathermap.org/data/3.0/onecall?appid=***&q=Kyiv

During handling of the above exception, another exception occurred:

Traceback (most recent call last):
  File "/home/seva/.local/lib/python3.10/site-packages/airflow/sensors/base.py", line 257, in execute
    raise e
  File "/home/seva/.local/lib/python3.10/site-packages/airflow/sensors/base.py", line 239, in execute
    poke_return = self.poke(context)
  File "/home/seva/.local/lib/python3.10/site-packages/airflow/providers/http/sensors/http.py", line 148, in poke
    raise exc
  File "/home/seva/.local/lib/python3.10/site-packages/airflow/providers/http/sensors/http.py", line 132, in poke
    response = hook.run(
  File "/home/seva/.local/lib/python3.10/site-packages/airflow/providers/http/hooks/http.py", line 166, in run
    return self.run_and_check(session, prepped_request, extra_options)
  File "/home/seva/.local/lib/python3.10/site-packages/airflow/providers/http/hooks/http.py", line 217, in run_and_check
    self.check_response(response)
  File "/home/seva/.local/lib/python3.10/site-packages/airflow/providers/http/hooks/http.py", line 180, in check_response
    raise AirflowException(str(response.status_code) + ":" + response.reason)
airflow.exceptions.AirflowException: 401:Unauthorized
[2023-11-30T12:56:46.658+0200] {taskinstance.py:1400} INFO - Marking task as FAILED. dag_id=weather_data_pipeline, task_id=check_api_Kyiv, execution_date=20231130T030000, start_date=20231130T105646, end_date=20231130T105646
[2023-11-30T12:56:46.677+0200] {standard_task_runner.py:104} ERROR - Failed to execute job 99 for task check_api_Kyiv (401:Unauthorized; 20465)
[2023-11-30T12:56:46.690+0200] {local_task_job_runner.py:228} INFO - Task exited with return code 1
[2023-11-30T12:56:46.758+0200] {taskinstance.py:2778} INFO - 0 downstream tasks scheduled from follow-on schedule check
[2023-11-30T13:15:11.807+0200] {taskinstance.py:1159} INFO - Dependencies all met for dep_context=non-requeueable deps ti=<TaskInstance: weather_data_pipeline.check_api_Kyiv scheduled__2023-11-30T03:00:00+00:00 [queued]>
[2023-11-30T13:15:11.815+0200] {taskinstance.py:1159} INFO - Dependencies all met for dep_context=requeueable deps ti=<TaskInstance: weather_data_pipeline.check_api_Kyiv scheduled__2023-11-30T03:00:00+00:00 [queued]>
[2023-11-30T13:15:11.815+0200] {taskinstance.py:1361} INFO - Starting attempt 1 of 1
[2023-11-30T13:15:11.837+0200] {taskinstance.py:1382} INFO - Executing <Task(HttpSensor): check_api_Kyiv> on 2023-11-30 03:00:00+00:00
[2023-11-30T13:15:11.839+0200] {standard_task_runner.py:57} INFO - Started process 22630 to run task
[2023-11-30T13:15:11.845+0200] {standard_task_runner.py:84} INFO - Running: ['airflow', 'tasks', 'run', 'weather_data_pipeline', 'check_api_Kyiv', 'scheduled__2023-11-30T03:00:00+00:00', '--job-id', '190', '--raw', '--subdir', 'DAGS_FOLDER/weather_pipeline.py', '--cfg-path', '/tmp/tmpiqa44g23']
[2023-11-30T13:15:11.847+0200] {standard_task_runner.py:85} INFO - Job 190: Subtask check_api_Kyiv
[2023-11-30T13:15:11.895+0200] {task_command.py:416} INFO - Running <TaskInstance: weather_data_pipeline.check_api_Kyiv scheduled__2023-11-30T03:00:00+00:00 [running]> on host DESKTOP-VD1PANR.
[2023-11-30T13:15:12.020+0200] {taskinstance.py:1662} INFO - Exporting env vars: AIRFLOW_CTX_DAG_OWNER='airflow' AIRFLOW_CTX_DAG_ID='weather_data_pipeline' AIRFLOW_CTX_TASK_ID='check_api_Kyiv' AIRFLOW_CTX_EXECUTION_DATE='2023-11-30T03:00:00+00:00' AIRFLOW_CTX_TRY_NUMBER='1' AIRFLOW_CTX_DAG_RUN_ID='scheduled__2023-11-30T03:00:00+00:00'
[2023-11-30T13:15:12.021+0200] {http.py:130} INFO - Poking: data/3.0/onecall
[2023-11-30T13:15:12.025+0200] {base.py:73} INFO - Using connection ID 'openweathermap_conn' for task execution.
[2023-11-30T13:15:12.122+0200] {http.py:178} ERROR - HTTP error: Unauthorized
[2023-11-30T13:15:12.123+0200] {http.py:179} ERROR - {"cod":401, "message": "Please note that using One Call 3.0 requires a separate subscription to the One Call by Call plan. Learn more here https://openweathermap.org/price. If you have a valid subscription to the One Call by Call plan, but still receive this error, then please see https://openweathermap.org/faq#error401 for more info."}
[2023-11-30T13:15:12.128+0200] {taskinstance.py:1937} ERROR - Task failed with exception
Traceback (most recent call last):
  File "/home/seva/.local/lib/python3.10/site-packages/airflow/providers/http/hooks/http.py", line 176, in check_response
    response.raise_for_status()
  File "/home/seva/.local/lib/python3.10/site-packages/requests/models.py", line 1021, in raise_for_status
    raise HTTPError(http_error_msg, response=self)
requests.exceptions.HTTPError: 401 Client Error: Unauthorized for url: http://api.openweathermap.org/data/3.0/onecall?appid=***&q=Kyiv

During handling of the above exception, another exception occurred:

Traceback (most recent call last):
  File "/home/seva/.local/lib/python3.10/site-packages/airflow/sensors/base.py", line 257, in execute
    raise e
  File "/home/seva/.local/lib/python3.10/site-packages/airflow/sensors/base.py", line 239, in execute
    poke_return = self.poke(context)
  File "/home/seva/.local/lib/python3.10/site-packages/airflow/providers/http/sensors/http.py", line 148, in poke
    raise exc
  File "/home/seva/.local/lib/python3.10/site-packages/airflow/providers/http/sensors/http.py", line 132, in poke
    response = hook.run(
  File "/home/seva/.local/lib/python3.10/site-packages/airflow/providers/http/hooks/http.py", line 166, in run
    return self.run_and_check(session, prepped_request, extra_options)
  File "/home/seva/.local/lib/python3.10/site-packages/airflow/providers/http/hooks/http.py", line 217, in run_and_check
    self.check_response(response)
  File "/home/seva/.local/lib/python3.10/site-packages/airflow/providers/http/hooks/http.py", line 180, in check_response
    raise AirflowException(str(response.status_code) + ":" + response.reason)
airflow.exceptions.AirflowException: 401:Unauthorized
[2023-11-30T13:15:12.132+0200] {taskinstance.py:1400} INFO - Marking task as FAILED. dag_id=weather_data_pipeline, task_id=check_api_Kyiv, execution_date=20231130T030000, start_date=20231130T111511, end_date=20231130T111512
[2023-11-30T13:15:12.158+0200] {standard_task_runner.py:104} ERROR - Failed to execute job 190 for task check_api_Kyiv (401:Unauthorized; 22630)
[2023-11-30T13:15:12.202+0200] {local_task_job_runner.py:228} INFO - Task exited with return code 1
[2023-11-30T13:15:12.271+0200] {taskinstance.py:2778} INFO - 0 downstream tasks scheduled from follow-on schedule check
[2023-11-30T13:25:01.569+0200] {taskinstance.py:1159} INFO - Dependencies all met for dep_context=non-requeueable deps ti=<TaskInstance: weather_data_pipeline.check_api_Kyiv scheduled__2023-11-30T03:00:00+00:00 [queued]>
[2023-11-30T13:25:01.578+0200] {taskinstance.py:1159} INFO - Dependencies all met for dep_context=requeueable deps ti=<TaskInstance: weather_data_pipeline.check_api_Kyiv scheduled__2023-11-30T03:00:00+00:00 [queued]>
[2023-11-30T13:25:01.579+0200] {taskinstance.py:1361} INFO - Starting attempt 1 of 1
[2023-11-30T13:25:01.601+0200] {taskinstance.py:1382} INFO - Executing <Task(HttpSensor): check_api_Kyiv> on 2023-11-30 03:00:00+00:00
[2023-11-30T13:25:01.604+0200] {standard_task_runner.py:57} INFO - Started process 23844 to run task
[2023-11-30T13:25:01.609+0200] {standard_task_runner.py:84} INFO - Running: ['airflow', 'tasks', 'run', 'weather_data_pipeline', 'check_api_Kyiv', 'scheduled__2023-11-30T03:00:00+00:00', '--job-id', '262', '--raw', '--subdir', 'DAGS_FOLDER/weather_pipeline.py', '--cfg-path', '/tmp/tmpwz_wfilg']
[2023-11-30T13:25:01.611+0200] {standard_task_runner.py:85} INFO - Job 262: Subtask check_api_Kyiv
[2023-11-30T13:25:01.664+0200] {task_command.py:416} INFO - Running <TaskInstance: weather_data_pipeline.check_api_Kyiv scheduled__2023-11-30T03:00:00+00:00 [running]> on host DESKTOP-VD1PANR.
[2023-11-30T13:25:01.814+0200] {taskinstance.py:1662} INFO - Exporting env vars: AIRFLOW_CTX_DAG_OWNER='airflow' AIRFLOW_CTX_DAG_ID='weather_data_pipeline' AIRFLOW_CTX_TASK_ID='check_api_Kyiv' AIRFLOW_CTX_EXECUTION_DATE='2023-11-30T03:00:00+00:00' AIRFLOW_CTX_TRY_NUMBER='1' AIRFLOW_CTX_DAG_RUN_ID='scheduled__2023-11-30T03:00:00+00:00'
[2023-11-30T13:25:01.815+0200] {http.py:130} INFO - Poking: data/3.0/onecall
[2023-11-30T13:25:01.824+0200] {base.py:73} INFO - Using connection ID 'openweathermap_conn' for task execution.
[2023-11-30T13:25:01.904+0200] {http.py:178} ERROR - HTTP error: Unauthorized
[2023-11-30T13:25:01.904+0200] {http.py:179} ERROR - {"cod":401, "message": "Please note that using One Call 3.0 requires a separate subscription to the One Call by Call plan. Learn more here https://openweathermap.org/price. If you have a valid subscription to the One Call by Call plan, but still receive this error, then please see https://openweathermap.org/faq#error401 for more info."}
[2023-11-30T13:25:01.912+0200] {taskinstance.py:1937} ERROR - Task failed with exception
Traceback (most recent call last):
  File "/home/seva/.local/lib/python3.10/site-packages/airflow/providers/http/hooks/http.py", line 176, in check_response
    response.raise_for_status()
  File "/home/seva/.local/lib/python3.10/site-packages/requests/models.py", line 1021, in raise_for_status
    raise HTTPError(http_error_msg, response=self)
requests.exceptions.HTTPError: 401 Client Error: Unauthorized for url: http://api.openweathermap.org/data/3.0/onecall?appid=***&q=Kyiv

During handling of the above exception, another exception occurred:

Traceback (most recent call last):
  File "/home/seva/.local/lib/python3.10/site-packages/airflow/sensors/base.py", line 257, in execute
    raise e
  File "/home/seva/.local/lib/python3.10/site-packages/airflow/sensors/base.py", line 239, in execute
    poke_return = self.poke(context)
  File "/home/seva/.local/lib/python3.10/site-packages/airflow/providers/http/sensors/http.py", line 148, in poke
    raise exc
  File "/home/seva/.local/lib/python3.10/site-packages/airflow/providers/http/sensors/http.py", line 132, in poke
    response = hook.run(
  File "/home/seva/.local/lib/python3.10/site-packages/airflow/providers/http/hooks/http.py", line 166, in run
    return self.run_and_check(session, prepped_request, extra_options)
  File "/home/seva/.local/lib/python3.10/site-packages/airflow/providers/http/hooks/http.py", line 217, in run_and_check
    self.check_response(response)
  File "/home/seva/.local/lib/python3.10/site-packages/airflow/providers/http/hooks/http.py", line 180, in check_response
    raise AirflowException(str(response.status_code) + ":" + response.reason)
airflow.exceptions.AirflowException: 401:Unauthorized
[2023-11-30T13:25:01.916+0200] {taskinstance.py:1400} INFO - Marking task as FAILED. dag_id=weather_data_pipeline, task_id=check_api_Kyiv, execution_date=20231130T030000, start_date=20231130T112501, end_date=20231130T112501
[2023-11-30T13:25:01.950+0200] {standard_task_runner.py:104} ERROR - Failed to execute job 262 for task check_api_Kyiv (401:Unauthorized; 23844)
[2023-11-30T13:25:01.958+0200] {local_task_job_runner.py:228} INFO - Task exited with return code 1
[2023-11-30T13:25:02.049+0200] {taskinstance.py:2778} INFO - 0 downstream tasks scheduled from follow-on schedule check
