[2023-11-30T12:41:21.508+0200] {taskinstance.py:1159} INFO - Dependencies all met for dep_context=non-requeueable deps ti=<TaskInstance: weather_data_pipeline.check_api_Kharkiv scheduled__2023-11-30T01:00:00+00:00 [queued]>
[2023-11-30T12:41:21.520+0200] {taskinstance.py:1159} INFO - Dependencies all met for dep_context=requeueable deps ti=<TaskInstance: weather_data_pipeline.check_api_Kharkiv scheduled__2023-11-30T01:00:00+00:00 [queued]>
[2023-11-30T12:41:21.520+0200] {taskinstance.py:1361} INFO - Starting attempt 1 of 1
[2023-11-30T12:41:21.543+0200] {taskinstance.py:1382} INFO - Executing <Task(HttpSensor): check_api_Kharkiv> on 2023-11-30 01:00:00+00:00
[2023-11-30T12:41:21.545+0200] {standard_task_runner.py:57} INFO - Started process 18569 to run task
[2023-11-30T12:41:21.550+0200] {standard_task_runner.py:84} INFO - Running: ['airflow', 'tasks', 'run', 'weather_data_pipeline', 'check_api_Kharkiv', 'scheduled__2023-11-30T01:00:00+00:00', '--job-id', '21', '--raw', '--subdir', 'DAGS_FOLDER/weather_pipeline.py', '--cfg-path', '/tmp/tmpsdx0b0z4']
[2023-11-30T12:41:21.551+0200] {standard_task_runner.py:85} INFO - Job 21: Subtask check_api_Kharkiv
[2023-11-30T12:41:21.595+0200] {task_command.py:416} INFO - Running <TaskInstance: weather_data_pipeline.check_api_Kharkiv scheduled__2023-11-30T01:00:00+00:00 [running]> on host DESKTOP-VD1PANR.
[2023-11-30T12:41:21.885+0200] {taskinstance.py:1662} INFO - Exporting env vars: AIRFLOW_CTX_DAG_OWNER='airflow' AIRFLOW_CTX_DAG_ID='weather_data_pipeline' AIRFLOW_CTX_TASK_ID='check_api_Kharkiv' AIRFLOW_CTX_EXECUTION_DATE='2023-11-30T01:00:00+00:00' AIRFLOW_CTX_TRY_NUMBER='1' AIRFLOW_CTX_DAG_RUN_ID='scheduled__2023-11-30T01:00:00+00:00'
[2023-11-30T12:41:21.886+0200] {http.py:130} INFO - Poking: data/3.0/onecall
[2023-11-30T12:41:21.894+0200] {taskinstance.py:1937} ERROR - Task failed with exception
Traceback (most recent call last):
  File "/home/seva/.local/lib/python3.10/site-packages/airflow/sensors/base.py", line 257, in execute
    raise e
  File "/home/seva/.local/lib/python3.10/site-packages/airflow/sensors/base.py", line 239, in execute
    poke_return = self.poke(context)
  File "/home/seva/.local/lib/python3.10/site-packages/airflow/providers/http/sensors/http.py", line 148, in poke
    raise exc
  File "/home/seva/.local/lib/python3.10/site-packages/airflow/providers/http/sensors/http.py", line 132, in poke
    response = hook.run(
  File "/home/seva/.local/lib/python3.10/site-packages/airflow/providers/http/hooks/http.py", line 145, in run
    session = self.get_conn(headers)
  File "/home/seva/.local/lib/python3.10/site-packages/airflow/providers/http/hooks/http.py", line 98, in get_conn
    conn = self.get_connection(self.http_conn_id)
  File "/home/seva/.local/lib/python3.10/site-packages/airflow/hooks/base.py", line 72, in get_connection
    conn = Connection.get_connection_from_secrets(conn_id)
  File "/home/seva/.local/lib/python3.10/site-packages/airflow/models/connection.py", line 477, in get_connection_from_secrets
    raise AirflowNotFoundException(f"The conn_id `{conn_id}` isn't defined")
airflow.exceptions.AirflowNotFoundException: The conn_id `openweathermap_conn` isn't defined
[2023-11-30T12:41:21.897+0200] {taskinstance.py:1400} INFO - Marking task as FAILED. dag_id=weather_data_pipeline, task_id=check_api_Kharkiv, execution_date=20231130T010000, start_date=20231130T104121, end_date=20231130T104121
[2023-11-30T12:41:21.910+0200] {standard_task_runner.py:104} ERROR - Failed to execute job 21 for task check_api_Kharkiv (The conn_id `openweathermap_conn` isn't defined; 18569)
[2023-11-30T12:41:21.928+0200] {local_task_job_runner.py:228} INFO - Task exited with return code 1
[2023-11-30T12:41:22.028+0200] {taskinstance.py:2778} INFO - 0 downstream tasks scheduled from follow-on schedule check
[2023-11-30T12:55:00.760+0200] {taskinstance.py:1159} INFO - Dependencies all met for dep_context=non-requeueable deps ti=<TaskInstance: weather_data_pipeline.check_api_Kharkiv scheduled__2023-11-30T01:00:00+00:00 [queued]>
[2023-11-30T12:55:00.768+0200] {taskinstance.py:1159} INFO - Dependencies all met for dep_context=requeueable deps ti=<TaskInstance: weather_data_pipeline.check_api_Kharkiv scheduled__2023-11-30T01:00:00+00:00 [queued]>
[2023-11-30T12:55:00.768+0200] {taskinstance.py:1361} INFO - Starting attempt 1 of 1
[2023-11-30T12:55:00.793+0200] {taskinstance.py:1382} INFO - Executing <Task(HttpSensor): check_api_Kharkiv> on 2023-11-30 01:00:00+00:00
[2023-11-30T12:55:00.798+0200] {standard_task_runner.py:57} INFO - Started process 20179 to run task
[2023-11-30T12:55:00.803+0200] {standard_task_runner.py:84} INFO - Running: ['airflow', 'tasks', 'run', 'weather_data_pipeline', 'check_api_Kharkiv', 'scheduled__2023-11-30T01:00:00+00:00', '--job-id', '63', '--raw', '--subdir', 'DAGS_FOLDER/weather_pipeline.py', '--cfg-path', '/tmp/tmppv89m6zb']
[2023-11-30T12:55:00.807+0200] {standard_task_runner.py:85} INFO - Job 63: Subtask check_api_Kharkiv
[2023-11-30T12:55:00.854+0200] {task_command.py:416} INFO - Running <TaskInstance: weather_data_pipeline.check_api_Kharkiv scheduled__2023-11-30T01:00:00+00:00 [running]> on host DESKTOP-VD1PANR.
[2023-11-30T12:55:00.996+0200] {taskinstance.py:1662} INFO - Exporting env vars: AIRFLOW_CTX_DAG_OWNER='airflow' AIRFLOW_CTX_DAG_ID='weather_data_pipeline' AIRFLOW_CTX_TASK_ID='check_api_Kharkiv' AIRFLOW_CTX_EXECUTION_DATE='2023-11-30T01:00:00+00:00' AIRFLOW_CTX_TRY_NUMBER='1' AIRFLOW_CTX_DAG_RUN_ID='scheduled__2023-11-30T01:00:00+00:00'
[2023-11-30T12:55:00.997+0200] {http.py:130} INFO - Poking: data/3.0/onecall
[2023-11-30T12:55:01.002+0200] {base.py:73} INFO - Using connection ID 'openweathermap_conn' for task execution.
[2023-11-30T12:55:01.088+0200] {http.py:178} ERROR - HTTP error: Unauthorized
[2023-11-30T12:55:01.089+0200] {http.py:179} ERROR - {"cod":401, "message": "Please note that using One Call 3.0 requires a separate subscription to the One Call by Call plan. Learn more here https://openweathermap.org/price. If you have a valid subscription to the One Call by Call plan, but still receive this error, then please see https://openweathermap.org/faq#error401 for more info."}
[2023-11-30T12:55:01.096+0200] {taskinstance.py:1937} ERROR - Task failed with exception
Traceback (most recent call last):
  File "/home/seva/.local/lib/python3.10/site-packages/airflow/providers/http/hooks/http.py", line 176, in check_response
    response.raise_for_status()
  File "/home/seva/.local/lib/python3.10/site-packages/requests/models.py", line 1021, in raise_for_status
    raise HTTPError(http_error_msg, response=self)
requests.exceptions.HTTPError: 401 Client Error: Unauthorized for url: http://api.openweathermap.org/data/3.0/onecall?appid=***&q=Kharkiv

During handling of the above exception, another exception occurred:

Traceback (most recent call last):
  File "/home/seva/.local/lib/python3.10/site-packages/airflow/sensors/base.py", line 257, in execute
    raise e
  File "/home/seva/.local/lib/python3.10/site-packages/airflow/sensors/base.py", line 239, in execute
    poke_return = self.poke(context)
  File "/home/seva/.local/lib/python3.10/site-packages/airflow/providers/http/sensors/http.py", line 148, in poke
    raise exc
  File "/home/seva/.local/lib/python3.10/site-packages/airflow/providers/http/sensors/http.py", line 132, in poke
    response = hook.run(
  File "/home/seva/.local/lib/python3.10/site-packages/airflow/providers/http/hooks/http.py", line 166, in run
    return self.run_and_check(session, prepped_request, extra_options)
  File "/home/seva/.local/lib/python3.10/site-packages/airflow/providers/http/hooks/http.py", line 217, in run_and_check
    self.check_response(response)
  File "/home/seva/.local/lib/python3.10/site-packages/airflow/providers/http/hooks/http.py", line 180, in check_response
    raise AirflowException(str(response.status_code) + ":" + response.reason)
airflow.exceptions.AirflowException: 401:Unauthorized
[2023-11-30T12:55:01.102+0200] {taskinstance.py:1400} INFO - Marking task as FAILED. dag_id=weather_data_pipeline, task_id=check_api_Kharkiv, execution_date=20231130T010000, start_date=20231130T105500, end_date=20231130T105501
[2023-11-30T12:55:01.128+0200] {standard_task_runner.py:104} ERROR - Failed to execute job 63 for task check_api_Kharkiv (401:Unauthorized; 20179)
[2023-11-30T12:55:01.150+0200] {local_task_job_runner.py:228} INFO - Task exited with return code 1
[2023-11-30T12:55:01.255+0200] {taskinstance.py:2778} INFO - 0 downstream tasks scheduled from follow-on schedule check
[2023-11-30T12:56:20.709+0200] {taskinstance.py:1159} INFO - Dependencies all met for dep_context=non-requeueable deps ti=<TaskInstance: weather_data_pipeline.check_api_Kharkiv scheduled__2023-11-30T01:00:00+00:00 [queued]>
[2023-11-30T12:56:20.718+0200] {taskinstance.py:1159} INFO - Dependencies all met for dep_context=requeueable deps ti=<TaskInstance: weather_data_pipeline.check_api_Kharkiv scheduled__2023-11-30T01:00:00+00:00 [queued]>
[2023-11-30T12:56:20.718+0200] {taskinstance.py:1361} INFO - Starting attempt 1 of 1
[2023-11-30T12:56:20.742+0200] {taskinstance.py:1382} INFO - Executing <Task(HttpSensor): check_api_Kharkiv> on 2023-11-30 01:00:00+00:00
[2023-11-30T12:56:20.746+0200] {standard_task_runner.py:57} INFO - Started process 20392 to run task
[2023-11-30T12:56:20.753+0200] {standard_task_runner.py:84} INFO - Running: ['airflow', 'tasks', 'run', 'weather_data_pipeline', 'check_api_Kharkiv', 'scheduled__2023-11-30T01:00:00+00:00', '--job-id', '88', '--raw', '--subdir', 'DAGS_FOLDER/weather_pipeline.py', '--cfg-path', '/tmp/tmpfbnyb9rm']
[2023-11-30T12:56:20.755+0200] {standard_task_runner.py:85} INFO - Job 88: Subtask check_api_Kharkiv
[2023-11-30T12:56:20.815+0200] {task_command.py:416} INFO - Running <TaskInstance: weather_data_pipeline.check_api_Kharkiv scheduled__2023-11-30T01:00:00+00:00 [running]> on host DESKTOP-VD1PANR.
[2023-11-30T12:56:21.000+0200] {taskinstance.py:1662} INFO - Exporting env vars: AIRFLOW_CTX_DAG_OWNER='airflow' AIRFLOW_CTX_DAG_ID='weather_data_pipeline' AIRFLOW_CTX_TASK_ID='check_api_Kharkiv' AIRFLOW_CTX_EXECUTION_DATE='2023-11-30T01:00:00+00:00' AIRFLOW_CTX_TRY_NUMBER='1' AIRFLOW_CTX_DAG_RUN_ID='scheduled__2023-11-30T01:00:00+00:00'
[2023-11-30T12:56:21.001+0200] {http.py:130} INFO - Poking: data/3.0/onecall
[2023-11-30T12:56:21.004+0200] {base.py:73} INFO - Using connection ID 'openweathermap_conn' for task execution.
[2023-11-30T12:56:21.113+0200] {http.py:178} ERROR - HTTP error: Unauthorized
[2023-11-30T12:56:21.114+0200] {http.py:179} ERROR - {"cod":401, "message": "Please note that using One Call 3.0 requires a separate subscription to the One Call by Call plan. Learn more here https://openweathermap.org/price. If you have a valid subscription to the One Call by Call plan, but still receive this error, then please see https://openweathermap.org/faq#error401 for more info."}
[2023-11-30T12:56:21.119+0200] {taskinstance.py:1937} ERROR - Task failed with exception
Traceback (most recent call last):
  File "/home/seva/.local/lib/python3.10/site-packages/airflow/providers/http/hooks/http.py", line 176, in check_response
    response.raise_for_status()
  File "/home/seva/.local/lib/python3.10/site-packages/requests/models.py", line 1021, in raise_for_status
    raise HTTPError(http_error_msg, response=self)
requests.exceptions.HTTPError: 401 Client Error: Unauthorized for url: http://api.openweathermap.org/data/3.0/onecall?appid=***&q=Kharkiv

During handling of the above exception, another exception occurred:

Traceback (most recent call last):
  File "/home/seva/.local/lib/python3.10/site-packages/airflow/sensors/base.py", line 257, in execute
    raise e
  File "/home/seva/.local/lib/python3.10/site-packages/airflow/sensors/base.py", line 239, in execute
    poke_return = self.poke(context)
  File "/home/seva/.local/lib/python3.10/site-packages/airflow/providers/http/sensors/http.py", line 148, in poke
    raise exc
  File "/home/seva/.local/lib/python3.10/site-packages/airflow/providers/http/sensors/http.py", line 132, in poke
    response = hook.run(
  File "/home/seva/.local/lib/python3.10/site-packages/airflow/providers/http/hooks/http.py", line 166, in run
    return self.run_and_check(session, prepped_request, extra_options)
  File "/home/seva/.local/lib/python3.10/site-packages/airflow/providers/http/hooks/http.py", line 217, in run_and_check
    self.check_response(response)
  File "/home/seva/.local/lib/python3.10/site-packages/airflow/providers/http/hooks/http.py", line 180, in check_response
    raise AirflowException(str(response.status_code) + ":" + response.reason)
airflow.exceptions.AirflowException: 401:Unauthorized
[2023-11-30T12:56:21.123+0200] {taskinstance.py:1400} INFO - Marking task as FAILED. dag_id=weather_data_pipeline, task_id=check_api_Kharkiv, execution_date=20231130T010000, start_date=20231130T105620, end_date=20231130T105621
[2023-11-30T12:56:21.155+0200] {standard_task_runner.py:104} ERROR - Failed to execute job 88 for task check_api_Kharkiv (401:Unauthorized; 20392)
[2023-11-30T12:56:21.177+0200] {local_task_job_runner.py:228} INFO - Task exited with return code 1
[2023-11-30T12:56:21.283+0200] {taskinstance.py:2778} INFO - 0 downstream tasks scheduled from follow-on schedule check
[2023-11-30T13:03:06.951+0200] {taskinstance.py:1159} INFO - Dependencies all met for dep_context=non-requeueable deps ti=<TaskInstance: weather_data_pipeline.check_api_Kharkiv scheduled__2023-11-30T01:00:00+00:00 [queued]>
[2023-11-30T13:03:06.958+0200] {taskinstance.py:1159} INFO - Dependencies all met for dep_context=requeueable deps ti=<TaskInstance: weather_data_pipeline.check_api_Kharkiv scheduled__2023-11-30T01:00:00+00:00 [queued]>
[2023-11-30T13:03:06.958+0200] {taskinstance.py:1361} INFO - Starting attempt 1 of 1
[2023-11-30T13:03:06.978+0200] {taskinstance.py:1382} INFO - Executing <Task(HttpSensor): check_api_Kharkiv> on 2023-11-30 01:00:00+00:00
[2023-11-30T13:03:06.981+0200] {standard_task_runner.py:57} INFO - Started process 21262 to run task
[2023-11-30T13:03:06.987+0200] {standard_task_runner.py:84} INFO - Running: ['airflow', 'tasks', 'run', 'weather_data_pipeline', 'check_api_Kharkiv', 'scheduled__2023-11-30T01:00:00+00:00', '--job-id', '154', '--raw', '--subdir', 'DAGS_FOLDER/weather_pipeline.py', '--cfg-path', '/tmp/tmpr1yko2f8']
[2023-11-30T13:03:06.988+0200] {standard_task_runner.py:85} INFO - Job 154: Subtask check_api_Kharkiv
[2023-11-30T13:03:07.028+0200] {task_command.py:416} INFO - Running <TaskInstance: weather_data_pipeline.check_api_Kharkiv scheduled__2023-11-30T01:00:00+00:00 [running]> on host DESKTOP-VD1PANR.
[2023-11-30T13:03:07.141+0200] {taskinstance.py:1662} INFO - Exporting env vars: AIRFLOW_CTX_DAG_OWNER='airflow' AIRFLOW_CTX_DAG_ID='weather_data_pipeline' AIRFLOW_CTX_TASK_ID='check_api_Kharkiv' AIRFLOW_CTX_EXECUTION_DATE='2023-11-30T01:00:00+00:00' AIRFLOW_CTX_TRY_NUMBER='1' AIRFLOW_CTX_DAG_RUN_ID='scheduled__2023-11-30T01:00:00+00:00'
[2023-11-30T13:03:07.141+0200] {http.py:130} INFO - Poking: data/3.0/onecall
[2023-11-30T13:03:07.145+0200] {base.py:73} INFO - Using connection ID 'openweathermap_conn' for task execution.
[2023-11-30T13:03:07.247+0200] {http.py:178} ERROR - HTTP error: Unauthorized
[2023-11-30T13:03:07.248+0200] {http.py:179} ERROR - {"cod":401, "message": "Please note that using One Call 3.0 requires a separate subscription to the One Call by Call plan. Learn more here https://openweathermap.org/price. If you have a valid subscription to the One Call by Call plan, but still receive this error, then please see https://openweathermap.org/faq#error401 for more info."}
[2023-11-30T13:03:07.255+0200] {taskinstance.py:1937} ERROR - Task failed with exception
Traceback (most recent call last):
  File "/home/seva/.local/lib/python3.10/site-packages/airflow/providers/http/hooks/http.py", line 176, in check_response
    response.raise_for_status()
  File "/home/seva/.local/lib/python3.10/site-packages/requests/models.py", line 1021, in raise_for_status
    raise HTTPError(http_error_msg, response=self)
requests.exceptions.HTTPError: 401 Client Error: Unauthorized for url: http://api.openweathermap.org/data/3.0/onecall?appid=***&q=Kharkiv

During handling of the above exception, another exception occurred:

Traceback (most recent call last):
  File "/home/seva/.local/lib/python3.10/site-packages/airflow/sensors/base.py", line 257, in execute
    raise e
  File "/home/seva/.local/lib/python3.10/site-packages/airflow/sensors/base.py", line 239, in execute
    poke_return = self.poke(context)
  File "/home/seva/.local/lib/python3.10/site-packages/airflow/providers/http/sensors/http.py", line 148, in poke
    raise exc
  File "/home/seva/.local/lib/python3.10/site-packages/airflow/providers/http/sensors/http.py", line 132, in poke
    response = hook.run(
  File "/home/seva/.local/lib/python3.10/site-packages/airflow/providers/http/hooks/http.py", line 166, in run
    return self.run_and_check(session, prepped_request, extra_options)
  File "/home/seva/.local/lib/python3.10/site-packages/airflow/providers/http/hooks/http.py", line 217, in run_and_check
    self.check_response(response)
  File "/home/seva/.local/lib/python3.10/site-packages/airflow/providers/http/hooks/http.py", line 180, in check_response
    raise AirflowException(str(response.status_code) + ":" + response.reason)
airflow.exceptions.AirflowException: 401:Unauthorized
[2023-11-30T13:03:07.258+0200] {taskinstance.py:1400} INFO - Marking task as FAILED. dag_id=weather_data_pipeline, task_id=check_api_Kharkiv, execution_date=20231130T010000, start_date=20231130T110306, end_date=20231130T110307
[2023-11-30T13:03:07.288+0200] {standard_task_runner.py:104} ERROR - Failed to execute job 154 for task check_api_Kharkiv (401:Unauthorized; 21262)
[2023-11-30T13:03:07.294+0200] {local_task_job_runner.py:228} INFO - Task exited with return code 1
[2023-11-30T13:03:07.370+0200] {taskinstance.py:2778} INFO - 0 downstream tasks scheduled from follow-on schedule check
[2023-11-30T13:14:50.116+0200] {taskinstance.py:1159} INFO - Dependencies all met for dep_context=non-requeueable deps ti=<TaskInstance: weather_data_pipeline.check_api_Kharkiv scheduled__2023-11-30T01:00:00+00:00 [queued]>
[2023-11-30T13:14:50.123+0200] {taskinstance.py:1159} INFO - Dependencies all met for dep_context=requeueable deps ti=<TaskInstance: weather_data_pipeline.check_api_Kharkiv scheduled__2023-11-30T01:00:00+00:00 [queued]>
[2023-11-30T13:14:50.123+0200] {taskinstance.py:1361} INFO - Starting attempt 1 of 1
[2023-11-30T13:14:50.145+0200] {taskinstance.py:1382} INFO - Executing <Task(HttpSensor): check_api_Kharkiv> on 2023-11-30 01:00:00+00:00
[2023-11-30T13:14:50.148+0200] {standard_task_runner.py:57} INFO - Started process 22572 to run task
[2023-11-30T13:14:50.153+0200] {standard_task_runner.py:84} INFO - Running: ['airflow', 'tasks', 'run', 'weather_data_pipeline', 'check_api_Kharkiv', 'scheduled__2023-11-30T01:00:00+00:00', '--job-id', '179', '--raw', '--subdir', 'DAGS_FOLDER/weather_pipeline.py', '--cfg-path', '/tmp/tmpvn1_rrgz']
[2023-11-30T13:14:50.155+0200] {standard_task_runner.py:85} INFO - Job 179: Subtask check_api_Kharkiv
[2023-11-30T13:14:50.197+0200] {task_command.py:416} INFO - Running <TaskInstance: weather_data_pipeline.check_api_Kharkiv scheduled__2023-11-30T01:00:00+00:00 [running]> on host DESKTOP-VD1PANR.
[2023-11-30T13:14:50.312+0200] {taskinstance.py:1662} INFO - Exporting env vars: AIRFLOW_CTX_DAG_OWNER='airflow' AIRFLOW_CTX_DAG_ID='weather_data_pipeline' AIRFLOW_CTX_TASK_ID='check_api_Kharkiv' AIRFLOW_CTX_EXECUTION_DATE='2023-11-30T01:00:00+00:00' AIRFLOW_CTX_TRY_NUMBER='1' AIRFLOW_CTX_DAG_RUN_ID='scheduled__2023-11-30T01:00:00+00:00'
[2023-11-30T13:14:50.312+0200] {http.py:130} INFO - Poking: data/3.0/onecall
[2023-11-30T13:14:50.316+0200] {base.py:73} INFO - Using connection ID 'openweathermap_conn' for task execution.
[2023-11-30T13:14:50.392+0200] {http.py:178} ERROR - HTTP error: Unauthorized
[2023-11-30T13:14:50.393+0200] {http.py:179} ERROR - {"cod":401, "message": "Please note that using One Call 3.0 requires a separate subscription to the One Call by Call plan. Learn more here https://openweathermap.org/price. If you have a valid subscription to the One Call by Call plan, but still receive this error, then please see https://openweathermap.org/faq#error401 for more info."}
[2023-11-30T13:14:50.399+0200] {taskinstance.py:1937} ERROR - Task failed with exception
Traceback (most recent call last):
  File "/home/seva/.local/lib/python3.10/site-packages/airflow/providers/http/hooks/http.py", line 176, in check_response
    response.raise_for_status()
  File "/home/seva/.local/lib/python3.10/site-packages/requests/models.py", line 1021, in raise_for_status
    raise HTTPError(http_error_msg, response=self)
requests.exceptions.HTTPError: 401 Client Error: Unauthorized for url: http://api.openweathermap.org/data/3.0/onecall?appid=***&q=Kharkiv

During handling of the above exception, another exception occurred:

Traceback (most recent call last):
  File "/home/seva/.local/lib/python3.10/site-packages/airflow/sensors/base.py", line 257, in execute
    raise e
  File "/home/seva/.local/lib/python3.10/site-packages/airflow/sensors/base.py", line 239, in execute
    poke_return = self.poke(context)
  File "/home/seva/.local/lib/python3.10/site-packages/airflow/providers/http/sensors/http.py", line 148, in poke
    raise exc
  File "/home/seva/.local/lib/python3.10/site-packages/airflow/providers/http/sensors/http.py", line 132, in poke
    response = hook.run(
  File "/home/seva/.local/lib/python3.10/site-packages/airflow/providers/http/hooks/http.py", line 166, in run
    return self.run_and_check(session, prepped_request, extra_options)
  File "/home/seva/.local/lib/python3.10/site-packages/airflow/providers/http/hooks/http.py", line 217, in run_and_check
    self.check_response(response)
  File "/home/seva/.local/lib/python3.10/site-packages/airflow/providers/http/hooks/http.py", line 180, in check_response
    raise AirflowException(str(response.status_code) + ":" + response.reason)
airflow.exceptions.AirflowException: 401:Unauthorized
[2023-11-30T13:14:50.402+0200] {taskinstance.py:1400} INFO - Marking task as FAILED. dag_id=weather_data_pipeline, task_id=check_api_Kharkiv, execution_date=20231130T010000, start_date=20231130T111450, end_date=20231130T111450
[2023-11-30T13:14:50.420+0200] {standard_task_runner.py:104} ERROR - Failed to execute job 179 for task check_api_Kharkiv (401:Unauthorized; 22572)
[2023-11-30T13:14:50.466+0200] {local_task_job_runner.py:228} INFO - Task exited with return code 1
[2023-11-30T13:14:50.530+0200] {taskinstance.py:2778} INFO - 0 downstream tasks scheduled from follow-on schedule check
[2023-11-30T13:24:39.837+0200] {taskinstance.py:1159} INFO - Dependencies all met for dep_context=non-requeueable deps ti=<TaskInstance: weather_data_pipeline.check_api_Kharkiv scheduled__2023-11-30T01:00:00+00:00 [queued]>
[2023-11-30T13:24:39.847+0200] {taskinstance.py:1159} INFO - Dependencies all met for dep_context=requeueable deps ti=<TaskInstance: weather_data_pipeline.check_api_Kharkiv scheduled__2023-11-30T01:00:00+00:00 [queued]>
[2023-11-30T13:24:39.847+0200] {taskinstance.py:1361} INFO - Starting attempt 1 of 1
[2023-11-30T13:24:39.868+0200] {taskinstance.py:1382} INFO - Executing <Task(HttpSensor): check_api_Kharkiv> on 2023-11-30 01:00:00+00:00
[2023-11-30T13:24:39.870+0200] {standard_task_runner.py:57} INFO - Started process 23783 to run task
[2023-11-30T13:24:39.875+0200] {standard_task_runner.py:84} INFO - Running: ['airflow', 'tasks', 'run', 'weather_data_pipeline', 'check_api_Kharkiv', 'scheduled__2023-11-30T01:00:00+00:00', '--job-id', '251', '--raw', '--subdir', 'DAGS_FOLDER/weather_pipeline.py', '--cfg-path', '/tmp/tmpy5shnm6g']
[2023-11-30T13:24:39.878+0200] {standard_task_runner.py:85} INFO - Job 251: Subtask check_api_Kharkiv
[2023-11-30T13:24:39.919+0200] {task_command.py:416} INFO - Running <TaskInstance: weather_data_pipeline.check_api_Kharkiv scheduled__2023-11-30T01:00:00+00:00 [running]> on host DESKTOP-VD1PANR.
[2023-11-30T13:24:40.043+0200] {taskinstance.py:1662} INFO - Exporting env vars: AIRFLOW_CTX_DAG_OWNER='airflow' AIRFLOW_CTX_DAG_ID='weather_data_pipeline' AIRFLOW_CTX_TASK_ID='check_api_Kharkiv' AIRFLOW_CTX_EXECUTION_DATE='2023-11-30T01:00:00+00:00' AIRFLOW_CTX_TRY_NUMBER='1' AIRFLOW_CTX_DAG_RUN_ID='scheduled__2023-11-30T01:00:00+00:00'
[2023-11-30T13:24:40.044+0200] {http.py:130} INFO - Poking: data/3.0/onecall
[2023-11-30T13:24:40.047+0200] {base.py:73} INFO - Using connection ID 'openweathermap_conn' for task execution.
[2023-11-30T13:24:40.126+0200] {http.py:178} ERROR - HTTP error: Unauthorized
[2023-11-30T13:24:40.126+0200] {http.py:179} ERROR - {"cod":401, "message": "Please note that using One Call 3.0 requires a separate subscription to the One Call by Call plan. Learn more here https://openweathermap.org/price. If you have a valid subscription to the One Call by Call plan, but still receive this error, then please see https://openweathermap.org/faq#error401 for more info."}
[2023-11-30T13:24:40.133+0200] {taskinstance.py:1937} ERROR - Task failed with exception
Traceback (most recent call last):
  File "/home/seva/.local/lib/python3.10/site-packages/airflow/providers/http/hooks/http.py", line 176, in check_response
    response.raise_for_status()
  File "/home/seva/.local/lib/python3.10/site-packages/requests/models.py", line 1021, in raise_for_status
    raise HTTPError(http_error_msg, response=self)
requests.exceptions.HTTPError: 401 Client Error: Unauthorized for url: http://api.openweathermap.org/data/3.0/onecall?appid=***&q=Kharkiv

During handling of the above exception, another exception occurred:

Traceback (most recent call last):
  File "/home/seva/.local/lib/python3.10/site-packages/airflow/sensors/base.py", line 257, in execute
    raise e
  File "/home/seva/.local/lib/python3.10/site-packages/airflow/sensors/base.py", line 239, in execute
    poke_return = self.poke(context)
  File "/home/seva/.local/lib/python3.10/site-packages/airflow/providers/http/sensors/http.py", line 148, in poke
    raise exc
  File "/home/seva/.local/lib/python3.10/site-packages/airflow/providers/http/sensors/http.py", line 132, in poke
    response = hook.run(
  File "/home/seva/.local/lib/python3.10/site-packages/airflow/providers/http/hooks/http.py", line 166, in run
    return self.run_and_check(session, prepped_request, extra_options)
  File "/home/seva/.local/lib/python3.10/site-packages/airflow/providers/http/hooks/http.py", line 217, in run_and_check
    self.check_response(response)
  File "/home/seva/.local/lib/python3.10/site-packages/airflow/providers/http/hooks/http.py", line 180, in check_response
    raise AirflowException(str(response.status_code) + ":" + response.reason)
airflow.exceptions.AirflowException: 401:Unauthorized
[2023-11-30T13:24:40.136+0200] {taskinstance.py:1400} INFO - Marking task as FAILED. dag_id=weather_data_pipeline, task_id=check_api_Kharkiv, execution_date=20231130T010000, start_date=20231130T112439, end_date=20231130T112440
[2023-11-30T13:24:40.164+0200] {standard_task_runner.py:104} ERROR - Failed to execute job 251 for task check_api_Kharkiv (401:Unauthorized; 23783)
[2023-11-30T13:24:40.180+0200] {local_task_job_runner.py:228} INFO - Task exited with return code 1
[2023-11-30T13:24:40.252+0200] {taskinstance.py:2778} INFO - 0 downstream tasks scheduled from follow-on schedule check
