[2023-11-30T12:57:28.699+0200] {taskinstance.py:1159} INFO - Dependencies all met for dep_context=non-requeueable deps ti=<TaskInstance: weather_data_pipeline.check_api_Zhmerynka scheduled__2023-11-30T06:00:00+00:00 [queued]>
[2023-11-30T12:57:28.706+0200] {taskinstance.py:1159} INFO - Dependencies all met for dep_context=requeueable deps ti=<TaskInstance: weather_data_pipeline.check_api_Zhmerynka scheduled__2023-11-30T06:00:00+00:00 [queued]>
[2023-11-30T12:57:28.706+0200] {taskinstance.py:1361} INFO - Starting attempt 1 of 1
[2023-11-30T12:57:28.727+0200] {taskinstance.py:1382} INFO - Executing <Task(HttpSensor): check_api_Zhmerynka> on 2023-11-30 06:00:00+00:00
[2023-11-30T12:57:28.733+0200] {standard_task_runner.py:57} INFO - Started process 20580 to run task
[2023-11-30T12:57:28.738+0200] {standard_task_runner.py:84} INFO - Running: ['airflow', 'tasks', 'run', 'weather_data_pipeline', 'check_api_Zhmerynka', 'scheduled__2023-11-30T06:00:00+00:00', '--job-id', '120', '--raw', '--subdir', 'DAGS_FOLDER/weather_pipeline.py', '--cfg-path', '/tmp/tmpqrxl7i2n']
[2023-11-30T12:57:28.739+0200] {standard_task_runner.py:85} INFO - Job 120: Subtask check_api_Zhmerynka
[2023-11-30T12:57:28.795+0200] {task_command.py:416} INFO - Running <TaskInstance: weather_data_pipeline.check_api_Zhmerynka scheduled__2023-11-30T06:00:00+00:00 [running]> on host DESKTOP-VD1PANR.
[2023-11-30T12:57:29.051+0200] {taskinstance.py:1662} INFO - Exporting env vars: AIRFLOW_CTX_DAG_OWNER='airflow' AIRFLOW_CTX_DAG_ID='weather_data_pipeline' AIRFLOW_CTX_TASK_ID='check_api_Zhmerynka' AIRFLOW_CTX_EXECUTION_DATE='2023-11-30T06:00:00+00:00' AIRFLOW_CTX_TRY_NUMBER='1' AIRFLOW_CTX_DAG_RUN_ID='scheduled__2023-11-30T06:00:00+00:00'
[2023-11-30T12:57:29.052+0200] {http.py:130} INFO - Poking: data/3.0/onecall
[2023-11-30T12:57:29.056+0200] {base.py:73} INFO - Using connection ID 'openweathermap_conn' for task execution.
[2023-11-30T12:57:29.137+0200] {http.py:178} ERROR - HTTP error: Unauthorized
[2023-11-30T12:57:29.138+0200] {http.py:179} ERROR - {"cod":401, "message": "Please note that using One Call 3.0 requires a separate subscription to the One Call by Call plan. Learn more here https://openweathermap.org/price. If you have a valid subscription to the One Call by Call plan, but still receive this error, then please see https://openweathermap.org/faq#error401 for more info."}
[2023-11-30T12:57:29.143+0200] {taskinstance.py:1937} ERROR - Task failed with exception
Traceback (most recent call last):
  File "/home/seva/.local/lib/python3.10/site-packages/airflow/providers/http/hooks/http.py", line 176, in check_response
    response.raise_for_status()
  File "/home/seva/.local/lib/python3.10/site-packages/requests/models.py", line 1021, in raise_for_status
    raise HTTPError(http_error_msg, response=self)
requests.exceptions.HTTPError: 401 Client Error: Unauthorized for url: http://api.openweathermap.org/data/3.0/onecall?appid=***&q=Zhmerynka

During handling of the above exception, another exception occurred:

Traceback (most recent call last):
  File "/home/seva/.local/lib/python3.10/site-packages/airflow/sensors/base.py", line 257, in execute
    raise e
  File "/home/seva/.local/lib/python3.10/site-packages/airflow/sensors/base.py", line 239, in execute
    poke_return = self.poke(context)
  File "/home/seva/.local/lib/python3.10/site-packages/airflow/providers/http/sensors/http.py", line 148, in poke
    raise exc
  File "/home/seva/.local/lib/python3.10/site-packages/airflow/providers/http/sensors/http.py", line 132, in poke
    response = hook.run(
  File "/home/seva/.local/lib/python3.10/site-packages/airflow/providers/http/hooks/http.py", line 166, in run
    return self.run_and_check(session, prepped_request, extra_options)
  File "/home/seva/.local/lib/python3.10/site-packages/airflow/providers/http/hooks/http.py", line 217, in run_and_check
    self.check_response(response)
  File "/home/seva/.local/lib/python3.10/site-packages/airflow/providers/http/hooks/http.py", line 180, in check_response
    raise AirflowException(str(response.status_code) + ":" + response.reason)
airflow.exceptions.AirflowException: 401:Unauthorized
[2023-11-30T12:57:29.146+0200] {taskinstance.py:1400} INFO - Marking task as FAILED. dag_id=weather_data_pipeline, task_id=check_api_Zhmerynka, execution_date=20231130T060000, start_date=20231130T105728, end_date=20231130T105729
[2023-11-30T12:57:29.162+0200] {standard_task_runner.py:104} ERROR - Failed to execute job 120 for task check_api_Zhmerynka (401:Unauthorized; 20580)
[2023-11-30T12:57:29.180+0200] {local_task_job_runner.py:228} INFO - Task exited with return code 1
[2023-11-30T12:57:29.252+0200] {taskinstance.py:2778} INFO - 0 downstream tasks scheduled from follow-on schedule check
[2023-11-30T13:15:54.292+0200] {taskinstance.py:1159} INFO - Dependencies all met for dep_context=non-requeueable deps ti=<TaskInstance: weather_data_pipeline.check_api_Zhmerynka scheduled__2023-11-30T06:00:00+00:00 [queued]>
[2023-11-30T13:15:54.299+0200] {taskinstance.py:1159} INFO - Dependencies all met for dep_context=requeueable deps ti=<TaskInstance: weather_data_pipeline.check_api_Zhmerynka scheduled__2023-11-30T06:00:00+00:00 [queued]>
[2023-11-30T13:15:54.299+0200] {taskinstance.py:1361} INFO - Starting attempt 1 of 1
[2023-11-30T13:15:54.317+0200] {taskinstance.py:1382} INFO - Executing <Task(HttpSensor): check_api_Zhmerynka> on 2023-11-30 06:00:00+00:00
[2023-11-30T13:15:54.319+0200] {standard_task_runner.py:57} INFO - Started process 22747 to run task
[2023-11-30T13:15:54.323+0200] {standard_task_runner.py:84} INFO - Running: ['airflow', 'tasks', 'run', 'weather_data_pipeline', 'check_api_Zhmerynka', 'scheduled__2023-11-30T06:00:00+00:00', '--job-id', '211', '--raw', '--subdir', 'DAGS_FOLDER/weather_pipeline.py', '--cfg-path', '/tmp/tmpzpywokpc']
[2023-11-30T13:15:54.326+0200] {standard_task_runner.py:85} INFO - Job 211: Subtask check_api_Zhmerynka
[2023-11-30T13:15:54.363+0200] {task_command.py:416} INFO - Running <TaskInstance: weather_data_pipeline.check_api_Zhmerynka scheduled__2023-11-30T06:00:00+00:00 [running]> on host DESKTOP-VD1PANR.
[2023-11-30T13:15:54.493+0200] {taskinstance.py:1662} INFO - Exporting env vars: AIRFLOW_CTX_DAG_OWNER='airflow' AIRFLOW_CTX_DAG_ID='weather_data_pipeline' AIRFLOW_CTX_TASK_ID='check_api_Zhmerynka' AIRFLOW_CTX_EXECUTION_DATE='2023-11-30T06:00:00+00:00' AIRFLOW_CTX_TRY_NUMBER='1' AIRFLOW_CTX_DAG_RUN_ID='scheduled__2023-11-30T06:00:00+00:00'
[2023-11-30T13:15:54.494+0200] {http.py:130} INFO - Poking: data/3.0/onecall
[2023-11-30T13:15:54.499+0200] {base.py:73} INFO - Using connection ID 'openweathermap_conn' for task execution.
[2023-11-30T13:15:54.586+0200] {http.py:178} ERROR - HTTP error: Bad Request
[2023-11-30T13:15:54.586+0200] {http.py:179} ERROR - {"cod":"400","message":"no location specified"}
[2023-11-30T13:15:54.590+0200] {taskinstance.py:1937} ERROR - Task failed with exception
Traceback (most recent call last):
  File "/home/seva/.local/lib/python3.10/site-packages/airflow/providers/http/hooks/http.py", line 176, in check_response
    response.raise_for_status()
  File "/home/seva/.local/lib/python3.10/site-packages/requests/models.py", line 1021, in raise_for_status
    raise HTTPError(http_error_msg, response=self)
requests.exceptions.HTTPError: 400 Client Error: Bad Request for url: http://api.openweathermap.org/data/3.0/onecall?appid=***&q=Zhmerynka

During handling of the above exception, another exception occurred:

Traceback (most recent call last):
  File "/home/seva/.local/lib/python3.10/site-packages/airflow/sensors/base.py", line 257, in execute
    raise e
  File "/home/seva/.local/lib/python3.10/site-packages/airflow/sensors/base.py", line 239, in execute
    poke_return = self.poke(context)
  File "/home/seva/.local/lib/python3.10/site-packages/airflow/providers/http/sensors/http.py", line 148, in poke
    raise exc
  File "/home/seva/.local/lib/python3.10/site-packages/airflow/providers/http/sensors/http.py", line 132, in poke
    response = hook.run(
  File "/home/seva/.local/lib/python3.10/site-packages/airflow/providers/http/hooks/http.py", line 166, in run
    return self.run_and_check(session, prepped_request, extra_options)
  File "/home/seva/.local/lib/python3.10/site-packages/airflow/providers/http/hooks/http.py", line 217, in run_and_check
    self.check_response(response)
  File "/home/seva/.local/lib/python3.10/site-packages/airflow/providers/http/hooks/http.py", line 180, in check_response
    raise AirflowException(str(response.status_code) + ":" + response.reason)
airflow.exceptions.AirflowException: 400:Bad Request
[2023-11-30T13:15:54.593+0200] {taskinstance.py:1400} INFO - Marking task as FAILED. dag_id=weather_data_pipeline, task_id=check_api_Zhmerynka, execution_date=20231130T060000, start_date=20231130T111554, end_date=20231130T111554
[2023-11-30T13:15:54.608+0200] {standard_task_runner.py:104} ERROR - Failed to execute job 211 for task check_api_Zhmerynka (400:Bad Request; 22747)
[2023-11-30T13:15:54.634+0200] {local_task_job_runner.py:228} INFO - Task exited with return code 1
[2023-11-30T13:15:54.701+0200] {taskinstance.py:2778} INFO - 0 downstream tasks scheduled from follow-on schedule check
[2023-11-30T13:25:49.296+0200] {taskinstance.py:1159} INFO - Dependencies all met for dep_context=non-requeueable deps ti=<TaskInstance: weather_data_pipeline.check_api_Zhmerynka scheduled__2023-11-30T06:00:00+00:00 [queued]>
[2023-11-30T13:25:49.304+0200] {taskinstance.py:1159} INFO - Dependencies all met for dep_context=requeueable deps ti=<TaskInstance: weather_data_pipeline.check_api_Zhmerynka scheduled__2023-11-30T06:00:00+00:00 [queued]>
[2023-11-30T13:25:49.304+0200] {taskinstance.py:1361} INFO - Starting attempt 1 of 1
[2023-11-30T13:25:49.323+0200] {taskinstance.py:1382} INFO - Executing <Task(HttpSensor): check_api_Zhmerynka> on 2023-11-30 06:00:00+00:00
[2023-11-30T13:25:49.325+0200] {standard_task_runner.py:57} INFO - Started process 23966 to run task
[2023-11-30T13:25:49.330+0200] {standard_task_runner.py:84} INFO - Running: ['airflow', 'tasks', 'run', 'weather_data_pipeline', 'check_api_Zhmerynka', 'scheduled__2023-11-30T06:00:00+00:00', '--job-id', '282', '--raw', '--subdir', 'DAGS_FOLDER/weather_pipeline.py', '--cfg-path', '/tmp/tmpblcqiwpj']
[2023-11-30T13:25:49.332+0200] {standard_task_runner.py:85} INFO - Job 282: Subtask check_api_Zhmerynka
[2023-11-30T13:25:49.467+0200] {task_command.py:416} INFO - Running <TaskInstance: weather_data_pipeline.check_api_Zhmerynka scheduled__2023-11-30T06:00:00+00:00 [running]> on host DESKTOP-VD1PANR.
[2023-11-30T13:25:49.547+0200] {taskinstance.py:1662} INFO - Exporting env vars: AIRFLOW_CTX_DAG_OWNER='airflow' AIRFLOW_CTX_DAG_ID='weather_data_pipeline' AIRFLOW_CTX_TASK_ID='check_api_Zhmerynka' AIRFLOW_CTX_EXECUTION_DATE='2023-11-30T06:00:00+00:00' AIRFLOW_CTX_TRY_NUMBER='1' AIRFLOW_CTX_DAG_RUN_ID='scheduled__2023-11-30T06:00:00+00:00'
[2023-11-30T13:25:49.548+0200] {http.py:130} INFO - Poking: data/3.0/onecall
[2023-11-30T13:25:49.554+0200] {base.py:73} INFO - Using connection ID 'openweathermap_conn' for task execution.
[2023-11-30T13:25:49.647+0200] {http.py:178} ERROR - HTTP error: Unauthorized
[2023-11-30T13:25:49.648+0200] {http.py:179} ERROR - {"cod":401, "message": "Please note that using One Call 3.0 requires a separate subscription to the One Call by Call plan. Learn more here https://openweathermap.org/price. If you have a valid subscription to the One Call by Call plan, but still receive this error, then please see https://openweathermap.org/faq#error401 for more info."}
[2023-11-30T13:25:49.656+0200] {taskinstance.py:1937} ERROR - Task failed with exception
Traceback (most recent call last):
  File "/home/seva/.local/lib/python3.10/site-packages/airflow/providers/http/hooks/http.py", line 176, in check_response
    response.raise_for_status()
  File "/home/seva/.local/lib/python3.10/site-packages/requests/models.py", line 1021, in raise_for_status
    raise HTTPError(http_error_msg, response=self)
requests.exceptions.HTTPError: 401 Client Error: Unauthorized for url: http://api.openweathermap.org/data/3.0/onecall?appid=***&q=Zhmerynka

During handling of the above exception, another exception occurred:

Traceback (most recent call last):
  File "/home/seva/.local/lib/python3.10/site-packages/airflow/sensors/base.py", line 257, in execute
    raise e
  File "/home/seva/.local/lib/python3.10/site-packages/airflow/sensors/base.py", line 239, in execute
    poke_return = self.poke(context)
  File "/home/seva/.local/lib/python3.10/site-packages/airflow/providers/http/sensors/http.py", line 148, in poke
    raise exc
  File "/home/seva/.local/lib/python3.10/site-packages/airflow/providers/http/sensors/http.py", line 132, in poke
    response = hook.run(
  File "/home/seva/.local/lib/python3.10/site-packages/airflow/providers/http/hooks/http.py", line 166, in run
    return self.run_and_check(session, prepped_request, extra_options)
  File "/home/seva/.local/lib/python3.10/site-packages/airflow/providers/http/hooks/http.py", line 217, in run_and_check
    self.check_response(response)
  File "/home/seva/.local/lib/python3.10/site-packages/airflow/providers/http/hooks/http.py", line 180, in check_response
    raise AirflowException(str(response.status_code) + ":" + response.reason)
airflow.exceptions.AirflowException: 401:Unauthorized
[2023-11-30T13:25:49.659+0200] {taskinstance.py:1400} INFO - Marking task as FAILED. dag_id=weather_data_pipeline, task_id=check_api_Zhmerynka, execution_date=20231130T060000, start_date=20231130T112549, end_date=20231130T112549
[2023-11-30T13:25:49.688+0200] {standard_task_runner.py:104} ERROR - Failed to execute job 282 for task check_api_Zhmerynka (401:Unauthorized; 23966)
[2023-11-30T13:25:49.708+0200] {local_task_job_runner.py:228} INFO - Task exited with return code 1
[2023-11-30T13:25:49.781+0200] {taskinstance.py:2778} INFO - 0 downstream tasks scheduled from follow-on schedule check
