[2023-11-30T12:58:00.223+0200] {taskinstance.py:1159} INFO - Dependencies all met for dep_context=non-requeueable deps ti=<TaskInstance: weather_data_pipeline.check_api_Odesa scheduled__2023-11-30T09:00:00+00:00 [queued]>
[2023-11-30T12:58:00.229+0200] {taskinstance.py:1159} INFO - Dependencies all met for dep_context=requeueable deps ti=<TaskInstance: weather_data_pipeline.check_api_Odesa scheduled__2023-11-30T09:00:00+00:00 [queued]>
[2023-11-30T12:58:00.229+0200] {taskinstance.py:1361} INFO - Starting attempt 1 of 1
[2023-11-30T12:58:00.249+0200] {taskinstance.py:1382} INFO - Executing <Task(HttpSensor): check_api_Odesa> on 2023-11-30 09:00:00+00:00
[2023-11-30T12:58:00.253+0200] {standard_task_runner.py:57} INFO - Started process 20669 to run task
[2023-11-30T12:58:00.258+0200] {standard_task_runner.py:84} INFO - Running: ['airflow', 'tasks', 'run', 'weather_data_pipeline', 'check_api_Odesa', 'scheduled__2023-11-30T09:00:00+00:00', '--job-id', '136', '--raw', '--subdir', 'DAGS_FOLDER/weather_pipeline.py', '--cfg-path', '/tmp/tmp119osary']
[2023-11-30T12:58:00.260+0200] {standard_task_runner.py:85} INFO - Job 136: Subtask check_api_Odesa
[2023-11-30T12:58:00.305+0200] {task_command.py:416} INFO - Running <TaskInstance: weather_data_pipeline.check_api_Odesa scheduled__2023-11-30T09:00:00+00:00 [running]> on host DESKTOP-VD1PANR.
[2023-11-30T12:58:00.421+0200] {taskinstance.py:1662} INFO - Exporting env vars: AIRFLOW_CTX_DAG_OWNER='airflow' AIRFLOW_CTX_DAG_ID='weather_data_pipeline' AIRFLOW_CTX_TASK_ID='check_api_Odesa' AIRFLOW_CTX_EXECUTION_DATE='2023-11-30T09:00:00+00:00' AIRFLOW_CTX_TRY_NUMBER='1' AIRFLOW_CTX_DAG_RUN_ID='scheduled__2023-11-30T09:00:00+00:00'
[2023-11-30T12:58:00.422+0200] {http.py:130} INFO - Poking: data/3.0/onecall
[2023-11-30T12:58:00.425+0200] {base.py:73} INFO - Using connection ID 'openweathermap_conn' for task execution.
[2023-11-30T12:58:00.581+0200] {http.py:178} ERROR - HTTP error: Unauthorized
[2023-11-30T12:58:00.582+0200] {http.py:179} ERROR - {"cod":401, "message": "Please note that using One Call 3.0 requires a separate subscription to the One Call by Call plan. Learn more here https://openweathermap.org/price. If you have a valid subscription to the One Call by Call plan, but still receive this error, then please see https://openweathermap.org/faq#error401 for more info."}
[2023-11-30T12:58:00.587+0200] {taskinstance.py:1937} ERROR - Task failed with exception
Traceback (most recent call last):
  File "/home/seva/.local/lib/python3.10/site-packages/airflow/providers/http/hooks/http.py", line 176, in check_response
    response.raise_for_status()
  File "/home/seva/.local/lib/python3.10/site-packages/requests/models.py", line 1021, in raise_for_status
    raise HTTPError(http_error_msg, response=self)
requests.exceptions.HTTPError: 401 Client Error: Unauthorized for url: http://api.openweathermap.org/data/3.0/onecall?appid=***&q=Odesa

During handling of the above exception, another exception occurred:

Traceback (most recent call last):
  File "/home/seva/.local/lib/python3.10/site-packages/airflow/sensors/base.py", line 257, in execute
    raise e
  File "/home/seva/.local/lib/python3.10/site-packages/airflow/sensors/base.py", line 239, in execute
    poke_return = self.poke(context)
  File "/home/seva/.local/lib/python3.10/site-packages/airflow/providers/http/sensors/http.py", line 148, in poke
    raise exc
  File "/home/seva/.local/lib/python3.10/site-packages/airflow/providers/http/sensors/http.py", line 132, in poke
    response = hook.run(
  File "/home/seva/.local/lib/python3.10/site-packages/airflow/providers/http/hooks/http.py", line 166, in run
    return self.run_and_check(session, prepped_request, extra_options)
  File "/home/seva/.local/lib/python3.10/site-packages/airflow/providers/http/hooks/http.py", line 217, in run_and_check
    self.check_response(response)
  File "/home/seva/.local/lib/python3.10/site-packages/airflow/providers/http/hooks/http.py", line 180, in check_response
    raise AirflowException(str(response.status_code) + ":" + response.reason)
airflow.exceptions.AirflowException: 401:Unauthorized
[2023-11-30T12:58:00.589+0200] {taskinstance.py:1400} INFO - Marking task as FAILED. dag_id=weather_data_pipeline, task_id=check_api_Odesa, execution_date=20231130T090000, start_date=20231130T105800, end_date=20231130T105800
[2023-11-30T12:58:00.620+0200] {standard_task_runner.py:104} ERROR - Failed to execute job 136 for task check_api_Odesa (401:Unauthorized; 20669)
[2023-11-30T12:58:00.660+0200] {local_task_job_runner.py:228} INFO - Task exited with return code 1
[2023-11-30T12:58:00.732+0200] {taskinstance.py:2778} INFO - 0 downstream tasks scheduled from follow-on schedule check
[2023-11-30T13:16:24.939+0200] {taskinstance.py:1159} INFO - Dependencies all met for dep_context=non-requeueable deps ti=<TaskInstance: weather_data_pipeline.check_api_Odesa scheduled__2023-11-30T09:00:00+00:00 [queued]>
[2023-11-30T13:16:24.949+0200] {taskinstance.py:1159} INFO - Dependencies all met for dep_context=requeueable deps ti=<TaskInstance: weather_data_pipeline.check_api_Odesa scheduled__2023-11-30T09:00:00+00:00 [queued]>
[2023-11-30T13:16:24.949+0200] {taskinstance.py:1361} INFO - Starting attempt 1 of 1
[2023-11-30T13:16:24.971+0200] {taskinstance.py:1382} INFO - Executing <Task(HttpSensor): check_api_Odesa> on 2023-11-30 09:00:00+00:00
[2023-11-30T13:16:24.974+0200] {standard_task_runner.py:57} INFO - Started process 22838 to run task
[2023-11-30T13:16:24.979+0200] {standard_task_runner.py:84} INFO - Running: ['airflow', 'tasks', 'run', 'weather_data_pipeline', 'check_api_Odesa', 'scheduled__2023-11-30T09:00:00+00:00', '--job-id', '228', '--raw', '--subdir', 'DAGS_FOLDER/weather_pipeline.py', '--cfg-path', '/tmp/tmprvmd6565']
[2023-11-30T13:16:24.981+0200] {standard_task_runner.py:85} INFO - Job 228: Subtask check_api_Odesa
[2023-11-30T13:16:25.028+0200] {task_command.py:416} INFO - Running <TaskInstance: weather_data_pipeline.check_api_Odesa scheduled__2023-11-30T09:00:00+00:00 [running]> on host DESKTOP-VD1PANR.
[2023-11-30T13:16:25.148+0200] {taskinstance.py:1662} INFO - Exporting env vars: AIRFLOW_CTX_DAG_OWNER='airflow' AIRFLOW_CTX_DAG_ID='weather_data_pipeline' AIRFLOW_CTX_TASK_ID='check_api_Odesa' AIRFLOW_CTX_EXECUTION_DATE='2023-11-30T09:00:00+00:00' AIRFLOW_CTX_TRY_NUMBER='1' AIRFLOW_CTX_DAG_RUN_ID='scheduled__2023-11-30T09:00:00+00:00'
[2023-11-30T13:16:25.149+0200] {http.py:130} INFO - Poking: data/3.0/onecall
[2023-11-30T13:16:25.153+0200] {base.py:73} INFO - Using connection ID 'openweathermap_conn' for task execution.
[2023-11-30T13:16:25.432+0200] {http.py:178} ERROR - HTTP error: Bad Request
[2023-11-30T13:16:25.433+0200] {http.py:179} ERROR - {"cod":"400","message":"no location specified"}
[2023-11-30T13:16:25.439+0200] {taskinstance.py:1937} ERROR - Task failed with exception
Traceback (most recent call last):
  File "/home/seva/.local/lib/python3.10/site-packages/airflow/providers/http/hooks/http.py", line 176, in check_response
    response.raise_for_status()
  File "/home/seva/.local/lib/python3.10/site-packages/requests/models.py", line 1021, in raise_for_status
    raise HTTPError(http_error_msg, response=self)
requests.exceptions.HTTPError: 400 Client Error: Bad Request for url: http://api.openweathermap.org/data/3.0/onecall?appid=***&q=Odesa

During handling of the above exception, another exception occurred:

Traceback (most recent call last):
  File "/home/seva/.local/lib/python3.10/site-packages/airflow/sensors/base.py", line 257, in execute
    raise e
  File "/home/seva/.local/lib/python3.10/site-packages/airflow/sensors/base.py", line 239, in execute
    poke_return = self.poke(context)
  File "/home/seva/.local/lib/python3.10/site-packages/airflow/providers/http/sensors/http.py", line 148, in poke
    raise exc
  File "/home/seva/.local/lib/python3.10/site-packages/airflow/providers/http/sensors/http.py", line 132, in poke
    response = hook.run(
  File "/home/seva/.local/lib/python3.10/site-packages/airflow/providers/http/hooks/http.py", line 166, in run
    return self.run_and_check(session, prepped_request, extra_options)
  File "/home/seva/.local/lib/python3.10/site-packages/airflow/providers/http/hooks/http.py", line 217, in run_and_check
    self.check_response(response)
  File "/home/seva/.local/lib/python3.10/site-packages/airflow/providers/http/hooks/http.py", line 180, in check_response
    raise AirflowException(str(response.status_code) + ":" + response.reason)
airflow.exceptions.AirflowException: 400:Bad Request
[2023-11-30T13:16:25.441+0200] {taskinstance.py:1400} INFO - Marking task as FAILED. dag_id=weather_data_pipeline, task_id=check_api_Odesa, execution_date=20231130T090000, start_date=20231130T111624, end_date=20231130T111625
[2023-11-30T13:16:25.470+0200] {standard_task_runner.py:104} ERROR - Failed to execute job 228 for task check_api_Odesa (400:Bad Request; 22838)
[2023-11-30T13:16:25.495+0200] {local_task_job_runner.py:228} INFO - Task exited with return code 1
[2023-11-30T13:16:25.565+0200] {taskinstance.py:2778} INFO - 0 downstream tasks scheduled from follow-on schedule check
[2023-11-30T13:26:22.366+0200] {taskinstance.py:1159} INFO - Dependencies all met for dep_context=non-requeueable deps ti=<TaskInstance: weather_data_pipeline.check_api_Odesa scheduled__2023-11-30T09:00:00+00:00 [queued]>
[2023-11-30T13:26:22.374+0200] {taskinstance.py:1159} INFO - Dependencies all met for dep_context=requeueable deps ti=<TaskInstance: weather_data_pipeline.check_api_Odesa scheduled__2023-11-30T09:00:00+00:00 [queued]>
[2023-11-30T13:26:22.374+0200] {taskinstance.py:1361} INFO - Starting attempt 1 of 1
[2023-11-30T13:26:22.394+0200] {taskinstance.py:1382} INFO - Executing <Task(HttpSensor): check_api_Odesa> on 2023-11-30 09:00:00+00:00
[2023-11-30T13:26:22.397+0200] {standard_task_runner.py:57} INFO - Started process 24061 to run task
[2023-11-30T13:26:22.401+0200] {standard_task_runner.py:84} INFO - Running: ['airflow', 'tasks', 'run', 'weather_data_pipeline', 'check_api_Odesa', 'scheduled__2023-11-30T09:00:00+00:00', '--job-id', '299', '--raw', '--subdir', 'DAGS_FOLDER/weather_pipeline.py', '--cfg-path', '/tmp/tmph89o1sk6']
[2023-11-30T13:26:22.403+0200] {standard_task_runner.py:85} INFO - Job 299: Subtask check_api_Odesa
[2023-11-30T13:26:22.449+0200] {task_command.py:416} INFO - Running <TaskInstance: weather_data_pipeline.check_api_Odesa scheduled__2023-11-30T09:00:00+00:00 [running]> on host DESKTOP-VD1PANR.
[2023-11-30T13:26:22.573+0200] {taskinstance.py:1662} INFO - Exporting env vars: AIRFLOW_CTX_DAG_OWNER='airflow' AIRFLOW_CTX_DAG_ID='weather_data_pipeline' AIRFLOW_CTX_TASK_ID='check_api_Odesa' AIRFLOW_CTX_EXECUTION_DATE='2023-11-30T09:00:00+00:00' AIRFLOW_CTX_TRY_NUMBER='1' AIRFLOW_CTX_DAG_RUN_ID='scheduled__2023-11-30T09:00:00+00:00'
[2023-11-30T13:26:22.574+0200] {http.py:130} INFO - Poking: data/3.0/onecall
[2023-11-30T13:26:22.578+0200] {base.py:73} INFO - Using connection ID 'openweathermap_conn' for task execution.
[2023-11-30T13:26:22.660+0200] {http.py:178} ERROR - HTTP error: Unauthorized
[2023-11-30T13:26:22.661+0200] {http.py:179} ERROR - {"cod":401, "message": "Please note that using One Call 3.0 requires a separate subscription to the One Call by Call plan. Learn more here https://openweathermap.org/price. If you have a valid subscription to the One Call by Call plan, but still receive this error, then please see https://openweathermap.org/faq#error401 for more info."}
[2023-11-30T13:26:22.666+0200] {taskinstance.py:1937} ERROR - Task failed with exception
Traceback (most recent call last):
  File "/home/seva/.local/lib/python3.10/site-packages/airflow/providers/http/hooks/http.py", line 176, in check_response
    response.raise_for_status()
  File "/home/seva/.local/lib/python3.10/site-packages/requests/models.py", line 1021, in raise_for_status
    raise HTTPError(http_error_msg, response=self)
requests.exceptions.HTTPError: 401 Client Error: Unauthorized for url: http://api.openweathermap.org/data/3.0/onecall?appid=***&q=Odesa

During handling of the above exception, another exception occurred:

Traceback (most recent call last):
  File "/home/seva/.local/lib/python3.10/site-packages/airflow/sensors/base.py", line 257, in execute
    raise e
  File "/home/seva/.local/lib/python3.10/site-packages/airflow/sensors/base.py", line 239, in execute
    poke_return = self.poke(context)
  File "/home/seva/.local/lib/python3.10/site-packages/airflow/providers/http/sensors/http.py", line 148, in poke
    raise exc
  File "/home/seva/.local/lib/python3.10/site-packages/airflow/providers/http/sensors/http.py", line 132, in poke
    response = hook.run(
  File "/home/seva/.local/lib/python3.10/site-packages/airflow/providers/http/hooks/http.py", line 166, in run
    return self.run_and_check(session, prepped_request, extra_options)
  File "/home/seva/.local/lib/python3.10/site-packages/airflow/providers/http/hooks/http.py", line 217, in run_and_check
    self.check_response(response)
  File "/home/seva/.local/lib/python3.10/site-packages/airflow/providers/http/hooks/http.py", line 180, in check_response
    raise AirflowException(str(response.status_code) + ":" + response.reason)
airflow.exceptions.AirflowException: 401:Unauthorized
[2023-11-30T13:26:22.669+0200] {taskinstance.py:1400} INFO - Marking task as FAILED. dag_id=weather_data_pipeline, task_id=check_api_Odesa, execution_date=20231130T090000, start_date=20231130T112622, end_date=20231130T112622
[2023-11-30T13:26:22.688+0200] {standard_task_runner.py:104} ERROR - Failed to execute job 299 for task check_api_Odesa (401:Unauthorized; 24061)
[2023-11-30T13:26:22.709+0200] {local_task_job_runner.py:228} INFO - Task exited with return code 1
[2023-11-30T13:26:22.786+0200] {taskinstance.py:2778} INFO - 0 downstream tasks scheduled from follow-on schedule check
