[2023-11-30T12:41:55.193+0200] {taskinstance.py:1159} INFO - Dependencies all met for dep_context=non-requeueable deps ti=<TaskInstance: weather_data_pipeline.check_api_Lviv scheduled__2023-11-30T04:00:00+00:00 [queued]>
[2023-11-30T12:41:55.200+0200] {taskinstance.py:1159} INFO - Dependencies all met for dep_context=requeueable deps ti=<TaskInstance: weather_data_pipeline.check_api_Lviv scheduled__2023-11-30T04:00:00+00:00 [queued]>
[2023-11-30T12:41:55.200+0200] {taskinstance.py:1361} INFO - Starting attempt 1 of 1
[2023-11-30T12:41:55.222+0200] {taskinstance.py:1382} INFO - Executing <Task(HttpSensor): check_api_Lviv> on 2023-11-30 04:00:00+00:00
[2023-11-30T12:41:55.225+0200] {standard_task_runner.py:57} INFO - Started process 18665 to run task
[2023-11-30T12:41:55.229+0200] {standard_task_runner.py:84} INFO - Running: ['airflow', 'tasks', 'run', 'weather_data_pipeline', 'check_api_Lviv', 'scheduled__2023-11-30T04:00:00+00:00', '--job-id', '37', '--raw', '--subdir', 'DAGS_FOLDER/weather_pipeline.py', '--cfg-path', '/tmp/tmpstwux415']
[2023-11-30T12:41:55.231+0200] {standard_task_runner.py:85} INFO - Job 37: Subtask check_api_Lviv
[2023-11-30T12:41:55.283+0200] {task_command.py:416} INFO - Running <TaskInstance: weather_data_pipeline.check_api_Lviv scheduled__2023-11-30T04:00:00+00:00 [running]> on host DESKTOP-VD1PANR.
[2023-11-30T12:41:55.468+0200] {taskinstance.py:1662} INFO - Exporting env vars: AIRFLOW_CTX_DAG_OWNER='airflow' AIRFLOW_CTX_DAG_ID='weather_data_pipeline' AIRFLOW_CTX_TASK_ID='check_api_Lviv' AIRFLOW_CTX_EXECUTION_DATE='2023-11-30T04:00:00+00:00' AIRFLOW_CTX_TRY_NUMBER='1' AIRFLOW_CTX_DAG_RUN_ID='scheduled__2023-11-30T04:00:00+00:00'
[2023-11-30T12:41:55.470+0200] {http.py:130} INFO - Poking: data/3.0/onecall
[2023-11-30T12:41:55.482+0200] {taskinstance.py:1937} ERROR - Task failed with exception
Traceback (most recent call last):
  File "/home/seva/.local/lib/python3.10/site-packages/airflow/sensors/base.py", line 257, in execute
    raise e
  File "/home/seva/.local/lib/python3.10/site-packages/airflow/sensors/base.py", line 239, in execute
    poke_return = self.poke(context)
  File "/home/seva/.local/lib/python3.10/site-packages/airflow/providers/http/sensors/http.py", line 148, in poke
    raise exc
  File "/home/seva/.local/lib/python3.10/site-packages/airflow/providers/http/sensors/http.py", line 132, in poke
    response = hook.run(
  File "/home/seva/.local/lib/python3.10/site-packages/airflow/providers/http/hooks/http.py", line 145, in run
    session = self.get_conn(headers)
  File "/home/seva/.local/lib/python3.10/site-packages/airflow/providers/http/hooks/http.py", line 98, in get_conn
    conn = self.get_connection(self.http_conn_id)
  File "/home/seva/.local/lib/python3.10/site-packages/airflow/hooks/base.py", line 72, in get_connection
    conn = Connection.get_connection_from_secrets(conn_id)
  File "/home/seva/.local/lib/python3.10/site-packages/airflow/models/connection.py", line 477, in get_connection_from_secrets
    raise AirflowNotFoundException(f"The conn_id `{conn_id}` isn't defined")
airflow.exceptions.AirflowNotFoundException: The conn_id `openweathermap_conn` isn't defined
[2023-11-30T12:41:55.485+0200] {taskinstance.py:1400} INFO - Marking task as FAILED. dag_id=weather_data_pipeline, task_id=check_api_Lviv, execution_date=20231130T040000, start_date=20231130T104155, end_date=20231130T104155
[2023-11-30T12:41:55.505+0200] {standard_task_runner.py:104} ERROR - Failed to execute job 37 for task check_api_Lviv (The conn_id `openweathermap_conn` isn't defined; 18665)
[2023-11-30T12:41:55.529+0200] {local_task_job_runner.py:228} INFO - Task exited with return code 1
[2023-11-30T12:41:55.621+0200] {taskinstance.py:2778} INFO - 0 downstream tasks scheduled from follow-on schedule check
[2023-11-30T12:56:55.324+0200] {taskinstance.py:1159} INFO - Dependencies all met for dep_context=non-requeueable deps ti=<TaskInstance: weather_data_pipeline.check_api_Lviv scheduled__2023-11-30T04:00:00+00:00 [queued]>
[2023-11-30T12:56:55.334+0200] {taskinstance.py:1159} INFO - Dependencies all met for dep_context=requeueable deps ti=<TaskInstance: weather_data_pipeline.check_api_Lviv scheduled__2023-11-30T04:00:00+00:00 [queued]>
[2023-11-30T12:56:55.335+0200] {taskinstance.py:1361} INFO - Starting attempt 1 of 1
[2023-11-30T12:56:55.356+0200] {taskinstance.py:1382} INFO - Executing <Task(HttpSensor): check_api_Lviv> on 2023-11-30 04:00:00+00:00
[2023-11-30T12:56:55.358+0200] {standard_task_runner.py:57} INFO - Started process 20488 to run task
[2023-11-30T12:56:55.363+0200] {standard_task_runner.py:84} INFO - Running: ['airflow', 'tasks', 'run', 'weather_data_pipeline', 'check_api_Lviv', 'scheduled__2023-11-30T04:00:00+00:00', '--job-id', '104', '--raw', '--subdir', 'DAGS_FOLDER/weather_pipeline.py', '--cfg-path', '/tmp/tmpiodra27c']
[2023-11-30T12:56:55.366+0200] {standard_task_runner.py:85} INFO - Job 104: Subtask check_api_Lviv
[2023-11-30T12:56:55.411+0200] {task_command.py:416} INFO - Running <TaskInstance: weather_data_pipeline.check_api_Lviv scheduled__2023-11-30T04:00:00+00:00 [running]> on host DESKTOP-VD1PANR.
[2023-11-30T12:56:55.544+0200] {taskinstance.py:1662} INFO - Exporting env vars: AIRFLOW_CTX_DAG_OWNER='airflow' AIRFLOW_CTX_DAG_ID='weather_data_pipeline' AIRFLOW_CTX_TASK_ID='check_api_Lviv' AIRFLOW_CTX_EXECUTION_DATE='2023-11-30T04:00:00+00:00' AIRFLOW_CTX_TRY_NUMBER='1' AIRFLOW_CTX_DAG_RUN_ID='scheduled__2023-11-30T04:00:00+00:00'
[2023-11-30T12:56:55.545+0200] {http.py:130} INFO - Poking: data/3.0/onecall
[2023-11-30T12:56:55.550+0200] {base.py:73} INFO - Using connection ID 'openweathermap_conn' for task execution.
[2023-11-30T12:56:55.638+0200] {http.py:178} ERROR - HTTP error: Unauthorized
[2023-11-30T12:56:55.638+0200] {http.py:179} ERROR - {"cod":401, "message": "Please note that using One Call 3.0 requires a separate subscription to the One Call by Call plan. Learn more here https://openweathermap.org/price. If you have a valid subscription to the One Call by Call plan, but still receive this error, then please see https://openweathermap.org/faq#error401 for more info."}
[2023-11-30T12:56:55.648+0200] {taskinstance.py:1937} ERROR - Task failed with exception
Traceback (most recent call last):
  File "/home/seva/.local/lib/python3.10/site-packages/airflow/providers/http/hooks/http.py", line 176, in check_response
    response.raise_for_status()
  File "/home/seva/.local/lib/python3.10/site-packages/requests/models.py", line 1021, in raise_for_status
    raise HTTPError(http_error_msg, response=self)
requests.exceptions.HTTPError: 401 Client Error: Unauthorized for url: http://api.openweathermap.org/data/3.0/onecall?appid=***&q=Lviv

During handling of the above exception, another exception occurred:

Traceback (most recent call last):
  File "/home/seva/.local/lib/python3.10/site-packages/airflow/sensors/base.py", line 257, in execute
    raise e
  File "/home/seva/.local/lib/python3.10/site-packages/airflow/sensors/base.py", line 239, in execute
    poke_return = self.poke(context)
  File "/home/seva/.local/lib/python3.10/site-packages/airflow/providers/http/sensors/http.py", line 148, in poke
    raise exc
  File "/home/seva/.local/lib/python3.10/site-packages/airflow/providers/http/sensors/http.py", line 132, in poke
    response = hook.run(
  File "/home/seva/.local/lib/python3.10/site-packages/airflow/providers/http/hooks/http.py", line 166, in run
    return self.run_and_check(session, prepped_request, extra_options)
  File "/home/seva/.local/lib/python3.10/site-packages/airflow/providers/http/hooks/http.py", line 217, in run_and_check
    self.check_response(response)
  File "/home/seva/.local/lib/python3.10/site-packages/airflow/providers/http/hooks/http.py", line 180, in check_response
    raise AirflowException(str(response.status_code) + ":" + response.reason)
airflow.exceptions.AirflowException: 401:Unauthorized
[2023-11-30T12:56:55.651+0200] {taskinstance.py:1400} INFO - Marking task as FAILED. dag_id=weather_data_pipeline, task_id=check_api_Lviv, execution_date=20231130T040000, start_date=20231130T105655, end_date=20231130T105655
[2023-11-30T12:56:55.677+0200] {standard_task_runner.py:104} ERROR - Failed to execute job 104 for task check_api_Lviv (401:Unauthorized; 20488)
[2023-11-30T12:56:55.714+0200] {local_task_job_runner.py:228} INFO - Task exited with return code 1
[2023-11-30T12:56:55.809+0200] {taskinstance.py:2778} INFO - 0 downstream tasks scheduled from follow-on schedule check
[2023-11-30T13:15:22.093+0200] {taskinstance.py:1159} INFO - Dependencies all met for dep_context=non-requeueable deps ti=<TaskInstance: weather_data_pipeline.check_api_Lviv scheduled__2023-11-30T04:00:00+00:00 [queued]>
[2023-11-30T13:15:22.099+0200] {taskinstance.py:1159} INFO - Dependencies all met for dep_context=requeueable deps ti=<TaskInstance: weather_data_pipeline.check_api_Lviv scheduled__2023-11-30T04:00:00+00:00 [queued]>
[2023-11-30T13:15:22.100+0200] {taskinstance.py:1361} INFO - Starting attempt 1 of 1
[2023-11-30T13:15:22.119+0200] {taskinstance.py:1382} INFO - Executing <Task(HttpSensor): check_api_Lviv> on 2023-11-30 04:00:00+00:00
[2023-11-30T13:15:22.121+0200] {standard_task_runner.py:57} INFO - Started process 22659 to run task
[2023-11-30T13:15:22.128+0200] {standard_task_runner.py:84} INFO - Running: ['airflow', 'tasks', 'run', 'weather_data_pipeline', 'check_api_Lviv', 'scheduled__2023-11-30T04:00:00+00:00', '--job-id', '195', '--raw', '--subdir', 'DAGS_FOLDER/weather_pipeline.py', '--cfg-path', '/tmp/tmpj90mt395']
[2023-11-30T13:15:22.130+0200] {standard_task_runner.py:85} INFO - Job 195: Subtask check_api_Lviv
[2023-11-30T13:15:22.168+0200] {task_command.py:416} INFO - Running <TaskInstance: weather_data_pipeline.check_api_Lviv scheduled__2023-11-30T04:00:00+00:00 [running]> on host DESKTOP-VD1PANR.
[2023-11-30T13:15:22.290+0200] {taskinstance.py:1662} INFO - Exporting env vars: AIRFLOW_CTX_DAG_OWNER='airflow' AIRFLOW_CTX_DAG_ID='weather_data_pipeline' AIRFLOW_CTX_TASK_ID='check_api_Lviv' AIRFLOW_CTX_EXECUTION_DATE='2023-11-30T04:00:00+00:00' AIRFLOW_CTX_TRY_NUMBER='1' AIRFLOW_CTX_DAG_RUN_ID='scheduled__2023-11-30T04:00:00+00:00'
[2023-11-30T13:15:22.291+0200] {http.py:130} INFO - Poking: data/3.0/onecall
[2023-11-30T13:15:22.294+0200] {base.py:73} INFO - Using connection ID 'openweathermap_conn' for task execution.
[2023-11-30T13:15:22.386+0200] {http.py:178} ERROR - HTTP error: Unauthorized
[2023-11-30T13:15:22.386+0200] {http.py:179} ERROR - {"cod":401, "message": "Please note that using One Call 3.0 requires a separate subscription to the One Call by Call plan. Learn more here https://openweathermap.org/price. If you have a valid subscription to the One Call by Call plan, but still receive this error, then please see https://openweathermap.org/faq#error401 for more info."}
[2023-11-30T13:15:22.393+0200] {taskinstance.py:1937} ERROR - Task failed with exception
Traceback (most recent call last):
  File "/home/seva/.local/lib/python3.10/site-packages/airflow/providers/http/hooks/http.py", line 176, in check_response
    response.raise_for_status()
  File "/home/seva/.local/lib/python3.10/site-packages/requests/models.py", line 1021, in raise_for_status
    raise HTTPError(http_error_msg, response=self)
requests.exceptions.HTTPError: 401 Client Error: Unauthorized for url: http://api.openweathermap.org/data/3.0/onecall?appid=***&q=Lviv

During handling of the above exception, another exception occurred:

Traceback (most recent call last):
  File "/home/seva/.local/lib/python3.10/site-packages/airflow/sensors/base.py", line 257, in execute
    raise e
  File "/home/seva/.local/lib/python3.10/site-packages/airflow/sensors/base.py", line 239, in execute
    poke_return = self.poke(context)
  File "/home/seva/.local/lib/python3.10/site-packages/airflow/providers/http/sensors/http.py", line 148, in poke
    raise exc
  File "/home/seva/.local/lib/python3.10/site-packages/airflow/providers/http/sensors/http.py", line 132, in poke
    response = hook.run(
  File "/home/seva/.local/lib/python3.10/site-packages/airflow/providers/http/hooks/http.py", line 166, in run
    return self.run_and_check(session, prepped_request, extra_options)
  File "/home/seva/.local/lib/python3.10/site-packages/airflow/providers/http/hooks/http.py", line 217, in run_and_check
    self.check_response(response)
  File "/home/seva/.local/lib/python3.10/site-packages/airflow/providers/http/hooks/http.py", line 180, in check_response
    raise AirflowException(str(response.status_code) + ":" + response.reason)
airflow.exceptions.AirflowException: 401:Unauthorized
[2023-11-30T13:15:22.398+0200] {taskinstance.py:1400} INFO - Marking task as FAILED. dag_id=weather_data_pipeline, task_id=check_api_Lviv, execution_date=20231130T040000, start_date=20231130T111522, end_date=20231130T111522
[2023-11-30T13:15:22.427+0200] {standard_task_runner.py:104} ERROR - Failed to execute job 195 for task check_api_Lviv (401:Unauthorized; 22659)
[2023-11-30T13:15:22.476+0200] {local_task_job_runner.py:228} INFO - Task exited with return code 1
[2023-11-30T13:15:22.605+0200] {taskinstance.py:2778} INFO - 0 downstream tasks scheduled from follow-on schedule check
[2023-11-30T13:25:09.600+0200] {taskinstance.py:1159} INFO - Dependencies all met for dep_context=non-requeueable deps ti=<TaskInstance: weather_data_pipeline.check_api_Lviv scheduled__2023-11-30T04:00:00+00:00 [queued]>
[2023-11-30T13:25:09.609+0200] {taskinstance.py:1159} INFO - Dependencies all met for dep_context=requeueable deps ti=<TaskInstance: weather_data_pipeline.check_api_Lviv scheduled__2023-11-30T04:00:00+00:00 [queued]>
[2023-11-30T13:25:09.609+0200] {taskinstance.py:1361} INFO - Starting attempt 1 of 1
[2023-11-30T13:25:09.632+0200] {taskinstance.py:1382} INFO - Executing <Task(HttpSensor): check_api_Lviv> on 2023-11-30 04:00:00+00:00
[2023-11-30T13:25:09.636+0200] {standard_task_runner.py:57} INFO - Started process 23864 to run task
[2023-11-30T13:25:09.641+0200] {standard_task_runner.py:84} INFO - Running: ['airflow', 'tasks', 'run', 'weather_data_pipeline', 'check_api_Lviv', 'scheduled__2023-11-30T04:00:00+00:00', '--job-id', '266', '--raw', '--subdir', 'DAGS_FOLDER/weather_pipeline.py', '--cfg-path', '/tmp/tmpos8pf12w']
[2023-11-30T13:25:09.643+0200] {standard_task_runner.py:85} INFO - Job 266: Subtask check_api_Lviv
[2023-11-30T13:25:09.693+0200] {task_command.py:416} INFO - Running <TaskInstance: weather_data_pipeline.check_api_Lviv scheduled__2023-11-30T04:00:00+00:00 [running]> on host DESKTOP-VD1PANR.
[2023-11-30T13:25:09.844+0200] {taskinstance.py:1662} INFO - Exporting env vars: AIRFLOW_CTX_DAG_OWNER='airflow' AIRFLOW_CTX_DAG_ID='weather_data_pipeline' AIRFLOW_CTX_TASK_ID='check_api_Lviv' AIRFLOW_CTX_EXECUTION_DATE='2023-11-30T04:00:00+00:00' AIRFLOW_CTX_TRY_NUMBER='1' AIRFLOW_CTX_DAG_RUN_ID='scheduled__2023-11-30T04:00:00+00:00'
[2023-11-30T13:25:09.845+0200] {http.py:130} INFO - Poking: data/3.0/onecall
[2023-11-30T13:25:09.852+0200] {base.py:73} INFO - Using connection ID 'openweathermap_conn' for task execution.
[2023-11-30T13:25:09.952+0200] {http.py:178} ERROR - HTTP error: Unauthorized
[2023-11-30T13:25:09.952+0200] {http.py:179} ERROR - {"cod":401, "message": "Please note that using One Call 3.0 requires a separate subscription to the One Call by Call plan. Learn more here https://openweathermap.org/price. If you have a valid subscription to the One Call by Call plan, but still receive this error, then please see https://openweathermap.org/faq#error401 for more info."}
[2023-11-30T13:25:09.957+0200] {taskinstance.py:1937} ERROR - Task failed with exception
Traceback (most recent call last):
  File "/home/seva/.local/lib/python3.10/site-packages/airflow/providers/http/hooks/http.py", line 176, in check_response
    response.raise_for_status()
  File "/home/seva/.local/lib/python3.10/site-packages/requests/models.py", line 1021, in raise_for_status
    raise HTTPError(http_error_msg, response=self)
requests.exceptions.HTTPError: 401 Client Error: Unauthorized for url: http://api.openweathermap.org/data/3.0/onecall?appid=***&q=Lviv

During handling of the above exception, another exception occurred:

Traceback (most recent call last):
  File "/home/seva/.local/lib/python3.10/site-packages/airflow/sensors/base.py", line 257, in execute
    raise e
  File "/home/seva/.local/lib/python3.10/site-packages/airflow/sensors/base.py", line 239, in execute
    poke_return = self.poke(context)
  File "/home/seva/.local/lib/python3.10/site-packages/airflow/providers/http/sensors/http.py", line 148, in poke
    raise exc
  File "/home/seva/.local/lib/python3.10/site-packages/airflow/providers/http/sensors/http.py", line 132, in poke
    response = hook.run(
  File "/home/seva/.local/lib/python3.10/site-packages/airflow/providers/http/hooks/http.py", line 166, in run
    return self.run_and_check(session, prepped_request, extra_options)
  File "/home/seva/.local/lib/python3.10/site-packages/airflow/providers/http/hooks/http.py", line 217, in run_and_check
    self.check_response(response)
  File "/home/seva/.local/lib/python3.10/site-packages/airflow/providers/http/hooks/http.py", line 180, in check_response
    raise AirflowException(str(response.status_code) + ":" + response.reason)
airflow.exceptions.AirflowException: 401:Unauthorized
[2023-11-30T13:25:09.962+0200] {taskinstance.py:1400} INFO - Marking task as FAILED. dag_id=weather_data_pipeline, task_id=check_api_Lviv, execution_date=20231130T040000, start_date=20231130T112509, end_date=20231130T112509
[2023-11-30T13:25:09.993+0200] {standard_task_runner.py:104} ERROR - Failed to execute job 266 for task check_api_Lviv (401:Unauthorized; 23864)
[2023-11-30T13:25:10.000+0200] {local_task_job_runner.py:228} INFO - Task exited with return code 1
[2023-11-30T13:25:10.088+0200] {taskinstance.py:2778} INFO - 0 downstream tasks scheduled from follow-on schedule check
