[2023-11-30T12:57:47.409+0200] {taskinstance.py:1159} INFO - Dependencies all met for dep_context=non-requeueable deps ti=<TaskInstance: weather_data_pipeline.check_api_Kyiv scheduled__2023-11-30T08:00:00+00:00 [queued]>
[2023-11-30T12:57:47.416+0200] {taskinstance.py:1159} INFO - Dependencies all met for dep_context=requeueable deps ti=<TaskInstance: weather_data_pipeline.check_api_Kyiv scheduled__2023-11-30T08:00:00+00:00 [queued]>
[2023-11-30T12:57:47.417+0200] {taskinstance.py:1361} INFO - Starting attempt 1 of 1
[2023-11-30T12:57:47.437+0200] {taskinstance.py:1382} INFO - Executing <Task(HttpSensor): check_api_Kyiv> on 2023-11-30 08:00:00+00:00
[2023-11-30T12:57:47.440+0200] {standard_task_runner.py:57} INFO - Started process 20631 to run task
[2023-11-30T12:57:47.445+0200] {standard_task_runner.py:84} INFO - Running: ['airflow', 'tasks', 'run', 'weather_data_pipeline', 'check_api_Kyiv', 'scheduled__2023-11-30T08:00:00+00:00', '--job-id', '129', '--raw', '--subdir', 'DAGS_FOLDER/weather_pipeline.py', '--cfg-path', '/tmp/tmpigzagp1t']
[2023-11-30T12:57:47.446+0200] {standard_task_runner.py:85} INFO - Job 129: Subtask check_api_Kyiv
[2023-11-30T12:57:47.495+0200] {task_command.py:416} INFO - Running <TaskInstance: weather_data_pipeline.check_api_Kyiv scheduled__2023-11-30T08:00:00+00:00 [running]> on host DESKTOP-VD1PANR.
[2023-11-30T12:57:47.657+0200] {taskinstance.py:1662} INFO - Exporting env vars: AIRFLOW_CTX_DAG_OWNER='airflow' AIRFLOW_CTX_DAG_ID='weather_data_pipeline' AIRFLOW_CTX_TASK_ID='check_api_Kyiv' AIRFLOW_CTX_EXECUTION_DATE='2023-11-30T08:00:00+00:00' AIRFLOW_CTX_TRY_NUMBER='1' AIRFLOW_CTX_DAG_RUN_ID='scheduled__2023-11-30T08:00:00+00:00'
[2023-11-30T12:57:47.658+0200] {http.py:130} INFO - Poking: data/3.0/onecall
[2023-11-30T12:57:47.661+0200] {base.py:73} INFO - Using connection ID 'openweathermap_conn' for task execution.
[2023-11-30T12:57:47.747+0200] {http.py:178} ERROR - HTTP error: Unauthorized
[2023-11-30T12:57:47.748+0200] {http.py:179} ERROR - {"cod":401, "message": "Please note that using One Call 3.0 requires a separate subscription to the One Call by Call plan. Learn more here https://openweathermap.org/price. If you have a valid subscription to the One Call by Call plan, but still receive this error, then please see https://openweathermap.org/faq#error401 for more info."}
[2023-11-30T12:57:47.755+0200] {taskinstance.py:1937} ERROR - Task failed with exception
Traceback (most recent call last):
  File "/home/seva/.local/lib/python3.10/site-packages/airflow/providers/http/hooks/http.py", line 176, in check_response
    response.raise_for_status()
  File "/home/seva/.local/lib/python3.10/site-packages/requests/models.py", line 1021, in raise_for_status
    raise HTTPError(http_error_msg, response=self)
requests.exceptions.HTTPError: 401 Client Error: Unauthorized for url: http://api.openweathermap.org/data/3.0/onecall?appid=***&q=Kyiv

During handling of the above exception, another exception occurred:

Traceback (most recent call last):
  File "/home/seva/.local/lib/python3.10/site-packages/airflow/sensors/base.py", line 257, in execute
    raise e
  File "/home/seva/.local/lib/python3.10/site-packages/airflow/sensors/base.py", line 239, in execute
    poke_return = self.poke(context)
  File "/home/seva/.local/lib/python3.10/site-packages/airflow/providers/http/sensors/http.py", line 148, in poke
    raise exc
  File "/home/seva/.local/lib/python3.10/site-packages/airflow/providers/http/sensors/http.py", line 132, in poke
    response = hook.run(
  File "/home/seva/.local/lib/python3.10/site-packages/airflow/providers/http/hooks/http.py", line 166, in run
    return self.run_and_check(session, prepped_request, extra_options)
  File "/home/seva/.local/lib/python3.10/site-packages/airflow/providers/http/hooks/http.py", line 217, in run_and_check
    self.check_response(response)
  File "/home/seva/.local/lib/python3.10/site-packages/airflow/providers/http/hooks/http.py", line 180, in check_response
    raise AirflowException(str(response.status_code) + ":" + response.reason)
airflow.exceptions.AirflowException: 401:Unauthorized
[2023-11-30T12:57:47.758+0200] {taskinstance.py:1400} INFO - Marking task as FAILED. dag_id=weather_data_pipeline, task_id=check_api_Kyiv, execution_date=20231130T080000, start_date=20231130T105747, end_date=20231130T105747
[2023-11-30T12:57:47.775+0200] {standard_task_runner.py:104} ERROR - Failed to execute job 129 for task check_api_Kyiv (401:Unauthorized; 20631)
[2023-11-30T12:57:47.792+0200] {local_task_job_runner.py:228} INFO - Task exited with return code 1
[2023-11-30T12:57:47.863+0200] {taskinstance.py:2778} INFO - 0 downstream tasks scheduled from follow-on schedule check
[2023-11-30T13:16:10.697+0200] {taskinstance.py:1159} INFO - Dependencies all met for dep_context=non-requeueable deps ti=<TaskInstance: weather_data_pipeline.check_api_Kyiv scheduled__2023-11-30T08:00:00+00:00 [queued]>
[2023-11-30T13:16:10.705+0200] {taskinstance.py:1159} INFO - Dependencies all met for dep_context=requeueable deps ti=<TaskInstance: weather_data_pipeline.check_api_Kyiv scheduled__2023-11-30T08:00:00+00:00 [queued]>
[2023-11-30T13:16:10.706+0200] {taskinstance.py:1361} INFO - Starting attempt 1 of 1
[2023-11-30T13:16:10.728+0200] {taskinstance.py:1382} INFO - Executing <Task(HttpSensor): check_api_Kyiv> on 2023-11-30 08:00:00+00:00
[2023-11-30T13:16:10.730+0200] {standard_task_runner.py:57} INFO - Started process 22798 to run task
[2023-11-30T13:16:10.735+0200] {standard_task_runner.py:84} INFO - Running: ['airflow', 'tasks', 'run', 'weather_data_pipeline', 'check_api_Kyiv', 'scheduled__2023-11-30T08:00:00+00:00', '--job-id', '220', '--raw', '--subdir', 'DAGS_FOLDER/weather_pipeline.py', '--cfg-path', '/tmp/tmptv785c45']
[2023-11-30T13:16:10.737+0200] {standard_task_runner.py:85} INFO - Job 220: Subtask check_api_Kyiv
[2023-11-30T13:16:10.782+0200] {task_command.py:416} INFO - Running <TaskInstance: weather_data_pipeline.check_api_Kyiv scheduled__2023-11-30T08:00:00+00:00 [running]> on host DESKTOP-VD1PANR.
[2023-11-30T13:16:10.914+0200] {taskinstance.py:1662} INFO - Exporting env vars: AIRFLOW_CTX_DAG_OWNER='airflow' AIRFLOW_CTX_DAG_ID='weather_data_pipeline' AIRFLOW_CTX_TASK_ID='check_api_Kyiv' AIRFLOW_CTX_EXECUTION_DATE='2023-11-30T08:00:00+00:00' AIRFLOW_CTX_TRY_NUMBER='1' AIRFLOW_CTX_DAG_RUN_ID='scheduled__2023-11-30T08:00:00+00:00'
[2023-11-30T13:16:10.915+0200] {http.py:130} INFO - Poking: data/3.0/onecall
[2023-11-30T13:16:10.919+0200] {base.py:73} INFO - Using connection ID 'openweathermap_conn' for task execution.
[2023-11-30T13:16:10.993+0200] {http.py:178} ERROR - HTTP error: Bad Request
[2023-11-30T13:16:10.994+0200] {http.py:179} ERROR - {"cod":"400","message":"no location specified"}
[2023-11-30T13:16:11.001+0200] {taskinstance.py:1937} ERROR - Task failed with exception
Traceback (most recent call last):
  File "/home/seva/.local/lib/python3.10/site-packages/airflow/providers/http/hooks/http.py", line 176, in check_response
    response.raise_for_status()
  File "/home/seva/.local/lib/python3.10/site-packages/requests/models.py", line 1021, in raise_for_status
    raise HTTPError(http_error_msg, response=self)
requests.exceptions.HTTPError: 400 Client Error: Bad Request for url: http://api.openweathermap.org/data/3.0/onecall?appid=***&q=Kyiv

During handling of the above exception, another exception occurred:

Traceback (most recent call last):
  File "/home/seva/.local/lib/python3.10/site-packages/airflow/sensors/base.py", line 257, in execute
    raise e
  File "/home/seva/.local/lib/python3.10/site-packages/airflow/sensors/base.py", line 239, in execute
    poke_return = self.poke(context)
  File "/home/seva/.local/lib/python3.10/site-packages/airflow/providers/http/sensors/http.py", line 148, in poke
    raise exc
  File "/home/seva/.local/lib/python3.10/site-packages/airflow/providers/http/sensors/http.py", line 132, in poke
    response = hook.run(
  File "/home/seva/.local/lib/python3.10/site-packages/airflow/providers/http/hooks/http.py", line 166, in run
    return self.run_and_check(session, prepped_request, extra_options)
  File "/home/seva/.local/lib/python3.10/site-packages/airflow/providers/http/hooks/http.py", line 217, in run_and_check
    self.check_response(response)
  File "/home/seva/.local/lib/python3.10/site-packages/airflow/providers/http/hooks/http.py", line 180, in check_response
    raise AirflowException(str(response.status_code) + ":" + response.reason)
airflow.exceptions.AirflowException: 400:Bad Request
[2023-11-30T13:16:11.004+0200] {taskinstance.py:1400} INFO - Marking task as FAILED. dag_id=weather_data_pipeline, task_id=check_api_Kyiv, execution_date=20231130T080000, start_date=20231130T111610, end_date=20231130T111611
[2023-11-30T13:16:11.024+0200] {standard_task_runner.py:104} ERROR - Failed to execute job 220 for task check_api_Kyiv (400:Bad Request; 22798)
[2023-11-30T13:16:11.046+0200] {local_task_job_runner.py:228} INFO - Task exited with return code 1
[2023-11-30T13:16:11.118+0200] {taskinstance.py:2778} INFO - 0 downstream tasks scheduled from follow-on schedule check
[2023-11-30T13:26:08.334+0200] {taskinstance.py:1159} INFO - Dependencies all met for dep_context=non-requeueable deps ti=<TaskInstance: weather_data_pipeline.check_api_Kyiv scheduled__2023-11-30T08:00:00+00:00 [queued]>
[2023-11-30T13:26:08.345+0200] {taskinstance.py:1159} INFO - Dependencies all met for dep_context=requeueable deps ti=<TaskInstance: weather_data_pipeline.check_api_Kyiv scheduled__2023-11-30T08:00:00+00:00 [queued]>
[2023-11-30T13:26:08.346+0200] {taskinstance.py:1361} INFO - Starting attempt 1 of 1
[2023-11-30T13:26:08.370+0200] {taskinstance.py:1382} INFO - Executing <Task(HttpSensor): check_api_Kyiv> on 2023-11-30 08:00:00+00:00
[2023-11-30T13:26:08.372+0200] {standard_task_runner.py:57} INFO - Started process 24023 to run task
[2023-11-30T13:26:08.377+0200] {standard_task_runner.py:84} INFO - Running: ['airflow', 'tasks', 'run', 'weather_data_pipeline', 'check_api_Kyiv', 'scheduled__2023-11-30T08:00:00+00:00', '--job-id', '292', '--raw', '--subdir', 'DAGS_FOLDER/weather_pipeline.py', '--cfg-path', '/tmp/tmpu9w2pzqg']
[2023-11-30T13:26:08.379+0200] {standard_task_runner.py:85} INFO - Job 292: Subtask check_api_Kyiv
[2023-11-30T13:26:08.423+0200] {task_command.py:416} INFO - Running <TaskInstance: weather_data_pipeline.check_api_Kyiv scheduled__2023-11-30T08:00:00+00:00 [running]> on host DESKTOP-VD1PANR.
[2023-11-30T13:26:08.542+0200] {taskinstance.py:1662} INFO - Exporting env vars: AIRFLOW_CTX_DAG_OWNER='airflow' AIRFLOW_CTX_DAG_ID='weather_data_pipeline' AIRFLOW_CTX_TASK_ID='check_api_Kyiv' AIRFLOW_CTX_EXECUTION_DATE='2023-11-30T08:00:00+00:00' AIRFLOW_CTX_TRY_NUMBER='1' AIRFLOW_CTX_DAG_RUN_ID='scheduled__2023-11-30T08:00:00+00:00'
[2023-11-30T13:26:08.543+0200] {http.py:130} INFO - Poking: data/3.0/onecall
[2023-11-30T13:26:08.548+0200] {base.py:73} INFO - Using connection ID 'openweathermap_conn' for task execution.
[2023-11-30T13:26:08.651+0200] {http.py:178} ERROR - HTTP error: Unauthorized
[2023-11-30T13:26:08.651+0200] {http.py:179} ERROR - {"cod":401, "message": "Please note that using One Call 3.0 requires a separate subscription to the One Call by Call plan. Learn more here https://openweathermap.org/price. If you have a valid subscription to the One Call by Call plan, but still receive this error, then please see https://openweathermap.org/faq#error401 for more info."}
[2023-11-30T13:26:08.658+0200] {taskinstance.py:1937} ERROR - Task failed with exception
Traceback (most recent call last):
  File "/home/seva/.local/lib/python3.10/site-packages/airflow/providers/http/hooks/http.py", line 176, in check_response
    response.raise_for_status()
  File "/home/seva/.local/lib/python3.10/site-packages/requests/models.py", line 1021, in raise_for_status
    raise HTTPError(http_error_msg, response=self)
requests.exceptions.HTTPError: 401 Client Error: Unauthorized for url: http://api.openweathermap.org/data/3.0/onecall?appid=***&q=Kyiv

During handling of the above exception, another exception occurred:

Traceback (most recent call last):
  File "/home/seva/.local/lib/python3.10/site-packages/airflow/sensors/base.py", line 257, in execute
    raise e
  File "/home/seva/.local/lib/python3.10/site-packages/airflow/sensors/base.py", line 239, in execute
    poke_return = self.poke(context)
  File "/home/seva/.local/lib/python3.10/site-packages/airflow/providers/http/sensors/http.py", line 148, in poke
    raise exc
  File "/home/seva/.local/lib/python3.10/site-packages/airflow/providers/http/sensors/http.py", line 132, in poke
    response = hook.run(
  File "/home/seva/.local/lib/python3.10/site-packages/airflow/providers/http/hooks/http.py", line 166, in run
    return self.run_and_check(session, prepped_request, extra_options)
  File "/home/seva/.local/lib/python3.10/site-packages/airflow/providers/http/hooks/http.py", line 217, in run_and_check
    self.check_response(response)
  File "/home/seva/.local/lib/python3.10/site-packages/airflow/providers/http/hooks/http.py", line 180, in check_response
    raise AirflowException(str(response.status_code) + ":" + response.reason)
airflow.exceptions.AirflowException: 401:Unauthorized
[2023-11-30T13:26:08.660+0200] {taskinstance.py:1400} INFO - Marking task as FAILED. dag_id=weather_data_pipeline, task_id=check_api_Kyiv, execution_date=20231130T080000, start_date=20231130T112608, end_date=20231130T112608
[2023-11-30T13:26:08.692+0200] {standard_task_runner.py:104} ERROR - Failed to execute job 292 for task check_api_Kyiv (401:Unauthorized; 24023)
[2023-11-30T13:26:08.731+0200] {local_task_job_runner.py:228} INFO - Task exited with return code 1
[2023-11-30T13:26:08.811+0200] {taskinstance.py:2778} INFO - 0 downstream tasks scheduled from follow-on schedule check
