[2023-11-30T13:00:06.865+0200] {taskinstance.py:1159} INFO - Dependencies all met for dep_context=non-requeueable deps ti=<TaskInstance: weather_data_pipeline.check_api_Kyiv scheduled__2023-11-30T10:00:00+00:00 [queued]>
[2023-11-30T13:00:06.871+0200] {taskinstance.py:1159} INFO - Dependencies all met for dep_context=requeueable deps ti=<TaskInstance: weather_data_pipeline.check_api_Kyiv scheduled__2023-11-30T10:00:00+00:00 [queued]>
[2023-11-30T13:00:06.872+0200] {taskinstance.py:1361} INFO - Starting attempt 1 of 1
[2023-11-30T13:00:06.892+0200] {taskinstance.py:1382} INFO - Executing <Task(HttpSensor): check_api_Kyiv> on 2023-11-30 10:00:00+00:00
[2023-11-30T13:00:06.895+0200] {standard_task_runner.py:57} INFO - Started process 20905 to run task
[2023-11-30T13:00:06.900+0200] {standard_task_runner.py:84} INFO - Running: ['airflow', 'tasks', 'run', 'weather_data_pipeline', 'check_api_Kyiv', 'scheduled__2023-11-30T10:00:00+00:00', '--job-id', '140', '--raw', '--subdir', 'DAGS_FOLDER/weather_pipeline.py', '--cfg-path', '/tmp/tmpqwi7qtk8']
[2023-11-30T13:00:06.901+0200] {standard_task_runner.py:85} INFO - Job 140: Subtask check_api_Kyiv
[2023-11-30T13:00:06.946+0200] {task_command.py:416} INFO - Running <TaskInstance: weather_data_pipeline.check_api_Kyiv scheduled__2023-11-30T10:00:00+00:00 [running]> on host DESKTOP-VD1PANR.
[2023-11-30T13:00:07.075+0200] {taskinstance.py:1662} INFO - Exporting env vars: AIRFLOW_CTX_DAG_OWNER='airflow' AIRFLOW_CTX_DAG_ID='weather_data_pipeline' AIRFLOW_CTX_TASK_ID='check_api_Kyiv' AIRFLOW_CTX_EXECUTION_DATE='2023-11-30T10:00:00+00:00' AIRFLOW_CTX_TRY_NUMBER='1' AIRFLOW_CTX_DAG_RUN_ID='scheduled__2023-11-30T10:00:00+00:00'
[2023-11-30T13:00:07.076+0200] {http.py:130} INFO - Poking: data/3.0/onecall
[2023-11-30T13:00:07.080+0200] {base.py:73} INFO - Using connection ID 'openweathermap_conn' for task execution.
[2023-11-30T13:00:07.156+0200] {http.py:178} ERROR - HTTP error: Unauthorized
[2023-11-30T13:00:07.157+0200] {http.py:179} ERROR - {"cod":401, "message": "Please note that using One Call 3.0 requires a separate subscription to the One Call by Call plan. Learn more here https://openweathermap.org/price. If you have a valid subscription to the One Call by Call plan, but still receive this error, then please see https://openweathermap.org/faq#error401 for more info."}
[2023-11-30T13:00:07.161+0200] {taskinstance.py:1937} ERROR - Task failed with exception
Traceback (most recent call last):
  File "/home/seva/.local/lib/python3.10/site-packages/airflow/providers/http/hooks/http.py", line 176, in check_response
    response.raise_for_status()
  File "/home/seva/.local/lib/python3.10/site-packages/requests/models.py", line 1021, in raise_for_status
    raise HTTPError(http_error_msg, response=self)
requests.exceptions.HTTPError: 401 Client Error: Unauthorized for url: http://api.openweathermap.org/data/3.0/onecall?appid=***&q=Kyiv

During handling of the above exception, another exception occurred:

Traceback (most recent call last):
  File "/home/seva/.local/lib/python3.10/site-packages/airflow/sensors/base.py", line 257, in execute
    raise e
  File "/home/seva/.local/lib/python3.10/site-packages/airflow/sensors/base.py", line 239, in execute
    poke_return = self.poke(context)
  File "/home/seva/.local/lib/python3.10/site-packages/airflow/providers/http/sensors/http.py", line 148, in poke
    raise exc
  File "/home/seva/.local/lib/python3.10/site-packages/airflow/providers/http/sensors/http.py", line 132, in poke
    response = hook.run(
  File "/home/seva/.local/lib/python3.10/site-packages/airflow/providers/http/hooks/http.py", line 166, in run
    return self.run_and_check(session, prepped_request, extra_options)
  File "/home/seva/.local/lib/python3.10/site-packages/airflow/providers/http/hooks/http.py", line 217, in run_and_check
    self.check_response(response)
  File "/home/seva/.local/lib/python3.10/site-packages/airflow/providers/http/hooks/http.py", line 180, in check_response
    raise AirflowException(str(response.status_code) + ":" + response.reason)
airflow.exceptions.AirflowException: 401:Unauthorized
[2023-11-30T13:00:07.164+0200] {taskinstance.py:1400} INFO - Marking task as FAILED. dag_id=weather_data_pipeline, task_id=check_api_Kyiv, execution_date=20231130T100000, start_date=20231130T110006, end_date=20231130T110007
[2023-11-30T13:00:07.184+0200] {standard_task_runner.py:104} ERROR - Failed to execute job 140 for task check_api_Kyiv (401:Unauthorized; 20905)
[2023-11-30T13:00:07.209+0200] {local_task_job_runner.py:228} INFO - Task exited with return code 1
[2023-11-30T13:00:07.283+0200] {taskinstance.py:2778} INFO - 0 downstream tasks scheduled from follow-on schedule check
[2023-11-30T13:16:30.928+0200] {taskinstance.py:1159} INFO - Dependencies all met for dep_context=non-requeueable deps ti=<TaskInstance: weather_data_pipeline.check_api_Kyiv scheduled__2023-11-30T10:00:00+00:00 [queued]>
[2023-11-30T13:16:30.935+0200] {taskinstance.py:1159} INFO - Dependencies all met for dep_context=requeueable deps ti=<TaskInstance: weather_data_pipeline.check_api_Kyiv scheduled__2023-11-30T10:00:00+00:00 [queued]>
[2023-11-30T13:16:30.936+0200] {taskinstance.py:1361} INFO - Starting attempt 1 of 1
[2023-11-30T13:16:30.957+0200] {taskinstance.py:1382} INFO - Executing <Task(HttpSensor): check_api_Kyiv> on 2023-11-30 10:00:00+00:00
[2023-11-30T13:16:30.959+0200] {standard_task_runner.py:57} INFO - Started process 22857 to run task
[2023-11-30T13:16:30.965+0200] {standard_task_runner.py:84} INFO - Running: ['airflow', 'tasks', 'run', 'weather_data_pipeline', 'check_api_Kyiv', 'scheduled__2023-11-30T10:00:00+00:00', '--job-id', '231', '--raw', '--subdir', 'DAGS_FOLDER/weather_pipeline.py', '--cfg-path', '/tmp/tmp_bqm7_5q']
[2023-11-30T13:16:30.966+0200] {standard_task_runner.py:85} INFO - Job 231: Subtask check_api_Kyiv
[2023-11-30T13:16:31.009+0200] {task_command.py:416} INFO - Running <TaskInstance: weather_data_pipeline.check_api_Kyiv scheduled__2023-11-30T10:00:00+00:00 [running]> on host DESKTOP-VD1PANR.
[2023-11-30T13:16:31.138+0200] {taskinstance.py:1662} INFO - Exporting env vars: AIRFLOW_CTX_DAG_OWNER='airflow' AIRFLOW_CTX_DAG_ID='weather_data_pipeline' AIRFLOW_CTX_TASK_ID='check_api_Kyiv' AIRFLOW_CTX_EXECUTION_DATE='2023-11-30T10:00:00+00:00' AIRFLOW_CTX_TRY_NUMBER='1' AIRFLOW_CTX_DAG_RUN_ID='scheduled__2023-11-30T10:00:00+00:00'
[2023-11-30T13:16:31.139+0200] {http.py:130} INFO - Poking: data/3.0/onecall
[2023-11-30T13:16:31.144+0200] {base.py:73} INFO - Using connection ID 'openweathermap_conn' for task execution.
[2023-11-30T13:16:31.245+0200] {http.py:178} ERROR - HTTP error: Bad Request
[2023-11-30T13:16:31.246+0200] {http.py:179} ERROR - {"cod":"400","message":"no location specified"}
[2023-11-30T13:16:31.251+0200] {taskinstance.py:1937} ERROR - Task failed with exception
Traceback (most recent call last):
  File "/home/seva/.local/lib/python3.10/site-packages/airflow/providers/http/hooks/http.py", line 176, in check_response
    response.raise_for_status()
  File "/home/seva/.local/lib/python3.10/site-packages/requests/models.py", line 1021, in raise_for_status
    raise HTTPError(http_error_msg, response=self)
requests.exceptions.HTTPError: 400 Client Error: Bad Request for url: http://api.openweathermap.org/data/3.0/onecall?appid=***&q=Kyiv

During handling of the above exception, another exception occurred:

Traceback (most recent call last):
  File "/home/seva/.local/lib/python3.10/site-packages/airflow/sensors/base.py", line 257, in execute
    raise e
  File "/home/seva/.local/lib/python3.10/site-packages/airflow/sensors/base.py", line 239, in execute
    poke_return = self.poke(context)
  File "/home/seva/.local/lib/python3.10/site-packages/airflow/providers/http/sensors/http.py", line 148, in poke
    raise exc
  File "/home/seva/.local/lib/python3.10/site-packages/airflow/providers/http/sensors/http.py", line 132, in poke
    response = hook.run(
  File "/home/seva/.local/lib/python3.10/site-packages/airflow/providers/http/hooks/http.py", line 166, in run
    return self.run_and_check(session, prepped_request, extra_options)
  File "/home/seva/.local/lib/python3.10/site-packages/airflow/providers/http/hooks/http.py", line 217, in run_and_check
    self.check_response(response)
  File "/home/seva/.local/lib/python3.10/site-packages/airflow/providers/http/hooks/http.py", line 180, in check_response
    raise AirflowException(str(response.status_code) + ":" + response.reason)
airflow.exceptions.AirflowException: 400:Bad Request
[2023-11-30T13:16:31.255+0200] {taskinstance.py:1400} INFO - Marking task as FAILED. dag_id=weather_data_pipeline, task_id=check_api_Kyiv, execution_date=20231130T100000, start_date=20231130T111630, end_date=20231130T111631
[2023-11-30T13:16:31.285+0200] {standard_task_runner.py:104} ERROR - Failed to execute job 231 for task check_api_Kyiv (400:Bad Request; 22857)
[2023-11-30T13:16:31.314+0200] {local_task_job_runner.py:228} INFO - Task exited with return code 1
[2023-11-30T13:16:31.384+0200] {taskinstance.py:2778} INFO - 0 downstream tasks scheduled from follow-on schedule check
[2023-11-30T13:26:30.012+0200] {taskinstance.py:1159} INFO - Dependencies all met for dep_context=non-requeueable deps ti=<TaskInstance: weather_data_pipeline.check_api_Kyiv scheduled__2023-11-30T10:00:00+00:00 [queued]>
[2023-11-30T13:26:30.023+0200] {taskinstance.py:1159} INFO - Dependencies all met for dep_context=requeueable deps ti=<TaskInstance: weather_data_pipeline.check_api_Kyiv scheduled__2023-11-30T10:00:00+00:00 [queued]>
[2023-11-30T13:26:30.024+0200] {taskinstance.py:1361} INFO - Starting attempt 1 of 1
[2023-11-30T13:26:30.046+0200] {taskinstance.py:1382} INFO - Executing <Task(HttpSensor): check_api_Kyiv> on 2023-11-30 10:00:00+00:00
[2023-11-30T13:26:30.049+0200] {standard_task_runner.py:57} INFO - Started process 24082 to run task
[2023-11-30T13:26:30.054+0200] {standard_task_runner.py:84} INFO - Running: ['airflow', 'tasks', 'run', 'weather_data_pipeline', 'check_api_Kyiv', 'scheduled__2023-11-30T10:00:00+00:00', '--job-id', '303', '--raw', '--subdir', 'DAGS_FOLDER/weather_pipeline.py', '--cfg-path', '/tmp/tmpxmb0a5i5']
[2023-11-30T13:26:30.056+0200] {standard_task_runner.py:85} INFO - Job 303: Subtask check_api_Kyiv
[2023-11-30T13:26:30.097+0200] {task_command.py:416} INFO - Running <TaskInstance: weather_data_pipeline.check_api_Kyiv scheduled__2023-11-30T10:00:00+00:00 [running]> on host DESKTOP-VD1PANR.
[2023-11-30T13:26:30.217+0200] {taskinstance.py:1662} INFO - Exporting env vars: AIRFLOW_CTX_DAG_OWNER='airflow' AIRFLOW_CTX_DAG_ID='weather_data_pipeline' AIRFLOW_CTX_TASK_ID='check_api_Kyiv' AIRFLOW_CTX_EXECUTION_DATE='2023-11-30T10:00:00+00:00' AIRFLOW_CTX_TRY_NUMBER='1' AIRFLOW_CTX_DAG_RUN_ID='scheduled__2023-11-30T10:00:00+00:00'
[2023-11-30T13:26:30.217+0200] {http.py:130} INFO - Poking: data/3.0/onecall
[2023-11-30T13:26:30.220+0200] {base.py:73} INFO - Using connection ID 'openweathermap_conn' for task execution.
[2023-11-30T13:26:30.314+0200] {http.py:178} ERROR - HTTP error: Unauthorized
[2023-11-30T13:26:30.315+0200] {http.py:179} ERROR - {"cod":401, "message": "Please note that using One Call 3.0 requires a separate subscription to the One Call by Call plan. Learn more here https://openweathermap.org/price. If you have a valid subscription to the One Call by Call plan, but still receive this error, then please see https://openweathermap.org/faq#error401 for more info."}
[2023-11-30T13:26:30.322+0200] {taskinstance.py:1937} ERROR - Task failed with exception
Traceback (most recent call last):
  File "/home/seva/.local/lib/python3.10/site-packages/airflow/providers/http/hooks/http.py", line 176, in check_response
    response.raise_for_status()
  File "/home/seva/.local/lib/python3.10/site-packages/requests/models.py", line 1021, in raise_for_status
    raise HTTPError(http_error_msg, response=self)
requests.exceptions.HTTPError: 401 Client Error: Unauthorized for url: http://api.openweathermap.org/data/3.0/onecall?appid=***&q=Kyiv

During handling of the above exception, another exception occurred:

Traceback (most recent call last):
  File "/home/seva/.local/lib/python3.10/site-packages/airflow/sensors/base.py", line 257, in execute
    raise e
  File "/home/seva/.local/lib/python3.10/site-packages/airflow/sensors/base.py", line 239, in execute
    poke_return = self.poke(context)
  File "/home/seva/.local/lib/python3.10/site-packages/airflow/providers/http/sensors/http.py", line 148, in poke
    raise exc
  File "/home/seva/.local/lib/python3.10/site-packages/airflow/providers/http/sensors/http.py", line 132, in poke
    response = hook.run(
  File "/home/seva/.local/lib/python3.10/site-packages/airflow/providers/http/hooks/http.py", line 166, in run
    return self.run_and_check(session, prepped_request, extra_options)
  File "/home/seva/.local/lib/python3.10/site-packages/airflow/providers/http/hooks/http.py", line 217, in run_and_check
    self.check_response(response)
  File "/home/seva/.local/lib/python3.10/site-packages/airflow/providers/http/hooks/http.py", line 180, in check_response
    raise AirflowException(str(response.status_code) + ":" + response.reason)
airflow.exceptions.AirflowException: 401:Unauthorized
[2023-11-30T13:26:30.325+0200] {taskinstance.py:1400} INFO - Marking task as FAILED. dag_id=weather_data_pipeline, task_id=check_api_Kyiv, execution_date=20231130T100000, start_date=20231130T112630, end_date=20231130T112630
[2023-11-30T13:26:30.353+0200] {standard_task_runner.py:104} ERROR - Failed to execute job 303 for task check_api_Kyiv (401:Unauthorized; 24082)
[2023-11-30T13:26:30.371+0200] {local_task_job_runner.py:228} INFO - Task exited with return code 1
[2023-11-30T13:26:30.454+0200] {taskinstance.py:2778} INFO - 0 downstream tasks scheduled from follow-on schedule check
