[2023-11-30T12:41:38.756+0200] {taskinstance.py:1159} INFO - Dependencies all met for dep_context=non-requeueable deps ti=<TaskInstance: weather_data_pipeline.check_api_Zhmerynka scheduled__2023-11-30T02:00:00+00:00 [queued]>
[2023-11-30T12:41:38.763+0200] {taskinstance.py:1159} INFO - Dependencies all met for dep_context=requeueable deps ti=<TaskInstance: weather_data_pipeline.check_api_Zhmerynka scheduled__2023-11-30T02:00:00+00:00 [queued]>
[2023-11-30T12:41:38.763+0200] {taskinstance.py:1361} INFO - Starting attempt 1 of 1
[2023-11-30T12:41:38.790+0200] {taskinstance.py:1382} INFO - Executing <Task(HttpSensor): check_api_Zhmerynka> on 2023-11-30 02:00:00+00:00
[2023-11-30T12:41:38.792+0200] {standard_task_runner.py:57} INFO - Started process 18618 to run task
[2023-11-30T12:41:38.797+0200] {standard_task_runner.py:84} INFO - Running: ['airflow', 'tasks', 'run', 'weather_data_pipeline', 'check_api_Zhmerynka', 'scheduled__2023-11-30T02:00:00+00:00', '--job-id', '29', '--raw', '--subdir', 'DAGS_FOLDER/weather_pipeline.py', '--cfg-path', '/tmp/tmpvalurx2q']
[2023-11-30T12:41:38.799+0200] {standard_task_runner.py:85} INFO - Job 29: Subtask check_api_Zhmerynka
[2023-11-30T12:41:38.848+0200] {task_command.py:416} INFO - Running <TaskInstance: weather_data_pipeline.check_api_Zhmerynka scheduled__2023-11-30T02:00:00+00:00 [running]> on host DESKTOP-VD1PANR.
[2023-11-30T12:41:38.996+0200] {taskinstance.py:1662} INFO - Exporting env vars: AIRFLOW_CTX_DAG_OWNER='airflow' AIRFLOW_CTX_DAG_ID='weather_data_pipeline' AIRFLOW_CTX_TASK_ID='check_api_Zhmerynka' AIRFLOW_CTX_EXECUTION_DATE='2023-11-30T02:00:00+00:00' AIRFLOW_CTX_TRY_NUMBER='1' AIRFLOW_CTX_DAG_RUN_ID='scheduled__2023-11-30T02:00:00+00:00'
[2023-11-30T12:41:38.997+0200] {http.py:130} INFO - Poking: data/3.0/onecall
[2023-11-30T12:41:39.006+0200] {taskinstance.py:1937} ERROR - Task failed with exception
Traceback (most recent call last):
  File "/home/seva/.local/lib/python3.10/site-packages/airflow/sensors/base.py", line 257, in execute
    raise e
  File "/home/seva/.local/lib/python3.10/site-packages/airflow/sensors/base.py", line 239, in execute
    poke_return = self.poke(context)
  File "/home/seva/.local/lib/python3.10/site-packages/airflow/providers/http/sensors/http.py", line 148, in poke
    raise exc
  File "/home/seva/.local/lib/python3.10/site-packages/airflow/providers/http/sensors/http.py", line 132, in poke
    response = hook.run(
  File "/home/seva/.local/lib/python3.10/site-packages/airflow/providers/http/hooks/http.py", line 145, in run
    session = self.get_conn(headers)
  File "/home/seva/.local/lib/python3.10/site-packages/airflow/providers/http/hooks/http.py", line 98, in get_conn
    conn = self.get_connection(self.http_conn_id)
  File "/home/seva/.local/lib/python3.10/site-packages/airflow/hooks/base.py", line 72, in get_connection
    conn = Connection.get_connection_from_secrets(conn_id)
  File "/home/seva/.local/lib/python3.10/site-packages/airflow/models/connection.py", line 477, in get_connection_from_secrets
    raise AirflowNotFoundException(f"The conn_id `{conn_id}` isn't defined")
airflow.exceptions.AirflowNotFoundException: The conn_id `openweathermap_conn` isn't defined
[2023-11-30T12:41:39.009+0200] {taskinstance.py:1400} INFO - Marking task as FAILED. dag_id=weather_data_pipeline, task_id=check_api_Zhmerynka, execution_date=20231130T020000, start_date=20231130T104138, end_date=20231130T104139
[2023-11-30T12:41:39.027+0200] {standard_task_runner.py:104} ERROR - Failed to execute job 29 for task check_api_Zhmerynka (The conn_id `openweathermap_conn` isn't defined; 18618)
[2023-11-30T12:41:39.064+0200] {local_task_job_runner.py:228} INFO - Task exited with return code 1
[2023-11-30T12:41:39.164+0200] {taskinstance.py:2778} INFO - 0 downstream tasks scheduled from follow-on schedule check
[2023-11-30T12:55:19.991+0200] {taskinstance.py:1159} INFO - Dependencies all met for dep_context=non-requeueable deps ti=<TaskInstance: weather_data_pipeline.check_api_Zhmerynka scheduled__2023-11-30T02:00:00+00:00 [queued]>
[2023-11-30T12:55:19.999+0200] {taskinstance.py:1159} INFO - Dependencies all met for dep_context=requeueable deps ti=<TaskInstance: weather_data_pipeline.check_api_Zhmerynka scheduled__2023-11-30T02:00:00+00:00 [queued]>
[2023-11-30T12:55:19.999+0200] {taskinstance.py:1361} INFO - Starting attempt 1 of 1
[2023-11-30T12:55:20.022+0200] {taskinstance.py:1382} INFO - Executing <Task(HttpSensor): check_api_Zhmerynka> on 2023-11-30 02:00:00+00:00
[2023-11-30T12:55:20.026+0200] {standard_task_runner.py:57} INFO - Started process 20240 to run task
[2023-11-30T12:55:20.031+0200] {standard_task_runner.py:84} INFO - Running: ['airflow', 'tasks', 'run', 'weather_data_pipeline', 'check_api_Zhmerynka', 'scheduled__2023-11-30T02:00:00+00:00', '--job-id', '71', '--raw', '--subdir', 'DAGS_FOLDER/weather_pipeline.py', '--cfg-path', '/tmp/tmp14giol2y']
[2023-11-30T12:55:20.032+0200] {standard_task_runner.py:85} INFO - Job 71: Subtask check_api_Zhmerynka
[2023-11-30T12:55:20.077+0200] {task_command.py:416} INFO - Running <TaskInstance: weather_data_pipeline.check_api_Zhmerynka scheduled__2023-11-30T02:00:00+00:00 [running]> on host DESKTOP-VD1PANR.
[2023-11-30T12:55:20.236+0200] {taskinstance.py:1662} INFO - Exporting env vars: AIRFLOW_CTX_DAG_OWNER='airflow' AIRFLOW_CTX_DAG_ID='weather_data_pipeline' AIRFLOW_CTX_TASK_ID='check_api_Zhmerynka' AIRFLOW_CTX_EXECUTION_DATE='2023-11-30T02:00:00+00:00' AIRFLOW_CTX_TRY_NUMBER='1' AIRFLOW_CTX_DAG_RUN_ID='scheduled__2023-11-30T02:00:00+00:00'
[2023-11-30T12:55:20.238+0200] {http.py:130} INFO - Poking: data/3.0/onecall
[2023-11-30T12:55:20.251+0200] {base.py:73} INFO - Using connection ID 'openweathermap_conn' for task execution.
[2023-11-30T12:55:20.367+0200] {http.py:178} ERROR - HTTP error: Unauthorized
[2023-11-30T12:55:20.368+0200] {http.py:179} ERROR - {"cod":401, "message": "Please note that using One Call 3.0 requires a separate subscription to the One Call by Call plan. Learn more here https://openweathermap.org/price. If you have a valid subscription to the One Call by Call plan, but still receive this error, then please see https://openweathermap.org/faq#error401 for more info."}
[2023-11-30T12:55:20.375+0200] {taskinstance.py:1937} ERROR - Task failed with exception
Traceback (most recent call last):
  File "/home/seva/.local/lib/python3.10/site-packages/airflow/providers/http/hooks/http.py", line 176, in check_response
    response.raise_for_status()
  File "/home/seva/.local/lib/python3.10/site-packages/requests/models.py", line 1021, in raise_for_status
    raise HTTPError(http_error_msg, response=self)
requests.exceptions.HTTPError: 401 Client Error: Unauthorized for url: http://api.openweathermap.org/data/3.0/onecall?appid=***&q=Zhmerynka

During handling of the above exception, another exception occurred:

Traceback (most recent call last):
  File "/home/seva/.local/lib/python3.10/site-packages/airflow/sensors/base.py", line 257, in execute
    raise e
  File "/home/seva/.local/lib/python3.10/site-packages/airflow/sensors/base.py", line 239, in execute
    poke_return = self.poke(context)
  File "/home/seva/.local/lib/python3.10/site-packages/airflow/providers/http/sensors/http.py", line 148, in poke
    raise exc
  File "/home/seva/.local/lib/python3.10/site-packages/airflow/providers/http/sensors/http.py", line 132, in poke
    response = hook.run(
  File "/home/seva/.local/lib/python3.10/site-packages/airflow/providers/http/hooks/http.py", line 166, in run
    return self.run_and_check(session, prepped_request, extra_options)
  File "/home/seva/.local/lib/python3.10/site-packages/airflow/providers/http/hooks/http.py", line 217, in run_and_check
    self.check_response(response)
  File "/home/seva/.local/lib/python3.10/site-packages/airflow/providers/http/hooks/http.py", line 180, in check_response
    raise AirflowException(str(response.status_code) + ":" + response.reason)
airflow.exceptions.AirflowException: 401:Unauthorized
[2023-11-30T12:55:20.380+0200] {taskinstance.py:1400} INFO - Marking task as FAILED. dag_id=weather_data_pipeline, task_id=check_api_Zhmerynka, execution_date=20231130T020000, start_date=20231130T105519, end_date=20231130T105520
[2023-11-30T12:55:20.399+0200] {standard_task_runner.py:104} ERROR - Failed to execute job 71 for task check_api_Zhmerynka (401:Unauthorized; 20240)
[2023-11-30T12:55:20.410+0200] {local_task_job_runner.py:228} INFO - Task exited with return code 1
[2023-11-30T12:55:20.521+0200] {taskinstance.py:2778} INFO - 0 downstream tasks scheduled from follow-on schedule check
[2023-11-30T12:56:40.024+0200] {taskinstance.py:1159} INFO - Dependencies all met for dep_context=non-requeueable deps ti=<TaskInstance: weather_data_pipeline.check_api_Zhmerynka scheduled__2023-11-30T02:00:00+00:00 [queued]>
[2023-11-30T12:56:40.036+0200] {taskinstance.py:1159} INFO - Dependencies all met for dep_context=requeueable deps ti=<TaskInstance: weather_data_pipeline.check_api_Zhmerynka scheduled__2023-11-30T02:00:00+00:00 [queued]>
[2023-11-30T12:56:40.036+0200] {taskinstance.py:1361} INFO - Starting attempt 1 of 1
[2023-11-30T12:56:40.058+0200] {taskinstance.py:1382} INFO - Executing <Task(HttpSensor): check_api_Zhmerynka> on 2023-11-30 02:00:00+00:00
[2023-11-30T12:56:40.062+0200] {standard_task_runner.py:57} INFO - Started process 20447 to run task
[2023-11-30T12:56:40.069+0200] {standard_task_runner.py:84} INFO - Running: ['airflow', 'tasks', 'run', 'weather_data_pipeline', 'check_api_Zhmerynka', 'scheduled__2023-11-30T02:00:00+00:00', '--job-id', '96', '--raw', '--subdir', 'DAGS_FOLDER/weather_pipeline.py', '--cfg-path', '/tmp/tmp99xri7ai']
[2023-11-30T12:56:40.071+0200] {standard_task_runner.py:85} INFO - Job 96: Subtask check_api_Zhmerynka
[2023-11-30T12:56:40.126+0200] {task_command.py:416} INFO - Running <TaskInstance: weather_data_pipeline.check_api_Zhmerynka scheduled__2023-11-30T02:00:00+00:00 [running]> on host DESKTOP-VD1PANR.
[2023-11-30T12:56:40.260+0200] {taskinstance.py:1662} INFO - Exporting env vars: AIRFLOW_CTX_DAG_OWNER='airflow' AIRFLOW_CTX_DAG_ID='weather_data_pipeline' AIRFLOW_CTX_TASK_ID='check_api_Zhmerynka' AIRFLOW_CTX_EXECUTION_DATE='2023-11-30T02:00:00+00:00' AIRFLOW_CTX_TRY_NUMBER='1' AIRFLOW_CTX_DAG_RUN_ID='scheduled__2023-11-30T02:00:00+00:00'
[2023-11-30T12:56:40.261+0200] {http.py:130} INFO - Poking: data/3.0/onecall
[2023-11-30T12:56:40.266+0200] {base.py:73} INFO - Using connection ID 'openweathermap_conn' for task execution.
[2023-11-30T12:56:40.362+0200] {http.py:178} ERROR - HTTP error: Unauthorized
[2023-11-30T12:56:40.363+0200] {http.py:179} ERROR - {"cod":401, "message": "Please note that using One Call 3.0 requires a separate subscription to the One Call by Call plan. Learn more here https://openweathermap.org/price. If you have a valid subscription to the One Call by Call plan, but still receive this error, then please see https://openweathermap.org/faq#error401 for more info."}
[2023-11-30T12:56:40.369+0200] {taskinstance.py:1937} ERROR - Task failed with exception
Traceback (most recent call last):
  File "/home/seva/.local/lib/python3.10/site-packages/airflow/providers/http/hooks/http.py", line 176, in check_response
    response.raise_for_status()
  File "/home/seva/.local/lib/python3.10/site-packages/requests/models.py", line 1021, in raise_for_status
    raise HTTPError(http_error_msg, response=self)
requests.exceptions.HTTPError: 401 Client Error: Unauthorized for url: http://api.openweathermap.org/data/3.0/onecall?appid=***&q=Zhmerynka

During handling of the above exception, another exception occurred:

Traceback (most recent call last):
  File "/home/seva/.local/lib/python3.10/site-packages/airflow/sensors/base.py", line 257, in execute
    raise e
  File "/home/seva/.local/lib/python3.10/site-packages/airflow/sensors/base.py", line 239, in execute
    poke_return = self.poke(context)
  File "/home/seva/.local/lib/python3.10/site-packages/airflow/providers/http/sensors/http.py", line 148, in poke
    raise exc
  File "/home/seva/.local/lib/python3.10/site-packages/airflow/providers/http/sensors/http.py", line 132, in poke
    response = hook.run(
  File "/home/seva/.local/lib/python3.10/site-packages/airflow/providers/http/hooks/http.py", line 166, in run
    return self.run_and_check(session, prepped_request, extra_options)
  File "/home/seva/.local/lib/python3.10/site-packages/airflow/providers/http/hooks/http.py", line 217, in run_and_check
    self.check_response(response)
  File "/home/seva/.local/lib/python3.10/site-packages/airflow/providers/http/hooks/http.py", line 180, in check_response
    raise AirflowException(str(response.status_code) + ":" + response.reason)
airflow.exceptions.AirflowException: 401:Unauthorized
[2023-11-30T12:56:40.373+0200] {taskinstance.py:1400} INFO - Marking task as FAILED. dag_id=weather_data_pipeline, task_id=check_api_Zhmerynka, execution_date=20231130T020000, start_date=20231130T105640, end_date=20231130T105640
[2023-11-30T12:56:40.390+0200] {standard_task_runner.py:104} ERROR - Failed to execute job 96 for task check_api_Zhmerynka (401:Unauthorized; 20447)
[2023-11-30T12:56:40.417+0200] {local_task_job_runner.py:228} INFO - Task exited with return code 1
[2023-11-30T12:56:40.490+0200] {taskinstance.py:2778} INFO - 0 downstream tasks scheduled from follow-on schedule check
[2023-11-30T13:03:23.666+0200] {taskinstance.py:1159} INFO - Dependencies all met for dep_context=non-requeueable deps ti=<TaskInstance: weather_data_pipeline.check_api_Zhmerynka scheduled__2023-11-30T02:00:00+00:00 [queued]>
[2023-11-30T13:03:23.677+0200] {taskinstance.py:1159} INFO - Dependencies all met for dep_context=requeueable deps ti=<TaskInstance: weather_data_pipeline.check_api_Zhmerynka scheduled__2023-11-30T02:00:00+00:00 [queued]>
[2023-11-30T13:03:23.678+0200] {taskinstance.py:1361} INFO - Starting attempt 1 of 1
[2023-11-30T13:03:23.702+0200] {taskinstance.py:1382} INFO - Executing <Task(HttpSensor): check_api_Zhmerynka> on 2023-11-30 02:00:00+00:00
[2023-11-30T13:03:23.705+0200] {standard_task_runner.py:57} INFO - Started process 21313 to run task
[2023-11-30T13:03:23.709+0200] {standard_task_runner.py:84} INFO - Running: ['airflow', 'tasks', 'run', 'weather_data_pipeline', 'check_api_Zhmerynka', 'scheduled__2023-11-30T02:00:00+00:00', '--job-id', '162', '--raw', '--subdir', 'DAGS_FOLDER/weather_pipeline.py', '--cfg-path', '/tmp/tmpxv8ve83u']
[2023-11-30T13:03:23.711+0200] {standard_task_runner.py:85} INFO - Job 162: Subtask check_api_Zhmerynka
[2023-11-30T13:03:23.823+0200] {task_command.py:416} INFO - Running <TaskInstance: weather_data_pipeline.check_api_Zhmerynka scheduled__2023-11-30T02:00:00+00:00 [running]> on host DESKTOP-VD1PANR.
[2023-11-30T13:03:23.881+0200] {taskinstance.py:1662} INFO - Exporting env vars: AIRFLOW_CTX_DAG_OWNER='airflow' AIRFLOW_CTX_DAG_ID='weather_data_pipeline' AIRFLOW_CTX_TASK_ID='check_api_Zhmerynka' AIRFLOW_CTX_EXECUTION_DATE='2023-11-30T02:00:00+00:00' AIRFLOW_CTX_TRY_NUMBER='1' AIRFLOW_CTX_DAG_RUN_ID='scheduled__2023-11-30T02:00:00+00:00'
[2023-11-30T13:03:23.882+0200] {http.py:130} INFO - Poking: data/3.0/onecall
[2023-11-30T13:03:23.886+0200] {base.py:73} INFO - Using connection ID 'openweathermap_conn' for task execution.
[2023-11-30T13:03:23.983+0200] {http.py:178} ERROR - HTTP error: Unauthorized
[2023-11-30T13:03:23.984+0200] {http.py:179} ERROR - {"cod":401, "message": "Please note that using One Call 3.0 requires a separate subscription to the One Call by Call plan. Learn more here https://openweathermap.org/price. If you have a valid subscription to the One Call by Call plan, but still receive this error, then please see https://openweathermap.org/faq#error401 for more info."}
[2023-11-30T13:03:23.989+0200] {taskinstance.py:1937} ERROR - Task failed with exception
Traceback (most recent call last):
  File "/home/seva/.local/lib/python3.10/site-packages/airflow/providers/http/hooks/http.py", line 176, in check_response
    response.raise_for_status()
  File "/home/seva/.local/lib/python3.10/site-packages/requests/models.py", line 1021, in raise_for_status
    raise HTTPError(http_error_msg, response=self)
requests.exceptions.HTTPError: 401 Client Error: Unauthorized for url: http://api.openweathermap.org/data/3.0/onecall?appid=***&q=Zhmerynka

During handling of the above exception, another exception occurred:

Traceback (most recent call last):
  File "/home/seva/.local/lib/python3.10/site-packages/airflow/sensors/base.py", line 257, in execute
    raise e
  File "/home/seva/.local/lib/python3.10/site-packages/airflow/sensors/base.py", line 239, in execute
    poke_return = self.poke(context)
  File "/home/seva/.local/lib/python3.10/site-packages/airflow/providers/http/sensors/http.py", line 148, in poke
    raise exc
  File "/home/seva/.local/lib/python3.10/site-packages/airflow/providers/http/sensors/http.py", line 132, in poke
    response = hook.run(
  File "/home/seva/.local/lib/python3.10/site-packages/airflow/providers/http/hooks/http.py", line 166, in run
    return self.run_and_check(session, prepped_request, extra_options)
  File "/home/seva/.local/lib/python3.10/site-packages/airflow/providers/http/hooks/http.py", line 217, in run_and_check
    self.check_response(response)
  File "/home/seva/.local/lib/python3.10/site-packages/airflow/providers/http/hooks/http.py", line 180, in check_response
    raise AirflowException(str(response.status_code) + ":" + response.reason)
airflow.exceptions.AirflowException: 401:Unauthorized
[2023-11-30T13:03:23.992+0200] {taskinstance.py:1400} INFO - Marking task as FAILED. dag_id=weather_data_pipeline, task_id=check_api_Zhmerynka, execution_date=20231130T020000, start_date=20231130T110323, end_date=20231130T110323
[2023-11-30T13:03:24.031+0200] {standard_task_runner.py:104} ERROR - Failed to execute job 162 for task check_api_Zhmerynka (401:Unauthorized; 21313)
[2023-11-30T13:03:24.058+0200] {local_task_job_runner.py:228} INFO - Task exited with return code 1
[2023-11-30T13:03:24.139+0200] {taskinstance.py:2778} INFO - 0 downstream tasks scheduled from follow-on schedule check
[2023-11-30T13:15:05.727+0200] {taskinstance.py:1159} INFO - Dependencies all met for dep_context=non-requeueable deps ti=<TaskInstance: weather_data_pipeline.check_api_Zhmerynka scheduled__2023-11-30T02:00:00+00:00 [queued]>
[2023-11-30T13:15:05.742+0200] {taskinstance.py:1159} INFO - Dependencies all met for dep_context=requeueable deps ti=<TaskInstance: weather_data_pipeline.check_api_Zhmerynka scheduled__2023-11-30T02:00:00+00:00 [queued]>
[2023-11-30T13:15:05.743+0200] {taskinstance.py:1361} INFO - Starting attempt 1 of 1
[2023-11-30T13:15:05.774+0200] {taskinstance.py:1382} INFO - Executing <Task(HttpSensor): check_api_Zhmerynka> on 2023-11-30 02:00:00+00:00
[2023-11-30T13:15:05.777+0200] {standard_task_runner.py:57} INFO - Started process 22612 to run task
[2023-11-30T13:15:05.781+0200] {standard_task_runner.py:84} INFO - Running: ['airflow', 'tasks', 'run', 'weather_data_pipeline', 'check_api_Zhmerynka', 'scheduled__2023-11-30T02:00:00+00:00', '--job-id', '187', '--raw', '--subdir', 'DAGS_FOLDER/weather_pipeline.py', '--cfg-path', '/tmp/tmpb_ghwkcz']
[2023-11-30T13:15:05.784+0200] {standard_task_runner.py:85} INFO - Job 187: Subtask check_api_Zhmerynka
[2023-11-30T13:15:05.921+0200] {task_command.py:416} INFO - Running <TaskInstance: weather_data_pipeline.check_api_Zhmerynka scheduled__2023-11-30T02:00:00+00:00 [running]> on host DESKTOP-VD1PANR.
[2023-11-30T13:15:06.012+0200] {taskinstance.py:1662} INFO - Exporting env vars: AIRFLOW_CTX_DAG_OWNER='airflow' AIRFLOW_CTX_DAG_ID='weather_data_pipeline' AIRFLOW_CTX_TASK_ID='check_api_Zhmerynka' AIRFLOW_CTX_EXECUTION_DATE='2023-11-30T02:00:00+00:00' AIRFLOW_CTX_TRY_NUMBER='1' AIRFLOW_CTX_DAG_RUN_ID='scheduled__2023-11-30T02:00:00+00:00'
[2023-11-30T13:15:06.013+0200] {http.py:130} INFO - Poking: data/3.0/onecall
[2023-11-30T13:15:06.017+0200] {base.py:73} INFO - Using connection ID 'openweathermap_conn' for task execution.
[2023-11-30T13:15:06.107+0200] {http.py:178} ERROR - HTTP error: Unauthorized
[2023-11-30T13:15:06.107+0200] {http.py:179} ERROR - {"cod":401, "message": "Please note that using One Call 3.0 requires a separate subscription to the One Call by Call plan. Learn more here https://openweathermap.org/price. If you have a valid subscription to the One Call by Call plan, but still receive this error, then please see https://openweathermap.org/faq#error401 for more info."}
[2023-11-30T13:15:06.118+0200] {taskinstance.py:1937} ERROR - Task failed with exception
Traceback (most recent call last):
  File "/home/seva/.local/lib/python3.10/site-packages/airflow/providers/http/hooks/http.py", line 176, in check_response
    response.raise_for_status()
  File "/home/seva/.local/lib/python3.10/site-packages/requests/models.py", line 1021, in raise_for_status
    raise HTTPError(http_error_msg, response=self)
requests.exceptions.HTTPError: 401 Client Error: Unauthorized for url: http://api.openweathermap.org/data/3.0/onecall?appid=***&q=Zhmerynka

During handling of the above exception, another exception occurred:

Traceback (most recent call last):
  File "/home/seva/.local/lib/python3.10/site-packages/airflow/sensors/base.py", line 257, in execute
    raise e
  File "/home/seva/.local/lib/python3.10/site-packages/airflow/sensors/base.py", line 239, in execute
    poke_return = self.poke(context)
  File "/home/seva/.local/lib/python3.10/site-packages/airflow/providers/http/sensors/http.py", line 148, in poke
    raise exc
  File "/home/seva/.local/lib/python3.10/site-packages/airflow/providers/http/sensors/http.py", line 132, in poke
    response = hook.run(
  File "/home/seva/.local/lib/python3.10/site-packages/airflow/providers/http/hooks/http.py", line 166, in run
    return self.run_and_check(session, prepped_request, extra_options)
  File "/home/seva/.local/lib/python3.10/site-packages/airflow/providers/http/hooks/http.py", line 217, in run_and_check
    self.check_response(response)
  File "/home/seva/.local/lib/python3.10/site-packages/airflow/providers/http/hooks/http.py", line 180, in check_response
    raise AirflowException(str(response.status_code) + ":" + response.reason)
airflow.exceptions.AirflowException: 401:Unauthorized
[2023-11-30T13:15:06.126+0200] {taskinstance.py:1400} INFO - Marking task as FAILED. dag_id=weather_data_pipeline, task_id=check_api_Zhmerynka, execution_date=20231130T020000, start_date=20231130T111505, end_date=20231130T111506
[2023-11-30T13:15:06.154+0200] {standard_task_runner.py:104} ERROR - Failed to execute job 187 for task check_api_Zhmerynka (401:Unauthorized; 22612)
[2023-11-30T13:15:06.172+0200] {local_task_job_runner.py:228} INFO - Task exited with return code 1
[2023-11-30T13:15:06.249+0200] {taskinstance.py:2778} INFO - 0 downstream tasks scheduled from follow-on schedule check
[2023-11-30T13:24:55.495+0200] {taskinstance.py:1159} INFO - Dependencies all met for dep_context=non-requeueable deps ti=<TaskInstance: weather_data_pipeline.check_api_Zhmerynka scheduled__2023-11-30T02:00:00+00:00 [queued]>
[2023-11-30T13:24:55.503+0200] {taskinstance.py:1159} INFO - Dependencies all met for dep_context=requeueable deps ti=<TaskInstance: weather_data_pipeline.check_api_Zhmerynka scheduled__2023-11-30T02:00:00+00:00 [queued]>
[2023-11-30T13:24:55.503+0200] {taskinstance.py:1361} INFO - Starting attempt 1 of 1
[2023-11-30T13:24:55.525+0200] {taskinstance.py:1382} INFO - Executing <Task(HttpSensor): check_api_Zhmerynka> on 2023-11-30 02:00:00+00:00
[2023-11-30T13:24:55.527+0200] {standard_task_runner.py:57} INFO - Started process 23826 to run task
[2023-11-30T13:24:55.531+0200] {standard_task_runner.py:84} INFO - Running: ['airflow', 'tasks', 'run', 'weather_data_pipeline', 'check_api_Zhmerynka', 'scheduled__2023-11-30T02:00:00+00:00', '--job-id', '259', '--raw', '--subdir', 'DAGS_FOLDER/weather_pipeline.py', '--cfg-path', '/tmp/tmpusx8mz2g']
[2023-11-30T13:24:55.533+0200] {standard_task_runner.py:85} INFO - Job 259: Subtask check_api_Zhmerynka
[2023-11-30T13:24:55.640+0200] {task_command.py:416} INFO - Running <TaskInstance: weather_data_pipeline.check_api_Zhmerynka scheduled__2023-11-30T02:00:00+00:00 [running]> on host DESKTOP-VD1PANR.
[2023-11-30T13:24:55.714+0200] {taskinstance.py:1662} INFO - Exporting env vars: AIRFLOW_CTX_DAG_OWNER='airflow' AIRFLOW_CTX_DAG_ID='weather_data_pipeline' AIRFLOW_CTX_TASK_ID='check_api_Zhmerynka' AIRFLOW_CTX_EXECUTION_DATE='2023-11-30T02:00:00+00:00' AIRFLOW_CTX_TRY_NUMBER='1' AIRFLOW_CTX_DAG_RUN_ID='scheduled__2023-11-30T02:00:00+00:00'
[2023-11-30T13:24:55.715+0200] {http.py:130} INFO - Poking: data/3.0/onecall
[2023-11-30T13:24:55.719+0200] {base.py:73} INFO - Using connection ID 'openweathermap_conn' for task execution.
[2023-11-30T13:24:55.825+0200] {http.py:178} ERROR - HTTP error: Unauthorized
[2023-11-30T13:24:55.826+0200] {http.py:179} ERROR - {"cod":401, "message": "Please note that using One Call 3.0 requires a separate subscription to the One Call by Call plan. Learn more here https://openweathermap.org/price. If you have a valid subscription to the One Call by Call plan, but still receive this error, then please see https://openweathermap.org/faq#error401 for more info."}
[2023-11-30T13:24:55.831+0200] {taskinstance.py:1937} ERROR - Task failed with exception
Traceback (most recent call last):
  File "/home/seva/.local/lib/python3.10/site-packages/airflow/providers/http/hooks/http.py", line 176, in check_response
    response.raise_for_status()
  File "/home/seva/.local/lib/python3.10/site-packages/requests/models.py", line 1021, in raise_for_status
    raise HTTPError(http_error_msg, response=self)
requests.exceptions.HTTPError: 401 Client Error: Unauthorized for url: http://api.openweathermap.org/data/3.0/onecall?appid=***&q=Zhmerynka

During handling of the above exception, another exception occurred:

Traceback (most recent call last):
  File "/home/seva/.local/lib/python3.10/site-packages/airflow/sensors/base.py", line 257, in execute
    raise e
  File "/home/seva/.local/lib/python3.10/site-packages/airflow/sensors/base.py", line 239, in execute
    poke_return = self.poke(context)
  File "/home/seva/.local/lib/python3.10/site-packages/airflow/providers/http/sensors/http.py", line 148, in poke
    raise exc
  File "/home/seva/.local/lib/python3.10/site-packages/airflow/providers/http/sensors/http.py", line 132, in poke
    response = hook.run(
  File "/home/seva/.local/lib/python3.10/site-packages/airflow/providers/http/hooks/http.py", line 166, in run
    return self.run_and_check(session, prepped_request, extra_options)
  File "/home/seva/.local/lib/python3.10/site-packages/airflow/providers/http/hooks/http.py", line 217, in run_and_check
    self.check_response(response)
  File "/home/seva/.local/lib/python3.10/site-packages/airflow/providers/http/hooks/http.py", line 180, in check_response
    raise AirflowException(str(response.status_code) + ":" + response.reason)
airflow.exceptions.AirflowException: 401:Unauthorized
[2023-11-30T13:24:55.836+0200] {taskinstance.py:1400} INFO - Marking task as FAILED. dag_id=weather_data_pipeline, task_id=check_api_Zhmerynka, execution_date=20231130T020000, start_date=20231130T112455, end_date=20231130T112455
[2023-11-30T13:24:55.861+0200] {standard_task_runner.py:104} ERROR - Failed to execute job 259 for task check_api_Zhmerynka (401:Unauthorized; 23826)
[2023-11-30T13:24:55.884+0200] {local_task_job_runner.py:228} INFO - Task exited with return code 1
[2023-11-30T13:24:55.987+0200] {taskinstance.py:2778} INFO - 0 downstream tasks scheduled from follow-on schedule check
