[2023-11-30T12:41:49.209+0200] {taskinstance.py:1159} INFO - Dependencies all met for dep_context=non-requeueable deps ti=<TaskInstance: weather_data_pipeline.check_api_Odesa scheduled__2023-11-30T03:00:00+00:00 [queued]>
[2023-11-30T12:41:49.216+0200] {taskinstance.py:1159} INFO - Dependencies all met for dep_context=requeueable deps ti=<TaskInstance: weather_data_pipeline.check_api_Odesa scheduled__2023-11-30T03:00:00+00:00 [queued]>
[2023-11-30T12:41:49.216+0200] {taskinstance.py:1361} INFO - Starting attempt 1 of 1
[2023-11-30T12:41:49.241+0200] {taskinstance.py:1382} INFO - Executing <Task(HttpSensor): check_api_Odesa> on 2023-11-30 03:00:00+00:00
[2023-11-30T12:41:49.244+0200] {standard_task_runner.py:57} INFO - Started process 18646 to run task
[2023-11-30T12:41:49.247+0200] {standard_task_runner.py:84} INFO - Running: ['airflow', 'tasks', 'run', 'weather_data_pipeline', 'check_api_Odesa', 'scheduled__2023-11-30T03:00:00+00:00', '--job-id', '34', '--raw', '--subdir', 'DAGS_FOLDER/weather_pipeline.py', '--cfg-path', '/tmp/tmp2g8fhter']
[2023-11-30T12:41:49.249+0200] {standard_task_runner.py:85} INFO - Job 34: Subtask check_api_Odesa
[2023-11-30T12:41:49.289+0200] {task_command.py:416} INFO - Running <TaskInstance: weather_data_pipeline.check_api_Odesa scheduled__2023-11-30T03:00:00+00:00 [running]> on host DESKTOP-VD1PANR.
[2023-11-30T12:41:49.413+0200] {taskinstance.py:1662} INFO - Exporting env vars: AIRFLOW_CTX_DAG_OWNER='airflow' AIRFLOW_CTX_DAG_ID='weather_data_pipeline' AIRFLOW_CTX_TASK_ID='check_api_Odesa' AIRFLOW_CTX_EXECUTION_DATE='2023-11-30T03:00:00+00:00' AIRFLOW_CTX_TRY_NUMBER='1' AIRFLOW_CTX_DAG_RUN_ID='scheduled__2023-11-30T03:00:00+00:00'
[2023-11-30T12:41:49.414+0200] {http.py:130} INFO - Poking: data/3.0/onecall
[2023-11-30T12:41:49.420+0200] {taskinstance.py:1937} ERROR - Task failed with exception
Traceback (most recent call last):
  File "/home/seva/.local/lib/python3.10/site-packages/airflow/sensors/base.py", line 257, in execute
    raise e
  File "/home/seva/.local/lib/python3.10/site-packages/airflow/sensors/base.py", line 239, in execute
    poke_return = self.poke(context)
  File "/home/seva/.local/lib/python3.10/site-packages/airflow/providers/http/sensors/http.py", line 148, in poke
    raise exc
  File "/home/seva/.local/lib/python3.10/site-packages/airflow/providers/http/sensors/http.py", line 132, in poke
    response = hook.run(
  File "/home/seva/.local/lib/python3.10/site-packages/airflow/providers/http/hooks/http.py", line 145, in run
    session = self.get_conn(headers)
  File "/home/seva/.local/lib/python3.10/site-packages/airflow/providers/http/hooks/http.py", line 98, in get_conn
    conn = self.get_connection(self.http_conn_id)
  File "/home/seva/.local/lib/python3.10/site-packages/airflow/hooks/base.py", line 72, in get_connection
    conn = Connection.get_connection_from_secrets(conn_id)
  File "/home/seva/.local/lib/python3.10/site-packages/airflow/models/connection.py", line 477, in get_connection_from_secrets
    raise AirflowNotFoundException(f"The conn_id `{conn_id}` isn't defined")
airflow.exceptions.AirflowNotFoundException: The conn_id `openweathermap_conn` isn't defined
[2023-11-30T12:41:49.424+0200] {taskinstance.py:1400} INFO - Marking task as FAILED. dag_id=weather_data_pipeline, task_id=check_api_Odesa, execution_date=20231130T030000, start_date=20231130T104149, end_date=20231130T104149
[2023-11-30T12:41:49.442+0200] {standard_task_runner.py:104} ERROR - Failed to execute job 34 for task check_api_Odesa (The conn_id `openweathermap_conn` isn't defined; 18646)
[2023-11-30T12:41:49.468+0200] {local_task_job_runner.py:228} INFO - Task exited with return code 1
[2023-11-30T12:41:49.546+0200] {taskinstance.py:2778} INFO - 0 downstream tasks scheduled from follow-on schedule check
[2023-11-30T12:56:49.702+0200] {taskinstance.py:1159} INFO - Dependencies all met for dep_context=non-requeueable deps ti=<TaskInstance: weather_data_pipeline.check_api_Odesa scheduled__2023-11-30T03:00:00+00:00 [queued]>
[2023-11-30T12:56:49.709+0200] {taskinstance.py:1159} INFO - Dependencies all met for dep_context=requeueable deps ti=<TaskInstance: weather_data_pipeline.check_api_Odesa scheduled__2023-11-30T03:00:00+00:00 [queued]>
[2023-11-30T12:56:49.710+0200] {taskinstance.py:1361} INFO - Starting attempt 1 of 1
[2023-11-30T12:56:49.730+0200] {taskinstance.py:1382} INFO - Executing <Task(HttpSensor): check_api_Odesa> on 2023-11-30 03:00:00+00:00
[2023-11-30T12:56:49.733+0200] {standard_task_runner.py:57} INFO - Started process 20475 to run task
[2023-11-30T12:56:49.737+0200] {standard_task_runner.py:84} INFO - Running: ['airflow', 'tasks', 'run', 'weather_data_pipeline', 'check_api_Odesa', 'scheduled__2023-11-30T03:00:00+00:00', '--job-id', '101', '--raw', '--subdir', 'DAGS_FOLDER/weather_pipeline.py', '--cfg-path', '/tmp/tmph5lcww20']
[2023-11-30T12:56:49.739+0200] {standard_task_runner.py:85} INFO - Job 101: Subtask check_api_Odesa
[2023-11-30T12:56:49.785+0200] {task_command.py:416} INFO - Running <TaskInstance: weather_data_pipeline.check_api_Odesa scheduled__2023-11-30T03:00:00+00:00 [running]> on host DESKTOP-VD1PANR.
[2023-11-30T12:56:49.917+0200] {taskinstance.py:1662} INFO - Exporting env vars: AIRFLOW_CTX_DAG_OWNER='airflow' AIRFLOW_CTX_DAG_ID='weather_data_pipeline' AIRFLOW_CTX_TASK_ID='check_api_Odesa' AIRFLOW_CTX_EXECUTION_DATE='2023-11-30T03:00:00+00:00' AIRFLOW_CTX_TRY_NUMBER='1' AIRFLOW_CTX_DAG_RUN_ID='scheduled__2023-11-30T03:00:00+00:00'
[2023-11-30T12:56:49.918+0200] {http.py:130} INFO - Poking: data/3.0/onecall
[2023-11-30T12:56:49.924+0200] {base.py:73} INFO - Using connection ID 'openweathermap_conn' for task execution.
[2023-11-30T12:56:50.004+0200] {http.py:178} ERROR - HTTP error: Unauthorized
[2023-11-30T12:56:50.005+0200] {http.py:179} ERROR - {"cod":401, "message": "Please note that using One Call 3.0 requires a separate subscription to the One Call by Call plan. Learn more here https://openweathermap.org/price. If you have a valid subscription to the One Call by Call plan, but still receive this error, then please see https://openweathermap.org/faq#error401 for more info."}
[2023-11-30T12:56:50.011+0200] {taskinstance.py:1937} ERROR - Task failed with exception
Traceback (most recent call last):
  File "/home/seva/.local/lib/python3.10/site-packages/airflow/providers/http/hooks/http.py", line 176, in check_response
    response.raise_for_status()
  File "/home/seva/.local/lib/python3.10/site-packages/requests/models.py", line 1021, in raise_for_status
    raise HTTPError(http_error_msg, response=self)
requests.exceptions.HTTPError: 401 Client Error: Unauthorized for url: http://api.openweathermap.org/data/3.0/onecall?appid=***&q=Odesa

During handling of the above exception, another exception occurred:

Traceback (most recent call last):
  File "/home/seva/.local/lib/python3.10/site-packages/airflow/sensors/base.py", line 257, in execute
    raise e
  File "/home/seva/.local/lib/python3.10/site-packages/airflow/sensors/base.py", line 239, in execute
    poke_return = self.poke(context)
  File "/home/seva/.local/lib/python3.10/site-packages/airflow/providers/http/sensors/http.py", line 148, in poke
    raise exc
  File "/home/seva/.local/lib/python3.10/site-packages/airflow/providers/http/sensors/http.py", line 132, in poke
    response = hook.run(
  File "/home/seva/.local/lib/python3.10/site-packages/airflow/providers/http/hooks/http.py", line 166, in run
    return self.run_and_check(session, prepped_request, extra_options)
  File "/home/seva/.local/lib/python3.10/site-packages/airflow/providers/http/hooks/http.py", line 217, in run_and_check
    self.check_response(response)
  File "/home/seva/.local/lib/python3.10/site-packages/airflow/providers/http/hooks/http.py", line 180, in check_response
    raise AirflowException(str(response.status_code) + ":" + response.reason)
airflow.exceptions.AirflowException: 401:Unauthorized
[2023-11-30T12:56:50.014+0200] {taskinstance.py:1400} INFO - Marking task as FAILED. dag_id=weather_data_pipeline, task_id=check_api_Odesa, execution_date=20231130T030000, start_date=20231130T105649, end_date=20231130T105650
[2023-11-30T12:56:50.032+0200] {standard_task_runner.py:104} ERROR - Failed to execute job 101 for task check_api_Odesa (401:Unauthorized; 20475)
[2023-11-30T12:56:50.046+0200] {local_task_job_runner.py:228} INFO - Task exited with return code 1
[2023-11-30T12:56:50.118+0200] {taskinstance.py:2778} INFO - 0 downstream tasks scheduled from follow-on schedule check
[2023-11-30T13:15:16.106+0200] {taskinstance.py:1159} INFO - Dependencies all met for dep_context=non-requeueable deps ti=<TaskInstance: weather_data_pipeline.check_api_Odesa scheduled__2023-11-30T03:00:00+00:00 [queued]>
[2023-11-30T13:15:16.113+0200] {taskinstance.py:1159} INFO - Dependencies all met for dep_context=requeueable deps ti=<TaskInstance: weather_data_pipeline.check_api_Odesa scheduled__2023-11-30T03:00:00+00:00 [queued]>
[2023-11-30T13:15:16.114+0200] {taskinstance.py:1361} INFO - Starting attempt 1 of 1
[2023-11-30T13:15:16.132+0200] {taskinstance.py:1382} INFO - Executing <Task(HttpSensor): check_api_Odesa> on 2023-11-30 03:00:00+00:00
[2023-11-30T13:15:16.134+0200] {standard_task_runner.py:57} INFO - Started process 22640 to run task
[2023-11-30T13:15:16.139+0200] {standard_task_runner.py:84} INFO - Running: ['airflow', 'tasks', 'run', 'weather_data_pipeline', 'check_api_Odesa', 'scheduled__2023-11-30T03:00:00+00:00', '--job-id', '192', '--raw', '--subdir', 'DAGS_FOLDER/weather_pipeline.py', '--cfg-path', '/tmp/tmp5kc4kzbm']
[2023-11-30T13:15:16.140+0200] {standard_task_runner.py:85} INFO - Job 192: Subtask check_api_Odesa
[2023-11-30T13:15:16.182+0200] {task_command.py:416} INFO - Running <TaskInstance: weather_data_pipeline.check_api_Odesa scheduled__2023-11-30T03:00:00+00:00 [running]> on host DESKTOP-VD1PANR.
[2023-11-30T13:15:16.306+0200] {taskinstance.py:1662} INFO - Exporting env vars: AIRFLOW_CTX_DAG_OWNER='airflow' AIRFLOW_CTX_DAG_ID='weather_data_pipeline' AIRFLOW_CTX_TASK_ID='check_api_Odesa' AIRFLOW_CTX_EXECUTION_DATE='2023-11-30T03:00:00+00:00' AIRFLOW_CTX_TRY_NUMBER='1' AIRFLOW_CTX_DAG_RUN_ID='scheduled__2023-11-30T03:00:00+00:00'
[2023-11-30T13:15:16.306+0200] {http.py:130} INFO - Poking: data/3.0/onecall
[2023-11-30T13:15:16.310+0200] {base.py:73} INFO - Using connection ID 'openweathermap_conn' for task execution.
[2023-11-30T13:15:16.389+0200] {http.py:178} ERROR - HTTP error: Unauthorized
[2023-11-30T13:15:16.389+0200] {http.py:179} ERROR - {"cod":401, "message": "Please note that using One Call 3.0 requires a separate subscription to the One Call by Call plan. Learn more here https://openweathermap.org/price. If you have a valid subscription to the One Call by Call plan, but still receive this error, then please see https://openweathermap.org/faq#error401 for more info."}
[2023-11-30T13:15:16.394+0200] {taskinstance.py:1937} ERROR - Task failed with exception
Traceback (most recent call last):
  File "/home/seva/.local/lib/python3.10/site-packages/airflow/providers/http/hooks/http.py", line 176, in check_response
    response.raise_for_status()
  File "/home/seva/.local/lib/python3.10/site-packages/requests/models.py", line 1021, in raise_for_status
    raise HTTPError(http_error_msg, response=self)
requests.exceptions.HTTPError: 401 Client Error: Unauthorized for url: http://api.openweathermap.org/data/3.0/onecall?appid=***&q=Odesa

During handling of the above exception, another exception occurred:

Traceback (most recent call last):
  File "/home/seva/.local/lib/python3.10/site-packages/airflow/sensors/base.py", line 257, in execute
    raise e
  File "/home/seva/.local/lib/python3.10/site-packages/airflow/sensors/base.py", line 239, in execute
    poke_return = self.poke(context)
  File "/home/seva/.local/lib/python3.10/site-packages/airflow/providers/http/sensors/http.py", line 148, in poke
    raise exc
  File "/home/seva/.local/lib/python3.10/site-packages/airflow/providers/http/sensors/http.py", line 132, in poke
    response = hook.run(
  File "/home/seva/.local/lib/python3.10/site-packages/airflow/providers/http/hooks/http.py", line 166, in run
    return self.run_and_check(session, prepped_request, extra_options)
  File "/home/seva/.local/lib/python3.10/site-packages/airflow/providers/http/hooks/http.py", line 217, in run_and_check
    self.check_response(response)
  File "/home/seva/.local/lib/python3.10/site-packages/airflow/providers/http/hooks/http.py", line 180, in check_response
    raise AirflowException(str(response.status_code) + ":" + response.reason)
airflow.exceptions.AirflowException: 401:Unauthorized
[2023-11-30T13:15:16.397+0200] {taskinstance.py:1400} INFO - Marking task as FAILED. dag_id=weather_data_pipeline, task_id=check_api_Odesa, execution_date=20231130T030000, start_date=20231130T111516, end_date=20231130T111516
[2023-11-30T13:15:16.416+0200] {standard_task_runner.py:104} ERROR - Failed to execute job 192 for task check_api_Odesa (401:Unauthorized; 22640)
[2023-11-30T13:15:16.448+0200] {local_task_job_runner.py:228} INFO - Task exited with return code 1
[2023-11-30T13:15:16.535+0200] {taskinstance.py:2778} INFO - 0 downstream tasks scheduled from follow-on schedule check
[2023-11-30T13:25:05.519+0200] {taskinstance.py:1159} INFO - Dependencies all met for dep_context=non-requeueable deps ti=<TaskInstance: weather_data_pipeline.check_api_Odesa scheduled__2023-11-30T03:00:00+00:00 [queued]>
[2023-11-30T13:25:05.527+0200] {taskinstance.py:1159} INFO - Dependencies all met for dep_context=requeueable deps ti=<TaskInstance: weather_data_pipeline.check_api_Odesa scheduled__2023-11-30T03:00:00+00:00 [queued]>
[2023-11-30T13:25:05.527+0200] {taskinstance.py:1361} INFO - Starting attempt 1 of 1
[2023-11-30T13:25:05.550+0200] {taskinstance.py:1382} INFO - Executing <Task(HttpSensor): check_api_Odesa> on 2023-11-30 03:00:00+00:00
[2023-11-30T13:25:05.552+0200] {standard_task_runner.py:57} INFO - Started process 23854 to run task
[2023-11-30T13:25:05.558+0200] {standard_task_runner.py:84} INFO - Running: ['airflow', 'tasks', 'run', 'weather_data_pipeline', 'check_api_Odesa', 'scheduled__2023-11-30T03:00:00+00:00', '--job-id', '264', '--raw', '--subdir', 'DAGS_FOLDER/weather_pipeline.py', '--cfg-path', '/tmp/tmprgbc7l4q']
[2023-11-30T13:25:05.559+0200] {standard_task_runner.py:85} INFO - Job 264: Subtask check_api_Odesa
[2023-11-30T13:25:05.607+0200] {task_command.py:416} INFO - Running <TaskInstance: weather_data_pipeline.check_api_Odesa scheduled__2023-11-30T03:00:00+00:00 [running]> on host DESKTOP-VD1PANR.
[2023-11-30T13:25:05.737+0200] {taskinstance.py:1662} INFO - Exporting env vars: AIRFLOW_CTX_DAG_OWNER='airflow' AIRFLOW_CTX_DAG_ID='weather_data_pipeline' AIRFLOW_CTX_TASK_ID='check_api_Odesa' AIRFLOW_CTX_EXECUTION_DATE='2023-11-30T03:00:00+00:00' AIRFLOW_CTX_TRY_NUMBER='1' AIRFLOW_CTX_DAG_RUN_ID='scheduled__2023-11-30T03:00:00+00:00'
[2023-11-30T13:25:05.737+0200] {http.py:130} INFO - Poking: data/3.0/onecall
[2023-11-30T13:25:05.741+0200] {base.py:73} INFO - Using connection ID 'openweathermap_conn' for task execution.
[2023-11-30T13:25:05.845+0200] {http.py:178} ERROR - HTTP error: Unauthorized
[2023-11-30T13:25:05.845+0200] {http.py:179} ERROR - {"cod":401, "message": "Please note that using One Call 3.0 requires a separate subscription to the One Call by Call plan. Learn more here https://openweathermap.org/price. If you have a valid subscription to the One Call by Call plan, but still receive this error, then please see https://openweathermap.org/faq#error401 for more info."}
[2023-11-30T13:25:05.851+0200] {taskinstance.py:1937} ERROR - Task failed with exception
Traceback (most recent call last):
  File "/home/seva/.local/lib/python3.10/site-packages/airflow/providers/http/hooks/http.py", line 176, in check_response
    response.raise_for_status()
  File "/home/seva/.local/lib/python3.10/site-packages/requests/models.py", line 1021, in raise_for_status
    raise HTTPError(http_error_msg, response=self)
requests.exceptions.HTTPError: 401 Client Error: Unauthorized for url: http://api.openweathermap.org/data/3.0/onecall?appid=***&q=Odesa

During handling of the above exception, another exception occurred:

Traceback (most recent call last):
  File "/home/seva/.local/lib/python3.10/site-packages/airflow/sensors/base.py", line 257, in execute
    raise e
  File "/home/seva/.local/lib/python3.10/site-packages/airflow/sensors/base.py", line 239, in execute
    poke_return = self.poke(context)
  File "/home/seva/.local/lib/python3.10/site-packages/airflow/providers/http/sensors/http.py", line 148, in poke
    raise exc
  File "/home/seva/.local/lib/python3.10/site-packages/airflow/providers/http/sensors/http.py", line 132, in poke
    response = hook.run(
  File "/home/seva/.local/lib/python3.10/site-packages/airflow/providers/http/hooks/http.py", line 166, in run
    return self.run_and_check(session, prepped_request, extra_options)
  File "/home/seva/.local/lib/python3.10/site-packages/airflow/providers/http/hooks/http.py", line 217, in run_and_check
    self.check_response(response)
  File "/home/seva/.local/lib/python3.10/site-packages/airflow/providers/http/hooks/http.py", line 180, in check_response
    raise AirflowException(str(response.status_code) + ":" + response.reason)
airflow.exceptions.AirflowException: 401:Unauthorized
[2023-11-30T13:25:05.854+0200] {taskinstance.py:1400} INFO - Marking task as FAILED. dag_id=weather_data_pipeline, task_id=check_api_Odesa, execution_date=20231130T030000, start_date=20231130T112505, end_date=20231130T112505
[2023-11-30T13:25:05.876+0200] {standard_task_runner.py:104} ERROR - Failed to execute job 264 for task check_api_Odesa (401:Unauthorized; 23854)
[2023-11-30T13:25:05.911+0200] {local_task_job_runner.py:228} INFO - Task exited with return code 1
[2023-11-30T13:25:05.982+0200] {taskinstance.py:2778} INFO - 0 downstream tasks scheduled from follow-on schedule check
