[2023-11-30T12:42:12.891+0200] {taskinstance.py:1159} INFO - Dependencies all met for dep_context=non-requeueable deps ti=<TaskInstance: weather_data_pipeline.check_api_Odesa scheduled__2023-11-30T05:00:00+00:00 [queued]>
[2023-11-30T12:42:12.900+0200] {taskinstance.py:1159} INFO - Dependencies all met for dep_context=requeueable deps ti=<TaskInstance: weather_data_pipeline.check_api_Odesa scheduled__2023-11-30T05:00:00+00:00 [queued]>
[2023-11-30T12:42:12.900+0200] {taskinstance.py:1361} INFO - Starting attempt 1 of 1
[2023-11-30T12:42:12.921+0200] {taskinstance.py:1382} INFO - Executing <Task(HttpSensor): check_api_Odesa> on 2023-11-30 05:00:00+00:00
[2023-11-30T12:42:12.924+0200] {standard_task_runner.py:57} INFO - Started process 18714 to run task
[2023-11-30T12:42:12.929+0200] {standard_task_runner.py:84} INFO - Running: ['airflow', 'tasks', 'run', 'weather_data_pipeline', 'check_api_Odesa', 'scheduled__2023-11-30T05:00:00+00:00', '--job-id', '45', '--raw', '--subdir', 'DAGS_FOLDER/weather_pipeline.py', '--cfg-path', '/tmp/tmpnsn5laa4']
[2023-11-30T12:42:12.931+0200] {standard_task_runner.py:85} INFO - Job 45: Subtask check_api_Odesa
[2023-11-30T12:42:12.987+0200] {task_command.py:416} INFO - Running <TaskInstance: weather_data_pipeline.check_api_Odesa scheduled__2023-11-30T05:00:00+00:00 [running]> on host DESKTOP-VD1PANR.
[2023-11-30T12:42:13.138+0200] {taskinstance.py:1662} INFO - Exporting env vars: AIRFLOW_CTX_DAG_OWNER='airflow' AIRFLOW_CTX_DAG_ID='weather_data_pipeline' AIRFLOW_CTX_TASK_ID='check_api_Odesa' AIRFLOW_CTX_EXECUTION_DATE='2023-11-30T05:00:00+00:00' AIRFLOW_CTX_TRY_NUMBER='1' AIRFLOW_CTX_DAG_RUN_ID='scheduled__2023-11-30T05:00:00+00:00'
[2023-11-30T12:42:13.139+0200] {http.py:130} INFO - Poking: data/3.0/onecall
[2023-11-30T12:42:13.159+0200] {taskinstance.py:1937} ERROR - Task failed with exception
Traceback (most recent call last):
  File "/home/seva/.local/lib/python3.10/site-packages/airflow/sensors/base.py", line 257, in execute
    raise e
  File "/home/seva/.local/lib/python3.10/site-packages/airflow/sensors/base.py", line 239, in execute
    poke_return = self.poke(context)
  File "/home/seva/.local/lib/python3.10/site-packages/airflow/providers/http/sensors/http.py", line 148, in poke
    raise exc
  File "/home/seva/.local/lib/python3.10/site-packages/airflow/providers/http/sensors/http.py", line 132, in poke
    response = hook.run(
  File "/home/seva/.local/lib/python3.10/site-packages/airflow/providers/http/hooks/http.py", line 145, in run
    session = self.get_conn(headers)
  File "/home/seva/.local/lib/python3.10/site-packages/airflow/providers/http/hooks/http.py", line 98, in get_conn
    conn = self.get_connection(self.http_conn_id)
  File "/home/seva/.local/lib/python3.10/site-packages/airflow/hooks/base.py", line 72, in get_connection
    conn = Connection.get_connection_from_secrets(conn_id)
  File "/home/seva/.local/lib/python3.10/site-packages/airflow/models/connection.py", line 477, in get_connection_from_secrets
    raise AirflowNotFoundException(f"The conn_id `{conn_id}` isn't defined")
airflow.exceptions.AirflowNotFoundException: The conn_id `openweathermap_conn` isn't defined
[2023-11-30T12:42:13.165+0200] {taskinstance.py:1400} INFO - Marking task as FAILED. dag_id=weather_data_pipeline, task_id=check_api_Odesa, execution_date=20231130T050000, start_date=20231130T104212, end_date=20231130T104213
[2023-11-30T12:42:13.188+0200] {standard_task_runner.py:104} ERROR - Failed to execute job 45 for task check_api_Odesa (The conn_id `openweathermap_conn` isn't defined; 18714)
[2023-11-30T12:42:13.237+0200] {local_task_job_runner.py:228} INFO - Task exited with return code 1
[2023-11-30T12:42:13.349+0200] {taskinstance.py:2778} INFO - 0 downstream tasks scheduled from follow-on schedule check
[2023-11-30T12:57:09.299+0200] {taskinstance.py:1159} INFO - Dependencies all met for dep_context=non-requeueable deps ti=<TaskInstance: weather_data_pipeline.check_api_Odesa scheduled__2023-11-30T05:00:00+00:00 [queued]>
[2023-11-30T12:57:09.312+0200] {taskinstance.py:1159} INFO - Dependencies all met for dep_context=requeueable deps ti=<TaskInstance: weather_data_pipeline.check_api_Odesa scheduled__2023-11-30T05:00:00+00:00 [queued]>
[2023-11-30T12:57:09.313+0200] {taskinstance.py:1361} INFO - Starting attempt 1 of 1
[2023-11-30T12:57:09.342+0200] {taskinstance.py:1382} INFO - Executing <Task(HttpSensor): check_api_Odesa> on 2023-11-30 05:00:00+00:00
[2023-11-30T12:57:09.346+0200] {standard_task_runner.py:57} INFO - Started process 20528 to run task
[2023-11-30T12:57:09.350+0200] {standard_task_runner.py:84} INFO - Running: ['airflow', 'tasks', 'run', 'weather_data_pipeline', 'check_api_Odesa', 'scheduled__2023-11-30T05:00:00+00:00', '--job-id', '112', '--raw', '--subdir', 'DAGS_FOLDER/weather_pipeline.py', '--cfg-path', '/tmp/tmpcihwv2jv']
[2023-11-30T12:57:09.353+0200] {standard_task_runner.py:85} INFO - Job 112: Subtask check_api_Odesa
[2023-11-30T12:57:09.410+0200] {task_command.py:416} INFO - Running <TaskInstance: weather_data_pipeline.check_api_Odesa scheduled__2023-11-30T05:00:00+00:00 [running]> on host DESKTOP-VD1PANR.
[2023-11-30T12:57:09.580+0200] {taskinstance.py:1662} INFO - Exporting env vars: AIRFLOW_CTX_DAG_OWNER='airflow' AIRFLOW_CTX_DAG_ID='weather_data_pipeline' AIRFLOW_CTX_TASK_ID='check_api_Odesa' AIRFLOW_CTX_EXECUTION_DATE='2023-11-30T05:00:00+00:00' AIRFLOW_CTX_TRY_NUMBER='1' AIRFLOW_CTX_DAG_RUN_ID='scheduled__2023-11-30T05:00:00+00:00'
[2023-11-30T12:57:09.581+0200] {http.py:130} INFO - Poking: data/3.0/onecall
[2023-11-30T12:57:09.587+0200] {base.py:73} INFO - Using connection ID 'openweathermap_conn' for task execution.
[2023-11-30T12:57:09.679+0200] {http.py:178} ERROR - HTTP error: Unauthorized
[2023-11-30T12:57:09.679+0200] {http.py:179} ERROR - {"cod":401, "message": "Please note that using One Call 3.0 requires a separate subscription to the One Call by Call plan. Learn more here https://openweathermap.org/price. If you have a valid subscription to the One Call by Call plan, but still receive this error, then please see https://openweathermap.org/faq#error401 for more info."}
[2023-11-30T12:57:09.686+0200] {taskinstance.py:1937} ERROR - Task failed with exception
Traceback (most recent call last):
  File "/home/seva/.local/lib/python3.10/site-packages/airflow/providers/http/hooks/http.py", line 176, in check_response
    response.raise_for_status()
  File "/home/seva/.local/lib/python3.10/site-packages/requests/models.py", line 1021, in raise_for_status
    raise HTTPError(http_error_msg, response=self)
requests.exceptions.HTTPError: 401 Client Error: Unauthorized for url: http://api.openweathermap.org/data/3.0/onecall?appid=***&q=Odesa

During handling of the above exception, another exception occurred:

Traceback (most recent call last):
  File "/home/seva/.local/lib/python3.10/site-packages/airflow/sensors/base.py", line 257, in execute
    raise e
  File "/home/seva/.local/lib/python3.10/site-packages/airflow/sensors/base.py", line 239, in execute
    poke_return = self.poke(context)
  File "/home/seva/.local/lib/python3.10/site-packages/airflow/providers/http/sensors/http.py", line 148, in poke
    raise exc
  File "/home/seva/.local/lib/python3.10/site-packages/airflow/providers/http/sensors/http.py", line 132, in poke
    response = hook.run(
  File "/home/seva/.local/lib/python3.10/site-packages/airflow/providers/http/hooks/http.py", line 166, in run
    return self.run_and_check(session, prepped_request, extra_options)
  File "/home/seva/.local/lib/python3.10/site-packages/airflow/providers/http/hooks/http.py", line 217, in run_and_check
    self.check_response(response)
  File "/home/seva/.local/lib/python3.10/site-packages/airflow/providers/http/hooks/http.py", line 180, in check_response
    raise AirflowException(str(response.status_code) + ":" + response.reason)
airflow.exceptions.AirflowException: 401:Unauthorized
[2023-11-30T12:57:09.690+0200] {taskinstance.py:1400} INFO - Marking task as FAILED. dag_id=weather_data_pipeline, task_id=check_api_Odesa, execution_date=20231130T050000, start_date=20231130T105709, end_date=20231130T105709
[2023-11-30T12:57:09.715+0200] {standard_task_runner.py:104} ERROR - Failed to execute job 112 for task check_api_Odesa (401:Unauthorized; 20528)
[2023-11-30T12:57:09.736+0200] {local_task_job_runner.py:228} INFO - Task exited with return code 1
[2023-11-30T12:57:09.817+0200] {taskinstance.py:2778} INFO - 0 downstream tasks scheduled from follow-on schedule check
[2023-11-30T13:15:37.001+0200] {taskinstance.py:1159} INFO - Dependencies all met for dep_context=non-requeueable deps ti=<TaskInstance: weather_data_pipeline.check_api_Odesa scheduled__2023-11-30T05:00:00+00:00 [queued]>
[2023-11-30T13:15:37.009+0200] {taskinstance.py:1159} INFO - Dependencies all met for dep_context=requeueable deps ti=<TaskInstance: weather_data_pipeline.check_api_Odesa scheduled__2023-11-30T05:00:00+00:00 [queued]>
[2023-11-30T13:15:37.009+0200] {taskinstance.py:1361} INFO - Starting attempt 1 of 1
[2023-11-30T13:15:37.028+0200] {taskinstance.py:1382} INFO - Executing <Task(HttpSensor): check_api_Odesa> on 2023-11-30 05:00:00+00:00
[2023-11-30T13:15:37.030+0200] {standard_task_runner.py:57} INFO - Started process 22699 to run task
[2023-11-30T13:15:37.035+0200] {standard_task_runner.py:84} INFO - Running: ['airflow', 'tasks', 'run', 'weather_data_pipeline', 'check_api_Odesa', 'scheduled__2023-11-30T05:00:00+00:00', '--job-id', '203', '--raw', '--subdir', 'DAGS_FOLDER/weather_pipeline.py', '--cfg-path', '/tmp/tmpmdjnllh7']
[2023-11-30T13:15:37.037+0200] {standard_task_runner.py:85} INFO - Job 203: Subtask check_api_Odesa
[2023-11-30T13:15:37.082+0200] {task_command.py:416} INFO - Running <TaskInstance: weather_data_pipeline.check_api_Odesa scheduled__2023-11-30T05:00:00+00:00 [running]> on host DESKTOP-VD1PANR.
[2023-11-30T13:15:37.233+0200] {taskinstance.py:1662} INFO - Exporting env vars: AIRFLOW_CTX_DAG_OWNER='airflow' AIRFLOW_CTX_DAG_ID='weather_data_pipeline' AIRFLOW_CTX_TASK_ID='check_api_Odesa' AIRFLOW_CTX_EXECUTION_DATE='2023-11-30T05:00:00+00:00' AIRFLOW_CTX_TRY_NUMBER='1' AIRFLOW_CTX_DAG_RUN_ID='scheduled__2023-11-30T05:00:00+00:00'
[2023-11-30T13:15:37.234+0200] {http.py:130} INFO - Poking: data/3.0/onecall
[2023-11-30T13:15:37.242+0200] {base.py:73} INFO - Using connection ID 'openweathermap_conn' for task execution.
[2023-11-30T13:15:37.320+0200] {http.py:178} ERROR - HTTP error: Unauthorized
[2023-11-30T13:15:37.320+0200] {http.py:179} ERROR - {"cod":401, "message": "Please note that using One Call 3.0 requires a separate subscription to the One Call by Call plan. Learn more here https://openweathermap.org/price. If you have a valid subscription to the One Call by Call plan, but still receive this error, then please see https://openweathermap.org/faq#error401 for more info."}
[2023-11-30T13:15:37.324+0200] {taskinstance.py:1937} ERROR - Task failed with exception
Traceback (most recent call last):
  File "/home/seva/.local/lib/python3.10/site-packages/airflow/providers/http/hooks/http.py", line 176, in check_response
    response.raise_for_status()
  File "/home/seva/.local/lib/python3.10/site-packages/requests/models.py", line 1021, in raise_for_status
    raise HTTPError(http_error_msg, response=self)
requests.exceptions.HTTPError: 401 Client Error: Unauthorized for url: http://api.openweathermap.org/data/3.0/onecall?appid=***&q=Odesa

During handling of the above exception, another exception occurred:

Traceback (most recent call last):
  File "/home/seva/.local/lib/python3.10/site-packages/airflow/sensors/base.py", line 257, in execute
    raise e
  File "/home/seva/.local/lib/python3.10/site-packages/airflow/sensors/base.py", line 239, in execute
    poke_return = self.poke(context)
  File "/home/seva/.local/lib/python3.10/site-packages/airflow/providers/http/sensors/http.py", line 148, in poke
    raise exc
  File "/home/seva/.local/lib/python3.10/site-packages/airflow/providers/http/sensors/http.py", line 132, in poke
    response = hook.run(
  File "/home/seva/.local/lib/python3.10/site-packages/airflow/providers/http/hooks/http.py", line 166, in run
    return self.run_and_check(session, prepped_request, extra_options)
  File "/home/seva/.local/lib/python3.10/site-packages/airflow/providers/http/hooks/http.py", line 217, in run_and_check
    self.check_response(response)
  File "/home/seva/.local/lib/python3.10/site-packages/airflow/providers/http/hooks/http.py", line 180, in check_response
    raise AirflowException(str(response.status_code) + ":" + response.reason)
airflow.exceptions.AirflowException: 401:Unauthorized
[2023-11-30T13:15:37.328+0200] {taskinstance.py:1400} INFO - Marking task as FAILED. dag_id=weather_data_pipeline, task_id=check_api_Odesa, execution_date=20231130T050000, start_date=20231130T111537, end_date=20231130T111537
[2023-11-30T13:15:37.348+0200] {standard_task_runner.py:104} ERROR - Failed to execute job 203 for task check_api_Odesa (401:Unauthorized; 22699)
[2023-11-30T13:15:37.394+0200] {local_task_job_runner.py:228} INFO - Task exited with return code 1
[2023-11-30T13:15:37.469+0200] {taskinstance.py:2778} INFO - 0 downstream tasks scheduled from follow-on schedule check
[2023-11-30T13:25:34.015+0200] {taskinstance.py:1159} INFO - Dependencies all met for dep_context=non-requeueable deps ti=<TaskInstance: weather_data_pipeline.check_api_Odesa scheduled__2023-11-30T05:00:00+00:00 [queued]>
[2023-11-30T13:25:34.023+0200] {taskinstance.py:1159} INFO - Dependencies all met for dep_context=requeueable deps ti=<TaskInstance: weather_data_pipeline.check_api_Odesa scheduled__2023-11-30T05:00:00+00:00 [queued]>
[2023-11-30T13:25:34.023+0200] {taskinstance.py:1361} INFO - Starting attempt 1 of 1
[2023-11-30T13:25:34.045+0200] {taskinstance.py:1382} INFO - Executing <Task(HttpSensor): check_api_Odesa> on 2023-11-30 05:00:00+00:00
[2023-11-30T13:25:34.047+0200] {standard_task_runner.py:57} INFO - Started process 23928 to run task
[2023-11-30T13:25:34.052+0200] {standard_task_runner.py:84} INFO - Running: ['airflow', 'tasks', 'run', 'weather_data_pipeline', 'check_api_Odesa', 'scheduled__2023-11-30T05:00:00+00:00', '--job-id', '275', '--raw', '--subdir', 'DAGS_FOLDER/weather_pipeline.py', '--cfg-path', '/tmp/tmp28yxwar3']
[2023-11-30T13:25:34.054+0200] {standard_task_runner.py:85} INFO - Job 275: Subtask check_api_Odesa
[2023-11-30T13:25:34.095+0200] {task_command.py:416} INFO - Running <TaskInstance: weather_data_pipeline.check_api_Odesa scheduled__2023-11-30T05:00:00+00:00 [running]> on host DESKTOP-VD1PANR.
[2023-11-30T13:25:34.228+0200] {taskinstance.py:1662} INFO - Exporting env vars: AIRFLOW_CTX_DAG_OWNER='airflow' AIRFLOW_CTX_DAG_ID='weather_data_pipeline' AIRFLOW_CTX_TASK_ID='check_api_Odesa' AIRFLOW_CTX_EXECUTION_DATE='2023-11-30T05:00:00+00:00' AIRFLOW_CTX_TRY_NUMBER='1' AIRFLOW_CTX_DAG_RUN_ID='scheduled__2023-11-30T05:00:00+00:00'
[2023-11-30T13:25:34.228+0200] {http.py:130} INFO - Poking: data/3.0/onecall
[2023-11-30T13:25:34.232+0200] {base.py:73} INFO - Using connection ID 'openweathermap_conn' for task execution.
[2023-11-30T13:25:34.313+0200] {http.py:178} ERROR - HTTP error: Unauthorized
[2023-11-30T13:25:34.313+0200] {http.py:179} ERROR - {"cod":401, "message": "Please note that using One Call 3.0 requires a separate subscription to the One Call by Call plan. Learn more here https://openweathermap.org/price. If you have a valid subscription to the One Call by Call plan, but still receive this error, then please see https://openweathermap.org/faq#error401 for more info."}
[2023-11-30T13:25:34.319+0200] {taskinstance.py:1937} ERROR - Task failed with exception
Traceback (most recent call last):
  File "/home/seva/.local/lib/python3.10/site-packages/airflow/providers/http/hooks/http.py", line 176, in check_response
    response.raise_for_status()
  File "/home/seva/.local/lib/python3.10/site-packages/requests/models.py", line 1021, in raise_for_status
    raise HTTPError(http_error_msg, response=self)
requests.exceptions.HTTPError: 401 Client Error: Unauthorized for url: http://api.openweathermap.org/data/3.0/onecall?appid=***&q=Odesa

During handling of the above exception, another exception occurred:

Traceback (most recent call last):
  File "/home/seva/.local/lib/python3.10/site-packages/airflow/sensors/base.py", line 257, in execute
    raise e
  File "/home/seva/.local/lib/python3.10/site-packages/airflow/sensors/base.py", line 239, in execute
    poke_return = self.poke(context)
  File "/home/seva/.local/lib/python3.10/site-packages/airflow/providers/http/sensors/http.py", line 148, in poke
    raise exc
  File "/home/seva/.local/lib/python3.10/site-packages/airflow/providers/http/sensors/http.py", line 132, in poke
    response = hook.run(
  File "/home/seva/.local/lib/python3.10/site-packages/airflow/providers/http/hooks/http.py", line 166, in run
    return self.run_and_check(session, prepped_request, extra_options)
  File "/home/seva/.local/lib/python3.10/site-packages/airflow/providers/http/hooks/http.py", line 217, in run_and_check
    self.check_response(response)
  File "/home/seva/.local/lib/python3.10/site-packages/airflow/providers/http/hooks/http.py", line 180, in check_response
    raise AirflowException(str(response.status_code) + ":" + response.reason)
airflow.exceptions.AirflowException: 401:Unauthorized
[2023-11-30T13:25:34.323+0200] {taskinstance.py:1400} INFO - Marking task as FAILED. dag_id=weather_data_pipeline, task_id=check_api_Odesa, execution_date=20231130T050000, start_date=20231130T112534, end_date=20231130T112534
[2023-11-30T13:25:34.341+0200] {standard_task_runner.py:104} ERROR - Failed to execute job 275 for task check_api_Odesa (401:Unauthorized; 23928)
[2023-11-30T13:25:34.367+0200] {local_task_job_runner.py:228} INFO - Task exited with return code 1
[2023-11-30T13:25:34.450+0200] {taskinstance.py:2778} INFO - 0 downstream tasks scheduled from follow-on schedule check
