[2023-11-30T12:41:02.014+0200] {taskinstance.py:1159} INFO - Dependencies all met for dep_context=non-requeueable deps ti=<TaskInstance: weather_data_pipeline.check_api_Zhmerynka scheduled__2023-11-30T00:00:00+00:00 [queued]>
[2023-11-30T12:41:02.038+0200] {taskinstance.py:1159} INFO - Dependencies all met for dep_context=requeueable deps ti=<TaskInstance: weather_data_pipeline.check_api_Zhmerynka scheduled__2023-11-30T00:00:00+00:00 [queued]>
[2023-11-30T12:41:02.039+0200] {taskinstance.py:1361} INFO - Starting attempt 1 of 1
[2023-11-30T12:41:02.061+0200] {taskinstance.py:1382} INFO - Executing <Task(HttpSensor): check_api_Zhmerynka> on 2023-11-30 00:00:00+00:00
[2023-11-30T12:41:02.066+0200] {standard_task_runner.py:57} INFO - Started process 18507 to run task
[2023-11-30T12:41:02.073+0200] {standard_task_runner.py:84} INFO - Running: ['airflow', 'tasks', 'run', 'weather_data_pipeline', 'check_api_Zhmerynka', 'scheduled__2023-11-30T00:00:00+00:00', '--job-id', '12', '--raw', '--subdir', 'DAGS_FOLDER/weather_pipeline.py', '--cfg-path', '/tmp/tmpd_qt9m7y']
[2023-11-30T12:41:02.075+0200] {standard_task_runner.py:85} INFO - Job 12: Subtask check_api_Zhmerynka
[2023-11-30T12:41:02.120+0200] {task_command.py:416} INFO - Running <TaskInstance: weather_data_pipeline.check_api_Zhmerynka scheduled__2023-11-30T00:00:00+00:00 [running]> on host DESKTOP-VD1PANR.
[2023-11-30T12:41:02.323+0200] {taskinstance.py:1662} INFO - Exporting env vars: AIRFLOW_CTX_DAG_OWNER='airflow' AIRFLOW_CTX_DAG_ID='weather_data_pipeline' AIRFLOW_CTX_TASK_ID='check_api_Zhmerynka' AIRFLOW_CTX_EXECUTION_DATE='2023-11-30T00:00:00+00:00' AIRFLOW_CTX_TRY_NUMBER='1' AIRFLOW_CTX_DAG_RUN_ID='scheduled__2023-11-30T00:00:00+00:00'
[2023-11-30T12:41:02.324+0200] {http.py:130} INFO - Poking: data/3.0/onecall
[2023-11-30T12:41:02.333+0200] {taskinstance.py:1937} ERROR - Task failed with exception
Traceback (most recent call last):
  File "/home/seva/.local/lib/python3.10/site-packages/airflow/sensors/base.py", line 257, in execute
    raise e
  File "/home/seva/.local/lib/python3.10/site-packages/airflow/sensors/base.py", line 239, in execute
    poke_return = self.poke(context)
  File "/home/seva/.local/lib/python3.10/site-packages/airflow/providers/http/sensors/http.py", line 148, in poke
    raise exc
  File "/home/seva/.local/lib/python3.10/site-packages/airflow/providers/http/sensors/http.py", line 132, in poke
    response = hook.run(
  File "/home/seva/.local/lib/python3.10/site-packages/airflow/providers/http/hooks/http.py", line 145, in run
    session = self.get_conn(headers)
  File "/home/seva/.local/lib/python3.10/site-packages/airflow/providers/http/hooks/http.py", line 98, in get_conn
    conn = self.get_connection(self.http_conn_id)
  File "/home/seva/.local/lib/python3.10/site-packages/airflow/hooks/base.py", line 72, in get_connection
    conn = Connection.get_connection_from_secrets(conn_id)
  File "/home/seva/.local/lib/python3.10/site-packages/airflow/models/connection.py", line 477, in get_connection_from_secrets
    raise AirflowNotFoundException(f"The conn_id `{conn_id}` isn't defined")
airflow.exceptions.AirflowNotFoundException: The conn_id `openweathermap_conn` isn't defined
[2023-11-30T12:41:02.337+0200] {taskinstance.py:1400} INFO - Marking task as FAILED. dag_id=weather_data_pipeline, task_id=check_api_Zhmerynka, execution_date=20231130T000000, start_date=20231130T104102, end_date=20231130T104102
[2023-11-30T12:41:02.354+0200] {standard_task_runner.py:104} ERROR - Failed to execute job 12 for task check_api_Zhmerynka (The conn_id `openweathermap_conn` isn't defined; 18507)
[2023-11-30T12:41:02.379+0200] {local_task_job_runner.py:228} INFO - Task exited with return code 1
[2023-11-30T12:41:02.525+0200] {taskinstance.py:2778} INFO - 0 downstream tasks scheduled from follow-on schedule check
[2023-11-30T12:54:38.924+0200] {taskinstance.py:1159} INFO - Dependencies all met for dep_context=non-requeueable deps ti=<TaskInstance: weather_data_pipeline.check_api_Zhmerynka scheduled__2023-11-30T00:00:00+00:00 [queued]>
[2023-11-30T12:54:38.939+0200] {taskinstance.py:1159} INFO - Dependencies all met for dep_context=requeueable deps ti=<TaskInstance: weather_data_pipeline.check_api_Zhmerynka scheduled__2023-11-30T00:00:00+00:00 [queued]>
[2023-11-30T12:54:38.940+0200] {taskinstance.py:1361} INFO - Starting attempt 1 of 1
[2023-11-30T12:54:38.966+0200] {taskinstance.py:1382} INFO - Executing <Task(HttpSensor): check_api_Zhmerynka> on 2023-11-30 00:00:00+00:00
[2023-11-30T12:54:38.970+0200] {standard_task_runner.py:57} INFO - Started process 20121 to run task
[2023-11-30T12:54:38.975+0200] {standard_task_runner.py:84} INFO - Running: ['airflow', 'tasks', 'run', 'weather_data_pipeline', 'check_api_Zhmerynka', 'scheduled__2023-11-30T00:00:00+00:00', '--job-id', '54', '--raw', '--subdir', 'DAGS_FOLDER/weather_pipeline.py', '--cfg-path', '/tmp/tmpexgakfwf']
[2023-11-30T12:54:38.977+0200] {standard_task_runner.py:85} INFO - Job 54: Subtask check_api_Zhmerynka
[2023-11-30T12:54:39.028+0200] {task_command.py:416} INFO - Running <TaskInstance: weather_data_pipeline.check_api_Zhmerynka scheduled__2023-11-30T00:00:00+00:00 [running]> on host DESKTOP-VD1PANR.
[2023-11-30T12:54:39.176+0200] {taskinstance.py:1662} INFO - Exporting env vars: AIRFLOW_CTX_DAG_OWNER='airflow' AIRFLOW_CTX_DAG_ID='weather_data_pipeline' AIRFLOW_CTX_TASK_ID='check_api_Zhmerynka' AIRFLOW_CTX_EXECUTION_DATE='2023-11-30T00:00:00+00:00' AIRFLOW_CTX_TRY_NUMBER='1' AIRFLOW_CTX_DAG_RUN_ID='scheduled__2023-11-30T00:00:00+00:00'
[2023-11-30T12:54:39.177+0200] {http.py:130} INFO - Poking: data/3.0/onecall
[2023-11-30T12:54:39.180+0200] {base.py:73} INFO - Using connection ID 'openweathermap_conn' for task execution.
[2023-11-30T12:54:39.276+0200] {http.py:178} ERROR - HTTP error: Unauthorized
[2023-11-30T12:54:39.277+0200] {http.py:179} ERROR - {"cod":401, "message": "Please note that using One Call 3.0 requires a separate subscription to the One Call by Call plan. Learn more here https://openweathermap.org/price. If you have a valid subscription to the One Call by Call plan, but still receive this error, then please see https://openweathermap.org/faq#error401 for more info."}
[2023-11-30T12:54:39.281+0200] {taskinstance.py:1937} ERROR - Task failed with exception
Traceback (most recent call last):
  File "/home/seva/.local/lib/python3.10/site-packages/airflow/providers/http/hooks/http.py", line 176, in check_response
    response.raise_for_status()
  File "/home/seva/.local/lib/python3.10/site-packages/requests/models.py", line 1021, in raise_for_status
    raise HTTPError(http_error_msg, response=self)
requests.exceptions.HTTPError: 401 Client Error: Unauthorized for url: http://api.openweathermap.org/data/3.0/onecall?appid=***&q=Zhmerynka

During handling of the above exception, another exception occurred:

Traceback (most recent call last):
  File "/home/seva/.local/lib/python3.10/site-packages/airflow/sensors/base.py", line 257, in execute
    raise e
  File "/home/seva/.local/lib/python3.10/site-packages/airflow/sensors/base.py", line 239, in execute
    poke_return = self.poke(context)
  File "/home/seva/.local/lib/python3.10/site-packages/airflow/providers/http/sensors/http.py", line 148, in poke
    raise exc
  File "/home/seva/.local/lib/python3.10/site-packages/airflow/providers/http/sensors/http.py", line 132, in poke
    response = hook.run(
  File "/home/seva/.local/lib/python3.10/site-packages/airflow/providers/http/hooks/http.py", line 166, in run
    return self.run_and_check(session, prepped_request, extra_options)
  File "/home/seva/.local/lib/python3.10/site-packages/airflow/providers/http/hooks/http.py", line 217, in run_and_check
    self.check_response(response)
  File "/home/seva/.local/lib/python3.10/site-packages/airflow/providers/http/hooks/http.py", line 180, in check_response
    raise AirflowException(str(response.status_code) + ":" + response.reason)
airflow.exceptions.AirflowException: 401:Unauthorized
[2023-11-30T12:54:39.284+0200] {taskinstance.py:1400} INFO - Marking task as FAILED. dag_id=weather_data_pipeline, task_id=check_api_Zhmerynka, execution_date=20231130T000000, start_date=20231130T105438, end_date=20231130T105439
[2023-11-30T12:54:39.325+0200] {standard_task_runner.py:104} ERROR - Failed to execute job 54 for task check_api_Zhmerynka (401:Unauthorized; 20121)
[2023-11-30T12:54:39.334+0200] {local_task_job_runner.py:228} INFO - Task exited with return code 1
[2023-11-30T12:54:39.411+0200] {taskinstance.py:2778} INFO - 0 downstream tasks scheduled from follow-on schedule check
[2023-11-30T12:55:57.991+0200] {taskinstance.py:1159} INFO - Dependencies all met for dep_context=non-requeueable deps ti=<TaskInstance: weather_data_pipeline.check_api_Zhmerynka scheduled__2023-11-30T00:00:00+00:00 [queued]>
[2023-11-30T12:55:58.002+0200] {taskinstance.py:1159} INFO - Dependencies all met for dep_context=requeueable deps ti=<TaskInstance: weather_data_pipeline.check_api_Zhmerynka scheduled__2023-11-30T00:00:00+00:00 [queued]>
[2023-11-30T12:55:58.002+0200] {taskinstance.py:1361} INFO - Starting attempt 1 of 1
[2023-11-30T12:55:58.022+0200] {taskinstance.py:1382} INFO - Executing <Task(HttpSensor): check_api_Zhmerynka> on 2023-11-30 00:00:00+00:00
[2023-11-30T12:55:58.027+0200] {standard_task_runner.py:57} INFO - Started process 20334 to run task
[2023-11-30T12:55:58.033+0200] {standard_task_runner.py:84} INFO - Running: ['airflow', 'tasks', 'run', 'weather_data_pipeline', 'check_api_Zhmerynka', 'scheduled__2023-11-30T00:00:00+00:00', '--job-id', '79', '--raw', '--subdir', 'DAGS_FOLDER/weather_pipeline.py', '--cfg-path', '/tmp/tmp0vmyif01']
[2023-11-30T12:55:58.035+0200] {standard_task_runner.py:85} INFO - Job 79: Subtask check_api_Zhmerynka
[2023-11-30T12:55:58.087+0200] {task_command.py:416} INFO - Running <TaskInstance: weather_data_pipeline.check_api_Zhmerynka scheduled__2023-11-30T00:00:00+00:00 [running]> on host DESKTOP-VD1PANR.
[2023-11-30T12:55:58.226+0200] {taskinstance.py:1662} INFO - Exporting env vars: AIRFLOW_CTX_DAG_OWNER='airflow' AIRFLOW_CTX_DAG_ID='weather_data_pipeline' AIRFLOW_CTX_TASK_ID='check_api_Zhmerynka' AIRFLOW_CTX_EXECUTION_DATE='2023-11-30T00:00:00+00:00' AIRFLOW_CTX_TRY_NUMBER='1' AIRFLOW_CTX_DAG_RUN_ID='scheduled__2023-11-30T00:00:00+00:00'
[2023-11-30T12:55:58.227+0200] {http.py:130} INFO - Poking: data/3.0/onecall
[2023-11-30T12:55:58.232+0200] {base.py:73} INFO - Using connection ID 'openweathermap_conn' for task execution.
[2023-11-30T12:55:58.308+0200] {http.py:178} ERROR - HTTP error: Unauthorized
[2023-11-30T12:55:58.309+0200] {http.py:179} ERROR - {"cod":401, "message": "Please note that using One Call 3.0 requires a separate subscription to the One Call by Call plan. Learn more here https://openweathermap.org/price. If you have a valid subscription to the One Call by Call plan, but still receive this error, then please see https://openweathermap.org/faq#error401 for more info."}
[2023-11-30T12:55:58.316+0200] {taskinstance.py:1937} ERROR - Task failed with exception
Traceback (most recent call last):
  File "/home/seva/.local/lib/python3.10/site-packages/airflow/providers/http/hooks/http.py", line 176, in check_response
    response.raise_for_status()
  File "/home/seva/.local/lib/python3.10/site-packages/requests/models.py", line 1021, in raise_for_status
    raise HTTPError(http_error_msg, response=self)
requests.exceptions.HTTPError: 401 Client Error: Unauthorized for url: http://api.openweathermap.org/data/3.0/onecall?appid=***&q=Zhmerynka

During handling of the above exception, another exception occurred:

Traceback (most recent call last):
  File "/home/seva/.local/lib/python3.10/site-packages/airflow/sensors/base.py", line 257, in execute
    raise e
  File "/home/seva/.local/lib/python3.10/site-packages/airflow/sensors/base.py", line 239, in execute
    poke_return = self.poke(context)
  File "/home/seva/.local/lib/python3.10/site-packages/airflow/providers/http/sensors/http.py", line 148, in poke
    raise exc
  File "/home/seva/.local/lib/python3.10/site-packages/airflow/providers/http/sensors/http.py", line 132, in poke
    response = hook.run(
  File "/home/seva/.local/lib/python3.10/site-packages/airflow/providers/http/hooks/http.py", line 166, in run
    return self.run_and_check(session, prepped_request, extra_options)
  File "/home/seva/.local/lib/python3.10/site-packages/airflow/providers/http/hooks/http.py", line 217, in run_and_check
    self.check_response(response)
  File "/home/seva/.local/lib/python3.10/site-packages/airflow/providers/http/hooks/http.py", line 180, in check_response
    raise AirflowException(str(response.status_code) + ":" + response.reason)
airflow.exceptions.AirflowException: 401:Unauthorized
[2023-11-30T12:55:58.320+0200] {taskinstance.py:1400} INFO - Marking task as FAILED. dag_id=weather_data_pipeline, task_id=check_api_Zhmerynka, execution_date=20231130T000000, start_date=20231130T105557, end_date=20231130T105558
[2023-11-30T12:55:58.338+0200] {standard_task_runner.py:104} ERROR - Failed to execute job 79 for task check_api_Zhmerynka (401:Unauthorized; 20334)
[2023-11-30T12:55:58.377+0200] {local_task_job_runner.py:228} INFO - Task exited with return code 1
[2023-11-30T12:55:58.455+0200] {taskinstance.py:2778} INFO - 0 downstream tasks scheduled from follow-on schedule check
[2023-11-30T13:02:59.098+0200] {taskinstance.py:1159} INFO - Dependencies all met for dep_context=non-requeueable deps ti=<TaskInstance: weather_data_pipeline.check_api_Zhmerynka scheduled__2023-11-30T00:00:00+00:00 [queued]>
[2023-11-30T13:02:59.108+0200] {taskinstance.py:1159} INFO - Dependencies all met for dep_context=requeueable deps ti=<TaskInstance: weather_data_pipeline.check_api_Zhmerynka scheduled__2023-11-30T00:00:00+00:00 [queued]>
[2023-11-30T13:02:59.109+0200] {taskinstance.py:1361} INFO - Starting attempt 1 of 1
[2023-11-30T13:02:59.132+0200] {taskinstance.py:1382} INFO - Executing <Task(HttpSensor): check_api_Zhmerynka> on 2023-11-30 00:00:00+00:00
[2023-11-30T13:02:59.137+0200] {standard_task_runner.py:57} INFO - Started process 21236 to run task
[2023-11-30T13:02:59.142+0200] {standard_task_runner.py:84} INFO - Running: ['airflow', 'tasks', 'run', 'weather_data_pipeline', 'check_api_Zhmerynka', 'scheduled__2023-11-30T00:00:00+00:00', '--job-id', '150', '--raw', '--subdir', 'DAGS_FOLDER/weather_pipeline.py', '--cfg-path', '/tmp/tmp7yz7uhfc']
[2023-11-30T13:02:59.146+0200] {standard_task_runner.py:85} INFO - Job 150: Subtask check_api_Zhmerynka
[2023-11-30T13:02:59.211+0200] {task_command.py:416} INFO - Running <TaskInstance: weather_data_pipeline.check_api_Zhmerynka scheduled__2023-11-30T00:00:00+00:00 [running]> on host DESKTOP-VD1PANR.
[2023-11-30T13:02:59.367+0200] {taskinstance.py:1662} INFO - Exporting env vars: AIRFLOW_CTX_DAG_OWNER='airflow' AIRFLOW_CTX_DAG_ID='weather_data_pipeline' AIRFLOW_CTX_TASK_ID='check_api_Zhmerynka' AIRFLOW_CTX_EXECUTION_DATE='2023-11-30T00:00:00+00:00' AIRFLOW_CTX_TRY_NUMBER='1' AIRFLOW_CTX_DAG_RUN_ID='scheduled__2023-11-30T00:00:00+00:00'
[2023-11-30T13:02:59.368+0200] {http.py:130} INFO - Poking: data/3.0/onecall
[2023-11-30T13:02:59.375+0200] {base.py:73} INFO - Using connection ID 'openweathermap_conn' for task execution.
[2023-11-30T13:02:59.462+0200] {http.py:178} ERROR - HTTP error: Unauthorized
[2023-11-30T13:02:59.462+0200] {http.py:179} ERROR - {"cod":401, "message": "Please note that using One Call 3.0 requires a separate subscription to the One Call by Call plan. Learn more here https://openweathermap.org/price. If you have a valid subscription to the One Call by Call plan, but still receive this error, then please see https://openweathermap.org/faq#error401 for more info."}
[2023-11-30T13:02:59.472+0200] {taskinstance.py:1937} ERROR - Task failed with exception
Traceback (most recent call last):
  File "/home/seva/.local/lib/python3.10/site-packages/airflow/providers/http/hooks/http.py", line 176, in check_response
    response.raise_for_status()
  File "/home/seva/.local/lib/python3.10/site-packages/requests/models.py", line 1021, in raise_for_status
    raise HTTPError(http_error_msg, response=self)
requests.exceptions.HTTPError: 401 Client Error: Unauthorized for url: http://api.openweathermap.org/data/3.0/onecall?appid=***&q=Zhmerynka

During handling of the above exception, another exception occurred:

Traceback (most recent call last):
  File "/home/seva/.local/lib/python3.10/site-packages/airflow/sensors/base.py", line 257, in execute
    raise e
  File "/home/seva/.local/lib/python3.10/site-packages/airflow/sensors/base.py", line 239, in execute
    poke_return = self.poke(context)
  File "/home/seva/.local/lib/python3.10/site-packages/airflow/providers/http/sensors/http.py", line 148, in poke
    raise exc
  File "/home/seva/.local/lib/python3.10/site-packages/airflow/providers/http/sensors/http.py", line 132, in poke
    response = hook.run(
  File "/home/seva/.local/lib/python3.10/site-packages/airflow/providers/http/hooks/http.py", line 166, in run
    return self.run_and_check(session, prepped_request, extra_options)
  File "/home/seva/.local/lib/python3.10/site-packages/airflow/providers/http/hooks/http.py", line 217, in run_and_check
    self.check_response(response)
  File "/home/seva/.local/lib/python3.10/site-packages/airflow/providers/http/hooks/http.py", line 180, in check_response
    raise AirflowException(str(response.status_code) + ":" + response.reason)
airflow.exceptions.AirflowException: 401:Unauthorized
[2023-11-30T13:02:59.477+0200] {taskinstance.py:1400} INFO - Marking task as FAILED. dag_id=weather_data_pipeline, task_id=check_api_Zhmerynka, execution_date=20231130T000000, start_date=20231130T110259, end_date=20231130T110259
[2023-11-30T13:02:59.509+0200] {standard_task_runner.py:104} ERROR - Failed to execute job 150 for task check_api_Zhmerynka (401:Unauthorized; 21236)
[2023-11-30T13:02:59.536+0200] {local_task_job_runner.py:228} INFO - Task exited with return code 1
[2023-11-30T13:02:59.616+0200] {taskinstance.py:2778} INFO - 0 downstream tasks scheduled from follow-on schedule check
[2023-11-30T13:14:31.652+0200] {taskinstance.py:1159} INFO - Dependencies all met for dep_context=non-requeueable deps ti=<TaskInstance: weather_data_pipeline.check_api_Zhmerynka scheduled__2023-11-30T00:00:00+00:00 [queued]>
[2023-11-30T13:14:31.670+0200] {taskinstance.py:1159} INFO - Dependencies all met for dep_context=requeueable deps ti=<TaskInstance: weather_data_pipeline.check_api_Zhmerynka scheduled__2023-11-30T00:00:00+00:00 [queued]>
[2023-11-30T13:14:31.670+0200] {taskinstance.py:1361} INFO - Starting attempt 1 of 1
[2023-11-30T13:14:31.690+0200] {taskinstance.py:1382} INFO - Executing <Task(HttpSensor): check_api_Zhmerynka> on 2023-11-30 00:00:00+00:00
[2023-11-30T13:14:31.692+0200] {standard_task_runner.py:57} INFO - Started process 22523 to run task
[2023-11-30T13:14:31.697+0200] {standard_task_runner.py:84} INFO - Running: ['airflow', 'tasks', 'run', 'weather_data_pipeline', 'check_api_Zhmerynka', 'scheduled__2023-11-30T00:00:00+00:00', '--job-id', '170', '--raw', '--subdir', 'DAGS_FOLDER/weather_pipeline.py', '--cfg-path', '/tmp/tmpbtunscju']
[2023-11-30T13:14:31.699+0200] {standard_task_runner.py:85} INFO - Job 170: Subtask check_api_Zhmerynka
[2023-11-30T13:14:31.770+0200] {task_command.py:416} INFO - Running <TaskInstance: weather_data_pipeline.check_api_Zhmerynka scheduled__2023-11-30T00:00:00+00:00 [running]> on host DESKTOP-VD1PANR.
[2023-11-30T13:14:31.998+0200] {taskinstance.py:1662} INFO - Exporting env vars: AIRFLOW_CTX_DAG_OWNER='airflow' AIRFLOW_CTX_DAG_ID='weather_data_pipeline' AIRFLOW_CTX_TASK_ID='check_api_Zhmerynka' AIRFLOW_CTX_EXECUTION_DATE='2023-11-30T00:00:00+00:00' AIRFLOW_CTX_TRY_NUMBER='1' AIRFLOW_CTX_DAG_RUN_ID='scheduled__2023-11-30T00:00:00+00:00'
[2023-11-30T13:14:31.998+0200] {http.py:130} INFO - Poking: data/3.0/onecall
[2023-11-30T13:14:32.005+0200] {base.py:73} INFO - Using connection ID 'openweathermap_conn' for task execution.
[2023-11-30T13:14:32.098+0200] {http.py:178} ERROR - HTTP error: Unauthorized
[2023-11-30T13:14:32.099+0200] {http.py:179} ERROR - {"cod":401, "message": "Please note that using One Call 3.0 requires a separate subscription to the One Call by Call plan. Learn more here https://openweathermap.org/price. If you have a valid subscription to the One Call by Call plan, but still receive this error, then please see https://openweathermap.org/faq#error401 for more info."}
[2023-11-30T13:14:32.107+0200] {taskinstance.py:1937} ERROR - Task failed with exception
Traceback (most recent call last):
  File "/home/seva/.local/lib/python3.10/site-packages/airflow/providers/http/hooks/http.py", line 176, in check_response
    response.raise_for_status()
  File "/home/seva/.local/lib/python3.10/site-packages/requests/models.py", line 1021, in raise_for_status
    raise HTTPError(http_error_msg, response=self)
requests.exceptions.HTTPError: 401 Client Error: Unauthorized for url: http://api.openweathermap.org/data/3.0/onecall?appid=***&q=Zhmerynka

During handling of the above exception, another exception occurred:

Traceback (most recent call last):
  File "/home/seva/.local/lib/python3.10/site-packages/airflow/sensors/base.py", line 257, in execute
    raise e
  File "/home/seva/.local/lib/python3.10/site-packages/airflow/sensors/base.py", line 239, in execute
    poke_return = self.poke(context)
  File "/home/seva/.local/lib/python3.10/site-packages/airflow/providers/http/sensors/http.py", line 148, in poke
    raise exc
  File "/home/seva/.local/lib/python3.10/site-packages/airflow/providers/http/sensors/http.py", line 132, in poke
    response = hook.run(
  File "/home/seva/.local/lib/python3.10/site-packages/airflow/providers/http/hooks/http.py", line 166, in run
    return self.run_and_check(session, prepped_request, extra_options)
  File "/home/seva/.local/lib/python3.10/site-packages/airflow/providers/http/hooks/http.py", line 217, in run_and_check
    self.check_response(response)
  File "/home/seva/.local/lib/python3.10/site-packages/airflow/providers/http/hooks/http.py", line 180, in check_response
    raise AirflowException(str(response.status_code) + ":" + response.reason)
airflow.exceptions.AirflowException: 401:Unauthorized
[2023-11-30T13:14:32.112+0200] {taskinstance.py:1400} INFO - Marking task as FAILED. dag_id=weather_data_pipeline, task_id=check_api_Zhmerynka, execution_date=20231130T000000, start_date=20231130T111431, end_date=20231130T111432
[2023-11-30T13:14:32.158+0200] {standard_task_runner.py:104} ERROR - Failed to execute job 170 for task check_api_Zhmerynka (401:Unauthorized; 22523)
[2023-11-30T13:14:32.203+0200] {local_task_job_runner.py:228} INFO - Task exited with return code 1
[2023-11-30T13:14:32.334+0200] {taskinstance.py:2778} INFO - 0 downstream tasks scheduled from follow-on schedule check
[2023-11-30T13:24:30.381+0200] {taskinstance.py:1159} INFO - Dependencies all met for dep_context=non-requeueable deps ti=<TaskInstance: weather_data_pipeline.check_api_Zhmerynka scheduled__2023-11-30T00:00:00+00:00 [queued]>
[2023-11-30T13:24:30.388+0200] {taskinstance.py:1159} INFO - Dependencies all met for dep_context=requeueable deps ti=<TaskInstance: weather_data_pipeline.check_api_Zhmerynka scheduled__2023-11-30T00:00:00+00:00 [queued]>
[2023-11-30T13:24:30.389+0200] {taskinstance.py:1361} INFO - Starting attempt 1 of 1
[2023-11-30T13:24:30.414+0200] {taskinstance.py:1382} INFO - Executing <Task(HttpSensor): check_api_Zhmerynka> on 2023-11-30 00:00:00+00:00
[2023-11-30T13:24:30.417+0200] {standard_task_runner.py:57} INFO - Started process 23757 to run task
[2023-11-30T13:24:30.422+0200] {standard_task_runner.py:84} INFO - Running: ['airflow', 'tasks', 'run', 'weather_data_pipeline', 'check_api_Zhmerynka', 'scheduled__2023-11-30T00:00:00+00:00', '--job-id', '247', '--raw', '--subdir', 'DAGS_FOLDER/weather_pipeline.py', '--cfg-path', '/tmp/tmpsboxg0wj']
[2023-11-30T13:24:30.424+0200] {standard_task_runner.py:85} INFO - Job 247: Subtask check_api_Zhmerynka
[2023-11-30T13:24:30.476+0200] {task_command.py:416} INFO - Running <TaskInstance: weather_data_pipeline.check_api_Zhmerynka scheduled__2023-11-30T00:00:00+00:00 [running]> on host DESKTOP-VD1PANR.
[2023-11-30T13:24:30.623+0200] {taskinstance.py:1662} INFO - Exporting env vars: AIRFLOW_CTX_DAG_OWNER='airflow' AIRFLOW_CTX_DAG_ID='weather_data_pipeline' AIRFLOW_CTX_TASK_ID='check_api_Zhmerynka' AIRFLOW_CTX_EXECUTION_DATE='2023-11-30T00:00:00+00:00' AIRFLOW_CTX_TRY_NUMBER='1' AIRFLOW_CTX_DAG_RUN_ID='scheduled__2023-11-30T00:00:00+00:00'
[2023-11-30T13:24:30.624+0200] {http.py:130} INFO - Poking: data/3.0/onecall
[2023-11-30T13:24:30.629+0200] {base.py:73} INFO - Using connection ID 'openweathermap_conn' for task execution.
[2023-11-30T13:24:30.718+0200] {http.py:178} ERROR - HTTP error: Unauthorized
[2023-11-30T13:24:30.718+0200] {http.py:179} ERROR - {"cod":401, "message": "Please note that using One Call 3.0 requires a separate subscription to the One Call by Call plan. Learn more here https://openweathermap.org/price. If you have a valid subscription to the One Call by Call plan, but still receive this error, then please see https://openweathermap.org/faq#error401 for more info."}
[2023-11-30T13:24:30.726+0200] {taskinstance.py:1937} ERROR - Task failed with exception
Traceback (most recent call last):
  File "/home/seva/.local/lib/python3.10/site-packages/airflow/providers/http/hooks/http.py", line 176, in check_response
    response.raise_for_status()
  File "/home/seva/.local/lib/python3.10/site-packages/requests/models.py", line 1021, in raise_for_status
    raise HTTPError(http_error_msg, response=self)
requests.exceptions.HTTPError: 401 Client Error: Unauthorized for url: http://api.openweathermap.org/data/3.0/onecall?appid=***&q=Zhmerynka

During handling of the above exception, another exception occurred:

Traceback (most recent call last):
  File "/home/seva/.local/lib/python3.10/site-packages/airflow/sensors/base.py", line 257, in execute
    raise e
  File "/home/seva/.local/lib/python3.10/site-packages/airflow/sensors/base.py", line 239, in execute
    poke_return = self.poke(context)
  File "/home/seva/.local/lib/python3.10/site-packages/airflow/providers/http/sensors/http.py", line 148, in poke
    raise exc
  File "/home/seva/.local/lib/python3.10/site-packages/airflow/providers/http/sensors/http.py", line 132, in poke
    response = hook.run(
  File "/home/seva/.local/lib/python3.10/site-packages/airflow/providers/http/hooks/http.py", line 166, in run
    return self.run_and_check(session, prepped_request, extra_options)
  File "/home/seva/.local/lib/python3.10/site-packages/airflow/providers/http/hooks/http.py", line 217, in run_and_check
    self.check_response(response)
  File "/home/seva/.local/lib/python3.10/site-packages/airflow/providers/http/hooks/http.py", line 180, in check_response
    raise AirflowException(str(response.status_code) + ":" + response.reason)
airflow.exceptions.AirflowException: 401:Unauthorized
[2023-11-30T13:24:30.732+0200] {taskinstance.py:1400} INFO - Marking task as FAILED. dag_id=weather_data_pipeline, task_id=check_api_Zhmerynka, execution_date=20231130T000000, start_date=20231130T112430, end_date=20231130T112430
[2023-11-30T13:24:30.765+0200] {standard_task_runner.py:104} ERROR - Failed to execute job 247 for task check_api_Zhmerynka (401:Unauthorized; 23757)
[2023-11-30T13:24:30.782+0200] {local_task_job_runner.py:228} INFO - Task exited with return code 1
[2023-11-30T13:24:30.858+0200] {taskinstance.py:2778} INFO - 0 downstream tasks scheduled from follow-on schedule check
