[2023-11-30T12:57:39.344+0200] {taskinstance.py:1159} INFO - Dependencies all met for dep_context=non-requeueable deps ti=<TaskInstance: weather_data_pipeline.check_api_Odesa scheduled__2023-11-30T07:00:00+00:00 [queued]>
[2023-11-30T12:57:39.351+0200] {taskinstance.py:1159} INFO - Dependencies all met for dep_context=requeueable deps ti=<TaskInstance: weather_data_pipeline.check_api_Odesa scheduled__2023-11-30T07:00:00+00:00 [queued]>
[2023-11-30T12:57:39.351+0200] {taskinstance.py:1361} INFO - Starting attempt 1 of 1
[2023-11-30T12:57:39.374+0200] {taskinstance.py:1382} INFO - Executing <Task(HttpSensor): check_api_Odesa> on 2023-11-30 07:00:00+00:00
[2023-11-30T12:57:39.376+0200] {standard_task_runner.py:57} INFO - Started process 20611 to run task
[2023-11-30T12:57:39.383+0200] {standard_task_runner.py:84} INFO - Running: ['airflow', 'tasks', 'run', 'weather_data_pipeline', 'check_api_Odesa', 'scheduled__2023-11-30T07:00:00+00:00', '--job-id', '125', '--raw', '--subdir', 'DAGS_FOLDER/weather_pipeline.py', '--cfg-path', '/tmp/tmpsb2sdigy']
[2023-11-30T12:57:39.387+0200] {standard_task_runner.py:85} INFO - Job 125: Subtask check_api_Odesa
[2023-11-30T12:57:39.443+0200] {task_command.py:416} INFO - Running <TaskInstance: weather_data_pipeline.check_api_Odesa scheduled__2023-11-30T07:00:00+00:00 [running]> on host DESKTOP-VD1PANR.
[2023-11-30T12:57:39.618+0200] {taskinstance.py:1662} INFO - Exporting env vars: AIRFLOW_CTX_DAG_OWNER='airflow' AIRFLOW_CTX_DAG_ID='weather_data_pipeline' AIRFLOW_CTX_TASK_ID='check_api_Odesa' AIRFLOW_CTX_EXECUTION_DATE='2023-11-30T07:00:00+00:00' AIRFLOW_CTX_TRY_NUMBER='1' AIRFLOW_CTX_DAG_RUN_ID='scheduled__2023-11-30T07:00:00+00:00'
[2023-11-30T12:57:39.619+0200] {http.py:130} INFO - Poking: data/3.0/onecall
[2023-11-30T12:57:39.624+0200] {base.py:73} INFO - Using connection ID 'openweathermap_conn' for task execution.
[2023-11-30T12:57:39.740+0200] {http.py:178} ERROR - HTTP error: Unauthorized
[2023-11-30T12:57:39.740+0200] {http.py:179} ERROR - {"cod":401, "message": "Please note that using One Call 3.0 requires a separate subscription to the One Call by Call plan. Learn more here https://openweathermap.org/price. If you have a valid subscription to the One Call by Call plan, but still receive this error, then please see https://openweathermap.org/faq#error401 for more info."}
[2023-11-30T12:57:39.748+0200] {taskinstance.py:1937} ERROR - Task failed with exception
Traceback (most recent call last):
  File "/home/seva/.local/lib/python3.10/site-packages/airflow/providers/http/hooks/http.py", line 176, in check_response
    response.raise_for_status()
  File "/home/seva/.local/lib/python3.10/site-packages/requests/models.py", line 1021, in raise_for_status
    raise HTTPError(http_error_msg, response=self)
requests.exceptions.HTTPError: 401 Client Error: Unauthorized for url: http://api.openweathermap.org/data/3.0/onecall?appid=***&q=Odesa

During handling of the above exception, another exception occurred:

Traceback (most recent call last):
  File "/home/seva/.local/lib/python3.10/site-packages/airflow/sensors/base.py", line 257, in execute
    raise e
  File "/home/seva/.local/lib/python3.10/site-packages/airflow/sensors/base.py", line 239, in execute
    poke_return = self.poke(context)
  File "/home/seva/.local/lib/python3.10/site-packages/airflow/providers/http/sensors/http.py", line 148, in poke
    raise exc
  File "/home/seva/.local/lib/python3.10/site-packages/airflow/providers/http/sensors/http.py", line 132, in poke
    response = hook.run(
  File "/home/seva/.local/lib/python3.10/site-packages/airflow/providers/http/hooks/http.py", line 166, in run
    return self.run_and_check(session, prepped_request, extra_options)
  File "/home/seva/.local/lib/python3.10/site-packages/airflow/providers/http/hooks/http.py", line 217, in run_and_check
    self.check_response(response)
  File "/home/seva/.local/lib/python3.10/site-packages/airflow/providers/http/hooks/http.py", line 180, in check_response
    raise AirflowException(str(response.status_code) + ":" + response.reason)
airflow.exceptions.AirflowException: 401:Unauthorized
[2023-11-30T12:57:39.755+0200] {taskinstance.py:1400} INFO - Marking task as FAILED. dag_id=weather_data_pipeline, task_id=check_api_Odesa, execution_date=20231130T070000, start_date=20231130T105739, end_date=20231130T105739
[2023-11-30T12:57:39.790+0200] {standard_task_runner.py:104} ERROR - Failed to execute job 125 for task check_api_Odesa (401:Unauthorized; 20611)
[2023-11-30T12:57:39.816+0200] {local_task_job_runner.py:228} INFO - Task exited with return code 1
[2023-11-30T12:57:39.916+0200] {taskinstance.py:2778} INFO - 0 downstream tasks scheduled from follow-on schedule check
[2023-11-30T13:16:03.471+0200] {taskinstance.py:1159} INFO - Dependencies all met for dep_context=non-requeueable deps ti=<TaskInstance: weather_data_pipeline.check_api_Odesa scheduled__2023-11-30T07:00:00+00:00 [queued]>
[2023-11-30T13:16:03.479+0200] {taskinstance.py:1159} INFO - Dependencies all met for dep_context=requeueable deps ti=<TaskInstance: weather_data_pipeline.check_api_Odesa scheduled__2023-11-30T07:00:00+00:00 [queued]>
[2023-11-30T13:16:03.479+0200] {taskinstance.py:1361} INFO - Starting attempt 1 of 1
[2023-11-30T13:16:03.500+0200] {taskinstance.py:1382} INFO - Executing <Task(HttpSensor): check_api_Odesa> on 2023-11-30 07:00:00+00:00
[2023-11-30T13:16:03.503+0200] {standard_task_runner.py:57} INFO - Started process 22778 to run task
[2023-11-30T13:16:03.507+0200] {standard_task_runner.py:84} INFO - Running: ['airflow', 'tasks', 'run', 'weather_data_pipeline', 'check_api_Odesa', 'scheduled__2023-11-30T07:00:00+00:00', '--job-id', '216', '--raw', '--subdir', 'DAGS_FOLDER/weather_pipeline.py', '--cfg-path', '/tmp/tmpsr9ug2em']
[2023-11-30T13:16:03.508+0200] {standard_task_runner.py:85} INFO - Job 216: Subtask check_api_Odesa
[2023-11-30T13:16:03.556+0200] {task_command.py:416} INFO - Running <TaskInstance: weather_data_pipeline.check_api_Odesa scheduled__2023-11-30T07:00:00+00:00 [running]> on host DESKTOP-VD1PANR.
[2023-11-30T13:16:03.675+0200] {taskinstance.py:1662} INFO - Exporting env vars: AIRFLOW_CTX_DAG_OWNER='airflow' AIRFLOW_CTX_DAG_ID='weather_data_pipeline' AIRFLOW_CTX_TASK_ID='check_api_Odesa' AIRFLOW_CTX_EXECUTION_DATE='2023-11-30T07:00:00+00:00' AIRFLOW_CTX_TRY_NUMBER='1' AIRFLOW_CTX_DAG_RUN_ID='scheduled__2023-11-30T07:00:00+00:00'
[2023-11-30T13:16:03.676+0200] {http.py:130} INFO - Poking: data/3.0/onecall
[2023-11-30T13:16:03.679+0200] {base.py:73} INFO - Using connection ID 'openweathermap_conn' for task execution.
[2023-11-30T13:16:03.780+0200] {http.py:178} ERROR - HTTP error: Bad Request
[2023-11-30T13:16:03.781+0200] {http.py:179} ERROR - {"cod":"400","message":"no location specified"}
[2023-11-30T13:16:03.786+0200] {taskinstance.py:1937} ERROR - Task failed with exception
Traceback (most recent call last):
  File "/home/seva/.local/lib/python3.10/site-packages/airflow/providers/http/hooks/http.py", line 176, in check_response
    response.raise_for_status()
  File "/home/seva/.local/lib/python3.10/site-packages/requests/models.py", line 1021, in raise_for_status
    raise HTTPError(http_error_msg, response=self)
requests.exceptions.HTTPError: 400 Client Error: Bad Request for url: http://api.openweathermap.org/data/3.0/onecall?appid=***&q=Odesa

During handling of the above exception, another exception occurred:

Traceback (most recent call last):
  File "/home/seva/.local/lib/python3.10/site-packages/airflow/sensors/base.py", line 257, in execute
    raise e
  File "/home/seva/.local/lib/python3.10/site-packages/airflow/sensors/base.py", line 239, in execute
    poke_return = self.poke(context)
  File "/home/seva/.local/lib/python3.10/site-packages/airflow/providers/http/sensors/http.py", line 148, in poke
    raise exc
  File "/home/seva/.local/lib/python3.10/site-packages/airflow/providers/http/sensors/http.py", line 132, in poke
    response = hook.run(
  File "/home/seva/.local/lib/python3.10/site-packages/airflow/providers/http/hooks/http.py", line 166, in run
    return self.run_and_check(session, prepped_request, extra_options)
  File "/home/seva/.local/lib/python3.10/site-packages/airflow/providers/http/hooks/http.py", line 217, in run_and_check
    self.check_response(response)
  File "/home/seva/.local/lib/python3.10/site-packages/airflow/providers/http/hooks/http.py", line 180, in check_response
    raise AirflowException(str(response.status_code) + ":" + response.reason)
airflow.exceptions.AirflowException: 400:Bad Request
[2023-11-30T13:16:03.790+0200] {taskinstance.py:1400} INFO - Marking task as FAILED. dag_id=weather_data_pipeline, task_id=check_api_Odesa, execution_date=20231130T070000, start_date=20231130T111603, end_date=20231130T111603
[2023-11-30T13:16:03.810+0200] {standard_task_runner.py:104} ERROR - Failed to execute job 216 for task check_api_Odesa (400:Bad Request; 22778)
[2023-11-30T13:16:03.853+0200] {local_task_job_runner.py:228} INFO - Task exited with return code 1
[2023-11-30T13:16:03.922+0200] {taskinstance.py:2778} INFO - 0 downstream tasks scheduled from follow-on schedule check
[2023-11-30T13:26:00.538+0200] {taskinstance.py:1159} INFO - Dependencies all met for dep_context=non-requeueable deps ti=<TaskInstance: weather_data_pipeline.check_api_Odesa scheduled__2023-11-30T07:00:00+00:00 [queued]>
[2023-11-30T13:26:00.546+0200] {taskinstance.py:1159} INFO - Dependencies all met for dep_context=requeueable deps ti=<TaskInstance: weather_data_pipeline.check_api_Odesa scheduled__2023-11-30T07:00:00+00:00 [queued]>
[2023-11-30T13:26:00.547+0200] {taskinstance.py:1361} INFO - Starting attempt 1 of 1
[2023-11-30T13:26:00.568+0200] {taskinstance.py:1382} INFO - Executing <Task(HttpSensor): check_api_Odesa> on 2023-11-30 07:00:00+00:00
[2023-11-30T13:26:00.571+0200] {standard_task_runner.py:57} INFO - Started process 24003 to run task
[2023-11-30T13:26:00.576+0200] {standard_task_runner.py:84} INFO - Running: ['airflow', 'tasks', 'run', 'weather_data_pipeline', 'check_api_Odesa', 'scheduled__2023-11-30T07:00:00+00:00', '--job-id', '288', '--raw', '--subdir', 'DAGS_FOLDER/weather_pipeline.py', '--cfg-path', '/tmp/tmpfkrxsh_3']
[2023-11-30T13:26:00.578+0200] {standard_task_runner.py:85} INFO - Job 288: Subtask check_api_Odesa
[2023-11-30T13:26:00.621+0200] {task_command.py:416} INFO - Running <TaskInstance: weather_data_pipeline.check_api_Odesa scheduled__2023-11-30T07:00:00+00:00 [running]> on host DESKTOP-VD1PANR.
[2023-11-30T13:26:00.741+0200] {taskinstance.py:1662} INFO - Exporting env vars: AIRFLOW_CTX_DAG_OWNER='airflow' AIRFLOW_CTX_DAG_ID='weather_data_pipeline' AIRFLOW_CTX_TASK_ID='check_api_Odesa' AIRFLOW_CTX_EXECUTION_DATE='2023-11-30T07:00:00+00:00' AIRFLOW_CTX_TRY_NUMBER='1' AIRFLOW_CTX_DAG_RUN_ID='scheduled__2023-11-30T07:00:00+00:00'
[2023-11-30T13:26:00.742+0200] {http.py:130} INFO - Poking: data/3.0/onecall
[2023-11-30T13:26:00.746+0200] {base.py:73} INFO - Using connection ID 'openweathermap_conn' for task execution.
[2023-11-30T13:26:00.847+0200] {http.py:178} ERROR - HTTP error: Unauthorized
[2023-11-30T13:26:00.848+0200] {http.py:179} ERROR - {"cod":401, "message": "Please note that using One Call 3.0 requires a separate subscription to the One Call by Call plan. Learn more here https://openweathermap.org/price. If you have a valid subscription to the One Call by Call plan, but still receive this error, then please see https://openweathermap.org/faq#error401 for more info."}
[2023-11-30T13:26:00.853+0200] {taskinstance.py:1937} ERROR - Task failed with exception
Traceback (most recent call last):
  File "/home/seva/.local/lib/python3.10/site-packages/airflow/providers/http/hooks/http.py", line 176, in check_response
    response.raise_for_status()
  File "/home/seva/.local/lib/python3.10/site-packages/requests/models.py", line 1021, in raise_for_status
    raise HTTPError(http_error_msg, response=self)
requests.exceptions.HTTPError: 401 Client Error: Unauthorized for url: http://api.openweathermap.org/data/3.0/onecall?appid=***&q=Odesa

During handling of the above exception, another exception occurred:

Traceback (most recent call last):
  File "/home/seva/.local/lib/python3.10/site-packages/airflow/sensors/base.py", line 257, in execute
    raise e
  File "/home/seva/.local/lib/python3.10/site-packages/airflow/sensors/base.py", line 239, in execute
    poke_return = self.poke(context)
  File "/home/seva/.local/lib/python3.10/site-packages/airflow/providers/http/sensors/http.py", line 148, in poke
    raise exc
  File "/home/seva/.local/lib/python3.10/site-packages/airflow/providers/http/sensors/http.py", line 132, in poke
    response = hook.run(
  File "/home/seva/.local/lib/python3.10/site-packages/airflow/providers/http/hooks/http.py", line 166, in run
    return self.run_and_check(session, prepped_request, extra_options)
  File "/home/seva/.local/lib/python3.10/site-packages/airflow/providers/http/hooks/http.py", line 217, in run_and_check
    self.check_response(response)
  File "/home/seva/.local/lib/python3.10/site-packages/airflow/providers/http/hooks/http.py", line 180, in check_response
    raise AirflowException(str(response.status_code) + ":" + response.reason)
airflow.exceptions.AirflowException: 401:Unauthorized
[2023-11-30T13:26:00.856+0200] {taskinstance.py:1400} INFO - Marking task as FAILED. dag_id=weather_data_pipeline, task_id=check_api_Odesa, execution_date=20231130T070000, start_date=20231130T112600, end_date=20231130T112600
[2023-11-30T13:26:00.875+0200] {standard_task_runner.py:104} ERROR - Failed to execute job 288 for task check_api_Odesa (401:Unauthorized; 24003)
[2023-11-30T13:26:00.890+0200] {local_task_job_runner.py:228} INFO - Task exited with return code 1
[2023-11-30T13:26:00.960+0200] {taskinstance.py:2778} INFO - 0 downstream tasks scheduled from follow-on schedule check
