[2023-11-30T12:57:41.410+0200] {taskinstance.py:1159} INFO - Dependencies all met for dep_context=non-requeueable deps ti=<TaskInstance: weather_data_pipeline.check_api_Zhmerynka scheduled__2023-11-30T07:00:00+00:00 [queued]>
[2023-11-30T12:57:41.418+0200] {taskinstance.py:1159} INFO - Dependencies all met for dep_context=requeueable deps ti=<TaskInstance: weather_data_pipeline.check_api_Zhmerynka scheduled__2023-11-30T07:00:00+00:00 [queued]>
[2023-11-30T12:57:41.419+0200] {taskinstance.py:1361} INFO - Starting attempt 1 of 1
[2023-11-30T12:57:41.439+0200] {taskinstance.py:1382} INFO - Executing <Task(HttpSensor): check_api_Zhmerynka> on 2023-11-30 07:00:00+00:00
[2023-11-30T12:57:41.442+0200] {standard_task_runner.py:57} INFO - Started process 20619 to run task
[2023-11-30T12:57:41.446+0200] {standard_task_runner.py:84} INFO - Running: ['airflow', 'tasks', 'run', 'weather_data_pipeline', 'check_api_Zhmerynka', 'scheduled__2023-11-30T07:00:00+00:00', '--job-id', '126', '--raw', '--subdir', 'DAGS_FOLDER/weather_pipeline.py', '--cfg-path', '/tmp/tmpfq68zm9u']
[2023-11-30T12:57:41.448+0200] {standard_task_runner.py:85} INFO - Job 126: Subtask check_api_Zhmerynka
[2023-11-30T12:57:41.553+0200] {task_command.py:416} INFO - Running <TaskInstance: weather_data_pipeline.check_api_Zhmerynka scheduled__2023-11-30T07:00:00+00:00 [running]> on host DESKTOP-VD1PANR.
[2023-11-30T12:57:41.614+0200] {taskinstance.py:1662} INFO - Exporting env vars: AIRFLOW_CTX_DAG_OWNER='airflow' AIRFLOW_CTX_DAG_ID='weather_data_pipeline' AIRFLOW_CTX_TASK_ID='check_api_Zhmerynka' AIRFLOW_CTX_EXECUTION_DATE='2023-11-30T07:00:00+00:00' AIRFLOW_CTX_TRY_NUMBER='1' AIRFLOW_CTX_DAG_RUN_ID='scheduled__2023-11-30T07:00:00+00:00'
[2023-11-30T12:57:41.615+0200] {http.py:130} INFO - Poking: data/3.0/onecall
[2023-11-30T12:57:41.619+0200] {base.py:73} INFO - Using connection ID 'openweathermap_conn' for task execution.
[2023-11-30T12:57:41.705+0200] {http.py:178} ERROR - HTTP error: Unauthorized
[2023-11-30T12:57:41.705+0200] {http.py:179} ERROR - {"cod":401, "message": "Please note that using One Call 3.0 requires a separate subscription to the One Call by Call plan. Learn more here https://openweathermap.org/price. If you have a valid subscription to the One Call by Call plan, but still receive this error, then please see https://openweathermap.org/faq#error401 for more info."}
[2023-11-30T12:57:41.710+0200] {taskinstance.py:1937} ERROR - Task failed with exception
Traceback (most recent call last):
  File "/home/seva/.local/lib/python3.10/site-packages/airflow/providers/http/hooks/http.py", line 176, in check_response
    response.raise_for_status()
  File "/home/seva/.local/lib/python3.10/site-packages/requests/models.py", line 1021, in raise_for_status
    raise HTTPError(http_error_msg, response=self)
requests.exceptions.HTTPError: 401 Client Error: Unauthorized for url: http://api.openweathermap.org/data/3.0/onecall?appid=***&q=Zhmerynka

During handling of the above exception, another exception occurred:

Traceback (most recent call last):
  File "/home/seva/.local/lib/python3.10/site-packages/airflow/sensors/base.py", line 257, in execute
    raise e
  File "/home/seva/.local/lib/python3.10/site-packages/airflow/sensors/base.py", line 239, in execute
    poke_return = self.poke(context)
  File "/home/seva/.local/lib/python3.10/site-packages/airflow/providers/http/sensors/http.py", line 148, in poke
    raise exc
  File "/home/seva/.local/lib/python3.10/site-packages/airflow/providers/http/sensors/http.py", line 132, in poke
    response = hook.run(
  File "/home/seva/.local/lib/python3.10/site-packages/airflow/providers/http/hooks/http.py", line 166, in run
    return self.run_and_check(session, prepped_request, extra_options)
  File "/home/seva/.local/lib/python3.10/site-packages/airflow/providers/http/hooks/http.py", line 217, in run_and_check
    self.check_response(response)
  File "/home/seva/.local/lib/python3.10/site-packages/airflow/providers/http/hooks/http.py", line 180, in check_response
    raise AirflowException(str(response.status_code) + ":" + response.reason)
airflow.exceptions.AirflowException: 401:Unauthorized
[2023-11-30T12:57:41.713+0200] {taskinstance.py:1400} INFO - Marking task as FAILED. dag_id=weather_data_pipeline, task_id=check_api_Zhmerynka, execution_date=20231130T070000, start_date=20231130T105741, end_date=20231130T105741
[2023-11-30T12:57:41.744+0200] {standard_task_runner.py:104} ERROR - Failed to execute job 126 for task check_api_Zhmerynka (401:Unauthorized; 20619)
[2023-11-30T12:57:41.753+0200] {local_task_job_runner.py:228} INFO - Task exited with return code 1
[2023-11-30T12:57:41.844+0200] {taskinstance.py:2778} INFO - 0 downstream tasks scheduled from follow-on schedule check
[2023-11-30T13:16:05.226+0200] {taskinstance.py:1159} INFO - Dependencies all met for dep_context=non-requeueable deps ti=<TaskInstance: weather_data_pipeline.check_api_Zhmerynka scheduled__2023-11-30T07:00:00+00:00 [queued]>
[2023-11-30T13:16:05.234+0200] {taskinstance.py:1159} INFO - Dependencies all met for dep_context=requeueable deps ti=<TaskInstance: weather_data_pipeline.check_api_Zhmerynka scheduled__2023-11-30T07:00:00+00:00 [queued]>
[2023-11-30T13:16:05.235+0200] {taskinstance.py:1361} INFO - Starting attempt 1 of 1
[2023-11-30T13:16:05.254+0200] {taskinstance.py:1382} INFO - Executing <Task(HttpSensor): check_api_Zhmerynka> on 2023-11-30 07:00:00+00:00
[2023-11-30T13:16:05.257+0200] {standard_task_runner.py:57} INFO - Started process 22780 to run task
[2023-11-30T13:16:05.262+0200] {standard_task_runner.py:84} INFO - Running: ['airflow', 'tasks', 'run', 'weather_data_pipeline', 'check_api_Zhmerynka', 'scheduled__2023-11-30T07:00:00+00:00', '--job-id', '217', '--raw', '--subdir', 'DAGS_FOLDER/weather_pipeline.py', '--cfg-path', '/tmp/tmp4u2icn6q']
[2023-11-30T13:16:05.264+0200] {standard_task_runner.py:85} INFO - Job 217: Subtask check_api_Zhmerynka
[2023-11-30T13:16:05.365+0200] {task_command.py:416} INFO - Running <TaskInstance: weather_data_pipeline.check_api_Zhmerynka scheduled__2023-11-30T07:00:00+00:00 [running]> on host DESKTOP-VD1PANR.
[2023-11-30T13:16:05.426+0200] {taskinstance.py:1662} INFO - Exporting env vars: AIRFLOW_CTX_DAG_OWNER='airflow' AIRFLOW_CTX_DAG_ID='weather_data_pipeline' AIRFLOW_CTX_TASK_ID='check_api_Zhmerynka' AIRFLOW_CTX_EXECUTION_DATE='2023-11-30T07:00:00+00:00' AIRFLOW_CTX_TRY_NUMBER='1' AIRFLOW_CTX_DAG_RUN_ID='scheduled__2023-11-30T07:00:00+00:00'
[2023-11-30T13:16:05.427+0200] {http.py:130} INFO - Poking: data/3.0/onecall
[2023-11-30T13:16:05.430+0200] {base.py:73} INFO - Using connection ID 'openweathermap_conn' for task execution.
[2023-11-30T13:16:05.506+0200] {http.py:178} ERROR - HTTP error: Bad Request
[2023-11-30T13:16:05.507+0200] {http.py:179} ERROR - {"cod":"400","message":"no location specified"}
[2023-11-30T13:16:05.513+0200] {taskinstance.py:1937} ERROR - Task failed with exception
Traceback (most recent call last):
  File "/home/seva/.local/lib/python3.10/site-packages/airflow/providers/http/hooks/http.py", line 176, in check_response
    response.raise_for_status()
  File "/home/seva/.local/lib/python3.10/site-packages/requests/models.py", line 1021, in raise_for_status
    raise HTTPError(http_error_msg, response=self)
requests.exceptions.HTTPError: 400 Client Error: Bad Request for url: http://api.openweathermap.org/data/3.0/onecall?appid=***&q=Zhmerynka

During handling of the above exception, another exception occurred:

Traceback (most recent call last):
  File "/home/seva/.local/lib/python3.10/site-packages/airflow/sensors/base.py", line 257, in execute
    raise e
  File "/home/seva/.local/lib/python3.10/site-packages/airflow/sensors/base.py", line 239, in execute
    poke_return = self.poke(context)
  File "/home/seva/.local/lib/python3.10/site-packages/airflow/providers/http/sensors/http.py", line 148, in poke
    raise exc
  File "/home/seva/.local/lib/python3.10/site-packages/airflow/providers/http/sensors/http.py", line 132, in poke
    response = hook.run(
  File "/home/seva/.local/lib/python3.10/site-packages/airflow/providers/http/hooks/http.py", line 166, in run
    return self.run_and_check(session, prepped_request, extra_options)
  File "/home/seva/.local/lib/python3.10/site-packages/airflow/providers/http/hooks/http.py", line 217, in run_and_check
    self.check_response(response)
  File "/home/seva/.local/lib/python3.10/site-packages/airflow/providers/http/hooks/http.py", line 180, in check_response
    raise AirflowException(str(response.status_code) + ":" + response.reason)
airflow.exceptions.AirflowException: 400:Bad Request
[2023-11-30T13:16:05.516+0200] {taskinstance.py:1400} INFO - Marking task as FAILED. dag_id=weather_data_pipeline, task_id=check_api_Zhmerynka, execution_date=20231130T070000, start_date=20231130T111605, end_date=20231130T111605
[2023-11-30T13:16:05.534+0200] {standard_task_runner.py:104} ERROR - Failed to execute job 217 for task check_api_Zhmerynka (400:Bad Request; 22780)
[2023-11-30T13:16:05.573+0200] {local_task_job_runner.py:228} INFO - Task exited with return code 1
[2023-11-30T13:16:05.641+0200] {taskinstance.py:2778} INFO - 0 downstream tasks scheduled from follow-on schedule check
[2023-11-30T13:26:02.301+0200] {taskinstance.py:1159} INFO - Dependencies all met for dep_context=non-requeueable deps ti=<TaskInstance: weather_data_pipeline.check_api_Zhmerynka scheduled__2023-11-30T07:00:00+00:00 [queued]>
[2023-11-30T13:26:02.311+0200] {taskinstance.py:1159} INFO - Dependencies all met for dep_context=requeueable deps ti=<TaskInstance: weather_data_pipeline.check_api_Zhmerynka scheduled__2023-11-30T07:00:00+00:00 [queued]>
[2023-11-30T13:26:02.312+0200] {taskinstance.py:1361} INFO - Starting attempt 1 of 1
[2023-11-30T13:26:02.342+0200] {taskinstance.py:1382} INFO - Executing <Task(HttpSensor): check_api_Zhmerynka> on 2023-11-30 07:00:00+00:00
[2023-11-30T13:26:02.344+0200] {standard_task_runner.py:57} INFO - Started process 24005 to run task
[2023-11-30T13:26:02.349+0200] {standard_task_runner.py:84} INFO - Running: ['airflow', 'tasks', 'run', 'weather_data_pipeline', 'check_api_Zhmerynka', 'scheduled__2023-11-30T07:00:00+00:00', '--job-id', '289', '--raw', '--subdir', 'DAGS_FOLDER/weather_pipeline.py', '--cfg-path', '/tmp/tmprwqd4kh_']
[2023-11-30T13:26:02.351+0200] {standard_task_runner.py:85} INFO - Job 289: Subtask check_api_Zhmerynka
[2023-11-30T13:26:02.392+0200] {task_command.py:416} INFO - Running <TaskInstance: weather_data_pipeline.check_api_Zhmerynka scheduled__2023-11-30T07:00:00+00:00 [running]> on host DESKTOP-VD1PANR.
[2023-11-30T13:26:02.510+0200] {taskinstance.py:1662} INFO - Exporting env vars: AIRFLOW_CTX_DAG_OWNER='airflow' AIRFLOW_CTX_DAG_ID='weather_data_pipeline' AIRFLOW_CTX_TASK_ID='check_api_Zhmerynka' AIRFLOW_CTX_EXECUTION_DATE='2023-11-30T07:00:00+00:00' AIRFLOW_CTX_TRY_NUMBER='1' AIRFLOW_CTX_DAG_RUN_ID='scheduled__2023-11-30T07:00:00+00:00'
[2023-11-30T13:26:02.511+0200] {http.py:130} INFO - Poking: data/3.0/onecall
[2023-11-30T13:26:02.515+0200] {base.py:73} INFO - Using connection ID 'openweathermap_conn' for task execution.
[2023-11-30T13:26:02.620+0200] {http.py:178} ERROR - HTTP error: Unauthorized
[2023-11-30T13:26:02.621+0200] {http.py:179} ERROR - {"cod":401, "message": "Please note that using One Call 3.0 requires a separate subscription to the One Call by Call plan. Learn more here https://openweathermap.org/price. If you have a valid subscription to the One Call by Call plan, but still receive this error, then please see https://openweathermap.org/faq#error401 for more info."}
[2023-11-30T13:26:02.627+0200] {taskinstance.py:1937} ERROR - Task failed with exception
Traceback (most recent call last):
  File "/home/seva/.local/lib/python3.10/site-packages/airflow/providers/http/hooks/http.py", line 176, in check_response
    response.raise_for_status()
  File "/home/seva/.local/lib/python3.10/site-packages/requests/models.py", line 1021, in raise_for_status
    raise HTTPError(http_error_msg, response=self)
requests.exceptions.HTTPError: 401 Client Error: Unauthorized for url: http://api.openweathermap.org/data/3.0/onecall?appid=***&q=Zhmerynka

During handling of the above exception, another exception occurred:

Traceback (most recent call last):
  File "/home/seva/.local/lib/python3.10/site-packages/airflow/sensors/base.py", line 257, in execute
    raise e
  File "/home/seva/.local/lib/python3.10/site-packages/airflow/sensors/base.py", line 239, in execute
    poke_return = self.poke(context)
  File "/home/seva/.local/lib/python3.10/site-packages/airflow/providers/http/sensors/http.py", line 148, in poke
    raise exc
  File "/home/seva/.local/lib/python3.10/site-packages/airflow/providers/http/sensors/http.py", line 132, in poke
    response = hook.run(
  File "/home/seva/.local/lib/python3.10/site-packages/airflow/providers/http/hooks/http.py", line 166, in run
    return self.run_and_check(session, prepped_request, extra_options)
  File "/home/seva/.local/lib/python3.10/site-packages/airflow/providers/http/hooks/http.py", line 217, in run_and_check
    self.check_response(response)
  File "/home/seva/.local/lib/python3.10/site-packages/airflow/providers/http/hooks/http.py", line 180, in check_response
    raise AirflowException(str(response.status_code) + ":" + response.reason)
airflow.exceptions.AirflowException: 401:Unauthorized
[2023-11-30T13:26:02.630+0200] {taskinstance.py:1400} INFO - Marking task as FAILED. dag_id=weather_data_pipeline, task_id=check_api_Zhmerynka, execution_date=20231130T070000, start_date=20231130T112602, end_date=20231130T112602
[2023-11-30T13:26:02.653+0200] {standard_task_runner.py:104} ERROR - Failed to execute job 289 for task check_api_Zhmerynka (401:Unauthorized; 24005)
[2023-11-30T13:26:02.702+0200] {local_task_job_runner.py:228} INFO - Task exited with return code 1
[2023-11-30T13:26:02.777+0200] {taskinstance.py:2778} INFO - 0 downstream tasks scheduled from follow-on schedule check
