[2023-11-30T12:40:54.104+0200] {taskinstance.py:1159} INFO - Dependencies all met for dep_context=non-requeueable deps ti=<TaskInstance: weather_data_pipeline.check_api_Lviv scheduled__2023-11-30T00:00:00+00:00 [queued]>
[2023-11-30T12:40:54.109+0200] {taskinstance.py:1159} INFO - Dependencies all met for dep_context=requeueable deps ti=<TaskInstance: weather_data_pipeline.check_api_Lviv scheduled__2023-11-30T00:00:00+00:00 [queued]>
[2023-11-30T12:40:54.109+0200] {taskinstance.py:1361} INFO - Starting attempt 1 of 1
[2023-11-30T12:40:54.128+0200] {taskinstance.py:1382} INFO - Executing <Task(HttpSensor): check_api_Lviv> on 2023-11-30 00:00:00+00:00
[2023-11-30T12:40:54.130+0200] {standard_task_runner.py:57} INFO - Started process 18483 to run task
[2023-11-30T12:40:54.134+0200] {standard_task_runner.py:84} INFO - Running: ['airflow', 'tasks', 'run', 'weather_data_pipeline', 'check_api_Lviv', 'scheduled__2023-11-30T00:00:00+00:00', '--job-id', '8', '--raw', '--subdir', 'DAGS_FOLDER/weather_pipeline.py', '--cfg-path', '/tmp/tmpl3a__7ia']
[2023-11-30T12:40:54.136+0200] {standard_task_runner.py:85} INFO - Job 8: Subtask check_api_Lviv
[2023-11-30T12:40:54.175+0200] {task_command.py:416} INFO - Running <TaskInstance: weather_data_pipeline.check_api_Lviv scheduled__2023-11-30T00:00:00+00:00 [running]> on host DESKTOP-VD1PANR.
[2023-11-30T12:40:54.288+0200] {taskinstance.py:1662} INFO - Exporting env vars: AIRFLOW_CTX_DAG_OWNER='airflow' AIRFLOW_CTX_DAG_ID='weather_data_pipeline' AIRFLOW_CTX_TASK_ID='check_api_Lviv' AIRFLOW_CTX_EXECUTION_DATE='2023-11-30T00:00:00+00:00' AIRFLOW_CTX_TRY_NUMBER='1' AIRFLOW_CTX_DAG_RUN_ID='scheduled__2023-11-30T00:00:00+00:00'
[2023-11-30T12:40:54.289+0200] {http.py:130} INFO - Poking: data/3.0/onecall
[2023-11-30T12:40:54.295+0200] {taskinstance.py:1937} ERROR - Task failed with exception
Traceback (most recent call last):
  File "/home/seva/.local/lib/python3.10/site-packages/airflow/sensors/base.py", line 257, in execute
    raise e
  File "/home/seva/.local/lib/python3.10/site-packages/airflow/sensors/base.py", line 239, in execute
    poke_return = self.poke(context)
  File "/home/seva/.local/lib/python3.10/site-packages/airflow/providers/http/sensors/http.py", line 148, in poke
    raise exc
  File "/home/seva/.local/lib/python3.10/site-packages/airflow/providers/http/sensors/http.py", line 132, in poke
    response = hook.run(
  File "/home/seva/.local/lib/python3.10/site-packages/airflow/providers/http/hooks/http.py", line 145, in run
    session = self.get_conn(headers)
  File "/home/seva/.local/lib/python3.10/site-packages/airflow/providers/http/hooks/http.py", line 98, in get_conn
    conn = self.get_connection(self.http_conn_id)
  File "/home/seva/.local/lib/python3.10/site-packages/airflow/hooks/base.py", line 72, in get_connection
    conn = Connection.get_connection_from_secrets(conn_id)
  File "/home/seva/.local/lib/python3.10/site-packages/airflow/models/connection.py", line 477, in get_connection_from_secrets
    raise AirflowNotFoundException(f"The conn_id `{conn_id}` isn't defined")
airflow.exceptions.AirflowNotFoundException: The conn_id `openweathermap_conn` isn't defined
[2023-11-30T12:40:54.297+0200] {taskinstance.py:1400} INFO - Marking task as FAILED. dag_id=weather_data_pipeline, task_id=check_api_Lviv, execution_date=20231130T000000, start_date=20231130T104054, end_date=20231130T104054
[2023-11-30T12:40:54.313+0200] {standard_task_runner.py:104} ERROR - Failed to execute job 8 for task check_api_Lviv (The conn_id `openweathermap_conn` isn't defined; 18483)
[2023-11-30T12:40:54.320+0200] {local_task_job_runner.py:228} INFO - Task exited with return code 1
[2023-11-30T12:40:54.381+0200] {taskinstance.py:2778} INFO - 0 downstream tasks scheduled from follow-on schedule check
[2023-11-30T12:54:30.413+0200] {taskinstance.py:1159} INFO - Dependencies all met for dep_context=non-requeueable deps ti=<TaskInstance: weather_data_pipeline.check_api_Lviv scheduled__2023-11-30T00:00:00+00:00 [queued]>
[2023-11-30T12:54:30.420+0200] {taskinstance.py:1159} INFO - Dependencies all met for dep_context=requeueable deps ti=<TaskInstance: weather_data_pipeline.check_api_Lviv scheduled__2023-11-30T00:00:00+00:00 [queued]>
[2023-11-30T12:54:30.420+0200] {taskinstance.py:1361} INFO - Starting attempt 1 of 1
[2023-11-30T12:54:30.442+0200] {taskinstance.py:1382} INFO - Executing <Task(HttpSensor): check_api_Lviv> on 2023-11-30 00:00:00+00:00
[2023-11-30T12:54:30.444+0200] {standard_task_runner.py:57} INFO - Started process 20089 to run task
[2023-11-30T12:54:30.449+0200] {standard_task_runner.py:84} INFO - Running: ['airflow', 'tasks', 'run', 'weather_data_pipeline', 'check_api_Lviv', 'scheduled__2023-11-30T00:00:00+00:00', '--job-id', '50', '--raw', '--subdir', 'DAGS_FOLDER/weather_pipeline.py', '--cfg-path', '/tmp/tmp9bbq5foh']
[2023-11-30T12:54:30.450+0200] {standard_task_runner.py:85} INFO - Job 50: Subtask check_api_Lviv
[2023-11-30T12:54:30.489+0200] {task_command.py:416} INFO - Running <TaskInstance: weather_data_pipeline.check_api_Lviv scheduled__2023-11-30T00:00:00+00:00 [running]> on host DESKTOP-VD1PANR.
[2023-11-30T12:54:30.609+0200] {taskinstance.py:1662} INFO - Exporting env vars: AIRFLOW_CTX_DAG_OWNER='airflow' AIRFLOW_CTX_DAG_ID='weather_data_pipeline' AIRFLOW_CTX_TASK_ID='check_api_Lviv' AIRFLOW_CTX_EXECUTION_DATE='2023-11-30T00:00:00+00:00' AIRFLOW_CTX_TRY_NUMBER='1' AIRFLOW_CTX_DAG_RUN_ID='scheduled__2023-11-30T00:00:00+00:00'
[2023-11-30T12:54:30.610+0200] {http.py:130} INFO - Poking: data/3.0/onecall
[2023-11-30T12:54:30.614+0200] {base.py:73} INFO - Using connection ID 'openweathermap_conn' for task execution.
[2023-11-30T12:54:30.697+0200] {http.py:178} ERROR - HTTP error: Unauthorized
[2023-11-30T12:54:30.697+0200] {http.py:179} ERROR - {"cod":401, "message": "Please note that using One Call 3.0 requires a separate subscription to the One Call by Call plan. Learn more here https://openweathermap.org/price. If you have a valid subscription to the One Call by Call plan, but still receive this error, then please see https://openweathermap.org/faq#error401 for more info."}
[2023-11-30T12:54:30.702+0200] {taskinstance.py:1937} ERROR - Task failed with exception
Traceback (most recent call last):
  File "/home/seva/.local/lib/python3.10/site-packages/airflow/providers/http/hooks/http.py", line 176, in check_response
    response.raise_for_status()
  File "/home/seva/.local/lib/python3.10/site-packages/requests/models.py", line 1021, in raise_for_status
    raise HTTPError(http_error_msg, response=self)
requests.exceptions.HTTPError: 401 Client Error: Unauthorized for url: http://api.openweathermap.org/data/3.0/onecall?appid=***&q=Lviv

During handling of the above exception, another exception occurred:

Traceback (most recent call last):
  File "/home/seva/.local/lib/python3.10/site-packages/airflow/sensors/base.py", line 257, in execute
    raise e
  File "/home/seva/.local/lib/python3.10/site-packages/airflow/sensors/base.py", line 239, in execute
    poke_return = self.poke(context)
  File "/home/seva/.local/lib/python3.10/site-packages/airflow/providers/http/sensors/http.py", line 148, in poke
    raise exc
  File "/home/seva/.local/lib/python3.10/site-packages/airflow/providers/http/sensors/http.py", line 132, in poke
    response = hook.run(
  File "/home/seva/.local/lib/python3.10/site-packages/airflow/providers/http/hooks/http.py", line 166, in run
    return self.run_and_check(session, prepped_request, extra_options)
  File "/home/seva/.local/lib/python3.10/site-packages/airflow/providers/http/hooks/http.py", line 217, in run_and_check
    self.check_response(response)
  File "/home/seva/.local/lib/python3.10/site-packages/airflow/providers/http/hooks/http.py", line 180, in check_response
    raise AirflowException(str(response.status_code) + ":" + response.reason)
airflow.exceptions.AirflowException: 401:Unauthorized
[2023-11-30T12:54:30.707+0200] {taskinstance.py:1400} INFO - Marking task as FAILED. dag_id=weather_data_pipeline, task_id=check_api_Lviv, execution_date=20231130T000000, start_date=20231130T105430, end_date=20231130T105430
[2023-11-30T12:54:30.726+0200] {standard_task_runner.py:104} ERROR - Failed to execute job 50 for task check_api_Lviv (401:Unauthorized; 20089)
[2023-11-30T12:54:30.760+0200] {local_task_job_runner.py:228} INFO - Task exited with return code 1
[2023-11-30T12:54:30.870+0200] {taskinstance.py:2778} INFO - 0 downstream tasks scheduled from follow-on schedule check
[2023-11-30T12:55:48.939+0200] {taskinstance.py:1159} INFO - Dependencies all met for dep_context=non-requeueable deps ti=<TaskInstance: weather_data_pipeline.check_api_Lviv scheduled__2023-11-30T00:00:00+00:00 [queued]>
[2023-11-30T12:55:48.946+0200] {taskinstance.py:1159} INFO - Dependencies all met for dep_context=requeueable deps ti=<TaskInstance: weather_data_pipeline.check_api_Lviv scheduled__2023-11-30T00:00:00+00:00 [queued]>
[2023-11-30T12:55:48.947+0200] {taskinstance.py:1361} INFO - Starting attempt 1 of 1
[2023-11-30T12:55:48.967+0200] {taskinstance.py:1382} INFO - Executing <Task(HttpSensor): check_api_Lviv> on 2023-11-30 00:00:00+00:00
[2023-11-30T12:55:48.969+0200] {standard_task_runner.py:57} INFO - Started process 20305 to run task
[2023-11-30T12:55:48.974+0200] {standard_task_runner.py:84} INFO - Running: ['airflow', 'tasks', 'run', 'weather_data_pipeline', 'check_api_Lviv', 'scheduled__2023-11-30T00:00:00+00:00', '--job-id', '75', '--raw', '--subdir', 'DAGS_FOLDER/weather_pipeline.py', '--cfg-path', '/tmp/tmprll5jxjr']
[2023-11-30T12:55:48.976+0200] {standard_task_runner.py:85} INFO - Job 75: Subtask check_api_Lviv
[2023-11-30T12:55:49.016+0200] {task_command.py:416} INFO - Running <TaskInstance: weather_data_pipeline.check_api_Lviv scheduled__2023-11-30T00:00:00+00:00 [running]> on host DESKTOP-VD1PANR.
[2023-11-30T12:55:49.158+0200] {taskinstance.py:1662} INFO - Exporting env vars: AIRFLOW_CTX_DAG_OWNER='airflow' AIRFLOW_CTX_DAG_ID='weather_data_pipeline' AIRFLOW_CTX_TASK_ID='check_api_Lviv' AIRFLOW_CTX_EXECUTION_DATE='2023-11-30T00:00:00+00:00' AIRFLOW_CTX_TRY_NUMBER='1' AIRFLOW_CTX_DAG_RUN_ID='scheduled__2023-11-30T00:00:00+00:00'
[2023-11-30T12:55:49.159+0200] {http.py:130} INFO - Poking: data/3.0/onecall
[2023-11-30T12:55:49.163+0200] {base.py:73} INFO - Using connection ID 'openweathermap_conn' for task execution.
[2023-11-30T12:55:49.245+0200] {http.py:178} ERROR - HTTP error: Unauthorized
[2023-11-30T12:55:49.245+0200] {http.py:179} ERROR - {"cod":401, "message": "Please note that using One Call 3.0 requires a separate subscription to the One Call by Call plan. Learn more here https://openweathermap.org/price. If you have a valid subscription to the One Call by Call plan, but still receive this error, then please see https://openweathermap.org/faq#error401 for more info."}
[2023-11-30T12:55:49.251+0200] {taskinstance.py:1937} ERROR - Task failed with exception
Traceback (most recent call last):
  File "/home/seva/.local/lib/python3.10/site-packages/airflow/providers/http/hooks/http.py", line 176, in check_response
    response.raise_for_status()
  File "/home/seva/.local/lib/python3.10/site-packages/requests/models.py", line 1021, in raise_for_status
    raise HTTPError(http_error_msg, response=self)
requests.exceptions.HTTPError: 401 Client Error: Unauthorized for url: http://api.openweathermap.org/data/3.0/onecall?appid=***&q=Lviv

During handling of the above exception, another exception occurred:

Traceback (most recent call last):
  File "/home/seva/.local/lib/python3.10/site-packages/airflow/sensors/base.py", line 257, in execute
    raise e
  File "/home/seva/.local/lib/python3.10/site-packages/airflow/sensors/base.py", line 239, in execute
    poke_return = self.poke(context)
  File "/home/seva/.local/lib/python3.10/site-packages/airflow/providers/http/sensors/http.py", line 148, in poke
    raise exc
  File "/home/seva/.local/lib/python3.10/site-packages/airflow/providers/http/sensors/http.py", line 132, in poke
    response = hook.run(
  File "/home/seva/.local/lib/python3.10/site-packages/airflow/providers/http/hooks/http.py", line 166, in run
    return self.run_and_check(session, prepped_request, extra_options)
  File "/home/seva/.local/lib/python3.10/site-packages/airflow/providers/http/hooks/http.py", line 217, in run_and_check
    self.check_response(response)
  File "/home/seva/.local/lib/python3.10/site-packages/airflow/providers/http/hooks/http.py", line 180, in check_response
    raise AirflowException(str(response.status_code) + ":" + response.reason)
airflow.exceptions.AirflowException: 401:Unauthorized
[2023-11-30T12:55:49.255+0200] {taskinstance.py:1400} INFO - Marking task as FAILED. dag_id=weather_data_pipeline, task_id=check_api_Lviv, execution_date=20231130T000000, start_date=20231130T105548, end_date=20231130T105549
[2023-11-30T12:55:49.273+0200] {standard_task_runner.py:104} ERROR - Failed to execute job 75 for task check_api_Lviv (401:Unauthorized; 20305)
[2023-11-30T12:55:49.285+0200] {local_task_job_runner.py:228} INFO - Task exited with return code 1
[2023-11-30T12:55:49.373+0200] {taskinstance.py:2778} INFO - 0 downstream tasks scheduled from follow-on schedule check
[2023-11-30T13:02:51.181+0200] {taskinstance.py:1159} INFO - Dependencies all met for dep_context=non-requeueable deps ti=<TaskInstance: weather_data_pipeline.check_api_Lviv scheduled__2023-11-30T00:00:00+00:00 [queued]>
[2023-11-30T13:02:51.189+0200] {taskinstance.py:1159} INFO - Dependencies all met for dep_context=requeueable deps ti=<TaskInstance: weather_data_pipeline.check_api_Lviv scheduled__2023-11-30T00:00:00+00:00 [queued]>
[2023-11-30T13:02:51.189+0200] {taskinstance.py:1361} INFO - Starting attempt 1 of 1
[2023-11-30T13:02:51.208+0200] {taskinstance.py:1382} INFO - Executing <Task(HttpSensor): check_api_Lviv> on 2023-11-30 00:00:00+00:00
[2023-11-30T13:02:51.211+0200] {standard_task_runner.py:57} INFO - Started process 21216 to run task
[2023-11-30T13:02:51.216+0200] {standard_task_runner.py:84} INFO - Running: ['airflow', 'tasks', 'run', 'weather_data_pipeline', 'check_api_Lviv', 'scheduled__2023-11-30T00:00:00+00:00', '--job-id', '146', '--raw', '--subdir', 'DAGS_FOLDER/weather_pipeline.py', '--cfg-path', '/tmp/tmp_rzl6dsr']
[2023-11-30T13:02:51.217+0200] {standard_task_runner.py:85} INFO - Job 146: Subtask check_api_Lviv
[2023-11-30T13:02:51.261+0200] {task_command.py:416} INFO - Running <TaskInstance: weather_data_pipeline.check_api_Lviv scheduled__2023-11-30T00:00:00+00:00 [running]> on host DESKTOP-VD1PANR.
[2023-11-30T13:02:51.406+0200] {taskinstance.py:1662} INFO - Exporting env vars: AIRFLOW_CTX_DAG_OWNER='airflow' AIRFLOW_CTX_DAG_ID='weather_data_pipeline' AIRFLOW_CTX_TASK_ID='check_api_Lviv' AIRFLOW_CTX_EXECUTION_DATE='2023-11-30T00:00:00+00:00' AIRFLOW_CTX_TRY_NUMBER='1' AIRFLOW_CTX_DAG_RUN_ID='scheduled__2023-11-30T00:00:00+00:00'
[2023-11-30T13:02:51.406+0200] {http.py:130} INFO - Poking: data/3.0/onecall
[2023-11-30T13:02:51.412+0200] {base.py:73} INFO - Using connection ID 'openweathermap_conn' for task execution.
[2023-11-30T13:02:51.506+0200] {http.py:178} ERROR - HTTP error: Unauthorized
[2023-11-30T13:02:51.506+0200] {http.py:179} ERROR - {"cod":401, "message": "Please note that using One Call 3.0 requires a separate subscription to the One Call by Call plan. Learn more here https://openweathermap.org/price. If you have a valid subscription to the One Call by Call plan, but still receive this error, then please see https://openweathermap.org/faq#error401 for more info."}
[2023-11-30T13:02:51.511+0200] {taskinstance.py:1937} ERROR - Task failed with exception
Traceback (most recent call last):
  File "/home/seva/.local/lib/python3.10/site-packages/airflow/providers/http/hooks/http.py", line 176, in check_response
    response.raise_for_status()
  File "/home/seva/.local/lib/python3.10/site-packages/requests/models.py", line 1021, in raise_for_status
    raise HTTPError(http_error_msg, response=self)
requests.exceptions.HTTPError: 401 Client Error: Unauthorized for url: http://api.openweathermap.org/data/3.0/onecall?appid=***&q=Lviv

During handling of the above exception, another exception occurred:

Traceback (most recent call last):
  File "/home/seva/.local/lib/python3.10/site-packages/airflow/sensors/base.py", line 257, in execute
    raise e
  File "/home/seva/.local/lib/python3.10/site-packages/airflow/sensors/base.py", line 239, in execute
    poke_return = self.poke(context)
  File "/home/seva/.local/lib/python3.10/site-packages/airflow/providers/http/sensors/http.py", line 148, in poke
    raise exc
  File "/home/seva/.local/lib/python3.10/site-packages/airflow/providers/http/sensors/http.py", line 132, in poke
    response = hook.run(
  File "/home/seva/.local/lib/python3.10/site-packages/airflow/providers/http/hooks/http.py", line 166, in run
    return self.run_and_check(session, prepped_request, extra_options)
  File "/home/seva/.local/lib/python3.10/site-packages/airflow/providers/http/hooks/http.py", line 217, in run_and_check
    self.check_response(response)
  File "/home/seva/.local/lib/python3.10/site-packages/airflow/providers/http/hooks/http.py", line 180, in check_response
    raise AirflowException(str(response.status_code) + ":" + response.reason)
airflow.exceptions.AirflowException: 401:Unauthorized
[2023-11-30T13:02:51.514+0200] {taskinstance.py:1400} INFO - Marking task as FAILED. dag_id=weather_data_pipeline, task_id=check_api_Lviv, execution_date=20231130T000000, start_date=20231130T110251, end_date=20231130T110251
[2023-11-30T13:02:51.536+0200] {standard_task_runner.py:104} ERROR - Failed to execute job 146 for task check_api_Lviv (401:Unauthorized; 21216)
[2023-11-30T13:02:51.568+0200] {local_task_job_runner.py:228} INFO - Task exited with return code 1
[2023-11-30T13:02:51.640+0200] {taskinstance.py:2778} INFO - 0 downstream tasks scheduled from follow-on schedule check
[2023-11-30T13:14:22.038+0200] {taskinstance.py:1159} INFO - Dependencies all met for dep_context=non-requeueable deps ti=<TaskInstance: weather_data_pipeline.check_api_Lviv scheduled__2023-11-30T00:00:00+00:00 [queued]>
[2023-11-30T13:14:22.044+0200] {taskinstance.py:1159} INFO - Dependencies all met for dep_context=requeueable deps ti=<TaskInstance: weather_data_pipeline.check_api_Lviv scheduled__2023-11-30T00:00:00+00:00 [queued]>
[2023-11-30T13:14:22.044+0200] {taskinstance.py:1361} INFO - Starting attempt 1 of 1
[2023-11-30T13:14:22.065+0200] {taskinstance.py:1382} INFO - Executing <Task(HttpSensor): check_api_Lviv> on 2023-11-30 00:00:00+00:00
[2023-11-30T13:14:22.067+0200] {standard_task_runner.py:57} INFO - Started process 22494 to run task
[2023-11-30T13:14:22.073+0200] {standard_task_runner.py:84} INFO - Running: ['airflow', 'tasks', 'run', 'weather_data_pipeline', 'check_api_Lviv', 'scheduled__2023-11-30T00:00:00+00:00', '--job-id', '166', '--raw', '--subdir', 'DAGS_FOLDER/weather_pipeline.py', '--cfg-path', '/tmp/tmp_1xx8imp']
[2023-11-30T13:14:22.074+0200] {standard_task_runner.py:85} INFO - Job 166: Subtask check_api_Lviv
[2023-11-30T13:14:22.114+0200] {task_command.py:416} INFO - Running <TaskInstance: weather_data_pipeline.check_api_Lviv scheduled__2023-11-30T00:00:00+00:00 [running]> on host DESKTOP-VD1PANR.
[2023-11-30T13:14:22.234+0200] {taskinstance.py:1662} INFO - Exporting env vars: AIRFLOW_CTX_DAG_OWNER='airflow' AIRFLOW_CTX_DAG_ID='weather_data_pipeline' AIRFLOW_CTX_TASK_ID='check_api_Lviv' AIRFLOW_CTX_EXECUTION_DATE='2023-11-30T00:00:00+00:00' AIRFLOW_CTX_TRY_NUMBER='1' AIRFLOW_CTX_DAG_RUN_ID='scheduled__2023-11-30T00:00:00+00:00'
[2023-11-30T13:14:22.234+0200] {http.py:130} INFO - Poking: data/3.0/onecall
[2023-11-30T13:14:22.237+0200] {base.py:73} INFO - Using connection ID 'openweathermap_conn' for task execution.
[2023-11-30T13:14:22.324+0200] {http.py:178} ERROR - HTTP error: Unauthorized
[2023-11-30T13:14:22.324+0200] {http.py:179} ERROR - {"cod":401, "message": "Please note that using One Call 3.0 requires a separate subscription to the One Call by Call plan. Learn more here https://openweathermap.org/price. If you have a valid subscription to the One Call by Call plan, but still receive this error, then please see https://openweathermap.org/faq#error401 for more info."}
[2023-11-30T13:14:22.330+0200] {taskinstance.py:1937} ERROR - Task failed with exception
Traceback (most recent call last):
  File "/home/seva/.local/lib/python3.10/site-packages/airflow/providers/http/hooks/http.py", line 176, in check_response
    response.raise_for_status()
  File "/home/seva/.local/lib/python3.10/site-packages/requests/models.py", line 1021, in raise_for_status
    raise HTTPError(http_error_msg, response=self)
requests.exceptions.HTTPError: 401 Client Error: Unauthorized for url: http://api.openweathermap.org/data/3.0/onecall?appid=***&q=Lviv

During handling of the above exception, another exception occurred:

Traceback (most recent call last):
  File "/home/seva/.local/lib/python3.10/site-packages/airflow/sensors/base.py", line 257, in execute
    raise e
  File "/home/seva/.local/lib/python3.10/site-packages/airflow/sensors/base.py", line 239, in execute
    poke_return = self.poke(context)
  File "/home/seva/.local/lib/python3.10/site-packages/airflow/providers/http/sensors/http.py", line 148, in poke
    raise exc
  File "/home/seva/.local/lib/python3.10/site-packages/airflow/providers/http/sensors/http.py", line 132, in poke
    response = hook.run(
  File "/home/seva/.local/lib/python3.10/site-packages/airflow/providers/http/hooks/http.py", line 166, in run
    return self.run_and_check(session, prepped_request, extra_options)
  File "/home/seva/.local/lib/python3.10/site-packages/airflow/providers/http/hooks/http.py", line 217, in run_and_check
    self.check_response(response)
  File "/home/seva/.local/lib/python3.10/site-packages/airflow/providers/http/hooks/http.py", line 180, in check_response
    raise AirflowException(str(response.status_code) + ":" + response.reason)
airflow.exceptions.AirflowException: 401:Unauthorized
[2023-11-30T13:14:22.332+0200] {taskinstance.py:1400} INFO - Marking task as FAILED. dag_id=weather_data_pipeline, task_id=check_api_Lviv, execution_date=20231130T000000, start_date=20231130T111422, end_date=20231130T111422
[2023-11-30T13:14:22.349+0200] {standard_task_runner.py:104} ERROR - Failed to execute job 166 for task check_api_Lviv (401:Unauthorized; 22494)
[2023-11-30T13:14:22.384+0200] {local_task_job_runner.py:228} INFO - Task exited with return code 1
[2023-11-30T13:14:22.450+0200] {taskinstance.py:2778} INFO - 0 downstream tasks scheduled from follow-on schedule check
[2023-11-30T13:24:20.879+0200] {taskinstance.py:1159} INFO - Dependencies all met for dep_context=non-requeueable deps ti=<TaskInstance: weather_data_pipeline.check_api_Lviv scheduled__2023-11-30T00:00:00+00:00 [queued]>
[2023-11-30T13:24:20.899+0200] {taskinstance.py:1159} INFO - Dependencies all met for dep_context=requeueable deps ti=<TaskInstance: weather_data_pipeline.check_api_Lviv scheduled__2023-11-30T00:00:00+00:00 [queued]>
[2023-11-30T13:24:20.901+0200] {taskinstance.py:1361} INFO - Starting attempt 1 of 1
[2023-11-30T13:24:20.933+0200] {taskinstance.py:1382} INFO - Executing <Task(HttpSensor): check_api_Lviv> on 2023-11-30 00:00:00+00:00
[2023-11-30T13:24:20.937+0200] {standard_task_runner.py:57} INFO - Started process 23731 to run task
[2023-11-30T13:24:20.944+0200] {standard_task_runner.py:84} INFO - Running: ['airflow', 'tasks', 'run', 'weather_data_pipeline', 'check_api_Lviv', 'scheduled__2023-11-30T00:00:00+00:00', '--job-id', '243', '--raw', '--subdir', 'DAGS_FOLDER/weather_pipeline.py', '--cfg-path', '/tmp/tmp83uasa6m']
[2023-11-30T13:24:20.946+0200] {standard_task_runner.py:85} INFO - Job 243: Subtask check_api_Lviv
[2023-11-30T13:24:21.016+0200] {task_command.py:416} INFO - Running <TaskInstance: weather_data_pipeline.check_api_Lviv scheduled__2023-11-30T00:00:00+00:00 [running]> on host DESKTOP-VD1PANR.
[2023-11-30T13:24:21.294+0200] {taskinstance.py:1662} INFO - Exporting env vars: AIRFLOW_CTX_DAG_OWNER='airflow' AIRFLOW_CTX_DAG_ID='weather_data_pipeline' AIRFLOW_CTX_TASK_ID='check_api_Lviv' AIRFLOW_CTX_EXECUTION_DATE='2023-11-30T00:00:00+00:00' AIRFLOW_CTX_TRY_NUMBER='1' AIRFLOW_CTX_DAG_RUN_ID='scheduled__2023-11-30T00:00:00+00:00'
[2023-11-30T13:24:21.295+0200] {http.py:130} INFO - Poking: data/3.0/onecall
[2023-11-30T13:24:21.305+0200] {base.py:73} INFO - Using connection ID 'openweathermap_conn' for task execution.
[2023-11-30T13:24:21.399+0200] {http.py:178} ERROR - HTTP error: Unauthorized
[2023-11-30T13:24:21.400+0200] {http.py:179} ERROR - {"cod":401, "message": "Please note that using One Call 3.0 requires a separate subscription to the One Call by Call plan. Learn more here https://openweathermap.org/price. If you have a valid subscription to the One Call by Call plan, but still receive this error, then please see https://openweathermap.org/faq#error401 for more info."}
[2023-11-30T13:24:21.412+0200] {taskinstance.py:1937} ERROR - Task failed with exception
Traceback (most recent call last):
  File "/home/seva/.local/lib/python3.10/site-packages/airflow/providers/http/hooks/http.py", line 176, in check_response
    response.raise_for_status()
  File "/home/seva/.local/lib/python3.10/site-packages/requests/models.py", line 1021, in raise_for_status
    raise HTTPError(http_error_msg, response=self)
requests.exceptions.HTTPError: 401 Client Error: Unauthorized for url: http://api.openweathermap.org/data/3.0/onecall?appid=***&q=Lviv

During handling of the above exception, another exception occurred:

Traceback (most recent call last):
  File "/home/seva/.local/lib/python3.10/site-packages/airflow/sensors/base.py", line 257, in execute
    raise e
  File "/home/seva/.local/lib/python3.10/site-packages/airflow/sensors/base.py", line 239, in execute
    poke_return = self.poke(context)
  File "/home/seva/.local/lib/python3.10/site-packages/airflow/providers/http/sensors/http.py", line 148, in poke
    raise exc
  File "/home/seva/.local/lib/python3.10/site-packages/airflow/providers/http/sensors/http.py", line 132, in poke
    response = hook.run(
  File "/home/seva/.local/lib/python3.10/site-packages/airflow/providers/http/hooks/http.py", line 166, in run
    return self.run_and_check(session, prepped_request, extra_options)
  File "/home/seva/.local/lib/python3.10/site-packages/airflow/providers/http/hooks/http.py", line 217, in run_and_check
    self.check_response(response)
  File "/home/seva/.local/lib/python3.10/site-packages/airflow/providers/http/hooks/http.py", line 180, in check_response
    raise AirflowException(str(response.status_code) + ":" + response.reason)
airflow.exceptions.AirflowException: 401:Unauthorized
[2023-11-30T13:24:21.420+0200] {taskinstance.py:1400} INFO - Marking task as FAILED. dag_id=weather_data_pipeline, task_id=check_api_Lviv, execution_date=20231130T000000, start_date=20231130T112420, end_date=20231130T112421
[2023-11-30T13:24:21.450+0200] {standard_task_runner.py:104} ERROR - Failed to execute job 243 for task check_api_Lviv (401:Unauthorized; 23731)
[2023-11-30T13:24:21.488+0200] {local_task_job_runner.py:228} INFO - Task exited with return code 1
[2023-11-30T13:24:21.717+0200] {taskinstance.py:2778} INFO - 0 downstream tasks scheduled from follow-on schedule check
