[2023-11-30T12:40:58.043+0200] {taskinstance.py:1159} INFO - Dependencies all met for dep_context=non-requeueable deps ti=<TaskInstance: weather_data_pipeline.check_api_Kharkiv scheduled__2023-11-30T00:00:00+00:00 [queued]>
[2023-11-30T12:40:58.048+0200] {taskinstance.py:1159} INFO - Dependencies all met for dep_context=requeueable deps ti=<TaskInstance: weather_data_pipeline.check_api_Kharkiv scheduled__2023-11-30T00:00:00+00:00 [queued]>
[2023-11-30T12:40:58.049+0200] {taskinstance.py:1361} INFO - Starting attempt 1 of 1
[2023-11-30T12:40:58.074+0200] {taskinstance.py:1382} INFO - Executing <Task(HttpSensor): check_api_Kharkiv> on 2023-11-30 00:00:00+00:00
[2023-11-30T12:40:58.077+0200] {standard_task_runner.py:57} INFO - Started process 18495 to run task
[2023-11-30T12:40:58.081+0200] {standard_task_runner.py:84} INFO - Running: ['airflow', 'tasks', 'run', 'weather_data_pipeline', 'check_api_Kharkiv', 'scheduled__2023-11-30T00:00:00+00:00', '--job-id', '10', '--raw', '--subdir', 'DAGS_FOLDER/weather_pipeline.py', '--cfg-path', '/tmp/tmp_aaa1l5a']
[2023-11-30T12:40:58.083+0200] {standard_task_runner.py:85} INFO - Job 10: Subtask check_api_Kharkiv
[2023-11-30T12:40:58.141+0200] {task_command.py:416} INFO - Running <TaskInstance: weather_data_pipeline.check_api_Kharkiv scheduled__2023-11-30T00:00:00+00:00 [running]> on host DESKTOP-VD1PANR.
[2023-11-30T12:40:58.331+0200] {taskinstance.py:1662} INFO - Exporting env vars: AIRFLOW_CTX_DAG_OWNER='airflow' AIRFLOW_CTX_DAG_ID='weather_data_pipeline' AIRFLOW_CTX_TASK_ID='check_api_Kharkiv' AIRFLOW_CTX_EXECUTION_DATE='2023-11-30T00:00:00+00:00' AIRFLOW_CTX_TRY_NUMBER='1' AIRFLOW_CTX_DAG_RUN_ID='scheduled__2023-11-30T00:00:00+00:00'
[2023-11-30T12:40:58.332+0200] {http.py:130} INFO - Poking: data/3.0/onecall
[2023-11-30T12:40:58.343+0200] {taskinstance.py:1937} ERROR - Task failed with exception
Traceback (most recent call last):
  File "/home/seva/.local/lib/python3.10/site-packages/airflow/sensors/base.py", line 257, in execute
    raise e
  File "/home/seva/.local/lib/python3.10/site-packages/airflow/sensors/base.py", line 239, in execute
    poke_return = self.poke(context)
  File "/home/seva/.local/lib/python3.10/site-packages/airflow/providers/http/sensors/http.py", line 148, in poke
    raise exc
  File "/home/seva/.local/lib/python3.10/site-packages/airflow/providers/http/sensors/http.py", line 132, in poke
    response = hook.run(
  File "/home/seva/.local/lib/python3.10/site-packages/airflow/providers/http/hooks/http.py", line 145, in run
    session = self.get_conn(headers)
  File "/home/seva/.local/lib/python3.10/site-packages/airflow/providers/http/hooks/http.py", line 98, in get_conn
    conn = self.get_connection(self.http_conn_id)
  File "/home/seva/.local/lib/python3.10/site-packages/airflow/hooks/base.py", line 72, in get_connection
    conn = Connection.get_connection_from_secrets(conn_id)
  File "/home/seva/.local/lib/python3.10/site-packages/airflow/models/connection.py", line 477, in get_connection_from_secrets
    raise AirflowNotFoundException(f"The conn_id `{conn_id}` isn't defined")
airflow.exceptions.AirflowNotFoundException: The conn_id `openweathermap_conn` isn't defined
[2023-11-30T12:40:58.349+0200] {taskinstance.py:1400} INFO - Marking task as FAILED. dag_id=weather_data_pipeline, task_id=check_api_Kharkiv, execution_date=20231130T000000, start_date=20231130T104058, end_date=20231130T104058
[2023-11-30T12:40:58.372+0200] {standard_task_runner.py:104} ERROR - Failed to execute job 10 for task check_api_Kharkiv (The conn_id `openweathermap_conn` isn't defined; 18495)
[2023-11-30T12:40:58.383+0200] {local_task_job_runner.py:228} INFO - Task exited with return code 1
[2023-11-30T12:40:58.475+0200] {taskinstance.py:2778} INFO - 0 downstream tasks scheduled from follow-on schedule check
[2023-11-30T12:54:34.923+0200] {taskinstance.py:1159} INFO - Dependencies all met for dep_context=non-requeueable deps ti=<TaskInstance: weather_data_pipeline.check_api_Kharkiv scheduled__2023-11-30T00:00:00+00:00 [queued]>
[2023-11-30T12:54:34.930+0200] {taskinstance.py:1159} INFO - Dependencies all met for dep_context=requeueable deps ti=<TaskInstance: weather_data_pipeline.check_api_Kharkiv scheduled__2023-11-30T00:00:00+00:00 [queued]>
[2023-11-30T12:54:34.931+0200] {taskinstance.py:1361} INFO - Starting attempt 1 of 1
[2023-11-30T12:54:34.959+0200] {taskinstance.py:1382} INFO - Executing <Task(HttpSensor): check_api_Kharkiv> on 2023-11-30 00:00:00+00:00
[2023-11-30T12:54:34.963+0200] {standard_task_runner.py:57} INFO - Started process 20108 to run task
[2023-11-30T12:54:34.967+0200] {standard_task_runner.py:84} INFO - Running: ['airflow', 'tasks', 'run', 'weather_data_pipeline', 'check_api_Kharkiv', 'scheduled__2023-11-30T00:00:00+00:00', '--job-id', '52', '--raw', '--subdir', 'DAGS_FOLDER/weather_pipeline.py', '--cfg-path', '/tmp/tmp7zk47e_4']
[2023-11-30T12:54:34.968+0200] {standard_task_runner.py:85} INFO - Job 52: Subtask check_api_Kharkiv
[2023-11-30T12:54:35.018+0200] {task_command.py:416} INFO - Running <TaskInstance: weather_data_pipeline.check_api_Kharkiv scheduled__2023-11-30T00:00:00+00:00 [running]> on host DESKTOP-VD1PANR.
[2023-11-30T12:54:35.164+0200] {taskinstance.py:1662} INFO - Exporting env vars: AIRFLOW_CTX_DAG_OWNER='airflow' AIRFLOW_CTX_DAG_ID='weather_data_pipeline' AIRFLOW_CTX_TASK_ID='check_api_Kharkiv' AIRFLOW_CTX_EXECUTION_DATE='2023-11-30T00:00:00+00:00' AIRFLOW_CTX_TRY_NUMBER='1' AIRFLOW_CTX_DAG_RUN_ID='scheduled__2023-11-30T00:00:00+00:00'
[2023-11-30T12:54:35.165+0200] {http.py:130} INFO - Poking: data/3.0/onecall
[2023-11-30T12:54:35.168+0200] {base.py:73} INFO - Using connection ID 'openweathermap_conn' for task execution.
[2023-11-30T12:54:35.261+0200] {http.py:178} ERROR - HTTP error: Unauthorized
[2023-11-30T12:54:35.261+0200] {http.py:179} ERROR - {"cod":401, "message": "Please note that using One Call 3.0 requires a separate subscription to the One Call by Call plan. Learn more here https://openweathermap.org/price. If you have a valid subscription to the One Call by Call plan, but still receive this error, then please see https://openweathermap.org/faq#error401 for more info."}
[2023-11-30T12:54:35.269+0200] {taskinstance.py:1937} ERROR - Task failed with exception
Traceback (most recent call last):
  File "/home/seva/.local/lib/python3.10/site-packages/airflow/providers/http/hooks/http.py", line 176, in check_response
    response.raise_for_status()
  File "/home/seva/.local/lib/python3.10/site-packages/requests/models.py", line 1021, in raise_for_status
    raise HTTPError(http_error_msg, response=self)
requests.exceptions.HTTPError: 401 Client Error: Unauthorized for url: http://api.openweathermap.org/data/3.0/onecall?appid=***&q=Kharkiv

During handling of the above exception, another exception occurred:

Traceback (most recent call last):
  File "/home/seva/.local/lib/python3.10/site-packages/airflow/sensors/base.py", line 257, in execute
    raise e
  File "/home/seva/.local/lib/python3.10/site-packages/airflow/sensors/base.py", line 239, in execute
    poke_return = self.poke(context)
  File "/home/seva/.local/lib/python3.10/site-packages/airflow/providers/http/sensors/http.py", line 148, in poke
    raise exc
  File "/home/seva/.local/lib/python3.10/site-packages/airflow/providers/http/sensors/http.py", line 132, in poke
    response = hook.run(
  File "/home/seva/.local/lib/python3.10/site-packages/airflow/providers/http/hooks/http.py", line 166, in run
    return self.run_and_check(session, prepped_request, extra_options)
  File "/home/seva/.local/lib/python3.10/site-packages/airflow/providers/http/hooks/http.py", line 217, in run_and_check
    self.check_response(response)
  File "/home/seva/.local/lib/python3.10/site-packages/airflow/providers/http/hooks/http.py", line 180, in check_response
    raise AirflowException(str(response.status_code) + ":" + response.reason)
airflow.exceptions.AirflowException: 401:Unauthorized
[2023-11-30T12:54:35.271+0200] {taskinstance.py:1400} INFO - Marking task as FAILED. dag_id=weather_data_pipeline, task_id=check_api_Kharkiv, execution_date=20231130T000000, start_date=20231130T105434, end_date=20231130T105435
[2023-11-30T12:54:35.301+0200] {standard_task_runner.py:104} ERROR - Failed to execute job 52 for task check_api_Kharkiv (401:Unauthorized; 20108)
[2023-11-30T12:54:35.315+0200] {local_task_job_runner.py:228} INFO - Task exited with return code 1
[2023-11-30T12:54:35.386+0200] {taskinstance.py:2778} INFO - 0 downstream tasks scheduled from follow-on schedule check
[2023-11-30T12:55:53.517+0200] {taskinstance.py:1159} INFO - Dependencies all met for dep_context=non-requeueable deps ti=<TaskInstance: weather_data_pipeline.check_api_Kharkiv scheduled__2023-11-30T00:00:00+00:00 [queued]>
[2023-11-30T12:55:53.542+0200] {taskinstance.py:1159} INFO - Dependencies all met for dep_context=requeueable deps ti=<TaskInstance: weather_data_pipeline.check_api_Kharkiv scheduled__2023-11-30T00:00:00+00:00 [queued]>
[2023-11-30T12:55:53.545+0200] {taskinstance.py:1361} INFO - Starting attempt 1 of 1
[2023-11-30T12:55:53.583+0200] {taskinstance.py:1382} INFO - Executing <Task(HttpSensor): check_api_Kharkiv> on 2023-11-30 00:00:00+00:00
[2023-11-30T12:55:53.586+0200] {standard_task_runner.py:57} INFO - Started process 20318 to run task
[2023-11-30T12:55:53.590+0200] {standard_task_runner.py:84} INFO - Running: ['airflow', 'tasks', 'run', 'weather_data_pipeline', 'check_api_Kharkiv', 'scheduled__2023-11-30T00:00:00+00:00', '--job-id', '77', '--raw', '--subdir', 'DAGS_FOLDER/weather_pipeline.py', '--cfg-path', '/tmp/tmpl2kvi7ba']
[2023-11-30T12:55:53.594+0200] {standard_task_runner.py:85} INFO - Job 77: Subtask check_api_Kharkiv
[2023-11-30T12:55:53.727+0200] {task_command.py:416} INFO - Running <TaskInstance: weather_data_pipeline.check_api_Kharkiv scheduled__2023-11-30T00:00:00+00:00 [running]> on host DESKTOP-VD1PANR.
[2023-11-30T12:55:53.955+0200] {taskinstance.py:1662} INFO - Exporting env vars: AIRFLOW_CTX_DAG_OWNER='airflow' AIRFLOW_CTX_DAG_ID='weather_data_pipeline' AIRFLOW_CTX_TASK_ID='check_api_Kharkiv' AIRFLOW_CTX_EXECUTION_DATE='2023-11-30T00:00:00+00:00' AIRFLOW_CTX_TRY_NUMBER='1' AIRFLOW_CTX_DAG_RUN_ID='scheduled__2023-11-30T00:00:00+00:00'
[2023-11-30T12:55:53.958+0200] {http.py:130} INFO - Poking: data/3.0/onecall
[2023-11-30T12:55:53.978+0200] {base.py:73} INFO - Using connection ID 'openweathermap_conn' for task execution.
[2023-11-30T12:55:54.074+0200] {http.py:178} ERROR - HTTP error: Unauthorized
[2023-11-30T12:55:54.074+0200] {http.py:179} ERROR - {"cod":401, "message": "Please note that using One Call 3.0 requires a separate subscription to the One Call by Call plan. Learn more here https://openweathermap.org/price. If you have a valid subscription to the One Call by Call plan, but still receive this error, then please see https://openweathermap.org/faq#error401 for more info."}
[2023-11-30T12:55:54.080+0200] {taskinstance.py:1937} ERROR - Task failed with exception
Traceback (most recent call last):
  File "/home/seva/.local/lib/python3.10/site-packages/airflow/providers/http/hooks/http.py", line 176, in check_response
    response.raise_for_status()
  File "/home/seva/.local/lib/python3.10/site-packages/requests/models.py", line 1021, in raise_for_status
    raise HTTPError(http_error_msg, response=self)
requests.exceptions.HTTPError: 401 Client Error: Unauthorized for url: http://api.openweathermap.org/data/3.0/onecall?appid=***&q=Kharkiv

During handling of the above exception, another exception occurred:

Traceback (most recent call last):
  File "/home/seva/.local/lib/python3.10/site-packages/airflow/sensors/base.py", line 257, in execute
    raise e
  File "/home/seva/.local/lib/python3.10/site-packages/airflow/sensors/base.py", line 239, in execute
    poke_return = self.poke(context)
  File "/home/seva/.local/lib/python3.10/site-packages/airflow/providers/http/sensors/http.py", line 148, in poke
    raise exc
  File "/home/seva/.local/lib/python3.10/site-packages/airflow/providers/http/sensors/http.py", line 132, in poke
    response = hook.run(
  File "/home/seva/.local/lib/python3.10/site-packages/airflow/providers/http/hooks/http.py", line 166, in run
    return self.run_and_check(session, prepped_request, extra_options)
  File "/home/seva/.local/lib/python3.10/site-packages/airflow/providers/http/hooks/http.py", line 217, in run_and_check
    self.check_response(response)
  File "/home/seva/.local/lib/python3.10/site-packages/airflow/providers/http/hooks/http.py", line 180, in check_response
    raise AirflowException(str(response.status_code) + ":" + response.reason)
airflow.exceptions.AirflowException: 401:Unauthorized
[2023-11-30T12:55:54.095+0200] {taskinstance.py:1400} INFO - Marking task as FAILED. dag_id=weather_data_pipeline, task_id=check_api_Kharkiv, execution_date=20231130T000000, start_date=20231130T105553, end_date=20231130T105554
[2023-11-30T12:55:54.115+0200] {standard_task_runner.py:104} ERROR - Failed to execute job 77 for task check_api_Kharkiv (401:Unauthorized; 20318)
[2023-11-30T12:55:54.128+0200] {local_task_job_runner.py:228} INFO - Task exited with return code 1
[2023-11-30T12:55:54.226+0200] {taskinstance.py:2778} INFO - 0 downstream tasks scheduled from follow-on schedule check
[2023-11-30T13:02:55.013+0200] {taskinstance.py:1159} INFO - Dependencies all met for dep_context=non-requeueable deps ti=<TaskInstance: weather_data_pipeline.check_api_Kharkiv scheduled__2023-11-30T00:00:00+00:00 [queued]>
[2023-11-30T13:02:55.019+0200] {taskinstance.py:1159} INFO - Dependencies all met for dep_context=requeueable deps ti=<TaskInstance: weather_data_pipeline.check_api_Kharkiv scheduled__2023-11-30T00:00:00+00:00 [queued]>
[2023-11-30T13:02:55.020+0200] {taskinstance.py:1361} INFO - Starting attempt 1 of 1
[2023-11-30T13:02:55.044+0200] {taskinstance.py:1382} INFO - Executing <Task(HttpSensor): check_api_Kharkiv> on 2023-11-30 00:00:00+00:00
[2023-11-30T13:02:55.046+0200] {standard_task_runner.py:57} INFO - Started process 21226 to run task
[2023-11-30T13:02:55.051+0200] {standard_task_runner.py:84} INFO - Running: ['airflow', 'tasks', 'run', 'weather_data_pipeline', 'check_api_Kharkiv', 'scheduled__2023-11-30T00:00:00+00:00', '--job-id', '148', '--raw', '--subdir', 'DAGS_FOLDER/weather_pipeline.py', '--cfg-path', '/tmp/tmpjv1lz33c']
[2023-11-30T13:02:55.053+0200] {standard_task_runner.py:85} INFO - Job 148: Subtask check_api_Kharkiv
[2023-11-30T13:02:55.092+0200] {task_command.py:416} INFO - Running <TaskInstance: weather_data_pipeline.check_api_Kharkiv scheduled__2023-11-30T00:00:00+00:00 [running]> on host DESKTOP-VD1PANR.
[2023-11-30T13:02:55.234+0200] {taskinstance.py:1662} INFO - Exporting env vars: AIRFLOW_CTX_DAG_OWNER='airflow' AIRFLOW_CTX_DAG_ID='weather_data_pipeline' AIRFLOW_CTX_TASK_ID='check_api_Kharkiv' AIRFLOW_CTX_EXECUTION_DATE='2023-11-30T00:00:00+00:00' AIRFLOW_CTX_TRY_NUMBER='1' AIRFLOW_CTX_DAG_RUN_ID='scheduled__2023-11-30T00:00:00+00:00'
[2023-11-30T13:02:55.235+0200] {http.py:130} INFO - Poking: data/3.0/onecall
[2023-11-30T13:02:55.244+0200] {base.py:73} INFO - Using connection ID 'openweathermap_conn' for task execution.
[2023-11-30T13:02:55.318+0200] {http.py:178} ERROR - HTTP error: Unauthorized
[2023-11-30T13:02:55.319+0200] {http.py:179} ERROR - {"cod":401, "message": "Please note that using One Call 3.0 requires a separate subscription to the One Call by Call plan. Learn more here https://openweathermap.org/price. If you have a valid subscription to the One Call by Call plan, but still receive this error, then please see https://openweathermap.org/faq#error401 for more info."}
[2023-11-30T13:02:55.324+0200] {taskinstance.py:1937} ERROR - Task failed with exception
Traceback (most recent call last):
  File "/home/seva/.local/lib/python3.10/site-packages/airflow/providers/http/hooks/http.py", line 176, in check_response
    response.raise_for_status()
  File "/home/seva/.local/lib/python3.10/site-packages/requests/models.py", line 1021, in raise_for_status
    raise HTTPError(http_error_msg, response=self)
requests.exceptions.HTTPError: 401 Client Error: Unauthorized for url: http://api.openweathermap.org/data/3.0/onecall?appid=***&q=Kharkiv

During handling of the above exception, another exception occurred:

Traceback (most recent call last):
  File "/home/seva/.local/lib/python3.10/site-packages/airflow/sensors/base.py", line 257, in execute
    raise e
  File "/home/seva/.local/lib/python3.10/site-packages/airflow/sensors/base.py", line 239, in execute
    poke_return = self.poke(context)
  File "/home/seva/.local/lib/python3.10/site-packages/airflow/providers/http/sensors/http.py", line 148, in poke
    raise exc
  File "/home/seva/.local/lib/python3.10/site-packages/airflow/providers/http/sensors/http.py", line 132, in poke
    response = hook.run(
  File "/home/seva/.local/lib/python3.10/site-packages/airflow/providers/http/hooks/http.py", line 166, in run
    return self.run_and_check(session, prepped_request, extra_options)
  File "/home/seva/.local/lib/python3.10/site-packages/airflow/providers/http/hooks/http.py", line 217, in run_and_check
    self.check_response(response)
  File "/home/seva/.local/lib/python3.10/site-packages/airflow/providers/http/hooks/http.py", line 180, in check_response
    raise AirflowException(str(response.status_code) + ":" + response.reason)
airflow.exceptions.AirflowException: 401:Unauthorized
[2023-11-30T13:02:55.328+0200] {taskinstance.py:1400} INFO - Marking task as FAILED. dag_id=weather_data_pipeline, task_id=check_api_Kharkiv, execution_date=20231130T000000, start_date=20231130T110255, end_date=20231130T110255
[2023-11-30T13:02:55.368+0200] {standard_task_runner.py:104} ERROR - Failed to execute job 148 for task check_api_Kharkiv (401:Unauthorized; 21226)
[2023-11-30T13:02:55.406+0200] {local_task_job_runner.py:228} INFO - Task exited with return code 1
[2023-11-30T13:02:55.505+0200] {taskinstance.py:2778} INFO - 0 downstream tasks scheduled from follow-on schedule check
[2023-11-30T13:14:26.060+0200] {taskinstance.py:1159} INFO - Dependencies all met for dep_context=non-requeueable deps ti=<TaskInstance: weather_data_pipeline.check_api_Kharkiv scheduled__2023-11-30T00:00:00+00:00 [queued]>
[2023-11-30T13:14:26.068+0200] {taskinstance.py:1159} INFO - Dependencies all met for dep_context=requeueable deps ti=<TaskInstance: weather_data_pipeline.check_api_Kharkiv scheduled__2023-11-30T00:00:00+00:00 [queued]>
[2023-11-30T13:14:26.068+0200] {taskinstance.py:1361} INFO - Starting attempt 1 of 1
[2023-11-30T13:14:26.091+0200] {taskinstance.py:1382} INFO - Executing <Task(HttpSensor): check_api_Kharkiv> on 2023-11-30 00:00:00+00:00
[2023-11-30T13:14:26.094+0200] {standard_task_runner.py:57} INFO - Started process 22507 to run task
[2023-11-30T13:14:26.102+0200] {standard_task_runner.py:84} INFO - Running: ['airflow', 'tasks', 'run', 'weather_data_pipeline', 'check_api_Kharkiv', 'scheduled__2023-11-30T00:00:00+00:00', '--job-id', '168', '--raw', '--subdir', 'DAGS_FOLDER/weather_pipeline.py', '--cfg-path', '/tmp/tmpa0kt0bh7']
[2023-11-30T13:14:26.108+0200] {standard_task_runner.py:85} INFO - Job 168: Subtask check_api_Kharkiv
[2023-11-30T13:14:26.161+0200] {task_command.py:416} INFO - Running <TaskInstance: weather_data_pipeline.check_api_Kharkiv scheduled__2023-11-30T00:00:00+00:00 [running]> on host DESKTOP-VD1PANR.
[2023-11-30T13:14:26.409+0200] {taskinstance.py:1662} INFO - Exporting env vars: AIRFLOW_CTX_DAG_OWNER='airflow' AIRFLOW_CTX_DAG_ID='weather_data_pipeline' AIRFLOW_CTX_TASK_ID='check_api_Kharkiv' AIRFLOW_CTX_EXECUTION_DATE='2023-11-30T00:00:00+00:00' AIRFLOW_CTX_TRY_NUMBER='1' AIRFLOW_CTX_DAG_RUN_ID='scheduled__2023-11-30T00:00:00+00:00'
[2023-11-30T13:14:26.410+0200] {http.py:130} INFO - Poking: data/3.0/onecall
[2023-11-30T13:14:26.427+0200] {base.py:73} INFO - Using connection ID 'openweathermap_conn' for task execution.
[2023-11-30T13:14:26.516+0200] {http.py:178} ERROR - HTTP error: Unauthorized
[2023-11-30T13:14:26.517+0200] {http.py:179} ERROR - {"cod":401, "message": "Please note that using One Call 3.0 requires a separate subscription to the One Call by Call plan. Learn more here https://openweathermap.org/price. If you have a valid subscription to the One Call by Call plan, but still receive this error, then please see https://openweathermap.org/faq#error401 for more info."}
[2023-11-30T13:14:26.532+0200] {taskinstance.py:1937} ERROR - Task failed with exception
Traceback (most recent call last):
  File "/home/seva/.local/lib/python3.10/site-packages/airflow/providers/http/hooks/http.py", line 176, in check_response
    response.raise_for_status()
  File "/home/seva/.local/lib/python3.10/site-packages/requests/models.py", line 1021, in raise_for_status
    raise HTTPError(http_error_msg, response=self)
requests.exceptions.HTTPError: 401 Client Error: Unauthorized for url: http://api.openweathermap.org/data/3.0/onecall?appid=***&q=Kharkiv

During handling of the above exception, another exception occurred:

Traceback (most recent call last):
  File "/home/seva/.local/lib/python3.10/site-packages/airflow/sensors/base.py", line 257, in execute
    raise e
  File "/home/seva/.local/lib/python3.10/site-packages/airflow/sensors/base.py", line 239, in execute
    poke_return = self.poke(context)
  File "/home/seva/.local/lib/python3.10/site-packages/airflow/providers/http/sensors/http.py", line 148, in poke
    raise exc
  File "/home/seva/.local/lib/python3.10/site-packages/airflow/providers/http/sensors/http.py", line 132, in poke
    response = hook.run(
  File "/home/seva/.local/lib/python3.10/site-packages/airflow/providers/http/hooks/http.py", line 166, in run
    return self.run_and_check(session, prepped_request, extra_options)
  File "/home/seva/.local/lib/python3.10/site-packages/airflow/providers/http/hooks/http.py", line 217, in run_and_check
    self.check_response(response)
  File "/home/seva/.local/lib/python3.10/site-packages/airflow/providers/http/hooks/http.py", line 180, in check_response
    raise AirflowException(str(response.status_code) + ":" + response.reason)
airflow.exceptions.AirflowException: 401:Unauthorized
[2023-11-30T13:14:26.545+0200] {taskinstance.py:1400} INFO - Marking task as FAILED. dag_id=weather_data_pipeline, task_id=check_api_Kharkiv, execution_date=20231130T000000, start_date=20231130T111426, end_date=20231130T111426
[2023-11-30T13:14:26.586+0200] {standard_task_runner.py:104} ERROR - Failed to execute job 168 for task check_api_Kharkiv (401:Unauthorized; 22507)
[2023-11-30T13:14:26.602+0200] {local_task_job_runner.py:228} INFO - Task exited with return code 1
[2023-11-30T13:14:26.786+0200] {taskinstance.py:2778} INFO - 0 downstream tasks scheduled from follow-on schedule check
[2023-11-30T13:24:26.040+0200] {taskinstance.py:1159} INFO - Dependencies all met for dep_context=non-requeueable deps ti=<TaskInstance: weather_data_pipeline.check_api_Kharkiv scheduled__2023-11-30T00:00:00+00:00 [queued]>
[2023-11-30T13:24:26.051+0200] {taskinstance.py:1159} INFO - Dependencies all met for dep_context=requeueable deps ti=<TaskInstance: weather_data_pipeline.check_api_Kharkiv scheduled__2023-11-30T00:00:00+00:00 [queued]>
[2023-11-30T13:24:26.052+0200] {taskinstance.py:1361} INFO - Starting attempt 1 of 1
[2023-11-30T13:24:26.071+0200] {taskinstance.py:1382} INFO - Executing <Task(HttpSensor): check_api_Kharkiv> on 2023-11-30 00:00:00+00:00
[2023-11-30T13:24:26.074+0200] {standard_task_runner.py:57} INFO - Started process 23747 to run task
[2023-11-30T13:24:26.077+0200] {standard_task_runner.py:84} INFO - Running: ['airflow', 'tasks', 'run', 'weather_data_pipeline', 'check_api_Kharkiv', 'scheduled__2023-11-30T00:00:00+00:00', '--job-id', '245', '--raw', '--subdir', 'DAGS_FOLDER/weather_pipeline.py', '--cfg-path', '/tmp/tmpezrxx0io']
[2023-11-30T13:24:26.079+0200] {standard_task_runner.py:85} INFO - Job 245: Subtask check_api_Kharkiv
[2023-11-30T13:24:26.121+0200] {task_command.py:416} INFO - Running <TaskInstance: weather_data_pipeline.check_api_Kharkiv scheduled__2023-11-30T00:00:00+00:00 [running]> on host DESKTOP-VD1PANR.
[2023-11-30T13:24:26.245+0200] {taskinstance.py:1662} INFO - Exporting env vars: AIRFLOW_CTX_DAG_OWNER='airflow' AIRFLOW_CTX_DAG_ID='weather_data_pipeline' AIRFLOW_CTX_TASK_ID='check_api_Kharkiv' AIRFLOW_CTX_EXECUTION_DATE='2023-11-30T00:00:00+00:00' AIRFLOW_CTX_TRY_NUMBER='1' AIRFLOW_CTX_DAG_RUN_ID='scheduled__2023-11-30T00:00:00+00:00'
[2023-11-30T13:24:26.246+0200] {http.py:130} INFO - Poking: data/3.0/onecall
[2023-11-30T13:24:26.250+0200] {base.py:73} INFO - Using connection ID 'openweathermap_conn' for task execution.
[2023-11-30T13:24:26.342+0200] {http.py:178} ERROR - HTTP error: Unauthorized
[2023-11-30T13:24:26.342+0200] {http.py:179} ERROR - {"cod":401, "message": "Please note that using One Call 3.0 requires a separate subscription to the One Call by Call plan. Learn more here https://openweathermap.org/price. If you have a valid subscription to the One Call by Call plan, but still receive this error, then please see https://openweathermap.org/faq#error401 for more info."}
[2023-11-30T13:24:26.349+0200] {taskinstance.py:1937} ERROR - Task failed with exception
Traceback (most recent call last):
  File "/home/seva/.local/lib/python3.10/site-packages/airflow/providers/http/hooks/http.py", line 176, in check_response
    response.raise_for_status()
  File "/home/seva/.local/lib/python3.10/site-packages/requests/models.py", line 1021, in raise_for_status
    raise HTTPError(http_error_msg, response=self)
requests.exceptions.HTTPError: 401 Client Error: Unauthorized for url: http://api.openweathermap.org/data/3.0/onecall?appid=***&q=Kharkiv

During handling of the above exception, another exception occurred:

Traceback (most recent call last):
  File "/home/seva/.local/lib/python3.10/site-packages/airflow/sensors/base.py", line 257, in execute
    raise e
  File "/home/seva/.local/lib/python3.10/site-packages/airflow/sensors/base.py", line 239, in execute
    poke_return = self.poke(context)
  File "/home/seva/.local/lib/python3.10/site-packages/airflow/providers/http/sensors/http.py", line 148, in poke
    raise exc
  File "/home/seva/.local/lib/python3.10/site-packages/airflow/providers/http/sensors/http.py", line 132, in poke
    response = hook.run(
  File "/home/seva/.local/lib/python3.10/site-packages/airflow/providers/http/hooks/http.py", line 166, in run
    return self.run_and_check(session, prepped_request, extra_options)
  File "/home/seva/.local/lib/python3.10/site-packages/airflow/providers/http/hooks/http.py", line 217, in run_and_check
    self.check_response(response)
  File "/home/seva/.local/lib/python3.10/site-packages/airflow/providers/http/hooks/http.py", line 180, in check_response
    raise AirflowException(str(response.status_code) + ":" + response.reason)
airflow.exceptions.AirflowException: 401:Unauthorized
[2023-11-30T13:24:26.352+0200] {taskinstance.py:1400} INFO - Marking task as FAILED. dag_id=weather_data_pipeline, task_id=check_api_Kharkiv, execution_date=20231130T000000, start_date=20231130T112426, end_date=20231130T112426
[2023-11-30T13:24:26.372+0200] {standard_task_runner.py:104} ERROR - Failed to execute job 245 for task check_api_Kharkiv (401:Unauthorized; 23747)
[2023-11-30T13:24:26.382+0200] {local_task_job_runner.py:228} INFO - Task exited with return code 1
[2023-11-30T13:24:26.460+0200] {taskinstance.py:2778} INFO - 0 downstream tasks scheduled from follow-on schedule check
