[2023-11-30T12:56:05.227+0200] {taskinstance.py:1159} INFO - Dependencies all met for dep_context=non-requeueable deps ti=<TaskInstance: weather_data_pipeline.check_api_Kharkiv manual__2023-11-30T10:55:40.484884+00:00 [queued]>
[2023-11-30T12:56:05.233+0200] {taskinstance.py:1159} INFO - Dependencies all met for dep_context=requeueable deps ti=<TaskInstance: weather_data_pipeline.check_api_Kharkiv manual__2023-11-30T10:55:40.484884+00:00 [queued]>
[2023-11-30T12:56:05.234+0200] {taskinstance.py:1361} INFO - Starting attempt 1 of 1
[2023-11-30T12:56:05.258+0200] {taskinstance.py:1382} INFO - Executing <Task(HttpSensor): check_api_Kharkiv> on 2023-11-30 10:55:40.484884+00:00
[2023-11-30T12:56:05.261+0200] {standard_task_runner.py:57} INFO - Started process 20355 to run task
[2023-11-30T12:56:05.265+0200] {standard_task_runner.py:84} INFO - Running: ['airflow', 'tasks', 'run', 'weather_data_pipeline', 'check_api_Kharkiv', 'manual__2023-11-30T10:55:40.484884+00:00', '--job-id', '82', '--raw', '--subdir', 'DAGS_FOLDER/weather_pipeline.py', '--cfg-path', '/tmp/tmpjs5s4dig']
[2023-11-30T12:56:05.267+0200] {standard_task_runner.py:85} INFO - Job 82: Subtask check_api_Kharkiv
[2023-11-30T12:56:05.324+0200] {task_command.py:416} INFO - Running <TaskInstance: weather_data_pipeline.check_api_Kharkiv manual__2023-11-30T10:55:40.484884+00:00 [running]> on host DESKTOP-VD1PANR.
[2023-11-30T12:56:05.500+0200] {taskinstance.py:1662} INFO - Exporting env vars: AIRFLOW_CTX_DAG_OWNER='airflow' AIRFLOW_CTX_DAG_ID='weather_data_pipeline' AIRFLOW_CTX_TASK_ID='check_api_Kharkiv' AIRFLOW_CTX_EXECUTION_DATE='2023-11-30T10:55:40.484884+00:00' AIRFLOW_CTX_TRY_NUMBER='1' AIRFLOW_CTX_DAG_RUN_ID='manual__2023-11-30T10:55:40.484884+00:00'
[2023-11-30T12:56:05.501+0200] {http.py:130} INFO - Poking: data/3.0/onecall
[2023-11-30T12:56:05.506+0200] {base.py:73} INFO - Using connection ID 'openweathermap_conn' for task execution.
[2023-11-30T12:56:05.603+0200] {http.py:178} ERROR - HTTP error: Unauthorized
[2023-11-30T12:56:05.604+0200] {http.py:179} ERROR - {"cod":401, "message": "Please note that using One Call 3.0 requires a separate subscription to the One Call by Call plan. Learn more here https://openweathermap.org/price. If you have a valid subscription to the One Call by Call plan, but still receive this error, then please see https://openweathermap.org/faq#error401 for more info."}
[2023-11-30T12:56:05.609+0200] {taskinstance.py:1937} ERROR - Task failed with exception
Traceback (most recent call last):
  File "/home/seva/.local/lib/python3.10/site-packages/airflow/providers/http/hooks/http.py", line 176, in check_response
    response.raise_for_status()
  File "/home/seva/.local/lib/python3.10/site-packages/requests/models.py", line 1021, in raise_for_status
    raise HTTPError(http_error_msg, response=self)
requests.exceptions.HTTPError: 401 Client Error: Unauthorized for url: http://api.openweathermap.org/data/3.0/onecall?appid=***&q=Kharkiv

During handling of the above exception, another exception occurred:

Traceback (most recent call last):
  File "/home/seva/.local/lib/python3.10/site-packages/airflow/sensors/base.py", line 257, in execute
    raise e
  File "/home/seva/.local/lib/python3.10/site-packages/airflow/sensors/base.py", line 239, in execute
    poke_return = self.poke(context)
  File "/home/seva/.local/lib/python3.10/site-packages/airflow/providers/http/sensors/http.py", line 148, in poke
    raise exc
  File "/home/seva/.local/lib/python3.10/site-packages/airflow/providers/http/sensors/http.py", line 132, in poke
    response = hook.run(
  File "/home/seva/.local/lib/python3.10/site-packages/airflow/providers/http/hooks/http.py", line 166, in run
    return self.run_and_check(session, prepped_request, extra_options)
  File "/home/seva/.local/lib/python3.10/site-packages/airflow/providers/http/hooks/http.py", line 217, in run_and_check
    self.check_response(response)
  File "/home/seva/.local/lib/python3.10/site-packages/airflow/providers/http/hooks/http.py", line 180, in check_response
    raise AirflowException(str(response.status_code) + ":" + response.reason)
airflow.exceptions.AirflowException: 401:Unauthorized
[2023-11-30T12:56:05.612+0200] {taskinstance.py:1400} INFO - Marking task as FAILED. dag_id=weather_data_pipeline, task_id=check_api_Kharkiv, execution_date=20231130T105540, start_date=20231130T105605, end_date=20231130T105605
[2023-11-30T12:56:05.635+0200] {standard_task_runner.py:104} ERROR - Failed to execute job 82 for task check_api_Kharkiv (401:Unauthorized; 20355)
[2023-11-30T12:56:05.669+0200] {local_task_job_runner.py:228} INFO - Task exited with return code 1
[2023-11-30T12:56:05.760+0200] {taskinstance.py:2778} INFO - 0 downstream tasks scheduled from follow-on schedule check
